Workbook
Name Autor_Jesus_Tassarolo: "Modelo financiero de embudos · creado por Jesús Tassarolo · TooAudience · youtube.com/@JesusTassaroloSinFiltro"

Sheet Inicio
B1: © Jesús Tassarolo · TooAudience · youtube.com/@JesusTassaroloSinFiltro · uso personal; no redistribuir modificado
B2: Modelo financiero · Embudo low-ticket con bumps y upsells
B3: Anuncios → página de ventas (VSL) → checkout → producto principal + bumps + OTOs + ascenso
B5: Para qué sirve este modelo
B6: Es el modelo financiero de un embudo de venta directa: anuncios que llevan a una página de ventas con video (VSL), un producto principal de precio bajo y una escalera de bumps, OTOs y un programa de ascenso. Con tus números (o con el ejemplo cargado) te dice cuánto vale cada visita que comprás con publicidad, hasta cuánto podés pagar por visita y por cada etapa siguiente, cuánto invertir para una meta de ventas, cuánta caja necesitás y qué palanca mejora más la ganancia.
B7: La unidad que comprás es la visita a la página. El número que manda es la diferencia entre lo que deja cada comprador sumando toda la escalera (AOV neto) y lo que te cuesta conseguirlo (CPA).
B9: Cómo usarlo en 6 pasos
B10: 1. Andá a Supuestos y reemplazá el ejemplo por tus números. Si todavía no tenés datos, dejá el escenario en 1 (conservador) y usá Benchmarks como referencia.
B11: 2. Mirá Resumen: ganancia del mes, ROAS, el techo y el objetivo de costo por visita, y el semáforo. Después Embudo: todos los pasos en orden con cuántos pasan, qué porcentaje se pierde y cuánto cuesta cada paso.
B12: 3. Abrí Escenarios para ver qué pasa si cambia el precio, la conversión o el costo. Las celdas amarillas de cada tabla se pueden cambiar.
B13: 4. Abrí Sensibilidad para saber qué variable conviene trabajar primero.
B14: 5. Antes de invertir, mirá Proyección 12 meses: la caja necesaria es la plata que tenés que tener para no frenar la pauta mientras cobrás. Si da 0, el embudo se autofinancia.
... B46: Este modelo se comparte para que lo uses con tus números. Si lo compartís, dejá esta línea: es la forma de saber de dónde salió.

Sheet Resumen
B1: © Jesús Tassarolo · TooAudience · youtube.com/@JesusTassaroloSinFiltro · uso personal; no redistribuir modificado
B2: Resumen: lo que hay que mirar
B3: Todo sale de Modelo con los supuestos del escenario en uso. Cambiá Supuestos y esto se actualiza.
B5: Indicador | C5: Valor | D5: Qué significa
B6: Resultado del mes
B7: Ganancia del período | C7: ='Modelo'!$C$41 | D7: Cash neto menos costos y menos inversión. Lo que queda.
B8: ROAS sobre cash neto | C8: ='Modelo'!$C$43 | D8: Cada dólar invertido vuelve como esto, ya neto.
B9: ROAS sobre facturado | C9: ='Modelo'!$C$42 | D9: Sobre facturado. Se infla con cuotas y comisiones: no decidas con este.
B10: Ventas del producto principal | C10: ='Modelo'!$C$10 | D10: Ventas del producto principal por mes.
B11: Unit economics
B12: Facturado por comprador (AOV) | C12: ='Modelo'!$C$30 | D12: Facturado por comprador sumando toda la escalera.
B13: Costo por comprador (CPA) | C13: ='Modelo'!$C$12 | D13: Lo que te cuesta cada comprador.
B14: AOV neto − CPA (lo que queda por comprador) | C14: ='Modelo'!$C$54 | D14: Si es negativo, cada venta pierde plata.
B15: Valor neto por visita | C15: ='Modelo'!$C$47 | D15: Lo que vale una visita en cash neto.
B16: Las dos caras de cada número
B17: Costo por visita | C17: ='Modelo'!$C$7 | D17: Lo que pagás por cada visita.
B18: Ganancia por visita | C18: ='Modelo'!$C$60 | D18: Lo que te queda por cada visita después de todo. La métrica más valiosa del embudo.
B19: Costo por cliente (CPA) | C19: ='Modelo'!$C$12 | D19: Lo que pagás por cada comprador.
B20: Ganancia por cliente | C20: ='Modelo'!$C$62 | D20: Lo que te queda por cada comprador después de todo.
B21: Order value (AOV) | C21: ='Modelo'!$C$30 | D21: Facturado por comprador con toda la escalera.
B22: Order value neto (AOV neto) | C22: ='Modelo'!$C$53 | D22: Lo mismo después de comisiones, reembolsos y costos por unidad.
B23: Hasta cuánto pagar
B24: Techo de costo por visita (break-even) | C24: ='Modelo'!$C$48 | D24: Costo por visita donde no ganás ni perdés.
B25: Objetivo de costo por visita | C25: ='Modelo'!$C$49 | D25: A este costo o menos estás en verde.
B26: Techo de costo por comprador (CPA máximo) | C26: ='Modelo'!$C$51 | D26: CPA máximo si lo demás se mantiene.
B27: Semáforo del costo por visita actual | C27: ='Modelo'!$C$56 | D27: Tu costo por visita actual contra techo y objetivo.
B28: Cuánto invertir y cuánta caja
B29: Inversión necesaria para la meta de ventas (al costo actual) | C29: ='Modelo'!$C$57 | D29: Para llegar a la meta de ventas de Supuestos, al costo actual.
B30: Caja que hay que tener (peor momento de la proyección) | C30: ='Proyección 12 meses'!$C$18 | D30: Si da 0, el embudo se autofinancia: cada mes cobra más de lo que invierte.
B31: Saldo mínimo de caja con tu caja inicial | C31: ='Proyección 12 meses'!$C$19 | D31: Si es negativo, la caja inicial no alcanza.
B32: Ganancia acumulada en 12 meses | C32: ='Proyección 12 meses'!$C$20 | D32: Con la inversión creciendo según el supuesto.
B34: Recomendación según el semáforo | C34: =IF('Modelo'!$C$56="VERDE","Sostener o subir un escalón (+25 %) y medir 7 días",IF('Modelo'!$C$56="AMARILLO","No subir. Si el costo está bien, el ROAS no llega al objetivo: mirá Sensibilidad. Si no, revisar en orden: CPM, creativo, página",IF('Modelo'!$C$56="ROJO","Bajar un escalón (−25 %) y arreglar antes de volver a subir","")))
B36: Modelo financiero de embudos · creado por Jesús Tassarolo · TooAudience · youtube.com/@JesusTassaroloSinFiltro · v1.2 · octubre 2026

Sheet Embudo
B1: © Jesús Tassarolo · TooAudience · youtube.com/@JesusTassaroloSinFiltro · uso personal; no redistribuir modificado
B2: Embudo: todos los pasos, cuántos pasan y, por cada uno, qué pagás, qué te queda y hasta cuánto podrías pagar
B3: Cada fila es un paso del embudo en orden. '% que pasa' compara con el paso anterior (o con el que dice la nota). Tres números por paso: lo que pagás hoy por cada uno (inversión ÷ cantidad), lo que te queda por cada uno (ganancia ÷ cantidad) y lo máximo que podrías pagar (el techo: lo que cada uno genera en cash neto). Techo = costo + ganancia + fijos repartidos.
B5: Paso | C5: Cantidad | D5: % que pasa | E5: % acumulado | F5: Costo por paso (pagás hoy) | G5: Ganancia por paso (te queda) | H5: Techo por paso (máximo a pagar) | I5: Qué se paga acá / cómo se lee
B6: Visitas a la página de ventas (VSL) | C6: ='Modelo'!$C$8 | D6: — | E6: =IF('Modelo'!$C$8=0,0,'Modelo'!$C$8/'Modelo'!$C$8) | F6: =IF('Modelo'!$C$8=0,0,'Supuestos'!$C$8*1/'Modelo'!$C$8) | G6: =IF('Modelo'!$C$8=0,0,'Modelo'!$C$41*1/'Modelo'!$C$8) | H6: =IF('Modelo'!$C$8=0,0,'Modelo'!$C$47*'Modelo'!$C$8*1/'Modelo'!$C$8) | I6: La unidad que compra la pauta. Costo por visita.
B7: Abren el checkout | C7: ='Modelo'!$C$9 | D7: =IF('Modelo'!$C$8=0,0,'Modelo'!$C$9/'Modelo'!$C$8) | E7: =IF('Modelo'!$C$8=0,0,'Modelo'!$C$9/'Modelo'!$C$8) | F7: =IF('Modelo'!$C$9=0,0,'Supuestos'!$C$8*1/'Modelo'!$C$9) | G7: =IF('Modelo'!$C$9=0,0,'Modelo'!$C$41*1/'Modelo'!$C$9) | H7: =IF('Modelo'!$C$9=0,0,'Modelo'!$C$47*'Modelo'!$C$8*1/'Modelo'!$C$9) | I7: Costo por checkout. Si se pierde mucho acá, es la VSL.
B8: Compran el producto principal | C8: ='Modelo'!$C$10 | D8: =IF('Modelo'!$C$9=0,0,'Modelo'!$C$10/'Modelo'!$C$9) | E8: =IF('Modelo'!$C$8=0,0,'Modelo'!$C$10/'Modelo'!$C$8) | F8: =IF('Modelo'!$C$10=0,0,'Supuestos'!$C$8*1/'Modelo'!$C$10) | G8: =IF('Modelo'!$C$10=0,0,'Modelo'!$C$41*1/'Modelo'!$C$10) | H8: =IF('Modelo'!$C$10=0,0,'Modelo'!$C$47*'Modelo'!$C$8*1/'Modelo'!$C$10) | I8: CPA: costo por comprador. Si se pierde mucho acá, es el checkout o la oferta.
B9: Toman el bump 1 | C9: ='Modelo'!$C$15 | D9: =IF('Modelo'!$C$10=0,0,'Modelo'!$C$15/'Modelo'!$C$10) | E9: =IF('Modelo'!$C$8=0,0,'Modelo'!$C$15/'Modelo'!$C$8) | F9: sin costo propio | G9: — | H9: — | I9: Sobre compradores del principal. Se pagó con el CPA; suma al AOV.
B10: Toman el bump 2 | C10: ='Modelo'!$C$17 | D10: =IF('Modelo'!$C$10=0,0,'Modelo'!$C$17/'Modelo'!$C$10) | E10: =IF('Modelo'!$C$8=0,0,'Modelo'!$C$17/'Modelo'!$C$8) | F10: sin costo propio | G10: — | H10: — | I10: Sobre compradores del principal.
B11: Toman la OTO 1 | C11: ='Modelo'!$C$19 | D11: =IF('Modelo'!$C$10=0,0,'Modelo'!$C$19/'Modelo'!$C$10) | E11: =IF('Modelo'!$C$8=0,0,'Modelo'!$C$19/'Modelo'!$C$8) | F11: sin costo propio | G11: — | H11: — | I11: Página 1 después del pago.
B12: Toman la OTO 2 | C12: ='Modelo'!$C$21 | D12: =IF('Modelo'!$C$10=0,0,'Modelo'!$C$21/'Modelo'!$C$10) | E12: =IF('Modelo'!$C$8=0,0,'Modelo'!$C$21/'Modelo'!$C$8) | F12: sin costo propio | G12: — | H12: — | I12: Página 2 (downsell de la OTO 1).
B13: Toman la OTO 3 | C13: ='Modelo'!$C$23 | D13: =IF('Modelo'!$C$10=0,0,'Modelo'!$C$23/'Modelo'!$C$10) | E13: =IF('Modelo'!$C$8=0,0,'Modelo'!$C$23/'Modelo'!$C$8) | F13: sin costo propio | G13: — | H13: — | I13: Página 3.
B14: Toman la OTO 4 | C14: ='Modelo'!$C$25 | D14: =IF('Modelo'!$C$10=0,0,'Modelo'!$C$25/'Modelo'!$C$10) | E14: =IF('Modelo'!$C$8=0,0,'Modelo'!$C$25/'Modelo'!$C$8) | F14: sin costo propio | G14: — | H14: — | I14: Página 4.
B15: Ascienden al programa | C15: ='Modelo'!$C$27 | D15: =IF('Modelo'!$C$10=0,0,'Modelo'!$C$27/'Modelo'!$C$10) | E15: =IF('Modelo'!$C$8=0,0,'Modelo'!$C$27/'Modelo'!$C$8) | F15: sin costo propio | G15: — | H15: — | I15: Sobre compradores del principal. El AOV neto resultante contra el CPA es lo que decide el embudo.
B17: Comprobalo con la fila de la unidad: costo + ganancia + fijos repartidos = techo | F17: =F6 | G17: =G6 | H17: =F6+G6+'Supuestos'!$C$37/'Modelo'!$C$8 | I17: Techo = costo + ganancia + fijos ÷ unidades. Lo que falta entre (costo + ganancia) y el techo son los costos fijos repartidos entre las unidades.
B18: Cómo se lee
B19: Cantidad: cuántas acciones o personas hubo en ese paso con los supuestos del escenario en uso.
B20: % que pasa: de los que estaban en el paso anterior (o en el paso que indica la nota), cuántos llegan a este. % acumulado: cuántos llegan a este paso por cada 100 unidades que compra la pauta.
B21: Costo por paso: inversión ÷ cantidad. Es lo que te está costando hoy cada persona que llega a ese paso.
B22: Ganancia por paso: ganancia del período ÷ cantidad. Lo que te queda por cada persona de ese paso después de pagar la pauta, las comisiones, los reembolsos y los fijos. La ganancia por visita es la métrica más valiosa del embudo: resume todo lo que pasa después.
B23: Techo por paso: lo que cada persona de ese paso genera en cash neto (cash neto menos costos por unidad, dividido por la cantidad). Es lo máximo que podrías pagar por ese paso antes de que la ganancia llegue a cero, si lo demás se mantiene. Por eso siempre es mayor que la ganancia: techo = costo + ganancia + fijos repartidos.
B24: Los bumps, las OTOs y la ascensión no tienen costo propio: se pagan con el CPA del comprador principal y se miden por lo que suman al AOV.

Sheet Supuestos
B1: © Jesús Tassarolo · TooAudience · youtube.com/@JesusTassaroloSinFiltro · uso personal; no redistribuir modificado
B2: Supuestos
B3: Celdas amarillas = las editás vos. Celdas azules = se calculan solas. Cada fila dice en qué unidad va y de dónde sale el valor del ejemplo.
B5: Supuesto | C5: Valor en uso | D5: Conservador | E5: Base | F5: Optimista | G5: Unidad | H5: Nota / fuente del ejemplo
B6: Escenario en uso (1 = conservador · 2 = base · 3 = optimista) | C6: 2 | G6: 1 / 2 / 3 | H6: Cambia todas las filas que tienen tres valores. Si una fila no tiene tres valores, se usa el de 'Valor en uso'.
B7: 1. Inversión y tráfico
B8: Inversión en publicidad por mes | C8: 9000 | G8: USD / mes | H8: El ejemplo invierte 300 USD por día.
B9: Costo por visita a la página de ventas (VSL) | C9: =IF('Supuestos'!$C$6=1,D9,IF('Supuestos'!$C$6=2,E9,F9)) | D9: 0.4 | E9: 0.3 | F9: 0.22 | G9: USD / visita | H9: Lo que pagás por cada persona que llega a la página. En tráfico frío hispano se mueve entre 0,20 y 0,50.
B11: 2. Conversión de la página de ventas
B12: % de visitas que llegan al checkout | C12: =IF('Supuestos'!$C$6=1,D12,IF('Supuestos'!$C$6=2,E12,F12)) | D12: 0.025 | E12: 0.035 | F12: 0.045 | G12: % | H12: Visitas que tocan 'comprar' y abren el checkout.
B13: % de checkouts que terminan en compra | C13: =IF('Supuestos'!$C$6=1,D13,IF('Supuestos'!$C$6=2,E13,F13)) | D13: 0.2 | E13: 0.26 | F13: 0.3 | G13: % | H13: Checkouts que pagan.
B15: 3. Escalera: producto principal → bumps 1 y 2 → OTO 1 a 4 → ascensión (precio y % sobre compradores del principal)
B16: Producto principal: precio | C16: 37 | G16: USD | H16: El producto que vende la VSL. Todo lo demás se mide como % de sus compradores.
B17: Bump 1: precio | C17: 17 | G17: USD | H17: Oferta extra en el checkout del principal (una casilla). % sobre compradores del principal.
B18: Bump 1: % de compradores que lo toman | C18: =IF('Supuestos'!$C$6=1,D18,IF('Supuestos'!$C$6=2,E18,F18)) | D18: 0.18 | E18: 0.25 | F18: 0.35 | G18: %
B19: Bump 2: precio | C19: 17 | G19: USD | H19: Segundo bump en el mismo checkout. Rinde algo menos que el primero.
B20: Bump 2: % de compradores que lo toman | C20: =IF('Supuestos'!$C$6=1,D20,IF('Supuestos'!$C$6=2,E20,F20)) | D20: 0.12 | E20: 0.18 | F20: 0.25 | G20: %
B21: OTO 1: precio | C21: 47 | G21: USD | H21: Página 1 después del pago: el primer upsell. % sobre compradores del principal.
B22: OTO 1: % de compradores que lo toman | C22: =IF('Supuestos'!$C$6=1,D22,IF('Supuestos'!$C$6=2,E22,F22)) | D22: 0.07 | E22: 0.1 | F22: 0.14 | G22: %
B23: OTO 2: precio | C23: 17 | G23: USD | H23: Página 2: suele ser el downsell de la OTO 1 (más barato). El % va sobre todos los compradores, para simplificar.
B24: OTO 2: % de compradores que lo toman | C24: =IF('Supuestos'!$C$6=1,D24,IF('Supuestos'!$C$6=2,E24,F24)) | D24: 0.04 | E24: 0.06 | F24: 0.09 | G24: %
B25: OTO 3: precio | C25: 97 | G25: USD | H25: Página 3: el segundo upsell.
B26: OTO 3: % de compradores que lo toman | C26: =IF('Supuestos'!$C$6=1,D26,IF('Supuestos'!$C$6=2,E26,F26)) | D26: 0.02 | E26: 0.03 | F26: 0.05 | G26: %
B27: OTO 4: precio | C27: 27 | G27: USD | H27: Página 4: el downsell del segundo upsell.
B28: OTO 4: % de compradores que lo toman | C28: =IF('Supuestos'!$C$6=1,D28,IF('Supuestos'!$C$6=2,E28,F28)) | D28: 0.03 | E28: 0.04 | F28: 0.06 | G28: %
B29: Ascensión (programa de mayor valor): precio | C29: 297 | G29: USD | H29: El upsell de ascensión: el programa que se vende después del embudo, por checkout o por llamada. % sobre compradores del principal.
B30: Ascensión (programa de mayor valor): % de compradores que lo toman | C30: =IF('Supuestos'!$C$6=1,D30,IF('Supuestos'!$C$6=2,E30,F30)) | D30: 0.01 | E30: 0.02 | F30: 0.04 | G30: %
B32: 4. Costos
B33: Comisión de la pasarela o plataforma de pago | C33: 0.1 | G33: % del cash | H33: Hotmart, Stripe, Mercado Pago: lo que se queda la plataforma.
B34: Comisión del equipo de ventas | C34: 0 | G34: % del cash | H34: Sobre el cash cobrado. En este embudo no hay llamadas: 0 %.
B35: Reembolsos y contracargos | C35: 0.05 | G35: % del cash | H35: 5 % es normal en productos digitales. Más de 10 % es un problema de oferta o de expectativa.
B36: Costos por visita (herramientas, WhatsApp, IA) | C36: 0 | G36: USD / visita | H36: Costos que crecen con el volumen. En venta directa suele ser 0.
B37: Costos fijos por mes | C37: 1500 | G37: USD / mes | H37: Equipo, herramientas, edición: lo que pagás aunque no vendas.
B39: 5. Cobranza
B40: % del facturado que entra en el mes 1 | C40: 1 | G40: % | H40: Pago único digital: 100 % en el mes 1.
B41: % que entra en el mes 2 | C41: 0 | G41: % | H41: Cuotas o pagos diferidos.
B42: % que entra en el mes 3 | C42: 0 | G42: % | H42: Los tres deben sumar 100 %.
B44: 6. Objetivos y proyección
B45: ROAS objetivo sobre cash neto | C45: 2 | G45: x | H45: El retorno mínimo que querés por cada dólar invertido, después de comisiones y reembolsos. Entra en el semáforo: sin llegar a este ROAS no hay verde.
B46: Margen de seguridad | C46: 0.3 | G46: % | H46: Colchón entre el techo (donde no ganás ni perdés) y el objetivo. 30 % es el estándar que usamos.
...

Sheet Modelo
B1: © Jesús Tassarolo · TooAudience · youtube.com/@JesusTassaroloSinFiltro · uso personal; no redistribuir modificado
B2: Modelo: la cadena completa del embudo
B3: Cada fila es una etapa o un resultado. No se edita: todo sale de Supuestos. La columna de la derecha dice cómo se calcula.
B5: Etapa / resultado | C5: Valor | D5: Cómo se calcula
B6: Tráfico y unidades
B7: Costo por visita (unidad de adquisición) | C7: ='Supuestos'!$C$9 | D7: El supuesto 'costo por visita'.
B8: Visitas a la página de ventas | C8: =IF('Modelo'!$C$7=0,0,'Supuestos'!$C$8/'Modelo'!$C$7) | D8: Inversión ÷ costo por visita.
B9: Checkouts iniciados | C9: ='Modelo'!$C$8*'Supuestos'!$C$12 | D9: Visitas × % que llega al checkout.
B10: Ventas del producto principal | C10: ='Modelo'!$C$9*'Supuestos'!$C$13 | D10: Checkouts × % que compra.
B11: % de visitas que compran | C11: =IF('Modelo'!$C$8=0,0,'Modelo'!$C$10/'Modelo'!$C$8) | D11: Ventas ÷ visitas. Las dos conversiones multiplicadas.
B12: Costo por comprador (CPA) | C12: =IF('Modelo'!$C$10=0,0,'Supuestos'!$C$8/'Modelo'!$C$10) | D12: Inversión ÷ ventas del principal.
B13: Facturación por producto
B14: Facturado: producto principal | C14: ='Modelo'!$C$10*'Supuestos'!$C$16 | D14: Ventas × precio.
B15: Ventas: Bump 1 | C15: ='Modelo'!$C$10*'Supuestos'!$C$18 | D15: Compradores del principal × % que lo toma.
B16: Facturado: Bump 1 | C16: ='Modelo'!$C$15*'Supuestos'!$C$17 | D16: Ventas × precio.
B17: Ventas: Bump 2 | C17: ='Modelo'!$C$10*'Supuestos'!$C$20 | D17: Compradores del principal × % que lo toma.
B18: Facturado: Bump 2 | C18: ='Modelo'!$C$17*'Supuestos'!$C$19 | D18: Ventas × precio.
B19: Ventas: OTO 1 | C19: ='Modelo'!$C$10*'Supuestos'!$C$22 | D19: Compradores del principal × % que lo toma.
B20: Facturado: OTO 1 | C20: ='Modelo'!$C$19*'Supuestos'!$C$21 | D20: Ventas × precio.
B21: Ventas: OTO 2 | C21: ='Modelo'!$C$10*'Supuestos'!$C$24 | D21: Compradores del principal × % que lo toma.
B22: Facturado: OTO 2 | C22: ='Modelo'!$C$21*'Supuestos'!$C$23 | D22: Ventas × precio.
B23: Ventas: OTO 3 | C23: ='Modelo'!$C$10*'Supuestos'!$C$26 | D23: Compradores del principal × % que lo toma.
B24: Facturado: OTO 3 | C24: ='Modelo'!$C$23*'Supuestos'!$C$25 | D24: Ventas × precio.
B25: Ventas: OTO 4 | C25: ='Modelo'!$C$10*'Supuestos'!$C$28 | D25: Compradores del principal × % que lo toma.
B26: Facturado: OTO 4 | C26: ='Modelo'!$C$25*'Supuestos'!$C$27 | D26: Ventas × precio.
B27: Ventas: Ascensión (programa de mayor valor) | C27: ='Modelo'!$C$10*'Supuestos'!$C$30 | D27: Compradores del principal × % que lo toma.
B28: Facturado: Ascensión (programa de mayor valor) | C28: ='Modelo'!$C$27*'Supuestos'!$C$29 | D28: Ventas × precio.
B29: Facturado total | C29: ='Modelo'!$C$14+'Modelo'!$C$16+'Modelo'!$C$18+'Modelo'!$C$20+'Modelo'!$C$22+'Modelo'!$C$24+'Modelo'!$C$26+'Modelo'!$C$28 | D29: Suma de todos los productos.
B30: Facturado por comprador (AOV) | C30: =IF('Modelo'!$C$10=0,0,'Modelo'!$C$29/'Modelo'!$C$10) | D30: Facturado total ÷ ventas del principal.
B31: AOV ÷ precio del principal | C31: =IF('Supuestos'!$C$16=0,0,'Modelo'!$C$30/'Supuestos'!$C$16) | D31: Cuánto multiplica la escalera al precio del front.
B32: Ventas del principal por visita (para la proyección) | C32: =IF('Modelo'!$C$8=0,0,'Modelo'!$C$10/'Modelo'!$C$8) | D32: Igual a '% de visitas que compran'.
B33: Facturado por visita | C33: =IF('Modelo'!$C$8=0,0,'Modelo'!$C$29/'Modelo'!$C$8) | D33: Facturado total ÷ visitas.
B34: Cash, costos y ganancia del período
B35: Cash a cobrar (facturado × cobranza completa) | C35: ='Modelo'!$C$29*('Supuestos'!$C$40+'Supuestos'!$C$41+'Supuestos'!$C$42) | D35: Facturado × (mes 1 + mes 2 + mes 3). Si la cobranza suma 100 %, es igual al facturado.
B36: Cash que entra en el primer mes | C36: ='Modelo'!$C$29*'Supuestos'!$C$40 | D36: Facturado × % del mes 1.
B37: Comisiones (pasarela + ventas) | C37: ='Modelo'!$C$35*('Supuestos'!$C$33+'Supuestos'!$C$34) | D37: Cash × (pasarela + equipo de ventas).
B38: Reembolsos | C38: ='Modelo'!$C$35*'Supuestos'!$C$35 | D38: Cash × % de reembolsos.
B39: Cash neto | C39: ='Modelo'!$C$35*(1-'Supuestos'!$C$33-'Supuestos'!$C$34-'Supuestos'!$C$35) | D39: Cash − comisiones − reembolsos. La base de verdad.
B40: Costos por visita (herramientas, WhatsApp, IA) | C40: ='Modelo'!$C$8*'Supuestos'!$C$36 | D40: Visitas × costo por visita.
B41: Ganancia del período | C41: ='Modelo'!$C$39-'Modelo'!$C$40-'Supuestos'!$C$37-'Supuestos'!$C$8 | D41: Cash neto − costos por unidad − fijos − inversión.
...

Sheet Escenarios
B1: © Jesús Tassarolo · TooAudience · youtube.com/@JesusTassaroloSinFiltro · uso personal; no redistribuir modificado
B2: Escenarios: qué pasa si cambian el precio, la conversión o el costo
B3: Las celdas amarillas de cada tabla (fila y columna) se pueden cambiar. Verde = ganancia, amarillo = cerca del cero, rojo = pérdida. Todo lo demás queda como en Supuestos.
B5: Umbral de 'cerca del cero' (inversión × margen de seguridad) | C5: ='Supuestos'!$C$8*'Supuestos'!$C$46
B7: Precio del producto principal × % de checkouts que compran → ganancia del mes
B8: Subir el precio suele bajar la conversión: la tabla muestra qué combinación gana.
B9: Precio ↓ / % checkout → compra → | C9: 0.18 | D9: 0.22 | E9: 0.26 | F9: 0.3 | G9: 0.34
B10: 27 | C10: =((((((((IF(('Supuestos'!$C$9)=0,0,'Supuestos'!$C$8/('Supuestos'!$C$9)))*'Supuestos'!$C$12)*C$9)*$B10)+(((((IF(('Supuestos'!$C$9)=0,0,'Supuestos'!$C$8/('Supuestos'!$C$9)))*'Supuestos'!$C$12)*C$9)*'Supuestos'!$C$18)*'Supuestos'!$C$17)+(((((IF(('Supuestos'!$C$9)=0,0,'Supuestos'!$C$8/('Supuestos'!$C$9)))*'Supuestos'!$C$12)*C$9)*'Supuestos'!$C$20)*'Supuestos'!$C$19)+(((((IF(('Supuestos'!$C$9)=0,0,'Supuestos'!$C$8/('Supuestos'!$C$9)))*'Supuestos'!$C$12)*C$9)*'Supuestos'!$C$22)*'Supuestos'!$C$21)+(((((IF(('Supuestos'!$C$9)=0,0,'Supuestos'!$C$8/('Supuestos'!$C$9)))*'Supuestos'!$C$12)*C$9)*'Supuestos'!$C$24)*'Supuestos'!$C$23)+(((((IF(('Supuestos'!$C$9)=0,0,'Supuestos'!$C$8/('Supuestos'!$C$9)))*'Supuestos'!$C$12)*C$9)*'Supuestos'!$C$26)*'Supuestos'!$C$25)+(((((IF(('Supuestos'!$C$9)=0,0,'Supuestos'!$C$8/('Supuestos'!$C$9)))*'Supuestos'!$C$12)*C$9)*'Supuestos'!$C$28)*'Supuestos'!$C$27)+(((((IF(('Supuestos'!$C$9)=0,0,'Supuestos'!$C$8/('Supuestos'!$C$9)))*'Supuestos'!$C$12)*C$9)*'Supuestos'!$C$30)*'Supuestos'!$C$29))*('Supuestos'!$C$40+'Supuestos'!$C$41+'Supuestos'!$C$42))*(1-'Supuestos'!$C$33-'Supuestos'!$C$34-'Supuestos'!$C$35))-((IF(('Supuestos'!$C$9)=0,0,'Supuestos'!$C$8/('Supuestos'!$C$9)))*'Supuestos'!$C$36)-'Supuestos'!$C$37-'Supuestos'!$C$8) | D10: =((((((((IF(('Supuestos'!$C$9)=0,0,'Supuestos'!$C$8/('Supuestos'!$C$9)))*'Supuestos'!$C$12)*D$9)*$B10)+(((((IF(('Supuestos'!$C$9)=0,0,'Supuestos'!$C$8/('Supuestos'!$C$9)))*'Supuestos'!$C$12)*D$9)*'Supuestos'!$C$18)*'Supuestos'!$C$17)+(((((IF(('Supuestos'!$C$9)=0,0,'Supuestos'!$C$8/('Supuestos'!$C$9)))*'Supuestos'!$C$12)*D$9)*'Supuestos'!$C$20)*'Supuestos'!$C$19)+(((((IF(('Supuestos'!$C$9)=0,0,'Supuestos'!$C$8/('Supuestos'!$C$9)))*'Supuestos'!$C$12)*D$9)*'Supuestos'!$C$22)*'Supuestos'!$C$21)+(((((IF(('Supuestos'!$C$9)=0,0,'Supuestos'!$C$8/('Supuestos'!$C$9)))*'Supuestos'!$C$12)*D$9)*'Supuestos'!$C$24)*'Supuestos'!$C$23)+(((((IF(('Supuestos'!$C$9)=0,0,'Supuestos'!$C$8/('Supuestos'!$C$9)))*'Supuestos'!$C$12)*D$9)*'Supuestos'!$C$26)*'Supuestos'!$C$25)+(((((IF(('Supuestos'!$C$9)=0,0,'Supuestos'!$C$8/('Supuestos'!$C$9)))*'Supuestos'!$C$12)*D$9)*'Supuestos'!$C$28)*'Supuestos'!$C$27)+(((((IF(('Supuestos'!$C$9)=0,0,'Supuestos'!$C$8/('Supuestos'!$C$9)))*'Supuestos'!$C$12)*D$9)*'Supuestos'!$C$30)*'Supuestos'!$C$29))*('Supuestos'!$C$40+'Supuestos'!$C$41+'Supuestos'!$C$42))*(1-'Supuestos'!$C$33-'Supuestos'!$C$34-'Supuestos'!$C$35))-((IF(('Supuestos'!$C$9)=0,0,'Supuestos'!$C$8/('Supuestos'!$C$9)))*'Supuestos'!$C$36)-'Supuestos'!$C$37-'Supuestos'!$C$8) | E10: =((((((((IF(('Supuestos'!$C$9)=0,0,'Supuestos'!$C$8/('Supuestos'!$C$9)))*'Supuestos'!$C$12)*E$9)*$B10)+(((((IF(('Supuestos'!$C$9)=0,0,'Supuestos'!$C$8/('Supuestos'!$C$9)))*'Supuestos'!$C$12)*E$9)*'Supuestos'!$C$18)*'Supuestos'!$C$17)+(((((IF(('Supuestos'!$C$9)=0,0,'Supuestos'!$C$8/('Supuestos'!$C$9)))*'Supuestos'!$C$12)*E$9)*'Supuestos'!$C$20)*'Supuestos'!$C$19)+(((((IF(('Supuestos'!$C$9)=0,0,'Supuestos'!$C$8/('Supuestos'!$C$9)))*'Supuestos'!$C$12)*E$9)*'Supuestos'!$C$22)*'Supuestos'!$C$21)+(((((IF(('Supuestos'!$C$9)=0,0,'Supuestos'!$C$8/('Supuestos'!$C$9)))*'Supuestos'!$C$12)*E$9)*'Supuestos'!$C$24)*'Supuestos'!$C$23)+(((((IF(('Supuestos'!$C$9)=0,0,'Supuestos'!$C$8/('Supuestos'!$C$9)))*'Supuestos'!$C$12)*E$9)*'Supuestos'!$C$26)*'Supuestos'!$C$25)+(((((IF(('Supuestos'!$C$9)=0,0,'Supuestos'!$C$8/('Supuestos'!$C$9)))*'Supuestos'!$C$12)*E$9)*'Supuestos'!$C$28)*'Supuestos'!$C$27)+(((((IF(('Supuestos'!$C$9)=0,0,'Supuestos'!$C$8/('Supuestos'!$C$9)))*'Supuestos'!$C$12)*E$9)*'Supuestos'!$C$30)*'Supuestos'!$C$29))*('Supuestos'!$C$40+'Supuestos'!$C$41+'Supuestos'!$C$42))*(1-'Supuestos'!$C$33-'Supuestos'!$C$34-'Supuestos'!$C$35))-((IF(('Supuestos'!$C$9)=0,0,'Supuestos'!$C$8/('Supuestos'!$C$9)))*'Supuestos'!$C$36)-'Supuestos'!$C$37-'Supuestos'!$C$8) | F10: =((((((((IF(('Supuestos'!$C$9)=0,0,'Supuestos'!$C$8/('Supuestos'!$C$9)))*'Supuestos'!$C$12)*F$9)*$B10)+(((((IF(('Supuestos'!$C$9)=0,0,'Supuestos'!$C$8/('Supuestos'!$C$9)))*'Supuestos'!$C$12)*F$9)*'Supuestos'!$C$18)*'Supuestos'!$C$17)+(((((IF(('Supuestos'!$C$9)=0,0,'Supuestos'!$C$8/('Supuestos'!$C$9)))*'Supuestos'!$C$12)*F$9)*'Supuestos'!$C$20)*'Supuestos'!$C$19)+(((((IF(('Supuestos'!$C$9)=0,0,'Supuestos'!$C$8/('Supuestos'!$C$9)))*'Supuestos'!$C$12)*F$9)*'Supuestos'!$C$22)*'Supuestos'!$C$21)+(((((IF(('Supuestos'!$C$9)=0,0,'Supuestos'!$C$8/('Supuestos'!$C$9)))*'Supuestos'!$C$12)*F$9)*'Supuestos'!$C$24)*'Supuestos'!$C$23)+(((((IF(('Supuestos'!$C$9)=0,0,'Supuestos'!$C$8/('Supuestos'!$C$9)))*'Supuestos'!$C$12)*F$9)*'Supuestos'!$C$26)*'Supuestos'!$C$25)+(((((IF(('Supuestos'!$C$9)=0,0,'Supuestos'!$C$8/('Supuestos'!$C$9)))*'Supuestos'!$C$12)*F$9)*'Supuestos'!$C$28)*'Supuestos'!$C$27)+(((((IF(('Supuestos'!$C$9)=0,0,'Supuestos'!$C$8/('Supuestos'!$C$9)))*'Supuestos'!$C$12)*F$9)*'Supuestos'!$C$30)*'Supuestos'!$C$29))*('Supuestos'!$C$40+'Supuestos'!$C$41+'Supuestos'!$C$42))*(1-'Supuestos'!$C$33-'Supuestos'!$C$34-'Supuestos'!$C$35))-((IF(('Supuestos'!$C$9)=0,0,'Supuestos'!$C$8/('Supuestos'!$C$9)))*'Supuestos'!$C$36)-'Supuestos'!$C$37-'Supuestos'!$C$8) | G10: =((((((((IF(('Supuestos'!$C$9)=0,0,'Supuestos'!$C$8/('Supuestos'!$C$9)))*'Supuestos'!$C$12)*G$9)*$B10)+(((((IF(('Supuestos'!$C$9)=0,0,'Supuestos'!$C$8/('Supuestos'!$C$9)))*'Supuestos'!$C$12)*G$9)*'Supuestos'!$C$18)*'Supuestos'!$C$17)+(((((IF(('Supuestos'!$C$9)=0,0,'Supuestos'!$C$8/('Supuestos'!$C$9)))*'Supuestos'!$C$12)*G$9)*'Supuestos'!$C$20)*'Supuestos'!$C$19)+(((((IF(('Supuestos'!$C$9)=0,0,'Supuestos'!$C$8/('Supuestos'!$C$9)))*'Supuestos'!$C$12)*G$9)*'Supuestos'!$C$22)*'Supuestos'!$C$21)+(((((IF(('Supuestos'!$C$9)=0,0,'Supuestos'!$C$8/('Supuestos'!$C$9)))*'Supuestos'!$C$12)*G$9)*'Supuestos'!$C$24)*'Supuestos'!$C$23)+(((((IF(('Supuestos'!$C$9)=0,0,'Supuestos'!$C$8/('Supuestos'!$C$9)))*'Supuestos'!$C$12)*G$9)*'Supuestos'!$C$26)*'Supuestos'!$C$25)+(((((IF(('Supuestos'!$C$9)=0,0,'Supuestos'!$C$8/('Supuestos'!$C$9)))*'Supuestos'!$C$12)*G$9)*'Supuestos'!$C$28)*'Supuestos'!$C$27)+(((((IF(('Supuestos'!$C$9)=0,0,'Supuestos'!$C$8/('Supuestos'!$C$9)))*'Supuestos'!$C$12)*G$9)*'Supuestos'!$C$30)*'Supuestos'!$C$29))*('Supuestos'!$C$40+'Supuestos'!$C$41+'Supuestos'!$C$42))*(1-'Supuestos'!$C$33-'Supuestos'!$C$34-'Supuestos'!$C$35))-((IF(('Supuestos'!$C$9)=0,0,'Supuestos'!$C$8/('Supuestos'!$C$9)))*'Supuestos'!$C$36)-'Supuestos'!$C$37-'Supuestos'!$C$8)
B11: 37 | C11: =((((((((IF(('Supuestos'!$C$9)=0,0,'Supuestos'!$C$8/('Supuestos'!$C$9)))*'Supuestos'!$C$12)*C$9)*$B11)+(((((IF(('Supuestos'!$C$9)=0,0,'Supuestos'!$C$8/('Supuestos'!$C$9)))*'Supuestos'!$C$12)*C$9)*'Supuestos'!$C$18)*'Supuestos'!$C$17)+(((((IF(('Supuestos'!$C$9)=0,0,'Supuestos'!$C$8/('Supuestos'!$C$9)))*'Supuestos'!$C$12)*C$9)*'Supuestos'!$C$20)*'Supuestos'!$C$19)+(((((IF(('Supuestos'!$C$9)=0,0,'Supuestos'!$C$8/('Supuestos'!$C$9)))*'Supuestos'!$C$12)*C$9)*'Supuestos'!$C$22)*'Supuestos'!$C$21)+(((((IF(('Supuestos'!$C$9)=0,0,'Supuestos'!$C$8/('Supuestos'!$C$9)))*'Supuestos'!$C$12)*C$9)*'Supuestos'!$C$24)*'Supuestos'!$C$23)+(((((IF(('Supuestos'!$C$9)=0,0,'Supuestos'!$C$8/('Supuestos'!$C$9)))*'Supuestos'!$C$12)*C$9)*'Supuestos'!$C$26)*'Supuestos'!$C$25)+(((((IF(('Supuestos'!$C$9)=0,0,'Supuestos'!$C$8/('Supuestos'!$C$9)))*'Supuestos'!$C$12)*C$9)*'Supuestos'!$C$28)*'Supuestos'!$C$27)+(((((IF(('Supuestos'!$C$9)=0,0,'Supuestos'!$C$8/('Supuestos'!$C$9)))*'Supuestos'!$C$12)*C$9)*'Supuestos'!$C$30)*'Supuestos'!$C$29))*('Supuestos'!$C$40+'Supuestos'!$C$41+'Supuestos'!$C$42))*(1-'Supuestos'!$C$33-'Supuestos'!$C$34-'Supuestos'!$C$35))-((IF(('Supuestos'!$C$9)=0,0,'Supuestos'!$C$8/('Supuestos'!$C$9)))*'Supuestos'!$C$36)-'Supuestos'!$C$37-'Supuestos'!$C$8) | D11: =((((((((IF(('Supuestos'!$C$9)=0,0,'Supuestos'!$C$8/('Supuestos'!$C$9)))*'Supuestos'!$C$12)*D$9)*$B11)+(((((IF(('Supuestos'!$C$9)=0,0,'Supuestos'!$C$8/('Supuestos'!$C$9)))*'Supuestos'!$C$12)*D$9)*'Supuestos'!$C$18)*'Supuestos'!$C$17)+(((((IF(('Supuestos'!$C$9)=0,0,'Supuestos'!$C$8/('Supuestos'!$C$9)))*'Supuestos'!$C$12)*D$9)*'Supuestos'!$C$20)*'Supuestos'!$C$19)+(((((IF(('Supuestos'!$C$9)=0,0,'Supuestos'!$C$8/('Supuestos'!$C$9)))*'Supuestos'!$C$12)*D$9)*'Supuestos'!$C$22)*'Supuestos'!$C$21)+(((((IF(('Supuestos'!$C$9)=0,0,'Supuestos'!$C$8/('Supuestos'!$C$9)))*'Supuestos'!$C$12)*D$9)*'Supuestos'!$C$24)*'Supuestos'!$C$23)+(((((IF(('Supuestos'!$C$9)=0,0,'Supuestos'!$C$8/('Supuestos'!$C$9)))*'Supuestos'!$C$12)*D$9)*'Supuestos'!$C$26)*'Supuestos'!$C$25)+(((((IF(('Supuestos'!$C$9)=0,0,'Supuestos'!$C$8/('Supuestos'!$C$9)))*'Supuestos'!$C$12)*D$9)*'Supuestos'!$C$28)*'Supuestos'!$C$27)+(((((IF(('Supuestos'!$C$9)=0,0,'Supuestos'!$C$8/('Supuestos'!$C$9)))*'Supuestos'!$C$12)*D$9)*'Supuestos'!$C$30)*'Supuestos'!$C$29))*('Supuestos'!$C$40+'Supuestos'!$C$41+'Supuestos'!$C$42))*(1-'Supuestos'!$C$33-'Supuestos'!$C$34-'Supuestos'!$C$35))-((IF(('Supuestos'!$C$9)=0,0,'Supuestos'!$C$8/('Supuestos'!$C$9)))*'Supuestos'!$C$36)-'Supuestos'!$C$37-'Supuestos'!$C$8) | E11: =((((((((IF(('Supuestos'!$C$9)=0,0,'Supuestos'!$C$8/('Supuestos'!$C$9)))*'Supuestos'!$C$12)*E$9)*$B11)+(((((IF(('Supuestos'!$C$9)=0,0,'Supuestos'!$C$8/('Supuestos'!$C$9)))*'Supuestos'!$C$12)*E$9)*'Supuestos'!$C$18)*'Supuestos'!$C$17)+(((((IF(('Supuestos'!$C$9)=0,0,'Supuestos'!$C$8/('Supuestos'!$C$9)))*'Supuestos'!$C$12)*E$9)*'Supuestos'!$C$20)*'Supuestos'!$C$19)+(((((IF(('Supuestos'!$C$9)=0,0,'Supuestos'!$C$8/('Supuestos'!$C$9)))*'Supuestos'!$C$12)*E$9)*'Supuestos'!$C$22)*'Supuestos'!$C$21)+(((((IF(('Supuestos'!$C$9)=0,0,'Supuestos'!$C$8/('Supuestos'!$C$9)))*'Supuestos'!$C$12)*E$9)*'Supuestos'!$C$24)*'Supuestos'!$C$23)+(((((IF(('Supuestos'!$C$9)=0,0,'Supuestos'!$C$8/('Supuestos'!$C$9)))*'Supuestos'!$C$12)*E$9)*'Supuestos'!$C$26)*'Supuestos'!$C$25)+(((((IF(('Supuestos'!$C$9)=0,0,'Supuestos'!$C$8/('Supuestos'!$C$9)))*'Supuestos'!$C$12)*E$9)*'Supuestos'!$C$28)*'Supuestos'!$C$27)+(((((IF(('Supuestos'!$C$9)=0,0,'Supuestos'!$C$8/('Supuestos'!$C$9)))*'Supuestos'!$C$12)*E$9)*'Supuestos'!$C$30)*'Supuestos'!$C$29))*('Supuestos'!$C$40+'Supuestos'!$C$41+'Supuestos'!$C$42))*(1-'Supuestos'!$C$33-'Supuestos'!$C$34-'Supuestos'!$C$35))-((IF(('Supuestos'!$C$9)=0,0,'Supuestos'!$C$8/('Supuestos'!$C$9)))*'Supuestos'!$C$36)-'Supuestos'!$C$37-'Supuestos'!$C$8) | F11: =((((((((IF(('Supuestos'!$C$9)=0,0,'Supuestos'!$C$8/('Supuestos'!$C$9)))*'Supuestos'!$C$12)*F$9)*$B11)+(((((IF(('Supuestos'!$C$9)=0,0,'Supuestos'!$C$8/('Supuestos'!$C$9)))*'Supuestos'!$C$12)*F$9)*'Supuestos'!$C$18)*'Supuestos'!$C$17)+(((((IF(('Supuestos'!$C$9)=0,0,'Supuestos'!$C$8/('Supuestos'!$C$9)))*'Supuestos'!$C$12)*F$9)*'Supuestos'!$C$20)*'Supuestos'!$C$19)+(((((IF(('Supuestos'!$C$9)=0,0,'Supuestos'!$C$8/('Supuestos'!$C$9)))*'Supuestos'!$C$12)*F$9)*'Supuestos'!$C$22)*'Supuestos'!$C$21)+(((((IF(('Supuestos'!$C$9)=0,0,'Supuestos'!$C$8/('Supuestos'!$C$9)))*'Supuestos'!$C$12)*F$9)*'Supuestos'!$C$24)*'Supuestos'!$C$23)+(((((IF(('Supuestos'!$C$9)=0,0,'Supuestos'!$C$8/('Supuestos'!$C$9)))*'Supuestos'!$C$12)*F$9)*'Supuestos'!$C$26)*'Supuestos'!$C$25)+(((((IF(('Supuestos'!$C$9)=0,0,'Supuestos'!$C$8/('Supuestos'!$C$9)))*'Supuestos'!$C$12)*F$9)*'Supuestos'!$C$28)*'Supuestos'!$C$27)+(((((IF(('Supuestos'!$C$9)=0,0,'Supuestos'!$C$8/('Supuestos'!$C$9)))*'Supuestos'!$C$12)*F$9)*'Supuestos'!$C$30)*'Supuestos'!$C$29))*('Supuestos'!$C$40+'Supuestos'!$C$41+'Supuestos'!$C$42))*(1-'Supuestos'!$C$33-'Supuestos'!$C$34-'Supuestos'!$C$35))-((IF(('Supuestos'!$C$9)=0,0,'Supuestos'!$C$8/('Supuestos'!$C$9)))*'Supuestos'!$C$36)-'Supuestos'!$C$37-'Supuestos'!$C$8) | G11: =((((((((IF(('Supuestos'!$C$9)=0,0,'Supuestos'!$C$8/('Supuestos'!$C$9)))*'Supuestos'!$C$12)*G$9)*$B11)+(((((IF(('Supuestos'!$C$9)=0,0,'Supuestos'!$C$8/('Supuestos'!$C$9)))*'Supuestos'!$C$12)*G$9)*'Supuestos'!$C$18)*'Supuestos'!$C$17)+(((((IF(('Supuestos'!$C$9)=0,0,'Supuestos'!$C$8/('Supuestos'!$C$9)))*'Supuestos'!$C$12)*G$9)*'Supuestos'!$C$20)*'Supuestos'!$C$19)+(((((IF(('Supuestos'!$C$9)=0,0,'Supuestos'!$C$8/('Supuestos'!$C$9)))*'Supuestos'!$C$12)*G$9)*'Supuestos'!$C$22)*'Supuestos'!$C$21)+(((((IF(('Supuestos'!$C$9)=0,0,'Supuestos'!$C$8/('Supuestos'!$C$9)))*'Supuestos'!$C$12)*G$9)*'Supuestos'!$C$24)*'Supuestos'!$C$23)+(((((IF(('Supuestos'!$C$9)=0,0,'Supuestos'!$C$8/('Supuestos'!$C$9)))*'Supuestos'!$C$12)*G$9)*'Supuestos'!$C$26)*'Supuestos'!$C$25)+(((((IF(('Supuestos'!$C$9)=0,0,'Supuestos'!$C$8/('Supuestos'!$C$9)))*'Supuestos'!$C$12)*G$9)*'Supuestos'!$C$28)*'Supuestos'!$C$27)+(((((IF(('Supuestos'!$C$9)=0,0,'Supuestos'!$C$8/('Supuestos'!$C$9)))*'Supuestos'!$C$12)*G$9)*'Supuestos'!$C$30)*'Supuestos'!$C$29))*('Supuestos'!$C$40+'Supuestos'!$C$41+'Supuestos'!$C$42))*(1-'Supuestos'!$C$33-'Supuestos'!$C$34-'Supuestos'!$C$35))-((IF(('Supuestos'!$C$9)=0,0,'Supuestos'!$C$8/('Supuestos'!$C$9)))*'Supuestos'!$C$36)-'Supuestos'!$C$37-'Supuestos'!$C$8)
B12: 47 | C12: =((((((((IF(('Supuestos'!$C$9)=0,0,'Supuestos'!$C$8/('Supuestos'!$C$9)))*'Supuestos'!$C$12)*C$9)*$B12)+(((((IF(('Supuestos'!$C$9)=0,0,'Supuestos'!$C$8/('Supuestos'!$C$9)))*'Supuestos'!$C$12)*C$9)*'Supuestos'!$C$18)*'Supuestos'!$C$17)+(((((IF(('Supuestos'!$C$9)=0,0,'Supuestos'!$C$8/('Supuestos'!$C$9)))*'Supuestos'!$C$12)*C$9)*'Supuestos'!$C$20)*'Supuestos'!$C$19)+(((((IF(('Supuestos'!$C$9)=0,0,'Supuestos'!$C$8/('Supuestos'!$C$9)))*'Supuestos'!$C$12)*C$9)*'Supuestos'!$C$22)*'Supuestos'!$C$21)+(((((IF(('Supuestos'!$C$9)=0,0,'Supuestos'!$C$8/('Supuestos'!$C$9)))*'Supuestos'!$C$12)*C$9)*'Supuestos'!$C$24)*'Supuestos'!$C$23)+(((((IF(('Supuestos'!$C$9)=0,0,'Supuestos'!$C$8/('Supuestos'!$C$9)))*'Supuestos'!$C$12)*C$9)*'Supuestos'!$C$26)*'Supuestos'!$C$25)+(((((IF(('Supuestos'!$C$9)=0,0,'Supuestos'!$C$8/('Supuestos'!$C$9)))*'Supuestos'!$C$12)*C$9)*'Supuestos'!$C$28)*'Supuestos'!$C$27)+(((((IF(('Supuestos'!$C$9)=0,0,'Supuestos'!$C$8/('Supuestos'!$C$9)))*'Supuestos'!$C$12)*C$9)*'Supuestos'!$C$30)*'Supuestos'!$C$29))*('Supuestos'!$C$40+'Supuestos'!$C$41+'Supuestos'!$C$42))*(1-'Supuestos'!$C$33-'Supuestos'!$C$34-'Supuestos'!$C$35))-((IF(('Supuestos'!$C$9)=0,0,'Supuestos'!$C$8/('Supuestos'!$C$9)))*'Supuestos'!$C$36)-'Supuestos'!$C$37-'Supuestos'!$C$8) | D12: =((((((((IF(('Supuestos'!$C$9)=0,0,'Supuestos'!$C$8/('Supuestos'!$C$9)))*'Supuestos'!$C$12)*D$9)*$B12)+(((((IF(('Supuestos'!$C$9)=0,0,'Supuestos'!$C$8/('Supuestos'!$C$9)))*'Supuestos'!$C$12)*D$9)*'Supuestos'!$C$18)*'Supuestos'!$C$17)+(((((IF(('Supuestos'!$C$9)=0,0,'Supuestos'!$C$8/('Supuestos'!$C$9)))*'Supuestos'!$C$12)*D$9)*'Supuestos'!$C$20)*'Supuestos'!$C$19)+(((((IF(('Supuestos'!$C$9)=0,0,'Supuestos'!$C$8/('Supuestos'!$C$9)))*'Supuestos'!$C$12)*D$9)*'Supuestos'!$C$22)*'Supuestos'!$C$21)+(((((IF(('Supuestos'!$C$9)=0,0,'Supuestos'!$C$8/('Supuestos'!$C$9)))*'Supuestos'!$C$12)*D$9)*'Supuestos'!$C$24)*'Supuestos'!$C$23)+(((((IF(('Supuestos'!$C$9)=0,0,'Supuestos'!$C$8/('Supuestos'!$C$9)))*'Supuestos'!$C$12)*D$9)*'Supuestos'!$C$26)*'Supuestos'!$C$25)+(((((IF(('Supuestos'!$C$9)=0,0,'Supuestos'!$C$8/('Supuestos'!$C$9)))*'Supuestos'!$C$12)*D$9)*'Supuestos'!$C$28)*'Supuestos'!$C$27)+(((((IF(('Supuestos'!$C$9)=0,0,'Supuestos'!$C$8/('Supuestos'!$C$9)))*'Supuestos'!$C$12)*D$9)*'Supuestos'!$C$30)*'Supuestos'!$C$29))*('Supuestos'!$C$40+'Supuestos'!$C$41+'Supuestos'!$C$42))*(1-'Supuestos'!$C$33-'Supuestos'!$C$34-'Supuestos'!$C$35))-((IF(('Supuestos'!$C$9)=0,0,'Supuestos'!$C$8/('Supuestos'!$C$9)))*'Supuestos'!$C$36)-'Supuestos'!$C$37-'Supuestos'!$C$8) | E12: =((((((((IF(('Supuestos'!$C$9)=0,0,'Supuestos'!$C$8/('Supuestos'!$C$9)))*'Supuestos'!$C$12)*E$9)*$B12)+(((((IF(('Supuestos'!$C$9)=0,0,'Supuestos'!$C$8/('Supuestos'!$C$9)))*'Supuestos'!$C$12)*E$9)*'Supuestos'!$C$18)*'Supuestos'!$C$17)+(((((IF(('Supuestos'!$C$9)=0,0,'Supuestos'!$C$8/('Supuestos'!$C$9)))*'Supuestos'!$C$12)*E$9)*'Supuestos'!$C$20)*'Supuestos'!$C$19)+(((((IF(('Supuestos'!$C$9)=0,0,'Supuestos'!$C$8/('Supuestos'!$C$9)))*'Supuestos'!$C$12)*E$9)*'Supuestos'!$C$22)*'Supuestos'!$C$21)+(((((IF(('Supuestos'!$C$9)=0,0,'Supuestos'!$C$8/('Supuestos'!$C$9)))*'Supuestos'!$C$12)*E$9)*'Supuestos'!$C$24)*'Supuestos'!$C$23)+(((((IF(('Supuestos'!$C$9)=0,0,'Supuestos'!$C$8/('Supuestos'!$C$9)))*'Supuestos'!$C$12)*E$9)*'Supuestos'!$C$26)*'Supuestos'!$C$25)+(((((IF(('Supuestos'!$C$9)=0,0,'Supuestos'!$C$8/('Supuestos'!$C$9)))*'Supuestos'!$C$12)*E$9)*'Supuestos'!$C$28)*'Supuestos'!$C$27)+(((((IF(('Supuestos'!$C$9)=0,0,'Supuestos'!$C$8/('Supuestos'!$C$9)))*'Supuestos'!$C$12)*E$9)*'Supuestos'!$C$30)*'Supuestos'!$C$29))*('Supuestos'!$C$40+'Supuestos'!$C$41+'Supuestos'!$C$42))*(1-'Supuestos'!$C$33-'Supuestos'!$C$34-'Supuestos'!$C$35))-((IF(('Supuestos'!$C$9)=0,0,'Supuestos'!$C$8/('Supuestos'!$C$9)))*'Supuestos'!$C$36)-'Supuestos'!$C$37-'Supuestos'!$C$8) | F12: =((((((((IF(('Supuestos'!$C$9)=0,0,'Supuestos'!$C$8/('Supuestos'!$C$9)))*'Supuestos'!$C$12)*F$9)*$B12)+(((((IF(('Supuestos'!$C$9)=0,0,'Supuestos'!$C$8/('Supuestos'!$C$9)))*'Supuestos'!$C$12)*F$9)*'Supuestos'!$C$18)*'Supuestos'!$C$17)+(((((IF(('Supuestos'!$C$9)=0,0,'Supuestos'!$C$8/('Supuestos'!$C$9)))*'Supuestos'!$C$12)*F$9)*'Supuestos'!$C$20)*'Supuestos'!$C$19)+(((((IF(('Supuestos'!$C$9)=0,0,'Supuestos'!$C$8/('Supuestos'!$C$9)))*'Supuestos'!$C$12)*F$9)*'Supuestos'!$C$22)*'Supuestos'!$C$21)+(((((IF(('Supuestos'!$C$9)=0,0,'Supuestos'!$C$8/('Supuestos'!$C$9)))*'Supuestos'!$C$12)*F$9)*'Supuestos'!$C$24)*'Supuestos'!$C$23)+(((((IF(('Supuestos'!$C$9)=0,0,'Supuestos'!$C$8/('Supuestos'!$C$9)))*'Supuestos'!$C$12)*F$9)*'Supuestos'!$C$26)*'Supuestos'!$C$25)+(((((IF(('Supuestos'!$C$9)=0,0,'Supuestos'!$C$8/('Supuestos'!$C$9)))*'Supuestos'!$C$12)*F$9)*'Supuestos'!$C$28)*'Supuestos'!$C$27)+(((((IF(('Supuestos'!$C$9)=0,0,'Supuestos'!$C$8/('Supuestos'!$C$9)))*'Supuestos'!$C$12)*F$9)*'Supuestos'!$C$30)*'Supuestos'!$C$29))*('Supuestos'!$C$40+'Supuestos'!$C$41+'Supuestos'!$C$42))*(1-'Supuestos'!$C$33-'Supuestos'!$C$34-'Supuestos'!$C$35))-((IF(('Supuestos'!$C$9)=0,0,'Supuestos'!$C$8/('Supuestos'!$C$9)))*'Supuestos'!$C$36)-'Supuestos'!$C$37-'Supuestos'!$C$8) | G12: =((((((((IF(('Supuestos'!$C$9)=0,0,'Supuestos'!$C$8/('Supuestos'!$C$9)))*'Supuestos'!$C$12)*G$9)*$B12)+(((((IF(('Supuestos'!$C$9)=0,0,'Supuestos'!$C$8/('Supuestos'!$C$9)))*'Supuestos'!$C$12)*G$9)*'Supuestos'!$C$18)*'Supuestos'!$C$17)+(((((IF(('Supuestos'!$C$9)=0,0,'Supuestos'!$C$8/('Supuestos'!$C$9)))*'Supuestos'!$C$12)*G$9)*'Supuestos'!$C$20)*'Supuestos'!$C$19)+(((((IF(('Supuestos'!$C$9)=0,0,'Supuestos'!$C$8/('Supuestos'!$C$9)))*'Supuestos'!$C$12)*G$9)*'Supuestos'!$C$22)*'Supuestos'!$C$21)+(((((IF(('Supuestos'!$C$9)=0,0,'Supuestos'!$C$8/('Supuestos'!$C$9)))*'Supuestos'!$C$12)*G$9)*'Supuestos'!$C$24)*'Supuestos'!$C$23)+(((((IF(('Supuestos'!$C$9)=0,0,'Supuestos'!$C$8/('Supuestos'!$C$9)))*'Supuestos'!$C$12)*G$9)*'Supuestos'!$C$26)*'Supuestos'!$C$25)+(((((IF(('Supuestos'!$C$9)=0,0,'Supuestos'!$C$8/('Supuestos'!$C$9)))*'Supuestos'!$C$12)*G$9)*'Supuestos'!$C$28)*'Supuestos'!$C$27)+(((((IF(('Supuestos'!$C$9)=0,0,'Supuestos'!$C$8/('Supuestos'!$C$9)))*'Supuestos'!$C$12)*G$9)*'Supuestos'!$C$30)*'Supuestos'!$C$29))*('Supuestos'!$C$40+'Supuestos'!$C$41+'Supuestos'!$C$42))*(1-'Supuestos'!$C$33-'Supuestos'!$C$34-'Supuestos'!$C$35))-((IF(('Supuestos'!$C$9)=0,0,'Supuestos'!$C$8/('Supuestos'!$C$9)))*'Supuestos'!$C$36)-'Supuestos'!$C$37-'Supuestos'!$C$8)
B13: 67 | C13: =((((((((IF(('Supuestos'!$C$9)=0,0,'Supuestos'!$C$8/('Supuestos'!$C$9)))*'Supuestos'!$C$12)*C$9)*$B13)+(((((IF(('Supuestos'!$C$9)=0,0,'Supuestos'!$C$8/('Supuestos'!$C$9)))*'Supuestos'!$C$12)*C$9)*'Supuestos'!$C$18)*'Supuestos'!$C$17)+(((((IF(('Supuestos'!$C$9)=0,0,'Supuestos'!$C$8/('Supuestos'!$C$9)))*'Supuestos'!$C$12)*C$9)*'Supuestos'!$C$20)*'Supuestos'!$C$19)+(((((IF(('Supuestos'!$C$9)=0,0,'Supuestos'!$C$8/('Supuestos'!$C$9)))*'Supuestos'!$C$12)*C$9)*'Supuestos'!$C$22)*'Supuestos'!$C$21)+(((((IF(('Supuestos'!$C$9)=0,0,'Supuestos'!$C$8/('Supuestos'!$C$9)))*'Supuestos'!$C$12)*C$9)*'Supuestos'!$C$24)*'Supuestos'!$C$23)+(((((IF(('Supuestos'!$C$9)=0,0,'Supuestos'!$C$8/('Supuestos'!$C$9)))*'Supuestos'!$C$12)*C$9)*'Supuestos'!$C$26)*'Supuestos'!$C$25)+(((((IF(('Supuestos'!$C$9)=0,0,'Supuestos'!$C$8/('Supuestos'!$C$9)))*'Supuestos'!$C$12)*C$9)*'Supuestos'!$C$28)*'Supuestos'!$C$27)+(((((IF(('Supuestos'!$C$9)=0,0,'Supuestos'!$C$8/('Supuestos'!$C$9)))*'Supuestos'!$C$12)*C$9)*'Supuestos'!$C$30)*'Supuestos'!$C$29))*('Supuestos'!$C$40+'Supuestos'!$C$41+'Supuestos'!$C$42))*(1-'Supuestos'!$C$33-'Supuestos'!$C$34-'Supuestos'!$C$35))-((IF(('Supuestos'!$C$9)=0,0,'Supuestos'!$C$8/('Supuestos'!$C$9)))*'Supuestos'!$C$36)-'Supuestos'!$C$37-'Supuestos'!$C$8) | D13: =((((((((IF(('Supuestos'!$C$9)=0,0,'Supuestos'!$C$8/('Supuestos'!$C$9)))*'Supuestos'!$C$12)*D$9)*$B13)+(((((IF(('Supuestos'!$C$9)=0,0,'Supuestos'!$C$8/('Supuestos'!$C$9)))*'Supuestos'!$C$12)*D$9)*'Supuestos'!$C$18)*'Supuestos'!$C$17)+(((((IF(('Supuestos'!$C$9)=0,0,'Supuestos'!$C$8/('Supuestos'!$C$9)))*'Supuestos'!$C$12)*D$9)*'Supuestos'!$C$20)*'Supuestos'!$C$19)+(((((IF(('Supuestos'!$C$9)=0,0,'Supuestos'!$C$8/('Supuestos'!$C$9)))*'Supuestos'!$C$12)*D$9)*'Supuestos'!$C$22)*'Supuestos'!$C$21)+(((((IF(('Supuestos'!$C$9)=0,0,'Supuestos'!$C$8/('Supuestos'!$C$9)))*'Supuestos'!$C$12)*D$9)*'Supuestos'!$C$24)*'Supuestos'!$C$23)+(((((IF(('Supuestos'!$C$9)=0,0,'Supuestos'!$C$8/('Supuestos'!$C$9)))*'Supuestos'!$C$12)*D$9)*'Supuestos'!$C$26)*'Supuestos'!$C$25)+(((((IF(('Supuestos'!$C$9)=0,0,'Supuestos'!$C$8/('Supuestos'!$C$9)))*'Supuestos'!$C$12)*D$9)*'Supuestos'!$C$28)*'Supuestos'!$C$27)+(((((IF(('Supuestos'!$C$9)=0,0,'Supuestos'!$C$8/('Supuestos'!$C$9)))*'Supuestos'!$C$12)*D$9)*'Supuestos'!$C$30)*'Supuestos'!$C$29))*('Supuestos'!$C$40+'Supuestos'!$C$41+'Supuestos'!$C$42))*(1-'Supuestos'!$C$33-'Supuestos'!$C$34-'Supuestos'!$C$35))-((IF(('Supuestos'!$C$9)=0,0,'Supuestos'!$C$8/('Supuestos'!$C$9)))*'Supuestos'!$C$36)-'Supuestos'!$C$37-'Supuestos'!$C$8) | E13: =((((((((IF(('Supuestos'!$C$9)=0,0,'Supuestos'!$C$8/('Supuestos'!$C$9)))*'Supuestos'!$C$12)*E$9)*$B13)+(((((IF(('Supuestos'!$C$9)=0,0,'Supuestos'!$C$8/('Supuestos'!$C$9)))*'Supuestos'!$C$12)*E$9)*'Supuestos'!$C$18)*'Supuestos'!$C$17)+(((((IF(('Supuestos'!$C$9)=0,0,'Supuestos'!$C$8/('Supuestos'!$C$9)))*'Supuestos'!$C$12)*E$9)*'Supuestos'!$C$20)*'Supuestos'!$C$19)+(((((IF(('Supuestos'!$C$9)=0,0,'Supuestos'!$C$8/('Supuestos'!$C$9)))*'Supuestos'!$C$12)*E$9)*'Supuestos'!$C$22)*'Supuestos'!$C$21)+(((((IF(('Supuestos'!$C$9)=0,0,'Supuestos'!$C$8/('Supuestos'!$C$9)))*'Supuestos'!$C$12)*E$9)*'Supuestos'!$C$24)*'Supuestos'!$C$23)+(((((IF(('Supuestos'!$C$9)=0,0,'Supuestos'!$C$8/('Supuestos'!$C$9)))*'Supuestos'!$C$12)*E$9)*'Supuestos'!$C$26)*'Supuestos'!$C$25)+(((((IF(('Supuestos'!$C$9)=0,0,'Supuestos'!$C$8/('Supuestos'!$C$9)))*'Supuestos'!$C$12)*E$9)*'Supuestos'!$C$28)*'Supuestos'!$C$27)+(((((IF(('Supuestos'!$C$9)=0,0,'Supuestos'!$C$8/('Supuestos'!$C$9)))*'Supuestos'!$C$12)*E$9)*'Supuestos'!$C$30)*'Supuestos'!$C$29))*('Supuestos'!$C$40+'Supuestos'!$C$41+'Supuestos'!$C$42))*(1-'Supuestos'!$C$33-'Supuestos'!$C$34-'Supuestos'!$C$35))-((IF(('Supuestos'!$C$9)=0,0,'Supuestos'!$C$8/('Supuestos'!$C$9)))*'Supuestos'!$C$36)-'Supuestos'!$C$37-'Supuestos'!$C$8) | F13: =((((((((IF(('Supuestos'!$C$9)=0,0,'Supuestos'!$C$8/('Supuestos'!$C$9)))*'Supuestos'!$C$12)*F$9)*$B13)+(((((IF(('Supuestos'!$C$9)=0,0,'Supuestos'!$C$8/('Supuestos'!$C$9)))*'Supuestos'!$C$12)*F$9)*'Supuestos'!$C$18)*'Supuestos'!$C$17)+(((((IF(('Supuestos'!$C$9)=0,0,'Supuestos'!$C$8/('Supuestos'!$C$9)))*'Supuestos'!$C$12)*F$9)*'Supuestos'!$C$20)*'Supuestos'!$C$19)+(((((IF(('Supuestos'!$C$9)=0,0,'Supuestos'!$C$8/('Supuestos'!$C$9)))*'Supuestos'!$C$12)*F$9)*'Supuestos'!$C$22)*'Supuestos'!$C$21)+(((((IF(('Supuestos'!$C$9)=0,0,'Supuestos'!$C$8/('Supuestos'!$C$9)))*'Supuestos'!$C$12)*F$9)*'Supuestos'!$C$24)*'Supuestos'!$C$23)+(((((IF(('Supuestos'!$C$9)=0,0,'Supuestos'!$C$8/('Supuestos'!$C$9)))*'Supuestos'!$C$12)*F$9)*'Supuestos'!$C$26)*'Supuestos'!$C$25)+(((((IF(('Supuestos'!$C$9)=0,0,'Supuestos'!$C$8/('Supuestos'!$C$9)))*'Supuestos'!$C$12)*F$9)*'Supuestos'!$C$28)*'Supuestos'!$C$27)+(((((IF(('Supuestos'!$C$9)=0,0,'Supuestos'!$C$8/('Supuestos'!$C$9)))*'Supuestos'!$C$12)*F$9)*'Supuestos'!$C$30)*'Supuestos'!$C$29))*('Supuestos'!$C$40+'Supuestos'!$C$41+'Supuestos'!$C$42))*(1-'Supuestos'!$C$33-'Supuestos'!$C$34-'Supuestos'!$C$35))-((IF(('Supuestos'!$C$9)=0,0,'Supuestos'!$C$8/('Supuestos'!$C$9)))*'Supuestos'!$C$36)-'Supuestos'!$C$37-'Supuestos'!$C$8) | G13: =((((((((IF(('Supuestos'!$C$9)=0,0,'Supuestos'!$C$8/('Supuestos'!$C$9)))*'Supuestos'!$C$12)*G$9)*$B13)+(((((IF(('Supuestos'!$C$9)=0,0,'Supuestos'!$C$8/('Supuestos'!$C$9)))*'Supuestos'!$C$12)*G$9)*'Supuestos'!$C$18)*'Supuestos'!$C$17)+(((((IF(('Supuestos'!$C$9)=0,0,'Supuestos'!$C$8/('Supuestos'!$C$9)))*'Supuestos'!$C$12)*G$9)*'Supuestos'!$C$20)*'Supuestos'!$C$19)+(((((IF(('Supuestos'!$C$9)=0,0,'Supuestos'!$C$8/('Supuestos'!$C$9)))*'Supuestos'!$C$12)*G$9)*'Supuestos'!$C$22)*'Supuestos'!$C$21)+(((((IF(('Supuestos'!$C$9)=0,0,'Supuestos'!$C$8/('Supuestos'!$C$9)))*'Supuestos'!$C$12)*G$9)*'Supuestos'!$C$24)*'Supuestos'!$C$23)+(((((IF(('Supuestos'!$C$9)=0,0,'Supuestos'!$C$8/('Supuestos'!$C$9)))*'Supuestos'!$C$12)*G$9)*'Supuestos'!$C$26)*'Supuestos'!$C$25)+(((((IF(('Supuestos'!$C$9)=0,0,'Supuestos'!$C$8/('Supuestos'!$C$9)))*'Supuestos'!$C$12)*G$9)*'Supuestos'!$C$28)*'Supuestos'!$C$27)+(((((IF(('Supuestos'!$C$9)=0,0,'Supuestos'!$C$8/('Supuestos'!$C$9)))*'Supuestos'!$C$12)*G$9)*'Supuestos'!$C$30)*'Supuestos'!$C$29))*('Supuestos'!$C$40+'Supuestos'!$C$41+'Supuestos'!$C$42))*(1-'Supuestos'!$C$33-'Supuestos'!$C$34-'Supuestos'!$C$35))-((IF(('Supuestos'!$C$9)=0,0,'Supuestos'!$C$8/('Supuestos'!$C$9)))*'Supuestos'!$C$36)-'Supuestos'!$C$37-'Supuestos'!$C$8)
B14: 97 | C14: =((((((((IF(('Supuestos'!$C$9)=0,0,'Supuestos'!$C$8/('Supuestos'!$C$9)))*'Supuestos'!$C$12)*C$9)*$B14)+(((((IF(('Supuestos'!$C$9)=0,0,'Supuestos'!$C$8/('Supuestos'!$C$9)))*'Supuestos'!$C$12)*C$9)*'Supuestos'!$C$18)*'Supuestos'!$C$17)+(((((IF(('Supuestos'!$C$9)=0,0,'Supuestos'!$C$8/('Supuestos'!$C$9)))*'Supuestos'!$C$12)*C$9)*'Supuestos'!$C$20)*'Supuestos'!$C$19)+(((((IF(('Supuestos'!$C$9)=0,0,'Supuestos'!$C$8/('Supuestos'!$C$9)))*'Supuestos'!$C$12)*C$9)*'Supuestos'!$C$22)*'Supuestos'!$C$21)+(((((IF(('Supuestos'!$C$9)=0,0,'Supuestos'!$C$8/('Supuestos'!$C$9)))*'Supuestos'!$C$12)*C$9)*'Supuestos'!$C$24)*'Supuestos'!$C$23)+(((((IF(('Supuestos'!$C$9)=0,0,'Supuestos'!$C$8/('Supuestos'!$C$9)))*'Supuestos'!$C$12)*C$9)*'Supuestos'!$C$26)*'Supuestos'!$C$25)+(((((IF(('Supuestos'!$C$9)=0,0,'Supuestos'!$C$8/('Supuestos'!$C$9)))*'Supuestos'!$C$12)*C$9)*'Supuestos'!$C$28)*'Supuestos'!$C$27)+(((((IF(('Supuestos'!$C$9)=0,0,'Supuestos'!$C$8/('Supuestos'!$C$9)))*'Supuestos'!$C$12)*C$9)*'Supuestos'!$C$30)*'Supuestos'!$C$29))*('Supuestos'!$C$40+'Supuestos'!$C$41+'Supuestos'!$C$42))*(1-'Supuestos'!$C$33-'Supuestos'!$C$34-'Supuestos'!$C$35))-((IF(('Supuestos'!$C$9)=0,0,'Supuestos'!$C$8/('Supuestos'!$C$9)))*'Supuestos'!$C$36)-'Supuestos'!$C$37-'Supuestos'!$C$8) | D14: =((((((((IF(('Supuestos'!$C$9)=0,0,'Supuestos'!$C$8/('Supuestos'!$C$9)))*'Supuestos'!$C$12)*D$9)*$B14)+(((((IF(('Supuestos'!$C$9)=0,0,'Supuestos'!$C$8/('Supuestos'!$C$9)))*'Supuestos'!$C$12)*D$9)*'Supuestos'!$C$18)*'Supuestos'!$C$17)+(((((IF(('Supuestos'!$C$9)=0,0,'Supuestos'!$C$8/('Supuestos'!$C$9)))*'Supuestos'!$C$12)*D$9)*'Supuestos'!$C$20)*'Supuestos'!$C$19)+(((((IF(('Supuestos'!$C$9)=0,0,'Supuestos'!$C$8/('Supuestos'!$C$9)))*'Supuestos'!$C$12)*D$9)*'Supuestos'!$C$22)*'Supuestos'!$C$21)+(((((IF(('Supuestos'!$C$9)=0,0,'Supuestos'!$C$8/('Supuestos'!$C$9)))*'Supuestos'!$C$12)*D$9)*'Supuestos'!$C$24)*'Supuestos'!$C$23)+(((((IF(('Supuestos'!$C$9)=0,0,'Supuestos'!$C$8/('Supuestos'!$C$9)))*'Supuestos'!$C$12)*D$9)*'Supuestos'!$C$26)*'Supuestos'!$C$25)+(((((IF(('Supuestos'!$C$9)=0,0,'Supuestos'!$C$8/('Supuestos'!$C$9)))*'Supuestos'!$C$12)*D$9)*'Supuestos'!$C$28)*'Supuestos'!$C$27)+(((((IF(('Supuestos'!$C$9)=0,0,'Supuestos'!$C$8/('Supuestos'!$C$9)))*'Supuestos'!$C$12)*D$9)*'Supuestos'!$C$30)*'Supuestos'!$C$29))*('Supuestos'!$C$40+'Supuestos'!$C$41+'Supuestos'!$C$42))*(1-'Supuestos'!$C$33-'Supuestos'!$C$34-'Supuestos'!$C$35))-((IF(('Supuestos'!$C$9)=0,0,'Supuestos'!$C$8/('Supuestos'!$C$9)))*'Supuestos'!$C$36)-'Supuestos'!$C$37-'Supuestos'!$C$8) | E14: =((((((((IF(('Supuestos'!$C$9)=0,0,'Supuestos'!$C$8/('Supuestos'!$C$9)))*'Supuestos'!$C$12)*E$9)*$B14)+(((((IF(('Supuestos'!$C$9)=0,0,'Supuestos'!$C$8/('Supuestos'!$C$9)))*'Supuestos'!$C$12)*E$9)*'Supuestos'!$C$18)*'Supuestos'!$C$17)+(((((IF(('Supuestos'!$C$9)=0,0,'Supuestos'!$C$8/('Supuestos'!$C$9)))*'Supuestos'!$C$12)*E$9)*'Supuestos'!$C$20)*'Supuestos'!$C$19)+(((((IF(('Supuestos'!$C$9)=0,0,'Supuestos'!$C$8/('Supuestos'!$C$9)))*'Supuestos'!$C$12)*E$9)*'Supuestos'!$C$22)*'Supuestos'!$C$21)+(((((IF(('Supuestos'!$C$9)=0,0,'Supuestos'!$C$8/('Supuestos'!$C$9)))*'Supuestos'!$C$12)*E$9)*'Supuestos'!$C$24)*'Supuestos'!$C$23)+(((((IF(('Supuestos'!$C$9)=0,0,'Supuestos'!$C$8/('Supuestos'!$C$9)))*'Supuestos'!$C$12)*E$9)*'Supuestos'!$C$26)*'Supuestos'!$C$25)+(((((IF(('Supuestos'!$C$9)=0,0,'Supuestos'!$C$8/('Supuestos'!$C$9)))*'Supuestos'!$C$12)*E$9)*'Supuestos'!$C$28)*'Supuestos'!$C$27)+(((((IF(('Supuestos'!$C$9)=0,0,'Supuestos'!$C$8/('Supuestos'!$C$9)))*'Supuestos'!$C$12)*E$9)*'Supuestos'!$C$30)*'Supuestos'!$C$29))*('Supuestos'!$C$40+'Supuestos'!$C$41+'Supuestos'!$C$42))*(1-'Supuestos'!$C$33-'Supuestos'!$C$34-'Supuestos'!$C$35))-((IF(('Supuestos'!$C$9)=0,0,'Supuestos'!$C$8/('Supuestos'!$C$9)))*'Supuestos'!$C$36)-'Supuestos'!$C$37-'Supuestos'!$C$8) | F14: =((((((((IF(('Supuestos'!$C$9)=0,0,'Supuestos'!$C$8/('Supuestos'!$C$9)))*'Supuestos'!$C$12)*F$9)*$B14)+(((((IF(('Supuestos'!$C$9)=0,0,'Supuestos'!$C$8/('Supuestos'!$C$9)))*'Supuestos'!$C$12)*F$9)*'Supuestos'!$C$18)*'Supuestos'!$C$17)+(((((IF(('Supuestos'!$C$9)=0,0,'Supuestos'!$C$8/('Supuestos'!$C$9)))*'Supuestos'!$C$12)*F$9)*'Supuestos'!$C$20)*'Supuestos'!$C$19)+(((((IF(('Supuestos'!$C$9)=0,0,'Supuestos'!$C$8/('Supuestos'!$C$9)))*'Supuestos'!$C$12)*F$9)*'Supuestos'!$C$22)*'Supuestos'!$C$21)+(((((IF(('Supuestos'!$C$9)=0,0,'Supuestos'!$C$8/('Supuestos'!$C$9)))*'Supuestos'!$C$12)*F$9)*'Supuestos'!$C$24)*'Supuestos'!$C$23)+(((((IF(('Supuestos'!$C$9)=0,0,'Supuestos'!$C$8/('Supuestos'!$C$9)))*'Supuestos'!$C$12)*F$9)*'Supuestos'!$C$26)*'Supuestos'!$C$25)+(((((IF(('Supuestos'!$C$9)=0,0,'Supuestos'!$C$8/('Supuestos'!$C$9)))*'Supuestos'!$C$12)*F$9)*'Supuestos'!$C$28)*'Supuestos'!$C$27)+(((((IF(('Supuestos'!$C$9)=0,0,'Supuestos'!$C$8/('Supuestos'!$C$9)))*'Supuestos'!$C$12)*F$9)*'Supuestos'!$C$30)*'Supuestos'!$C$29))*('Supuestos'!$C$40+'Supuestos'!$C$41+'Supuestos'!$C$42))*(1-'Supuestos'!$C$33-'Supuestos'!$C$34-'Supuestos'!$C$35))-((IF(('Supuestos'!$C$9)=0,0,'Supuestos'!$C$8/('Supuestos'!$C$9)))*'Supuestos'!$C$36)-'Supuestos'!$C$37-'Supuestos'!$C$8) | G14: =((((((((IF(('Supuestos'!$C$9)=0,0,'Supuestos'!$C$8/('Supuestos'!$C$9)))*'Supuestos'!$C$12)*G$9)*$B14)+(((((IF(('Supuestos'!$C$9)=0,0,'Supuestos'!$C$8/('Supuestos'!$C$9)))*'Supuestos'!$C$12)*G$9)*'Supuestos'!$C$18)*'Supuestos'!$C$17)+(((((IF(('Supuestos'!$C$9)=0,0,'Supuestos'!$C$8/('Supuestos'!$C$9)))*'Supuestos'!$C$12)*G$9)*'Supuestos'!$C$20)*'Supuestos'!$C$19)+(((((IF(('Supuestos'!$C$9)=0,0,'Supuestos'!$C$8/('Supuestos'!$C$9)))*'Supuestos'!$C$12)*G$9)*'Supuestos'!$C$22)*'Supuestos'!$C$21)+(((((IF(('Supuestos'!$C$9)=0,0,'Supuestos'!$C$8/('Supuestos'!$C$9)))*'Supuestos'!$C$12)*G$9)*'Supuestos'!$C$24)*'Supuestos'!$C$23)+(((((IF(('Supuestos'!$C$9)=0,0,'Supuestos'!$C$8/('Supuestos'!$C$9)))*'Supuestos'!$C$12)*G$9)*'Supuestos'!$C$26)*'Supuestos'!$C$25)+(((((IF(('Supuestos'!$C$9)=0,0,'Supuestos'!$C$8/('Supuestos'!$C$9)))*'Supuestos'!$C$12)*G$9)*'Supuestos'!$C$28)*'Supuestos'!$C$27)+(((((IF(('Supuestos'!$C$9)=0,0,'Supuestos'!$C$8/('Supuestos'!$C$9)))*'Supuestos'!$C$12)*G$9)*'Supuestos'!$C$30)*'Supuestos'!$C$29))*('Supuestos'!$C$40+'Supuestos'!$C$41+'Supuestos'!$C$42))*(1-'Supuestos'!$C$33-'Supuestos'!$C$34-'Supuestos'!$C$35))-((IF(('Supuestos'!$C$9)=0,0,'Supuestos'!$C$8/('Supuestos'!$C$9)))*'Supuestos'!$C$36)-'Supuestos'!$C$37-'Supuestos'!$C$8)
B17: Costo por visita × % de visitas que llegan al checkout → ganancia del mes
B18: La tabla del tráfico: cuánto podés pagar por visita según lo que convierte la página.
B19: Costo por visita ↓ / % visita → checkout → | C19: 0.02 | D19: 0.025 | E19: 0.03 | F19: 0.035 | G19: 0.04 | H19: 0.05
B20: 0.15 | C20: =((((((((IF($B20=0,0,'Supuestos'!$C$8/$B20))*C$19)*'Supuestos'!$C$13)*'Supuestos'!$C$16)+(((((IF($B20=0,0,'Supuestos'!$C$8/$B20))*C$19)*'Supuestos'!$C$13)*'Supuestos'!$C$18)*'Supuestos'!$C$17)+(((((IF($B20=0,0,'Supuestos'!$C$8/$B20))*C$19)*'Supuestos'!$C$13)*'Supuestos'!$C$20)*'Supuestos'!$C$19)+(((((IF($B20=0,0,'Supuestos'!$C$8/$B20))*C$19)*'Supuestos'!$C$13)*'Supuestos'!$C$22)*'Supuestos'!$C$21)+(((((IF($B20=0,0,'Supuestos'!$C$8/$B20))*C$19)*'Supuestos'!$C$13)*'Supuestos'!$C$24)*'Supuestos'!$C$23)+(((((IF($B20=0,0,'Supuestos'!$C$8/$B20))*C$19)*'Supuestos'!$C$13)*'Supuestos'!$C$26)*'Supuestos'!$C$25)+(((((IF($B20=0,0,'Supuestos'!$C$8/$B20))*C$19)*'Supuestos'!$C$13)*'Supuestos'!$C$28)*'Supuestos'!$C$27)+(((((IF($B20=0,0,'Supuestos'!$C$8/$B20))*C$19)*'Supuestos'!$C$13)*'Supuestos'!$C$30)*'Supuestos'!$C$29))*('Supuestos'!$C$40+'Supuestos'!$C$41+'Supuestos'!$C$42))*(1-'Supuestos'!$C$33-'Supuestos'!$C$34-'Supuestos'!$C$35))-((IF($B20=0,0,'Supuestos'!$C$8/$B20))*'Supuestos'!$C$36)-'Supuestos'!$C$37-'Supuestos'!$C$8) | D20: =((((((((IF($B20=0,0,'Supuestos'!$C$8/$B20))*D$19)*'Supuestos'!$C$13)*'Supuestos'!$C$16)+(((((IF($B20=0,0,'Supuestos'!$C$8/$B20))*D$19)*'Supuestos'!$C$13)*'Supuestos'!$C$18)*'Supuestos'!$C$17)+(((((IF($B20=0,0,'Supuestos'!$C$8/$B20))*D$19)*'Supuestos'!$C$13)*'Supuestos'!$C$20)*'Supuestos'!$C$19)+(((((IF($B20=0,0,'Supuestos'!$C$8/$B20))*D$19)*'Supuestos'!$C$13)*'Supuestos'!$C$22)*'Supuestos'!$C$21)+(((((IF($B20=0,0,'Supuestos'!$C$8/$B20))*D$19)*'Supuestos'!$C$13)*'Supuestos'!$C$24)*'Supuestos'!$C$23)+(((((IF($B20=0,0,'Supuestos'!$C$8/$B20))*D$19)*'Supuestos'!$C$13)*'Supuestos'!$C$26)*'Supuestos'!$C$25)+(((((IF($B20=0,0,'Supuestos'!$C$8/$B20))*D$19)*'Supuestos'!$C$13)*'Supuestos'!$C$28)*'Supuestos'!$C$27)+(((((IF($B20=0,0,'Supuestos'!$C$8/$B20))*D$19)*'Supuestos'!$C$13)*'Supuestos'!$C$30)*'Supuestos'!$C$29))*('Supuestos'!$C$40+'Supuestos'!$C$41+'Supuestos'!$C$42))*(1-'Supuestos'!$C$33-'Supuestos'!$C$34-'Supuestos'!$C$35))-((IF($B20=0,0,'Supuestos'!$C$8/$B20))*'Supuestos'!$C$36)-'Supuestos'!$C$37-'Supuestos'!$C$8) | E20: =((((((((IF($B20=0,0,'Supuestos'!$C$8/$B20))*E$19)*'Supuestos'!$C$13)*'Supuestos'!$C$16)+(((((IF($B20=0,0,'Supuestos'!$C$8/$B20))*E$19)*'Supuestos'!$C$13)*'Supuestos'!$C$18)*'Supuestos'!$C$17)+(((((IF($B20=0,0,'Supuestos'!$C$8/$B20))*E$19)*'Supuestos'!$C$13)*'Supuestos'!$C$20)*'Supuestos'!$C$19)+(((((IF($B20=0,0,'Supuestos'!$C$8/$B20))*E$19)*'Supuestos'!$C$13)*'Supuestos'!$C$22)*'Supuestos'!$C$21)+(((((IF($B20=0,0,'Supuestos'!$C$8/$B20))*E$19)*'Supuestos'!$C$13)*'Supuestos'!$C$24)*'Supuestos'!$C$23)+(((((IF($B20=0,0,'Supuestos'!$C$8/$B20))*E$19)*'Supuestos'!$C$13)*'Supuestos'!$C$26)*'Supuestos'!$C$25)+(((((IF($B20=0,0,'Supuestos'!$C$8/$B20))*E$19)*'Supuestos'!$C$13)*'Supuestos'!$C$28)*'Supuestos'!$C$27)+(((((IF($B20=0,0,'Supuestos'!$C$8/$B20))*E$19)*'Supuestos'!$C$13)*'Supuestos'!$C$30)*'Supuestos'!$C$29))*('Supuestos'!$C$40+'Supuestos'!$C$41+'Supuestos'!$C$42))*(1-'Supuestos'!$C$33-'Supuestos'!$C$34-'Supuestos'!$C$35))-((IF($B20=0,0,'Supuestos'!$C$8/$B20))*'Supuestos'!$C$36)-'Supuestos'!$C$37-'Supuestos'!$C$8) | F20: =((((((((IF($B20=0,0,'Supuestos'!$C$8/$B20))*F$19)*'Supuestos'!$C$13)*'Supuestos'!$C$16)+(((((IF($B20=0,0,'Supuestos'!$C$8/$B20))*F$19)*'Supuestos'!$C$13)*'Supuestos'!$C$18)*'Supuestos'!$C$17)+(((((IF($B20=0,0,'Supuestos'!$C$8/$B20))*F$19)*'Supuestos'!$C$13)*'Supuestos'!$C$20)*'Supuestos'!$C$19)+(((((IF($B20=0,0,'Supuestos'!$C$8/$B20))*F$19)*'Supuestos'!$C$13)*'Supuestos'!$C$22)*'Supuestos'!$C$21)+(((((IF($B20=0,0,'Supuestos'!$C$8/$B20))*F$19)*'Supuestos'!$C$13)*'Supuestos'!$C$24)*'Supuestos'!$C$23)+(((((IF($B20=0,0,'Supuestos'!$C$8/$B20))*F$19)*'Supuestos'!$C$13)*'Supuestos'!$C$26)*'Supuestos'!$C$25)+(((((IF($B20=0,0,'Supuestos'!$C$8/$B20))*F$19)*'Supuestos'!$C$13)*'Supuestos'!$C$28)*'Supuestos'!$C$27)+(((((IF($B20=0,0,'Supuestos'!$C$8/$B20))*F$19)*'Supuestos'!$C$13)*'Supuestos'!$C$30)*'Supuestos'!$C$29))*('Supuestos'!$C$40+'Supuestos'!$C$41+'Supuestos'!$C$42))*(1-'Supuestos'!$C$33-'Supuestos'!$C$34-'Supuestos'!$C$35))-((IF($B20=0,0,'Supuestos'!$C$8/$B20))*'Supuestos'!$C$36)-'Supuestos'!$C$37-'Supuestos'!$C$8) | G20: =((((((((IF($B20=0,0,'Supuestos'!$C$8/$B20))*G$19)*'Supuestos'!$C$13)*'Supuestos'!$C$16)+(((((IF($B20=0,0,'Supuestos'!$C$8/$B20))*G$19)*'Supuestos'!$C$13)*'Supuestos'!$C$18)*'Supuestos'!$C$17)+(((((IF($B20=0,0,'Supuestos'!$C$8/$B20))*G$19)*'Supuestos'!$C$13)*'Supuestos'!$C$20)*'Supuestos'!$C$19)+(((((IF($B20=0,0,'Supuestos'!$C$8/$B20))*G$19)*'Supuestos'!$C$13)*'Supuestos'!$C$22)*'Supuestos'!$C$21)+(((((IF($B20=0,0,'Supuestos'!$C$8/$B20))*G$19)*'Supuestos'!$C$13)*'Supuestos'!$C$24)*'Supuestos'!$C$23)+(((((IF($B20=0,0,'Supuestos'!$C$8/$B20))*G$19)*'Supuestos'!$C$13)*'Supuestos'!$C$26)*'Supuestos'!$C$25)+(((((IF($B20=0,0,'Supuestos'!$C$8/$B20))*G$19)*'Supuestos'!$C$13)*'Supuestos'!$C$28)*'Supuestos'!$C$27)+(((((IF($B20=0,0,'Supuestos'!$C$8/$B20))*G$19)*'Supuestos'!$C$13)*'Supuestos'!$C$30)*'Supuestos'!$C$29))*('Supuestos'!$C$40+'Supuestos'!$C$41+'Supuestos'!$C$42))*(1-'Supuestos'!$C$33-'Supuestos'!$C$34-'Supuestos'!$C$35))-((IF($B20=0,0,'Supuestos'!$C$8/$B20))*'Supuestos'!$C$36)-'Supuestos'!$C$37-'Supuestos'!$C$8) | H20: =((((((((IF($B20=0,0,'Supuestos'!$C$8/$B20))*H$19)*'Supuestos'!$C$13)*'Supuestos'!$C$16)+(((((IF($B20=0,0,'Supuestos'!$C$8/$B20))*H$19)*'Supuestos'!$C$13)*'Supuestos'!$C$18)*'Supuestos'!$C$17)+(((((IF($B20=0,0,'Supuestos'!$C$8/$B20))*H$19)*'Supuestos'!$C$13)*'Supuestos'!$C$20)*'Supuestos'!$C$19)+(((((IF($B20=0,0,'Supuestos'!$C$8/$B20))*H$19)*'Supuestos'!$C$13)*'Supuestos'!$C$22)*'Supuestos'!$C$21)+(((((IF($B20=0,0,'Supuestos'!$C$8/$B20))*H$19)*'Supuestos'!$C$13)*'Supuestos'!$C$24)*'Supuestos'!$C$23)+(((((IF($B20=0,0,'Supuestos'!$C$8/$B20))*H$19)*'Supuestos'!$C$13)*'Supuestos'!$C$26)*'Supuestos'!$C$25)+(((((IF($B20=0,0,'Supuestos'!$C$8/$B20))*H$19)*'Supuestos'!$C$13)*'Supuestos'!$C$28)*'Supuestos'!$C$27)+(((((IF($B20=0,0,'Supuestos'!$C$8/$B20))*H$19)*'Supuestos'!$C$13)*'Supuestos'!$C$30)*'Supuestos'!$C$29))*('Supuestos'!$C$40+'Supuestos'!$C$41+'Supuestos'!$C$42))*(1-'Supuestos'!$C$33-'Supuestos'!$C$34-'Supuestos'!$C$35))-((IF($B20=0,0,'Supuestos'!$C$8/$B20))*'Supuestos'!$C$36)-'Supuestos'!$C$37-'Supuestos'!$C$8)
