Workbook

Sheet Inicio
B2: Modelo financiero · Embudo de webinar gratuito
B3: Anuncios → landing de registro → grupo de WhatsApp → webinar en vivo y replay → oferta + bump + programa superior
B5: Para qué sirve este modelo
B6: Es el modelo financiero de un embudo de webinar gratuito: anuncios que llevan a una landing de registro, un grupo de WhatsApp, un webinar en vivo (con replay) donde se presenta una oferta, y un programa superior que se vende después. Con tus números (o con el ejemplo cargado) te dice cuánto vale cada registro que comprás con publicidad, hasta cuánto podés pagar por registro y por cada etapa siguiente, cuánto invertir para una meta de ventas, cuánta caja necesitás y qué palanca mejora más la ganancia.
B7: La unidad que comprás es el registro (lead). El número que manda es el valor neto por registro contra el costo por registro (CPL real y CPL calificado). Después, escalón por escalón: costo por persona en el grupo, costo por asistente en vivo, costo por solicitud y cierre, cada uno con su cantidad y su porcentaje.
B9: Cómo usarlo en 6 pasos
B10: 1. Andá a Supuestos y reemplazá el ejemplo por tus números. Si todavía no tenés datos, dejá el escenario en 1 (conservador) y usá Benchmarks como referencia.
B11: 2. Mirá Resumen: ganancia del lanzamiento, ROAS, el techo y el objetivo de costo por registro, y el semáforo. Después Embudo: todos los pasos en orden con cuántos pasan, qué porcentaje se pierde y cuánto cuesta cada paso.
B12: 3. Abrí Escenarios para ver qué pasa si cambia el precio, la conversión o el costo. Las celdas amarillas de cada tabla se pueden cambiar.
B13: 4. Abrí Sensibilidad para saber qué variable conviene trabajar primero.
B14: 5. Antes de invertir, mirá Proyección 12 meses: la caja necesaria es la plata que tenés que tener para no frenar la pauta mientras cobrás. Si da 0, el embudo se autofinancia.
B15: 6. Cuando el embudo esté andando, completá una columna de Seguimiento por lanzamiento. El semáforo te dice si estás pagando de más por cada registro.
... B46: Este modelo se comparte para que lo uses con tus números. Si lo compartís, dejá esta línea: es la forma de saber de dónde salió.

Sheet Resumen
B2: Resumen: lo que hay que mirar
B3: Todo sale de Modelo con los supuestos del escenario en uso. Cambiá Supuestos y esto se actualiza.
B5: Indicador | C5: Valor | D5: Qué significa
B6: Resultado del lanzamiento
B7: Ganancia del período | C7: ='Modelo'!$C$45 | D7: Cash neto menos costos y menos inversión.
B8: ROAS sobre cash neto | C8: ='Modelo'!$C$47 | D8: Cada dólar invertido vuelve como esto, ya neto.
B9: ROAS sobre facturado | C9: ='Modelo'!$C$46 | D9: Sobre facturado. No decidas con este.
B10: Registros (leads) | C10: ='Modelo'!$C$11 | D10: Registros que compra la pauta.
B11: Asistentes en vivo | C11: ='Modelo'!$C$17 | D11: Asistentes en vivo.
B12: Ventas de la oferta | C12: ='Modelo'!$C$26 | D12: Ventas de la oferta (vivo + replay).
B13: Unit economics
B14: Costo por registro (CPL) | C14: ='Modelo'!$C$10 | D14: CPL real: inversión ÷ registros.
B15: Costo por registro calificado (CPL calificado) | C15: ='Modelo'!$C$13 | D15: CPL calificado: inversión ÷ registros que califican.
B16: Costo por persona en el grupo | C16: ='Modelo'!$C$16 | D16: Lo que te cuesta cada persona que entra al grupo.
B17: Valor neto por registro | C17: ='Modelo'!$C$51 | D17: Lo que vale un registro en cash neto.
B18: Costo por asistente en vivo | C18: ='Modelo'!$C$19 | D18: Lo que te cuesta cada persona que asiste en vivo.
B19: Las dos caras de cada número
B20: Ganancia por visita | C20: ='Modelo'!$C$66 | D20: Lo que te queda por cada visita a la landing. La métrica más valiosa del embudo.
B21: Ganancia por clic | C21: ='Modelo'!$C$67 | D21: Lo que te queda por cada clic. Su par es el costo por clic (Embudo).
B22: Ganancia por lead | C22: ='Modelo'!$C$68 | D22: Lo que te queda por cada registro. Su par es el CPL.
B23: Ganancia por cliente | C23: ='Modelo'!$C$71 | D23: Lo que te queda por cada comprador. Su par es el CPA.
B24: Order value (AOV) | C24: ='Modelo'!$C$35 | D24: Facturado por comprador con bump y programa.
B25: Order value neto (AOV neto) | C25: ='Modelo'!$C$65 | D25: Lo mismo después de comisiones, reembolsos y costos por registro.
B26: Solicitudes (total) | C26: ='Modelo'!$C$23 | D26: Formularios de compra, aplicaciones o pedidos de hablar con un vendedor.
B27: Costo por solicitud | C27: ='Modelo'!$C$25 | D27: Lo que te cuesta cada solicitud.
B28: Costo por comprador (CPA) | C28: ='Modelo'!$C$28 | D28: Lo que te cuesta cada comprador.
B29: Hasta cuánto pagar
B30: Techo de CPL (break-even) | C30: ='Modelo'!$C$52 | D30: CPL donde no ganás ni perdés.
B31: Objetivo de CPL | C31: ='Modelo'!$C$53 | D31: A este CPL o menos estás en verde.
B32: Techo de costo por asistente en vivo | C32: ='Modelo'!$C$55 | D32: Costo máximo por asistente en vivo.
B33: Techo de costo por solicitud | C33: ='Modelo'!$C$57 | D33: Costo máximo por solicitud.
B34: Techo de costo por comprador (CPA máximo) | C34: ='Modelo'!$C$58 | D34: CPA máximo si lo demás se mantiene.
B35: Semáforo del CPL actual | C35: ='Modelo'!$C$61 | D35: Tu CPL actual contra techo y objetivo.
B36: Cuánto invertir y cuánta caja
B37: Inversión necesaria para la meta de ventas (al CPL actual) | C37: ='Modelo'!$C$62 | D37: Para la meta de ventas de Supuestos, al CPL actual.
B38: Caja que hay que tener (peor momento de la proyección) | C38: ='Proyección 12 meses'!$C$18 | D38: Si da 0, el embudo se autofinancia: cada mes cobra más de lo que invierte.
B39: Saldo mínimo de caja con tu caja inicial | C39: ='Proyección 12 meses'!$C$19 | D39: Si es negativo, la caja inicial no alcanza.
B40: Ganancia acumulada en 12 meses | C40: ='Proyección 12 meses'!$C$20 | D40: Con la inversión creciendo según el supuesto.
B42: Recomendación según el semáforo | C42: =IF('Modelo'!$C$61="VERDE","Sostener o subir un escalón (+25 %) y medir 7 días",IF('Modelo'!$C$61="AMARILLO","No subir. Si el costo está bien, el ROAS no llega al objetivo: mirá Sensibilidad. Si no, revisar en orden: CPM, creativo, página",IF('Modelo'!$C$61="ROJO","Bajar un escalón (−25 %) y arreglar antes de volver a subir","")))
B44: Modelo financiero de embudos · creado por Jesús Tassarolo · TooAudience · youtube.com/@JesusTassaroloSinFiltro · v1.2 · octubre 2026

Sheet Embudo
B2: Embudo: todos los pasos, cuántos pasan y, por cada uno, qué pagás, qué te queda y hasta cuánto podrías pagar
B3: Cada fila es un paso del embudo en orden. '% que pasa' compara con el paso anterior (o con el que dice la nota). Tres números por paso: lo que pagás hoy por cada uno (inversión ÷ cantidad), lo que te queda por cada uno (ganancia ÷ cantidad) y lo máximo que podrías pagar (el techo: lo que cada uno genera en cash neto). Techo = costo + ganancia + fijos repartidos.
B5: Paso | C5: Cantidad | D5: % que pasa | E5: % acumulado | F5: Costo por paso (pagás hoy) | G5: Ganancia por paso (te queda) | H5: Techo por paso (máximo a pagar) | I5: Qué se paga acá / cómo se lee
B6: Impresiones del anuncio (por mil) | C6: ='Modelo'!$C$7 | D6: — | E6: — | F6: =IF('Modelo'!$C$7=0,0,'Supuestos'!$C$8*1000/'Modelo'!$C$7) | G6: =IF('Modelo'!$C$7=0,0,'Modelo'!$C$45*1000/'Modelo'!$C$7) | H6: =IF('Modelo'!$C$7=0,0,'Modelo'!$C$51*'Modelo'!$C$11*1000/'Modelo'!$C$7) | I6: Costo por mil impresiones (CPM) y CPM máximo. Palancas: público, frecuencia, horario.
B7: Clics al enlace | C7: ='Modelo'!$C$8 | D7: =IF('Modelo'!$C$7=0,0,'Modelo'!$C$8/'Modelo'!$C$7) | E7: — | F7: =IF('Modelo'!$C$8=0,0,'Supuestos'!$C$8*1/'Modelo'!$C$8) | G7: =IF('Modelo'!$C$8=0,0,'Modelo'!$C$45*1/'Modelo'!$C$8) | H7: =IF('Modelo'!$C$8=0,0,'Modelo'!$C$51*'Modelo'!$C$11*1/'Modelo'!$C$8) | I7: Costo por clic. Palanca: el creativo (CTR).
B8: Visitas a la landing | C8: ='Modelo'!$C$9 | D8: =IF('Modelo'!$C$8=0,0,'Modelo'!$C$9/'Modelo'!$C$8) | E8: — | F8: =IF('Modelo'!$C$9=0,0,'Supuestos'!$C$8*1/'Modelo'!$C$9) | G8: =IF('Modelo'!$C$9=0,0,'Modelo'!$C$45*1/'Modelo'!$C$9) | H8: =IF('Modelo'!$C$9=0,0,'Modelo'!$C$51*'Modelo'!$C$11*1/'Modelo'!$C$9) | I8: Costo por visita. Palanca: velocidad de carga, enlace correcto.
B9: Registros (leads) | C9: ='Modelo'!$C$11 | D9: =IF('Modelo'!$C$9=0,0,'Modelo'!$C$11/'Modelo'!$C$9) | E9: =IF('Modelo'!$C$11=0,0,'Modelo'!$C$11/'Modelo'!$C$11) | F9: =IF('Modelo'!$C$11=0,0,'Supuestos'!$C$8*1/'Modelo'!$C$11) | G9: =IF('Modelo'!$C$11=0,0,'Modelo'!$C$45*1/'Modelo'!$C$11) | H9: =IF('Modelo'!$C$11=0,0,'Modelo'!$C$51*'Modelo'!$C$11*1/'Modelo'!$C$11) | I9: CPL real. Palanca: promesa y formulario del landing.
B10: Registros calificados | C10: ='Modelo'!$C$12 | D10: =IF('Modelo'!$C$11=0,0,'Modelo'!$C$12/'Modelo'!$C$11) | E10: =IF('Modelo'!$C$11=0,0,'Modelo'!$C$12/'Modelo'!$C$11) | F10: =IF('Modelo'!$C$12=0,0,'Supuestos'!$C$8*1/'Modelo'!$C$12) | G10: =IF('Modelo'!$C$12=0,0,'Modelo'!$C$45*1/'Modelo'!$C$12) | H10: =IF('Modelo'!$C$12=0,0,'Modelo'!$C$51*'Modelo'!$C$11*1/'Modelo'!$C$12) | I10: CPL calificado. Sobre registros.
B11: Entran al grupo de WhatsApp | C11: ='Modelo'!$C$15 | D11: =IF('Modelo'!$C$11=0,0,'Modelo'!$C$15/'Modelo'!$C$11) | E11: =IF('Modelo'!$C$11=0,0,'Modelo'!$C$15/'Modelo'!$C$11) | F11: =IF('Modelo'!$C$15=0,0,'Supuestos'!$C$8*1/'Modelo'!$C$15) | G11: =IF('Modelo'!$C$15=0,0,'Modelo'!$C$45*1/'Modelo'!$C$15) | H11: =IF('Modelo'!$C$15=0,0,'Modelo'!$C$51*'Modelo'!$C$11*1/'Modelo'!$C$15) | I11: Costo por persona en el grupo. Sobre registros.
B12: Asisten en vivo | C12: ='Modelo'!$C$17 | D12: =IF('Modelo'!$C$11=0,0,'Modelo'!$C$17/'Modelo'!$C$11) | E12: =IF('Modelo'!$C$11=0,0,'Modelo'!$C$17/'Modelo'!$C$11) | F12: =IF('Modelo'!$C$17=0,0,'Supuestos'!$C$8*1/'Modelo'!$C$17) | G12: =IF('Modelo'!$C$17=0,0,'Modelo'!$C$45*1/'Modelo'!$C$17) | H12: =IF('Modelo'!$C$17=0,0,'Modelo'!$C$51*'Modelo'!$C$11*1/'Modelo'!$C$17) | I12: Costo por asistente en vivo. Sobre registros. Palancas: recordatorios, grupo, horario.
B13: Ven el replay | C13: ='Modelo'!$C$18 | D13: =IF('Modelo'!$C$11=0,0,'Modelo'!$C$18/'Modelo'!$C$11) | E13: =IF('Modelo'!$C$11=0,0,'Modelo'!$C$18/'Modelo'!$C$11) | F13: =IF('Modelo'!$C$18=0,0,'Supuestos'!$C$8*1/'Modelo'!$C$18) | G13: =IF('Modelo'!$C$18=0,0,'Modelo'!$C$45*1/'Modelo'!$C$18) | H13: =IF('Modelo'!$C$18=0,0,'Modelo'!$C$51*'Modelo'!$C$11*1/'Modelo'!$C$18) | I13: Costo por persona que vio el replay. Sobre registros.
B14: Solicitan, de los que estuvieron en vivo | C14: ='Modelo'!$C$21 | D14: =IF('Modelo'!$C$17=0,0,'Modelo'!$C$21/'Modelo'!$C$17) | E14: =IF('Modelo'!$C$11=0,0,'Modelo'!$C$21/'Modelo'!$C$11) | F14: =IF('Modelo'!$C$21=0,0,'Supuestos'!$C$8*1/'Modelo'!$C$21) | G14: =IF('Modelo'!$C$21=0,0,'Modelo'!$C$45*1/'Modelo'!$C$21) | H14: =IF('Modelo'!$C$21=0,0,'Modelo'!$C$51*'Modelo'!$C$11*1/'Modelo'!$C$21) | I14: Formulario de compra, aplicación o vendedor. Sobre asistentes en vivo. Palancas: oferta, pitch.
B15: Solicitan, de los que vieron el replay | C15: ='Modelo'!$C$22 | D15: =IF('Modelo'!$C$18=0,0,'Modelo'!$C$22/'Modelo'!$C$18) | E15: =IF('Modelo'!$C$11=0,0,'Modelo'!$C$22/'Modelo'!$C$11) | F15: =IF('Modelo'!$C$22=0,0,'Supuestos'!$C$8*1/'Modelo'!$C$22) | G15: =IF('Modelo'!$C$22=0,0,'Modelo'!$C$45*1/'Modelo'!$C$22) | H15: =IF('Modelo'!$C$22=0,0,'Modelo'!$C$51*'Modelo'!$C$11*1/'Modelo'!$C$22) | I15: Sobre los que vieron el replay.
B16: Solicitudes (total) | C16: ='Modelo'!$C$23 | D16: =IF('Modelo'!$C$11=0,0,'Modelo'!$C$23/'Modelo'!$C$11) | E16: =IF('Modelo'!$C$11=0,0,'Modelo'!$C$23/'Modelo'!$C$11) | F16: =IF('Modelo'!$C$23=0,0,'Supuestos'!$C$8*1/'Modelo'!$C$23) | G16: =IF('Modelo'!$C$23=0,0,'Modelo'!$C$45*1/'Modelo'!$C$23) | H16: =IF('Modelo'!$C$23=0,0,'Modelo'!$C$51*'Modelo'!$C$11*1/'Modelo'!$C$23) | I16: Costo por solicitud. Sobre registros.
B17: Compran la oferta | C17: ='Modelo'!$C$26 | D17: =IF('Modelo'!$C$23=0,0,'Modelo'!$C$26/'Modelo'!$C$23) | E17: =IF('Modelo'!$C$11=0,0,'Modelo'!$C$26/'Modelo'!$C$11) | F17: =IF('Modelo'!$C$26=0,0,'Supuestos'!$C$8*1/'Modelo'!$C$26) | G17: =IF('Modelo'!$C$26=0,0,'Modelo'!$C$45*1/'Modelo'!$C$26) | H17: =IF('Modelo'!$C$26=0,0,'Modelo'!$C$51*'Modelo'!$C$11*1/'Modelo'!$C$26) | I17: CPA: costo por comprador. Sobre solicitudes (cierre). Palancas: seguimiento, vendedor, forma de pago.
B18: Toman el bump | C18: ='Modelo'!$C$30 | D18: =IF('Modelo'!$C$26=0,0,'Modelo'!$C$30/'Modelo'!$C$26) | E18: =IF('Modelo'!$C$11=0,0,'Modelo'!$C$30/'Modelo'!$C$11) | F18: sin costo propio | G18: — | H18: — | I18: Sobre compradores. Se pagó con el CPA; suma al AOV.
B19: Pasan al programa superior | C19: ='Modelo'!$C$32 | D19: =IF('Modelo'!$C$26=0,0,'Modelo'!$C$32/'Modelo'!$C$26) | E19: =IF('Modelo'!$C$11=0,0,'Modelo'!$C$32/'Modelo'!$C$11) | F19: sin costo propio | G19: — | H19: — | I19: Sobre compradores.
B21: Comprobalo con la fila de la unidad: costo + ganancia + fijos repartidos = techo | F21: =F9 | G21: =G9 | H21: =F9+G9+'Supuestos'!$C$38/'Modelo'!$C$11 | I21: Techo = costo + ganancia + fijos ÷ unidades. Lo que falta entre (costo + ganancia) y el techo son los costos fijos repartidos entre las unidades.
B22: Cómo se lee
B23: Cantidad: cuántas acciones o personas hubo en ese paso con los supuestos del escenario en uso.
B24: % que pasa: de los que estaban en el paso anterior (o en el paso que indica la nota), cuántos llegan a este. % acumulado: cuántos llegan a este paso por cada 100 unidades que compra la pauta.
B25: Costo por paso: inversión ÷ cantidad. Es lo que te está costando hoy cada persona que llega a ese paso.
B26: Ganancia por paso: ganancia del período ÷ cantidad. Lo que te queda por cada persona de ese paso después de pagar la pauta, las comisiones, los reembolsos y los fijos. La ganancia por visita es la métrica más valiosa del embudo: resume todo lo que pasa después.
B27: Techo por paso: lo que cada persona de ese paso genera en cash neto (cash neto menos costos por unidad, dividido por la cantidad). Es lo máximo que podrías pagar por ese paso antes de que la ganancia llegue a cero, si lo demás se mantiene. Por eso siempre es mayor que la ganancia: techo = costo + ganancia + fijos repartidos.
B28: Los bumps, las OTOs y la ascensión no tienen costo propio: se pagan con el CPA del comprador principal y se miden por lo que suman al AOV.

Sheet Supuestos
B2: Supuestos
B3: Celdas amarillas = las editás vos. Celdas azules = se calculan solas. Cada fila dice en qué unidad va y de dónde sale el valor del ejemplo.
B5: Supuesto | C5: Valor en uso | D5: Conservador | E5: Base | F5: Optimista | G5: Unidad | H5: Nota / fuente del ejemplo
B6: Escenario en uso (1 = conservador · 2 = base · 3 = optimista) | C6: 2 | G6: 1 / 2 / 3 | H6: Cambia todas las filas que tienen tres valores. Si una fila no tiene tres valores, se usa el de 'Valor en uso'.
B7: 1. Inversión y tráfico
B8: Inversión en publicidad por lanzamiento | C8: 6000 | G8: USD / lanzamiento | H8: Un lanzamiento = un ciclo de captación + webinar + venta (en el ejemplo, una semana).
B9: Lanzamientos por mes (para la proyección) | C9: 4 | G9: lanzamientos / mes | H9: Cuántos lanzamientos como este hacés por mes. La proyección multiplica inversión, costos fijos y ventas por este número.
B10: CPM (costo por mil impresiones) | C10: =IF('Supuestos'!$C$6=1,D10,IF('Supuestos'!$C$6=2,E10,F10)) | D10: 6 | E10: 4.5 | F10: 3.5 | G10: USD | H10: Lo que cobra Meta por mil impresiones. Hispano: 3 a 7.
B11: CTR al enlace | C11: =IF('Supuestos'!$C$6=1,D11,IF('Supuestos'!$C$6=2,E11,F11)) | D11: 0.016 | E11: 0.022 | F11: 0.03 | G11: % | H11: Clics en el enlace ÷ impresiones.
B12: % de clics que cargan la landing | C12: 0.9 | G12: % | H12: Siempre menor a 100 %: una parte cierra antes de que cargue.
B14: 2. Landing de registro
B15: % de visitas que se registran | C15: =IF('Supuestos'!$C$6=1,D15,IF('Supuestos'!$C$6=2,E15,F15)) | D15: 0.18 | E15: 0.23 | F15: 0.3 | G15: % | H15: La conversión del landing. Con nombre + WhatsApp: 20 a 30 %.
B16: % de registros que califican (si el formulario tiene una pregunta que califica) | C16: =IF('Supuestos'!$C$6=1,D16,IF('Supuestos'!$C$6=2,E16,F16)) | D16: 0.5 | E16: 0.6 | F16: 0.7 | G16: % | H16: Si no calificás en el formulario, poné 100 %. Sirve para ver el CPL calificado además del CPL real.
B18: 3. Grupo de WhatsApp y asistencia
B19: % de registrados que entran al grupo de WhatsApp | C19: =IF('Supuestos'!$C$6=1,D19,IF('Supuestos'!$C$6=2,E19,F19)) | D19: 0.55 | E19: 0.67 | F19: 0.78 | G19: % | H19: Si no usás grupo, poné 0 %: no afecta las ventas en este modelo, solo el techo por persona en el grupo.
B20: % de registrados que asisten en vivo | C20: =IF('Supuestos'!$C$6=1,D20,IF('Supuestos'!$C$6=2,E20,F20)) | D20: 0.11 | E20: 0.15 | F20: 0.2 | G20: % | H20: Tráfico frío hispano: 10 a 20 %. En B2B USA promedia 33 %.
B21: % de registrados que ven el replay | C21: =IF('Supuestos'!$C$6=1,D21,IF('Supuestos'!$C$6=2,E21,F21)) | D21: 0.4 | E21: 0.55 | F21: 0.7 | G21: % | H21: Sin contar a los que fueron en vivo.
B23: 4. Oferta y escalera
B24: Oferta del webinar: precio | C24: 297 | G24: USD | H24: El producto que se presenta en el webinar.
B25: % de asistentes en vivo que solicitan (formulario de compra, de aplicación o hablar con un vendedor) | C25: =IF('Supuestos'!$C$6=1,D25,IF('Supuestos'!$C$6=2,E25,F25)) | D25: 0.06 | E25: 0.1 | F25: 0.15 | G25: % | H25: La solicitud es lo que pasa en el webinar cuando se presenta la oferta. Incluye la ventana de 72 h.
B26: % de los que ven el replay que solicitan | C26: =IF('Supuestos'!$C$6=1,D26,IF('Supuestos'!$C$6=2,E26,F26)) | D26: 0.012 | E26: 0.025 | F26: 0.04 | G26: % | H26: Mucho menor que en vivo.
B27: % de solicitudes que terminan en compra | C27: =IF('Supuestos'!$C$6=1,D27,IF('Supuestos'!$C$6=2,E27,F27)) | D27: 0.3 | E27: 0.4 | F27: 0.5 | G27: % | H27: Con compra directa en el formulario suele ser alto; con vendedor o aplicación, 30 a 50 %.
B28: Bump en el checkout: precio | C28: 47 | G28: USD | H28: Oferta extra con una casilla en el checkout.
B29: Bump: % de compradores que lo toman | C29: =IF('Supuestos'!$C$6=1,D29,IF('Supuestos'!$C$6=2,E29,F29)) | D29: 0.12 | E29: 0.2 | F29: 0.3 | G29: %
B30: Programa superior: precio | C30: 997 | G30: USD | H30: Se vende después de la oferta, por llamada o por ascenso.
B31: Programa superior: % de compradores que lo toman | C31: =IF('Supuestos'!$C$6=1,D31,IF('Supuestos'!$C$6=2,E31,F31)) | D31: 0.03 | E31: 0.05 | F31: 0.08 | G31: % | H31: Sobre compradores de la oferta.
B33: 5. Costos
B34: Comisión de la pasarela o plataforma de pago | C34: 0.1 | G34: % del cash | H34: Hotmart, Stripe, Mercado Pago: lo que se queda la plataforma.
B35: Comisión del equipo de ventas | C35: 0 | G35: % del cash | H35: Sobre el cash cobrado. Si vendés el programa superior por llamada, poné acá la comisión del closer (10 a 15 % de esa parte).
B36: Reembolsos y contracargos | C36: 0.05 | G36: % del cash | H36: 5 % es normal en productos digitales. Más de 10 % es un problema de oferta o de expectativa.
B37: Costos por registro (herramientas, WhatsApp, IA) | C37: 0.1 | G37: USD / registro | H37: WhatsApp API, email, IA: lo que pagás por cada registro.
B38: Costos fijos por lanzamiento | C38: 1200 | G38: USD / lanzamiento | H38: Equipo, herramientas, edición: lo que pagás aunque no vendas.
B40: 6. Cobranza
B41: % del facturado que entra en el mes 1 | C41: 0.7 | G41: % | H41: Con cuotas, el 70 % entra el primer mes y el resto en los dos siguientes.
B42: % que entra en el mes 2 | C42: 0.15 | G42: % | H42: Cuotas o pagos diferidos.
B43: % que entra en el mes 3 | C43: 0.15 | G43: % | H43: Los tres deben sumar 100 %.
B45: 7. Objetivos y proyección
B46: ROAS objetivo sobre cash neto | C46: 2 | G46: x | H46: El retorno mínimo que querés por cada dólar invertido, después de comisiones y reembolsos. Entra en el semáforo: sin llegar a este ROAS no hay verde.
B47: Margen de seguridad | C47: 0.3 | G47: % | H47: Colchón entre el techo (donde no ganás ni perdés) y el objetivo. 30 % es el estándar que usamos.
B48: Meta de ventas del producto principal | C48: 60 | G48: ventas / lanzamiento | H48: Para calcular cuánto invertir.
...

Sheet Modelo
B2: Modelo: la cadena completa del embudo
B3: Cada fila es una etapa o un resultado. No se edita: todo sale de Supuestos. La columna de la derecha dice cómo se calcula.
B5: Etapa / resultado | C5: Valor | D5: Cómo se calcula
B6: Tráfico y registros
B7: Impresiones | C7: =IF('Supuestos'!$C$10=0,0,'Supuestos'!$C$8/'Supuestos'!$C$10*1000) | D7: Inversión ÷ CPM × 1.000.
B8: Clics al enlace | C8: ='Modelo'!$C$7*'Supuestos'!$C$11 | D8: Impresiones × CTR.
B9: Visitas a la landing | C9: ='Modelo'!$C$8*'Supuestos'!$C$12 | D9: Clics × % que carga.
B10: Costo por registro (CPL) | C10: =IF('Supuestos'!$C$11*'Supuestos'!$C$12*'Supuestos'!$C$15=0,0,'Supuestos'!$C$10/1000/('Supuestos'!$C$11*'Supuestos'!$C$12*'Supuestos'!$C$15)) | D10: CPM ÷ 1.000 ÷ (CTR × clic→visita × conversión del landing).
B11: Registros (leads) | C11: =IF('Modelo'!$C$10=0,0,'Supuestos'!$C$8/'Modelo'!$C$10) | D11: Inversión ÷ CPL.
B12: Registros calificados | C12: ='Modelo'!$C$11*'Supuestos'!$C$16 | D12: Registros × % que califica.
B13: Costo por registro calificado (CPL calificado) | C13: =IF('Modelo'!$C$12=0,0,'Supuestos'!$C$8/'Modelo'!$C$12) | D13: Inversión ÷ registros calificados.
B14: Grupo y asistencia
B15: Personas en el grupo de WhatsApp | C15: ='Modelo'!$C$11*'Supuestos'!$C$19 | D15: Registros × % que entra.
B16: Costo por persona en el grupo | C16: =IF('Modelo'!$C$15=0,0,'Supuestos'!$C$8/'Modelo'!$C$15) | D16: Inversión ÷ personas en el grupo.
B17: Asistentes en vivo | C17: ='Modelo'!$C$11*'Supuestos'!$C$20 | D17: Registros × show rate en vivo.
B18: Vieron el replay | C18: ='Modelo'!$C$11*'Supuestos'!$C$21 | D18: Registros × % que ve el replay.
B19: Costo por asistente en vivo | C19: =IF('Modelo'!$C$17=0,0,'Supuestos'!$C$8/'Modelo'!$C$17) | D19: Inversión ÷ asistentes en vivo.
B20: Solicitudes (formulario de compra, aplicación o vendedor), ventas y facturación
B21: Solicitudes: en vivo | C21: ='Modelo'!$C$17*'Supuestos'!$C$25 | D21: Asistentes en vivo × % que solicita.
B22: Solicitudes: replay | C22: ='Modelo'!$C$18*'Supuestos'!$C$26 | D22: Replay × % que solicita.
B23: Solicitudes (total) | C23: ='Modelo'!$C$21+'Modelo'!$C$22 | D23: En vivo + replay.
B24: % de registros que solicitan | C24: =IF('Modelo'!$C$11=0,0,'Modelo'!$C$23/'Modelo'!$C$11) | D24: Solicitudes ÷ registros.
B25: Costo por solicitud | C25: =IF('Modelo'!$C$23=0,0,'Supuestos'!$C$8/'Modelo'!$C$23) | D25: Inversión ÷ solicitudes.
B26: Ventas de la oferta | C26: ='Modelo'!$C$23*'Supuestos'!$C$27 | D26: Solicitudes × % que termina en compra.
B27: % de registros que compran | C27: =IF('Modelo'!$C$11=0,0,'Modelo'!$C$26/'Modelo'!$C$11) | D27: Ventas ÷ registros.
B28: Costo por comprador (CPA) | C28: =IF('Modelo'!$C$26=0,0,'Supuestos'!$C$8/'Modelo'!$C$26) | D28: Inversión ÷ ventas de la oferta.
B29: Facturado: oferta | C29: ='Modelo'!$C$26*'Supuestos'!$C$24 | D29: Ventas × precio.
B30: Ventas: bump | C30: ='Modelo'!$C$26*'Supuestos'!$C$29 | D30: Compradores × % que lo toma.
B31: Facturado: bump | C31: ='Modelo'!$C$30*'Supuestos'!$C$28 | D31: Ventas × precio.
B32: Ventas: programa superior | C32: ='Modelo'!$C$26*'Supuestos'!$C$31 | D32: Compradores × % que asciende.
B33: Facturado: programa superior | C33: ='Modelo'!$C$32*'Supuestos'!$C$30 | D33: Ventas × precio.
B34: Facturado total | C34: ='Modelo'!$C$29+'Modelo'!$C$31+'Modelo'!$C$33 | D34: Oferta + bump + programa.
B35: Facturado por comprador (AOV) | C35: =IF('Modelo'!$C$26=0,0,'Modelo'!$C$34/'Modelo'!$C$26) | D35: Facturado ÷ ventas de la oferta.
B36: Ventas de la oferta por registro (para la proyección) | C36: =IF('Modelo'!$C$11=0,0,'Modelo'!$C$26/'Modelo'!$C$11) | D36: Igual a '% de registros que compran'.
B37: Facturado por registro | C37: =IF('Modelo'!$C$11=0,0,'Modelo'!$C$34/'Modelo'!$C$11) | D37: Facturado ÷ registros.
B38: Cash, costos y ganancia del período
B39: Cash a cobrar (facturado × cobranza completa) | C39: ='Modelo'!$C$34*('Supuestos'!$C$41+'Supuestos'!$C$42+'Supuestos'!$C$43) | D39: Facturado × (mes 1 + mes 2 + mes 3). Si la cobranza suma 100 %, es igual al facturado.
B40: Cash que entra en el primer mes | C40: ='Modelo'!$C$34*'Supuestos'!$C$41 | D40: Facturado × % del mes 1.
B41: Comisiones (pasarela + ventas) | C41: ='Modelo'!$C$39*('Supuestos'!$C$34+'Supuestos'!$C$35) | D41: Cash × (pasarela + equipo de ventas).
B42: Reembolsos | C42: ='Modelo'!$C$39*'Supuestos'!$C$36 | D42: Cash × % de reembolsos.
...

Sheet Escenarios
B2: Escenarios: qué pasa si cambian el precio, la conversión o el costo
B3: Las celdas amarillas de cada tabla (fila y columna) se pueden cambiar. Verde = ganancia, amarillo = cerca del cero, rojo = pérdida. Todo lo demás queda como en Supuestos.
B5: Umbral de 'cerca del cero' (inversión × margen de seguridad) | C5: ='Supuestos'!$C$8*'Supuestos'!$C$47
B7: Precio de la oferta × % de solicitudes que terminan en compra → ganancia del lanzamiento
B8: A más precio, menos cierre: la tabla muestra qué combinación gana.
B9: Precio ↓ / % solicitud → compra → | C9: 0.25 | D9: 0.3 | E9: 0.4 | F9: 0.5 | G9: 0.6
B10: 97 | C10: =((((((((((IF((IF('Supuestos'!$C$11*'Supuestos'!$C$12*'Supuestos'!$C$15=0,0,'Supuestos'!$C$10/1000/('Supuestos'!$C$11*'Supuestos'!$C$12*'Supuestos'!$C$15)))=0,0,'Supuestos'!$C$8/(IF('Supuestos'!$C$11*'Supuestos'!$C$12*'Supuestos'!$C$15=0,0,'Supuestos'!$C$10/1000/('Supuestos'!$C$11*'Supuestos'!$C$12*'Supuestos'!$C$15)))))*'Supuestos'!$C$20)*'Supuestos'!$C$25)+(((IF((IF('Supuestos'!$C$11*'Supuestos'!$C$12*'Supuestos'!$C$15=0,0,'Supuestos'!$C$10/1000/('Supuestos'!$C$11*'Supuestos'!$C$12*'Supuestos'!$C$15)))=0,0,'Supuestos'!$C$8/(IF('Supuestos'!$C$11*'Supuestos'!$C$12*'Supuestos'!$C$15=0,0,'Supuestos'!$C$10/1000/('Supuestos'!$C$11*'Supuestos'!$C$12*'Supuestos'!$C$15)))))*'Supuestos'!$C$21)*'Supuestos'!$C$26))*C$9)*$B10)+(((((((IF((IF('Supuestos'!$C$11*'Supuestos'!$C$12*'Supuestos'!$C$15=0,0,'Supuestos'!$C$10/1000/('Supuestos'!$C$11*'Supuestos'!$C$12*'Supuestos'!$C$15)))=0,0,'Supuestos'!$C$8/(IF('Supuestos'!$C$11*'Supuestos'!$C$12*'Supuestos'!$C$15=0,0,'Supuestos'!$C$10/1000/('Supuestos'!$C$11*'Supuestos'!$C$12*'Supuestos'!$C$15)))))*'Supuestos'!$C$20)*'Supuestos'!$C$25)+(((IF((IF('Supuestos'!$C$11*'Supuestos'!$C$12*'Supuestos'!$C$15=0,0,'Supuestos'!$C$10/1000/('Supuestos'!$C$11*'Supuestos'!$C$12*'Supuestos'!$C$15)))=0,0,'Supuestos'!$C$8/(IF('Supuestos'!$C$11*'Supuestos'!$C$12*'Supuestos'!$C$15=0,0,'Supuestos'!$C$10/1000/('Supuestos'!$C$11*'Supuestos'!$C$12*'Supuestos'!$C$15)))))*'Supuestos'!$C$21)*'Supuestos'!$C$26))*C$9)*'Supuestos'!$C$29)*'Supuestos'!$C$28)+(((((((IF((IF('Supuestos'!$C$11*'Supuestos'!$C$12*'Supuestos'!$C$15=0,0,'Supuestos'!$C$10/1000/('Supuestos'!$C$11*'Supuestos'!$C$12*'Supuestos'!$C$15)))=0,0,'Supuestos'!$C$8/(IF('Supuestos'!$C$11*'Supuestos'!$C$12*'Supuestos'!$C$15=0,0,'Supuestos'!$C$10/1000/('Supuestos'!$C$11*'Supuestos'!$C$12*'Supuestos'!$C$15)))))*'Supuestos'!$C$20)*'Supuestos'!$C$25)+(((IF((IF('Supuestos'!$C$11*'Supuestos'!$C$12*'Supuestos'!$C$15=0,0,'Supuestos'!$C$10/1000/('Supuestos'!$C$11*'Supuestos'!$C$12*'Supuestos'!$C$15)))=0,0,'Supuestos'!$C$8/(IF('Supuestos'!$C$11*'Supuestos'!$C$12*'Supuestos'!$C$15=0,0,'Supuestos'!$C$10/1000/('Supuestos'!$C$11*'Supuestos'!$C$12*'Supuestos'!$C$15)))))*'Supuestos'!$C$21)*'Supuestos'!$C$26))*C$9)*'Supuestos'!$C$31)*'Supuestos'!$C$30))*('Supuestos'!$C$41+'Supuestos'!$C$42+'Supuestos'!$C$43))*(1-'Supuestos'!$C$34-'Supuestos'!$C$35-'Supuestos'!$C$36))-((IF((IF('Supuestos'!$C$11*'Supuestos'!$C$12*'Supuestos'!$C$15=0,0,'Supuestos'!$C$10/1000/('Supuestos'!$C$11*'Supuestos'!$C$12*'Supuestos'!$C$15)))=0,0,'Supuestos'!$C$8/(IF('Supuestos'!$C$11*'Supuestos'!$C$12*'Supuestos'!$C$15=0,0,'Supuestos'!$C$10/1000/('Supuestos'!$C$11*'Supuestos'!$C$12*'Supuestos'!$C$15)))))*'Supuestos'!$C$37)-'Supuestos'!$C$38-'Supuestos'!$C$8) | D10: =((((((((((IF((IF('Supuestos'!$C$11*'Supuestos'!$C$12*'Supuestos'!$C$15=0,0,'Supuestos'!$C$10/1000/('Supuestos'!$C$11*'Supuestos'!$C$12*'Supuestos'!$C$15)))=0,0,'Supuestos'!$C$8/(IF('Supuestos'!$C$11*'Supuestos'!$C$12*'Supuestos'!$C$15=0,0,'Supuestos'!$C$10/1000/('Supuestos'!$C$11*'Supuestos'!$C$12*'Supuestos'!$C$15)))))*'Supuestos'!$C$20)*'Supuestos'!$C$25)+(((IF((IF('Supuestos'!$C$11*'Supuestos'!$C$12*'Supuestos'!$C$15=0,0,'Supuestos'!$C$10/1000/('Supuestos'!$C$11*'Supuestos'!$C$12*'Supuestos'!$C$15)))=0,0,'Supuestos'!$C$8/(IF('Supuestos'!$C$11*'Supuestos'!$C$12*'Supuestos'!$C$15=0,0,'Supuestos'!$C$10/1000/('Supuestos'!$C$11*'Supuestos'!$C$12*'Supuestos'!$C$15)))))*'Supuestos'!$C$21)*'Supuestos'!$C$26))*D$9)*$B10)+(((((((IF((IF('Supuestos'!$C$11*'Supuestos'!$C$12*'Supuestos'!$C$15=0,0,'Supuestos'!$C$10/1000/('Supuestos'!$C$11*'Supuestos'!$C$12*'Supuestos'!$C$15)))=0,0,'Supuestos'!$C$8/(IF('Supuestos'!$C$11*'Supuestos'!$C$12*'Supuestos'!$C$15=0,0,'Supuestos'!$C$10/1000/('Supuestos'!$C$11*'Supuestos'!$C$12*'Supuestos'!$C$15)))))*'Supuestos'!$C$20)*'Supuestos'!$C$25)+(((IF((IF('Supuestos'!$C$11*'Supuestos'!$C$12*'Supuestos'!$C$15=0,0,'Supuestos'!$C$10/1000/('Supuestos'!$C$11*'Supuestos'!$C$12*'Supuestos'!$C$15)))=0,0,'Supuestos'!$C$8/(IF('Supuestos'!$C$11*'Supuestos'!$C$12*'Supuestos'!$C$15=0,0,'Supuestos'!$C$10/1000/('Supuestos'!$C$11*'Supuestos'!$C$12*'Supuestos'!$C$15)))))*'Supuestos'!$C$21)*'Supuestos'!$C$26))*D$9)*'Supuestos'!$C$29)*'Supuestos'!$C$28)+(((((((IF((IF('Supuestos'!$C$11*'Supuestos'!$C$12*'Supuestos'!$C$15=0,0,'Supuestos'!$C$10/1000/('Supuestos'!$C$11*'Supuestos'!$C$12*'Supuestos'!$C$15)))=0,0,'Supuestos'!$C$8/(IF('Supuestos'!$C$11*'Supuestos'!$C$12*'Supuestos'!$C$15=0,0,'Supuestos'!$C$10/1000/('Supuestos'!$C$11*'Supuestos'!$C$12*'Supuestos'!$C$15)))))*'Supuestos'!$C$20)*'Supuestos'!$C$25)+(((IF((IF('Supuestos'!$C$11*'Supuestos'!$C$12*'Supuestos'!$C$15=0,0,'Supuestos'!$C$10/1000/('Supuestos'!$C$11*'Supuestos'!$C$12*'Supuestos'!$C$15)))=0,0,'Supuestos'!$C$8/(IF('Supuestos'!$C$11*'Supuestos'!$C$12*'Supuestos'!$C$15=0,0,'Supuestos'!$C$10/1000/('Supuestos'!$C$11*'Supuestos'!$C$12*'Supuestos'!$C$15)))))*'Supuestos'!$C$21)*'Supuestos'!$C$26))*D$9)*'Supuestos'!$C$31)*'Supuestos'!$C$30))*('Supuestos'!$C$41+'Supuestos'!$C$42+'Supuestos'!$C$43))*(1-'Supuestos'!$C$34-'Supuestos'!$C$35-'Supuestos'!$C$36))-((IF((IF('Supuestos'!$C$11*'Supuestos'!$C$12*'Supuestos'!$C$15=0,0,'Supuestos'!$C$10/1000/('Supuestos'!$C$11*'Supuestos'!$C$12*'Supuestos'!$C$15)))=0,0,'Supuestos'!$C$8/(IF('Supuestos'!$C$11*'Supuestos'!$C$12*'Supuestos'!$C$15=0,0,'Supuestos'!$C$10/1000/('Supuestos'!$C$11*'Supuestos'!$C$12*'Supuestos'!$C$15)))))*'Supuestos'!$C$37)-'Supuestos'!$C$38-'Supuestos'!$C$8) | E10: =((((((((((IF((IF('Supuestos'!$C$11*'Supuestos'!$C$12*'Supuestos'!$C$15=0,0,'Supuestos'!$C$10/1000/('Supuestos'!$C$11*'Supuestos'!$C$12*'Supuestos'!$C$15)))=0,0,'Supuestos'!$C$8/(IF('Supuestos'!$C$11*'Supuestos'!$C$12*'Supuestos'!$C$15=0,0,'Supuestos'!$C$10/1000/('Supuestos'!$C$11*'Supuestos'!$C$12*'Supuestos'!$C$15)))))*'Supuestos'!$C$20)*'Supuestos'!$C$25)+(((IF((IF('Supuestos'!$C$11*'Supuestos'!$C$12*'Supuestos'!$C$15=0,0,'Supuestos'!$C$10/1000/('Supuestos'!$C$11*'Supuestos'!$C$12*'Supuestos'!$C$15)))=0,0,'Supuestos'!$C$8/(IF('Supuestos'!$C$11*'Supuestos'!$C$12*'Supuestos'!$C$15=0,0,'Supuestos'!$C$10/1000/('Supuestos'!$C$11*'Supuestos'!$C$12*'Supuestos'!$C$15)))))*'Supuestos'!$C$21)*'Supuestos'!$C$26))*E$9)*$B10)+(((((((IF((IF('Supuestos'!$C$11*'Supuestos'!$C$12*'Supuestos'!$C$15=0,0,'Supuestos'!$C$10/1000/('Supuestos'!$C$11*'Supuestos'!$C$12*'Supuestos'!$C$15)))=0,0,'Supuestos'!$C$8/(IF('Supuestos'!$C$11*'Supuestos'!$C$12*'Supuestos'!$C$15=0,0,'Supuestos'!$C$10/1000/('Supuestos'!$C$11*'Supuestos'!$C$12*'Supuestos'!$C$15)))))*'Supuestos'!$C$20)*'Supuestos'!$C$25)+(((IF((IF('Supuestos'!$C$11*'Supuestos'!$C$12*'Supuestos'!$C$15=0,0,'Supuestos'!$C$10/1000/('Supuestos'!$C$11*'Supuestos'!$C$12*'Supuestos'!$C$15)))=0,0,'Supuestos'!$C$8/(IF('Supuestos'!$C$11*'Supuestos'!$C$12*'Supuestos'!$C$15=0,0,'Supuestos'!$C$10/1000/('Supuestos'!$C$11*'Supuestos'!$C$12*'Supuestos'!$C$15)))))*'Supuestos'!$C$21)*'Supuestos'!$C$26))*E$9)*'Supuestos'!$C$29)*'Supuestos'!$C$28)+(((((((IF((IF('Supuestos'!$C$11*'Supuestos'!$C$12*'Supuestos'!$C$15=0,0,'Supuestos'!$C$10/1000/('Supuestos'!$C$11*'Supuestos'!$C$12*'Supuestos'!$C$15)))=0,0,'Supuestos'!$C$8/(IF('Supuestos'!$C$11*'Supuestos'!$C$12*'Supuestos'!$C$15=0,0,'Supuestos'!$C$10/1000/('Supuestos'!$C$11*'Supuestos'!$C$12*'Supuestos'!$C$15)))))*'Supuestos'!$C$20)*'Supuestos'!$C$25)+(((IF((IF('Supuestos'!$C$11*'Supuestos'!$C$12*'Supuestos'!$C$15=0,0,'Supuestos'!$C$10/1000/('Supuestos'!$C$11*'Supuestos'!$C$12*'Supuestos'!$C$15)))=0,0,'Supuestos'!$C$8/(IF('Supuestos'!$C$11*'Supuestos'!$C$12*'Supuestos'!$C$15=0,0,'Supuestos'!$C$10/1000/('Supuestos'!$C$11*'Supuestos'!$C$12*'Supuestos'!$C$15)))))*'Supuestos'!$C$21)*'Supuestos'!$C$26))*E$9)*'Supuestos'!$C$31)*'Supuestos'!$C$30))*('Supuestos'!$C$41+'Supuestos'!$C$42+'Supuestos'!$C$43))*(1-'Supuestos'!$C$34-'Supuestos'!$C$35-'Supuestos'!$C$36))-((IF((IF('Supuestos'!$C$11*'Supuestos'!$C$12*'Supuestos'!$C$15=0,0,'Supuestos'!$C$10/1000/('Supuestos'!$C$11*'Supuestos'!$C$12*'Supuestos'!$C$15)))=0,0,'Supuestos'!$C$8/(IF('Supuestos'!$C$11*'Supuestos'!$C$12*'Supuestos'!$C$15=0,0,'Supuestos'!$C$10/1000/('Supuestos'!$C$11*'Supuestos'!$C$12*'Supuestos'!$C$15)))))*'Supuestos'!$C$37)-'Supuestos'!$C$38-'Supuestos'!$C$8) | F10: =((((((((((IF((IF('Supuestos'!$C$11*'Supuestos'!$C$12*'Supuestos'!$C$15=0,0,'Supuestos'!$C$10/1000/('Supuestos'!$C$11*'Supuestos'!$C$12*'Supuestos'!$C$15)))=0,0,'Supuestos'!$C$8/(IF('Supuestos'!$C$11*'Supuestos'!$C$12*'Supuestos'!$C$15=0,0,'Supuestos'!$C$10/1000/('Supuestos'!$C$11*'Supuestos'!$C$12*'Supuestos'!$C$15)))))*'Supuestos'!$C$20)*'Supuestos'!$C$25)+(((IF((IF('Supuestos'!$C$11*'Supuestos'!$C$12*'Supuestos'!$C$15=0,0,'Supuestos'!$C$10/1000/('Supuestos'!$C$11*'Supuestos'!$C$12*'Supuestos'!$C$15)))=0,0,'Supuestos'!$C$8/(IF('Supuestos'!$C$11*'Supuestos'!$C$12*'Supuestos'!$C$15=0,0,'Supuestos'!$C$10/1000/('Supuestos'!$C$11*'Supuestos'!$C$12*'Supuestos'!$C$15)))))*'Supuestos'!$C$21)*'Supuestos'!$C$26))*F$9)*$B10)+(((((((IF((IF('Supuestos'!$C$11*'Supuestos'!$C$12*'Supuestos'!$C$15=0,0,'Supuestos'!$C$10/1000/('Supuestos'!$C$11*'Supuestos'!$C$12*'Supuestos'!$C$15)))=0,0,'Supuestos'!$C$8/(IF('Supuestos'!$C$11*'Supuestos'!$C$12*'Supuestos'!$C$15=0,0,'Supuestos'!$C$10/1000/('Supuestos'!$C$11*'Supuestos'!$C$12*'Supuestos'!$C$15)))))*'Supuestos'!$C$20)*'Supuestos'!$C$25)+(((IF((IF('Supuestos'!$C$11*'Supuestos'!$C$12*'Supuestos'!$C$15=0,0,'Supuestos'!$C$10/1000/('Supuestos'!$C$11*'Supuestos'!$C$12*'Supuestos'!$C$15)))=0,0,'Supuestos'!$C$8/(IF('Supuestos'!$C$11*'Supuestos'!$C$12*'Supuestos'!$C$15=0,0,'Supuestos'!$C$10/1000/('Supuestos'!$C$11*'Supuestos'!$C$12*'Supuestos'!$C$15)))))*'Supuestos'!$C$21)*'Supuestos'!$C$26))*F$9)*'Supuestos'!$C$29)*'Supuestos'!$C$28)+(((((((IF((IF('Supuestos'!$C$11*'Supuestos'!$C$12*'Supuestos'!$C$15=0,0,'Supuestos'!$C$10/1000/('Supuestos'!$C$11*'Supuestos'!$C$12*'Supuestos'!$C$15)))=0,0,'Supuestos'!$C$8/(IF('Supuestos'!$C$11*'Supuestos'!$C$12*'Supuestos'!$C$15=0,0,'Supuestos'!$C$10/1000/('Supuestos'!$C$11*'Supuestos'!$C$12*'Supuestos'!$C$15)))))*'Supuestos'!$C$20)*'Supuestos'!$C$25)+(((IF((IF('Supuestos'!$C$11*'Supuestos'!$C$12*'Supuestos'!$C$15=0,0,'Supuestos'!$C$10/1000/('Supuestos'!$C$11*'Supuestos'!$C$12*'Supuestos'!$C$15)))=0,0,'Supuestos'!$C$8/(IF('Supuestos'!$C$11*'Supuestos'!$C$12*'Supuestos'!$C$15=0,0,'Supuestos'!$C$10/1000/('Supuestos'!$C$11*'Supuestos'!$C$12*'Supuestos'!$C$15)))))*'Supuestos'!$C$21)*'Supuestos'!$C$26))*F$9)*'Supuestos'!$C$31)*'Supuestos'!$C$30))*('Supuestos'!$C$41+'Supuestos'!$C$42+'Supuestos'!$C$43))*(1-'Supuestos'!$C$34-'Supuestos'!$C$35-'Supuestos'!$C$36))-((IF((IF('Supuestos'!$C$11*'Supuestos'!$C$12*'Supuestos'!$C$15=0,0,'Supuestos'!$C$10/1000/('Supuestos'!$C$11*'Supuestos'!$C$12*'Supuestos'!$C$15)))=0,0,'Supuestos'!$C$8/(IF('Supuestos'!$C$11*'Supuestos'!$C$12*'Supuestos'!$C$15=0,0,'Supuestos'!$C$10/1000/('Supuestos'!$C$11*'Supuestos'!$C$12*'Supuestos'!$C$15)))))*'Supuestos'!$C$37)-'Supuestos'!$C$38-'Supuestos'!$C$8) | G10: =((((((((((IF((IF('Supuestos'!$C$11*'Supuestos'!$C$12*'Supuestos'!$C$15=0,0,'Supuestos'!$C$10/1000/('Supuestos'!$C$11*'Supuestos'!$C$12*'Supuestos'!$C$15)))=0,0,'Supuestos'!$C$8/(IF('Supuestos'!$C$11*'Supuestos'!$C$12*'Supuestos'!$C$15=0,0,'Supuestos'!$C$10/1000/('Supuestos'!$C$11*'Supuestos'!$C$12*'Supuestos'!$C$15)))))*'Supuestos'!$C$20)*'Supuestos'!$C$25)+(((IF((IF('Supuestos'!$C$11*'Supuestos'!$C$12*'Supuestos'!$C$15=0,0,'Supuestos'!$C$10/1000/('Supuestos'!$C$11*'Supuestos'!$C$12*'Supuestos'!$C$15)))=0,0,'Supuestos'!$C$8/(IF('Supuestos'!$C$11*'Supuestos'!$C$12*'Supuestos'!$C$15=0,0,'Supuestos'!$C$10/1000/('Supuestos'!$C$11*'Supuestos'!$C$12*'Supuestos'!$C$15)))))*'Supuestos'!$C$21)*'Supuestos'!$C$26))*G$9)*$B10)+(((((((IF((IF('Supuestos'!$C$11*'Supuestos'!$C$12*'Supuestos'!$C$15=0,0,'Supuestos'!$C$10/1000/('Supuestos'!$C$11*'Supuestos'!$C$12*'Supuestos'!$C$15)))=0,0,'Supuestos'!$C$8/(IF('Supuestos'!$C$11*'Supuestos'!$C$12*'Supuestos'!$C$15=0,0,'Supuestos'!$C$10/1000/('Supuestos'!$C$11*'Supuestos'!$C$12*'Supuestos'!$C$15)))))*'Supuestos'!$C$20)*'Supuestos'!$C$25)+(((IF((IF('Supuestos'!$C$11*'Supuestos'!$C$12*'Supuestos'!$C$15=0,0,'Supuestos'!$C$10/1000/('Supuestos'!$C$11*'Supuestos'!$C$12*'Supuestos'!$C$15)))=0,0,'Supuestos'!$C$8/(IF('Supuestos'!$C$11*'Supuestos'!$C$12*'Supuestos'!$C$15=0,0,'Supuestos'!$C$10/1000/('Supuestos'!$C$11*'Supuestos'!$C$12*'Supuestos'!$C$15)))))*'Supuestos'!$C$21)*'Supuestos'!$C$26))*G$9)*'Supuestos'!$C$29)*'Supuestos'!$C$28)+(((((((IF((IF('Supuestos'!$C$11*'Supuestos'!$C$12*'Supuestos'!$C$15=0,0,'Supuestos'!$C$10/1000/('Supuestos'!$C$11*'Supuestos'!$C$12*'Supuestos'!$C$15)))=0,0,'Supuestos'!$C$8/(IF('Supuestos'!$C$11*'Supuestos'!$C$12*'Supuestos'!$C$15=0,0,'Supuestos'!$C$10/1000/('Supuestos'!$C$11*'Supuestos'!$C$12*'Supuestos'!$C$15)))))*'Supuestos'!$C$20)*'Supuestos'!$C$25)+(((IF((IF('Supuestos'!$C$11*'Supuestos'!$C$12*'Supuestos'!$C$15=0,0,'Supuestos'!$C$10/1000/('Supuestos'!$C$11*'Supuestos'!$C$12*'Supuestos'!$C$15)))=0,0,'Supuestos'!$C$8/(IF('Supuestos'!$C$11*'Supuestos'!$C$12*'Supuestos'!$C$15=0,0,'Supuestos'!$C$10/1000/('Supuestos'!$C$11*'Supuestos'!$C$12*'Supuestos'!$C$15)))))*'Supuestos'!$C$21)*'Supuestos'!$C$26))*G$9)*'Supuestos'!$C$31)*'Supuestos'!$C$30))*('Supuestos'!$C$41+'Supuestos'!$C$42+'Supuestos'!$C$43))*(1-'Supuestos'!$C$34-'Supuestos'!$C$35-'Supuestos'!$C$36))-((IF((IF('Supuestos'!$C$11*'Supuestos'!$C$12*'Supuestos'!$C$15=0,0,'Supuestos'!$C$10/1000/('Supuestos'!$C$11*'Supuestos'!$C$12*'Supuestos'!$C$15)))=0,0,'Supuestos'!$C$8/(IF('Supuestos'!$C$11*'Supuestos'!$C$12*'Supuestos'!$C$15=0,0,'Supuestos'!$C$10/1000/('Supuestos'!$C$11*'Supuestos'!$C$12*'Supuestos'!$C$15)))))*'Supuestos'!$C$37)-'Supuestos'!$C$38-'Supuestos'!$C$8)
B11: 197 | C11: =((((((((((IF((IF('Supuestos'!$C$11*'Supuestos'!$C$12*'Supuestos'!$C$15=0,0,'Supuestos'!$C$10/1000/('Supuestos'!$C$11*'Supuestos'!$C$12*'Supuestos'!$C$15)))=0,0,'Supuestos'!$C$8/(IF('Supuestos'!$C$11*'Supuestos'!$C$12*'Supuestos'!$C$15=0,0,'Supuestos'!$C$10/1000/('Supuestos'!$C$11*'Supuestos'!$C$12*'Supuestos'!$C$15)))))*'Supuestos'!$C$20)*'Supuestos'!$C$25)+(((IF((IF('Supuestos'!$C$11*'Supuestos'!$C$12*'Supuestos'!$C$15=0,0,'Supuestos'!$C$10/1000/('Supuestos'!$C$11*'Supuestos'!$C$12*'Supuestos'!$C$15)))=0,0,'Supuestos'!$C$8/(IF('Supuestos'!$C$11*'Supuestos'!$C$12*'Supuestos'!$C$15=0,0,'Supuestos'!$C$10/1000/('Supuestos'!$C$11*'Supuestos'!$C$12*'Supuestos'!$C$15)))))*'Supuestos'!$C$21)*'Supuestos'!$C$26))*C$9)*$B11)+(((((((IF((IF('Supuestos'!$C$11*'Supuestos'!$C$12*'Supuestos'!$C$15=0,0,'Supuestos'!$C$10/1000/('Supuestos'!$C$11*'Supuestos'!$C$12*'Supuestos'!$C$15)))=0,0,'Supuestos'!$C$8/(IF('Supuestos'!$C$11*'Supuestos'!$C$12*'Supuestos'!$C$15=0,0,'Supuestos'!$C$10/1000/('Supuestos'!$C$11*'Supuestos'!$C$12*'Supuestos'!$C$15)))))*'Supuestos'!$C$20)*'Supuestos'!$C$25)+(((IF((IF('Supuestos'!$C$11*'Supuestos'!$C$12*'Supuestos'!$C$15=0,0,'Supuestos'!$C$10/1000/('Supuestos'!$C$11*'Supuestos'!$C$12*'Supuestos'!$C$15)))=0,0,'Supuestos'!$C$8/(IF('Supuestos'!$C$11*'Supuestos'!$C$12*'Supuestos'!$C$15=0,0,'Supuestos'!$C$10/1000/('Supuestos'!$C$11*'Supuestos'!$C$12*'Supuestos'!$C$15)))))*'Supuestos'!$C$21)*'Supuestos'!$C$26))*C$9)*'Supuestos'!$C$29)*'Supuestos'!$C$28)+(((((((IF((IF('Supuestos'!$C$11*'Supuestos'!$C$12*'Supuestos'!$C$15=0,0,'Supuestos'!$C$10/1000/('Supuestos'!$C$11*'Supuestos'!$C$12*'Supuestos'!$C$15)))=0,0,'Supuestos'!$C$8/(IF('Supuestos'!$C$11*'Supuestos'!$C$12*'Supuestos'!$C$15=0,0,'Supuestos'!$C$10/1000/('Supuestos'!$C$11*'Supuestos'!$C$12*'Supuestos'!$C$15)))))*'Supuestos'!$C$20)*'Supuestos'!$C$25)+(((IF((IF('Supuestos'!$C$11*'Supuestos'!$C$12*'Supuestos'!$C$15=0,0,'Supuestos'!$C$10/1000/('Supuestos'!$C$11*'Supuestos'!$C$12*'Supuestos'!$C$15)))=0,0,'Supuestos'!$C$8/(IF('Supuestos'!$C$11*'Supuestos'!$C$12*'Supuestos'!$C$15=0,0,'Supuestos'!$C$10/1000/('Supuestos'!$C$11*'Supuestos'!$C$12*'Supuestos'!$C$15)))))*'Supuestos'!$C$21)*'Supuestos'!$C$26))*C$9)*'Supuestos'!$C$31)*'Supuestos'!$C$30))*('Supuestos'!$C$41+'Supuestos'!$C$42+'Supuestos'!$C$43))*(1-'Supuestos'!$C$34-'Supuestos'!$C$35-'Supuestos'!$C$36))-((IF((IF('Supuestos'!$C$11*'Supuestos'!$C$12*'Supuestos'!$C$15=0,0,'Supuestos'!$C$10/1000/('Supuestos'!$C$11*'Supuestos'!$C$12*'Supuestos'!$C$15)))=0,0,'Supuestos'!$C$8/(IF('Supuestos'!$C$11*'Supuestos'!$C$12*'Supuestos'!$C$15=0,0,'Supuestos'!$C$10/1000/('Supuestos'!$C$11*'Supuestos'!$C$12*'Supuestos'!$C$15)))))*'Supuestos'!$C$37)-'Supuestos'!$C$38-'Supuestos'!$C$8) | D11: =((((((((((IF((IF('Supuestos'!$C$11*'Supuestos'!$C$12*'Supuestos'!$C$15=0,0,'Supuestos'!$C$10/1000/('Supuestos'!$C$11*'Supuestos'!$C$12*'Supuestos'!$C$15)))=0,0,'Supuestos'!$C$8/(IF('Supuestos'!$C$11*'Supuestos'!$C$12*'Supuestos'!$C$15=0,0,'Supuestos'!$C$10/1000/('Supuestos'!$C$11*'Supuestos'!$C$12*'Supuestos'!$C$15)))))*'Supuestos'!$C$20)*'Supuestos'!$C$25)+(((IF((IF('Supuestos'!$C$11*'Supuestos'!$C$12*'Supuestos'!$C$15=0,0,'Supuestos'!$C$10/1000/('Supuestos'!$C$11*'Supuestos'!$C$12*'Supuestos'!$C$15)))=0,0,'Supuestos'!$C$8/(IF('Supuestos'!$C$11*'Supuestos'!$C$12*'Supuestos'!$C$15=0,0,'Supuestos'!$C$10/1000/('Supuestos'!$C$11*'Supuestos'!$C$12*'Supuestos'!$C$15)))))*'Supuestos'!$C$21)*'Supuestos'!$C$26))*D$9)*$B11)+(((((((IF((IF('Supuestos'!$C$11*'Supuestos'!$C$12*'Supuestos'!$C$15=0,0,'Supuestos'!$C$10/1000/('Supuestos'!$C$11*'Supuestos'!$C$12*'Supuestos'!$C$15)))=0,0,'Supuestos'!$C$8/(IF('Supuestos'!$C$11*'Supuestos'!$C$12*'Supuestos'!$C$15=0,0,'Supuestos'!$C$10/1000/('Supuestos'!$C$11*'Supuestos'!$C$12*'Supuestos'!$C$15)))))*'Supuestos'!$C$20)*'Supuestos'!$C$25)+(((IF((IF('Supuestos'!$C$11*'Supuestos'!$C$12*'Supuestos'!$C$15=0,0,'Supuestos'!$C$10/1000/('Supuestos'!$C$11*'Supuestos'!$C$12*'Supuestos'!$C$15)))=0,0,'Supuestos'!$C$8/(IF('Supuestos'!$C$11*'Supuestos'!$C$12*'Supuestos'!$C$15=0,0,'Supuestos'!$C$10/1000/('Supuestos'!$C$11*'Supuestos'!$C$12*'Supuestos'!$C$15)))))*'Supuestos'!$C$21)*'Supuestos'!$C$26))*D$9)*'Supuestos'!$C$29)*'Supuestos'!$C$28)+(((((((IF((IF('Supuestos'!$C$11*'Supuestos'!$C$12*'Supuestos'!$C$15=0,0,'Supuestos'!$C$10/1000/('Supuestos'!$C$11*'Supuestos'!$C$12*'Supuestos'!$C$15)))=0,0,'Supuestos'!$C$8/(IF('Supuestos'!$C$11*'Supuestos'!$C$12*'Supuestos'!$C$15=0,0,'Supuestos'!$C$10/1000/('Supuestos'!$C$11*'Supuestos'!$C$12*'Supuestos'!$C$15)))))*'Supuestos'!$C$20)*'Supuestos'!$C$25)+(((IF((IF('Supuestos'!$C$11*'Supuestos'!$C$12*'Supuestos'!$C$15=0,0,'Supuestos'!$C$10/1000/('Supuestos'!$C$11*'Supuestos'!$C$12*'Supuestos'!$C$15)))=0,0,'Supuestos'!$C$8/(IF('Supuestos'!$C$11*'Supuestos'!$C$12*'Supuestos'!$C$15=0,0,'Supuestos'!$C$10/1000/('Supuestos'!$C$11*'Supuestos'!$C$12*'Supuestos'!$C$15)))))*'Supuestos'!$C$21)*'Supuestos'!$C$26))*D$9)*'Supuestos'!$C$31)*'Supuestos'!$C$30))*('Supuestos'!$C$41+'Supuestos'!$C$42+'Supuestos'!$C$43))*(1-'Supuestos'!$C$34-'Supuestos'!$C$35-'Supuestos'!$C$36))-((IF((IF('Supuestos'!$C$11*'Supuestos'!$C$12*'Supuestos'!$C$15=0,0,'Supuestos'!$C$10/1000/('Supuestos'!$C$11*'Supuestos'!$C$12*'Supuestos'!$C$15)))=0,0,'Supuestos'!$C$8/(IF('Supuestos'!$C$11*'Supuestos'!$C$12*'Supuestos'!$C$15=0,0,'Supuestos'!$C$10/1000/('Supuestos'!$C$11*'Supuestos'!$C$12*'Supuestos'!$C$15)))))*'Supuestos'!$C$37)-'Supuestos'!$C$38-'Supuestos'!$C$8) | E11: =((((((((((IF((IF('Supuestos'!$C$11*'Supuestos'!$C$12*'Supuestos'!$C$15=0,0,'Supuestos'!$C$10/1000/('Supuestos'!$C$11*'Supuestos'!$C$12*'Supuestos'!$C$15)))=0,0,'Supuestos'!$C$8/(IF('Supuestos'!$C$11*'Supuestos'!$C$12*'Supuestos'!$C$15=0,0,'Supuestos'!$C$10/1000/('Supuestos'!$C$11*'Supuestos'!$C$12*'Supuestos'!$C$15)))))*'Supuestos'!$C$20)*'Supuestos'!$C$25)+(((IF((IF('Supuestos'!$C$11*'Supuestos'!$C$12*'Supuestos'!$C$15=0,0,'Supuestos'!$C$10/1000/('Supuestos'!$C$11*'Supuestos'!$C$12*'Supuestos'!$C$15)))=0,0,'Supuestos'!$C$8/(IF('Supuestos'!$C$11*'Supuestos'!$C$12*'Supuestos'!$C$15=0,0,'Supuestos'!$C$10/1000/('Supuestos'!$C$11*'Supuestos'!$C$12*'Supuestos'!$C$15)))))*'Supuestos'!$C$21)*'Supuestos'!$C$26))*E$9)*$B11)+(((((((IF((IF('Supuestos'!$C$11*'Supuestos'!$C$12*'Supuestos'!$C$15=0,0,'Supuestos'!$C$10/1000/('Supuestos'!$C$11*'Supuestos'!$C$12*'Supuestos'!$C$15)))=0,0,'Supuestos'!$C$8/(IF('Supuestos'!$C$11*'Supuestos'!$C$12*'Supuestos'!$C$15=0,0,'Supuestos'!$C$10/1000/('Supuestos'!$C$11*'Supuestos'!$C$12*'Supuestos'!$C$15)))))*'Supuestos'!$C$20)*'Supuestos'!$C$25)+(((IF((IF('Supuestos'!$C$11*'Supuestos'!$C$12*'Supuestos'!$C$15=0,0,'Supuestos'!$C$10/1000/('Supuestos'!$C$11*'Supuestos'!$C$12*'Supuestos'!$C$15)))=0,0,'Supuestos'!$C$8/(IF('Supuestos'!$C$11*'Supuestos'!$C$12*'Supuestos'!$C$15=0,0,'Supuestos'!$C$10/1000/('Supuestos'!$C$11*'Supuestos'!$C$12*'Supuestos'!$C$15)))))*'Supuestos'!$C$21)*'Supuestos'!$C$26))*E$9)*'Supuestos'!$C$29)*'Supuestos'!$C$28)+(((((((IF((IF('Supuestos'!$C$11*'Supuestos'!$C$12*'Supuestos'!$C$15=0,0,'Supuestos'!$C$10/1000/('Supuestos'!$C$11*'Supuestos'!$C$12*'Supuestos'!$C$15)))=0,0,'Supuestos'!$C$8/(IF('Supuestos'!$C$11*'Supuestos'!$C$12*'Supuestos'!$C$15=0,0,'Supuestos'!$C$10/1000/('Supuestos'!$C$11*'Supuestos'!$C$12*'Supuestos'!$C$15)))))*'Supuestos'!$C$20)*'Supuestos'!$C$25)+(((IF((IF('Supuestos'!$C$11*'Supuestos'!$C$12*'Supuestos'!$C$15=0,0,'Supuestos'!$C$10/1000/('Supuestos'!$C$11*'Supuestos'!$C$12*'Supuestos'!$C$15)))=0,0,'Supuestos'!$C$8/(IF('Supuestos'!$C$11*'Supuestos'!$C$12*'Supuestos'!$C$15=0,0,'Supuestos'!$C$10/1000/('Supuestos'!$C$11*'Supuestos'!$C$12*'Supuestos'!$C$15)))))*'Supuestos'!$C$21)*'Supuestos'!$C$26))*E$9)*'Supuestos'!$C$31)*'Supuestos'!$C$30))*('Supuestos'!$C$41+'Supuestos'!$C$42+'Supuestos'!$C$43))*(1-'Supuestos'!$C$34-'Supuestos'!$C$35-'Supuestos'!$C$36))-((IF((IF('Supuestos'!$C$11*'Supuestos'!$C$12*'Supuestos'!$C$15=0,0,'Supuestos'!$C$10/1000/('Supuestos'!$C$11*'Supuestos'!$C$12*'Supuestos'!$C$15)))=0,0,'Supuestos'!$C$8/(IF('Supuestos'!$C$11*'Supuestos'!$C$12*'Supuestos'!$C$15=0,0,'Supuestos'!$C$10/1000/('Supuestos'!$C$11*'Supuestos'!$C$12*'Supuestos'!$C$15)))))*'Supuestos'!$C$37)-'Supuestos'!$C$38-'Supuestos'!$C$8) | F11: =((((((((((IF((IF('Supuestos'!$C$11*'Supuestos'!$C$12*'Supuestos'!$C$15=0,0,'Supuestos'!$C$10/1000/('Supuestos'!$C$11*'Supuestos'!$C$12*'Supuestos'!$C$15)))=0,0,'Supuestos'!$C$8/(IF('Supuestos'!$C$11*'Supuestos'!$C$12*'Supuestos'!$C$15=0,0,'Supuestos'!$C$10/1000/('Supuestos'!$C$11*'Supuestos'!$C$12*'Supuestos'!$C$15)))))*'Supuestos'!$C$20)*'Supuestos'!$C$25)+(((IF((IF('Supuestos'!$C$11*'Supuestos'!$C$12*'Supuestos'!$C$15=0,0,'Supuestos'!$C$10/1000/('Supuestos'!$C$11*'Supuestos'!$C$12*'Supuestos'!$C$15)))=0,0,'Supuestos'!$C$8/(IF('Supuestos'!$C$11*'Supuestos'!$C$12*'Supuestos'!$C$15=0,0,'Supuestos'!$C$10/1000/('Supuestos'!$C$11*'Supuestos'!$C$12*'Supuestos'!$C$15)))))*'Supuestos'!$C$21)*'Supuestos'!$C$26))*F$9)*$B11)+(((((((IF((IF('Supuestos'!$C$11*'Supuestos'!$C$12*'Supuestos'!$C$15=0,0,'Supuestos'!$C$10/1000/('Supuestos'!$C$11*'Supuestos'!$C$12*'Supuestos'!$C$15)))=0,0,'Supuestos'!$C$8/(IF('Supuestos'!$C$11*'Supuestos'!$C$12*'Supuestos'!$C$15=0,0,'Supuestos'!$C$10/1000/('Supuestos'!$C$11*'Supuestos'!$C$12*'Supuestos'!$C$15)))))*'Supuestos'!$C$20)*'Supuestos'!$C$25)+(((IF((IF('Supuestos'!$C$11*'Supuestos'!$C$12*'Supuestos'!$C$15=0,0,'Supuestos'!$C$10/1000/('Supuestos'!$C$11*'Supuestos'!$C$12*'Supuestos'!$C$15)))=0,0,'Supuestos'!$C$8/(IF('Supuestos'!$C$11*'Supuestos'!$C$12*'Supuestos'!$C$15=0,0,'Supuestos'!$C$10/1000/('Supuestos'!$C$11*'Supuestos'!$C$12*'Supuestos'!$C$15)))))*'Supuestos'!$C$21)*'Supuestos'!$C$26))*F$9)*'Supuestos'!$C$29)*'Supuestos'!$C$28)+(((((((IF((IF('Supuestos'!$C$11*'Supuestos'!$C$12*'Supuestos'!$C$15=0,0,'Supuestos'!$C$10/1000/('Supuestos'!$C$11*'Supuestos'!$C$12*'Supuestos'!$C$15)))=0,0,'Supuestos'!$C$8/(IF('Supuestos'!$C$11*'Supuestos'!$C$12*'Supuestos'!$C$15=0,0,'Supuestos'!$C$10/1000/('Supuestos'!$C$11*'Supuestos'!$C$12*'Supuestos'!$C$15)))))*'Supuestos'!$C$20)*'Supuestos'!$C$25)+(((IF((IF('Supuestos'!$C$11*'Supuestos'!$C$12*'Supuestos'!$C$15=0,0,'Supuestos'!$C$10/1000/('Supuestos'!$C$11*'Supuestos'!$C$12*'Supuestos'!$C$15)))=0,0,'Supuestos'!$C$8/(IF('Supuestos'!$C$11*'Supuestos'!$C$12*'Supuestos'!$C$15=0,0,'Supuestos'!$C$10/1000/('Supuestos'!$C$11*'Supuestos'!$C$12*'Supuestos'!$C$15)))))*'Supuestos'!$C$21)*'Supuestos'!$C$26))*F$9)*'Supuestos'!$C$31)*'Supuestos'!$C$30))*('Supuestos'!$C$41+'Supuestos'!$C$42+'Supuestos'!$C$43))*(1-'Supuestos'!$C$34-'Supuestos'!$C$35-'Supuestos'!$C$36))-((IF((IF('Supuestos'!$C$11*'Supuestos'!$C$12*'Supuestos'!$C$15=0,0,'Supuestos'!$C$10/1000/('Supuestos'!$C$11*'Supuestos'!$C$12*'Supuestos'!$C$15)))=0,0,'Supuestos'!$C$8/(IF('Supuestos'!$C$11*'Supuestos'!$C$12*'Supuestos'!$C$15=0,0,'Supuestos'!$C$10/1000/('Supuestos'!$C$11*'Supuestos'!$C$12*'Supuestos'!$C$15)))))*'Supuestos'!$C$37)-'Supuestos'!$C$38-'Supuestos'!$C$8) | G11: =((((((((((IF((IF('Supuestos'!$C$11*'Supuestos'!$C$12*'Supuestos'!$C$15=0,0,'Supuestos'!$C$10/1000/('Supuestos'!$C$11*'Supuestos'!$C$12*'Supuestos'!$C$15)))=0,0,'Supuestos'!$C$8/(IF('Supuestos'!$C$11*'Supuestos'!$C$12*'Supuestos'!$C$15=0,0,'Supuestos'!$C$10/1000/('Supuestos'!$C$11*'Supuestos'!$C$12*'Supuestos'!$C$15)))))*'Supuestos'!$C$20)*'Supuestos'!$C$25)+(((IF((IF('Supuestos'!$C$11*'Supuestos'!$C$12*'Supuestos'!$C$15=0,0,'Supuestos'!$C$10/1000/('Supuestos'!$C$11*'Supuestos'!$C$12*'Supuestos'!$C$15)))=0,0,'Supuestos'!$C$8/(IF('Supuestos'!$C$11*'Supuestos'!$C$12*'Supuestos'!$C$15=0,0,'Supuestos'!$C$10/1000/('Supuestos'!$C$11*'Supuestos'!$C$12*'Supuestos'!$C$15)))))*'Supuestos'!$C$21)*'Supuestos'!$C$26))*G$9)*$B11)+(((((((IF((IF('Supuestos'!$C$11*'Supuestos'!$C$12*'Supuestos'!$C$15=0,0,'Supuestos'!$C$10/1000/('Supuestos'!$C$11*'Supuestos'!$C$12*'Supuestos'!$C$15)))=0,0,'Supuestos'!$C$8/(IF('Supuestos'!$C$11*'Supuestos'!$C$12*'Supuestos'!$C$15=0,0,'Supuestos'!$C$10/1000/('Supuestos'!$C$11*'Supuestos'!$C$12*'Supuestos'!$C$15)))))*'Supuestos'!$C$20)*'Supuestos'!$C$25)+(((IF((IF('Supuestos'!$C$11*'Supuestos'!$C$12*'Supuestos'!$C$15=0,0,'Supuestos'!$C$10/1000/('Supuestos'!$C$11*'Supuestos'!$C$12*'Supuestos'!$C$15)))=0,0,'Supuestos'!$C$8/(IF('Supuestos'!$C$11*'Supuestos'!$C$12*'Supuestos'!$C$15=0,0,'Supuestos'!$C$10/1000/('Supuestos'!$C$11*'Supuestos'!$C$12*'Supuestos'!$C$15)))))*'Supuestos'!$C$21)*'Supuestos'!$C$26))*G$9)*'Supuestos'!$C$29)*'Supuestos'!$C$28)+(((((((IF((IF('Supuestos'!$C$11*'Supuestos'!$C$12*'Supuestos'!$C$15=0,0,'Supuestos'!$C$10/1000/('Supuestos'!$C$11*'Supuestos'!$C$12*'Supuestos'!$C$15)))=0,0,'Supuestos'!$C$8/(IF('Supuestos'!$C$11*'Supuestos'!$C$12*'Supuestos'!$C$15=0,0,'Supuestos'!$C$10/1000/('Supuestos'!$C$11*'Supuestos'!$C$12*'Supuestos'!$C$15)))))*'Supuestos'!$C$20)*'Supuestos'!$C$25)+(((IF((IF('Supuestos'!$C$11*'Supuestos'!$C$12*'Supuestos'!$C$15=0,0,'Supuestos'!$C$10/1000/('Supuestos'!$C$11*'Supuestos'!$C$12*'Supuestos'!$C$15)))=0,0,'Supuestos'!$C$8/(IF('Supuestos'!$C$11*'Supuestos'!$C$12*'Supuestos'!$C$15=0,0,'Supuestos'!$C$10/1000/('Supuestos'!$C$11*'Supuestos'!$C$12*'Supuestos'!$C$15)))))*'Supuestos'!$C$21)*'Supuestos'!$C$26))*G$9)*'Supuestos'!$C$31)*'Supuestos'!$C$30))*('Supuestos'!$C$41+'Supuestos'!$C$42+'Supuestos'!$C$43))*(1-'Supuestos'!$C$34-'Supuestos'!$C$35-'Supuestos'!$C$36))-((IF((IF('Supuestos'!$C$11*'Supuestos'!$C$12*'Supuestos'!$C$15=0,0,'Supuestos'!$C$10/1000/('Supuestos'!$C$11*'Supuestos'!$C$12*'Supuestos'!$C$15)))=0,0,'Supuestos'!$C$8/(IF('Supuestos'!$C$11*'Supuestos'!$C$12*'Supuestos'!$C$15=0,0,'Supuestos'!$C$10/1000/('Supuestos'!$C$11*'Supuestos'!$C$12*'Supuestos'!$C$15)))))*'Supuestos'!$C$37)-'Supuestos'!$C$38-'Supuestos'!$C$8)
