Workbook
Name Autor_Jesus_Tassarolo: "Modelo financiero de embudos · creado por Jesús Tassarolo · TooAudience · youtube.com/@JesusTassaroloSinFiltro"

Sheet Inicio
B1: © Jesús Tassarolo · TooAudience · youtube.com/@JesusTassaroloSinFiltro · uso personal; no redistribuir modificado
B2: Modelo financiero · Embudo de webinar pago (evento pago)
B3: Anuncios → página de ventas de la entrada → entrada + bump → grupo de WhatsApp → evento en vivo y replay → oferta → programa superior
B5: Para qué sirve este modelo
B6: Es el modelo financiero de un embudo de webinar pago: anuncios que venden una entrada barata a un evento, un grupo de WhatsApp, el evento en vivo (con replay) donde se presenta la oferta principal, y un programa superior que se vende después. Con tus números (o con el ejemplo cargado) te dice cuánto vale cada entrada que comprás con publicidad, hasta cuánto podés pagar por entrada y por cada etapa siguiente, cuánto invertir para una meta de ventas, cuánta caja necesitás y qué palanca mejora más la ganancia.
B7: La unidad que comprás es la entrada vendida: acá los leads ya son compradores de un low ticket, no registros. Lo primero que se mira es qué parte de la pauta recupera la entrada (ROAS del front); después, escalón por escalón: costo por persona en el grupo, costo por asistente en vivo (mucho más alto que en gratuito porque pagaron), costo por solicitud y cierre, cada uno con su cantidad y su porcentaje.
B9: Cómo usarlo en 7 pasos
B10: 1. Andá a Supuestos y reemplazá el ejemplo por tus números. Si todavía no tenés datos, dejá el escenario en 1 (conservador) y usá Benchmarks como referencia.
B11: 2. Mirá Resumen: ganancia del lanzamiento, ROAS, el techo y el objetivo de costo por entrada, y el semáforo. Después Embudo: todos los pasos en orden con cuántos pasan, lo que pagás, lo que te queda y lo máximo que podrías pagar por cada uno.
B12: 3. Abrí Simulador para jugar: cada supuesto está en orden de embudo (inversión, CPM, CTR, visitas, conversión de la landing, asistencia, solicitudes, cierre, precios, costos) con tu número en amarillo al lado de la base. Cambiá uno y mirá cómo se mueven todos los demás contra la base; la columna Diferencia te dice cuánto. No toca Supuestos.
B13: 4. Abrí Escenarios para ver qué pasa si cambia el precio, la conversión o el costo en tablas de dos variables, y Sensibilidad para saber qué variable conviene trabajar primero.
B14: 5. Antes de invertir, mirá Proyección 12 meses: la caja necesaria es la plata que tenés que tener para no frenar la pauta mientras cobrás. Si da 0, el embudo se autofinancia.
... B47: Este modelo se comparte para que lo uses con tus números. Si lo compartís, dejá esta línea: es la forma de saber de dónde salió.

Sheet Resumen
B1: © Jesús Tassarolo · TooAudience · youtube.com/@JesusTassaroloSinFiltro · uso personal; no redistribuir modificado
B2: Resumen: lo que hay que mirar
B3: Todo sale de Modelo con los supuestos del escenario en uso. Cambiá Supuestos y esto se actualiza.
B5: Indicador | C5: Valor | D5: Qué significa
B6: Resultado del lanzamiento
B7: Ganancia del período | C7: ='Modelo'!$C$44 | D7: Cash neto menos costos y menos inversión.
B8: ROAS del front (qué parte de la pauta recupera la entrada) | C8: ='Modelo'!$C$14 | D8: Qué parte de la pauta recupera la entrada antes del evento. Cerca de 1 = el evento se paga solo.
B9: ROAS sobre cash neto | C9: ='Modelo'!$C$46 | D9: Total, sobre cash neto.
B10: Entradas vendidas | C10: ='Modelo'!$C$9 | D10: Entradas vendidas.
B11: Asistentes en vivo | C11: ='Modelo'!$C$18 | D11: Asistentes en vivo.
B12: Ventas de la oferta | C12: ='Modelo'!$C$27 | D12: Ventas de la oferta (vivo + replay).
B13: Unit economics
B14: Costo por entrada vendida | C14: ='Modelo'!$C$8 | D14: Costo por entrada vendida.
B15: Valor neto por entrada | C15: ='Modelo'!$C$50 | D15: Lo que vale una entrada en cash neto, con todo lo que viene después.
B16: Costo por persona en el grupo | C16: ='Modelo'!$C$17 | D16: Lo que te cuesta cada persona que entra al grupo.
B17: Costo por asistente en vivo | C17: ='Modelo'!$C$20 | D17: Lo que te cuesta cada asistente en vivo.
B18: Solicitudes (total) | C18: ='Modelo'!$C$24 | D18: Formularios de compra, aplicaciones o pedidos de hablar con un vendedor.
B19: Costo por solicitud | C19: ='Modelo'!$C$26 | D19: Lo que te cuesta cada solicitud.
B20: Costo por comprador de la oferta | C20: ='Modelo'!$C$29 | D20: Lo que te cuesta cada comprador de la oferta.
B21: Las dos caras de cada número
B22: Ganancia por visita | C22: ='Modelo'!$C$64 | D22: Lo que te queda por cada visita a la página de ventas. La métrica más valiosa del embudo.
B23: Ganancia por entrada | C23: ='Modelo'!$C$65 | D23: Lo que te queda por cada entrada vendida. Su par es el costo por entrada.
B24: Ganancia por cliente | C24: ='Modelo'!$C$68 | D24: Lo que te queda por cada comprador de la oferta. Su par es el costo por comprador.
B25: Order value (AOV) | C25: ='Modelo'!$C$34 | D25: Facturado por comprador de la oferta, con todo lo demás.
B26: Order value neto (AOV neto) | C26: ='Modelo'!$C$63 | D26: Lo mismo después de comisiones, reembolsos y costos por entrada.
B27: Hasta cuánto pagar
B28: Techo de costo por entrada (break-even) | C28: ='Modelo'!$C$51 | D28: Costo por entrada donde no ganás ni perdés.
B29: Objetivo de costo por entrada | C29: ='Modelo'!$C$52 | D29: A este costo o menos estás en verde.
B30: Techo de costo por visita a la página | C30: ='Modelo'!$C$53 | D30: Costo máximo por visita a la página de ventas.
B31: Techo de costo por solicitud | C31: ='Modelo'!$C$55 | D31: Costo máximo por solicitud.
B32: Techo de costo por comprador de la oferta | C32: ='Modelo'!$C$56 | D32: Costo máximo por comprador de la oferta.
B33: Semáforo del costo por entrada actual | C33: ='Modelo'!$C$59 | D33: Tu costo por entrada actual contra techo y objetivo.
B34: Cuánto invertir y cuánta caja
B35: Inversión necesaria para la meta de ventas de la oferta (al costo actual) | C35: ='Modelo'!$C$60 | D35: Para la meta de ventas de Supuestos, al costo actual.
B36: Caja que hay que tener (peor momento de la proyección) | C36: ='Proyección 12 meses'!$C$18 | D36: Si da 0, el embudo se autofinancia: cada mes cobra más de lo que invierte.
B37: Saldo mínimo de caja con tu caja inicial | C37: ='Proyección 12 meses'!$C$19 | D37: Si es negativo, la caja inicial no alcanza.
B38: Ganancia acumulada en 12 meses | C38: ='Proyección 12 meses'!$C$20 | D38: Con la inversión creciendo según el supuesto.
B40: Recomendación según el semáforo | C40: =IF('Modelo'!$C$59="VERDE","Sostener o subir un escalón (+25 %) y medir 7 días",IF('Modelo'!$C$59="AMARILLO","No subir. Si el costo está bien, el ROAS no llega al objetivo: mirá Sensibilidad. Si no, revisar en orden: CPM, creativo, página",IF('Modelo'!$C$59="ROJO","Bajar un escalón (−25 %) y arreglar antes de volver a subir","")))
B42: Modelo financiero de embudos · creado por Jesús Tassarolo · TooAudience · youtube.com/@JesusTassaroloSinFiltro · v1.2 · octubre 2026

Sheet Simulador
B1: © Jesús Tassarolo · TooAudience · youtube.com/@JesusTassaroloSinFiltro · uso personal; no redistribuir modificado
B2: Simulador: movés un número y ves cómo se mueve todo el embudo
B3: Amarillo = tu número: arranca igual a Supuestos; escribí encima para probar (CPM, CTR, conversiones, precios, costos). Al lado, la base. 'Con tus números' se recalcula al instante y se compara con el Modelo. Para volver a la base, borrá la celda amarilla y escribí =D seguido del número de fila (por ejemplo =D9).
B5: Paso / métrica | C5: Tu número (editable) | D5: Base (Supuestos) | E5: Con tus números | F5: Base (Modelo) | G5: Diferencia | H5: Cómo se calcula
B6: Tráfico y entradas
B7: Costo por visita a la página de ventas de la entrada | C7: ='Supuestos'!$C$10 | D7: ='Supuestos'!$C$10 | G7: =IF(C7<>D7,"← cambiado","") | H7: Supuesto. Escribí encima para probar; la base queda al lado.
B8: Inversión en publicidad por lanzamiento | C8: ='Supuestos'!$C$8 | D8: ='Supuestos'!$C$8 | G8: =IF(C8<>D8,"← cambiado","") | H8: Supuesto. Escribí encima para probar; la base queda al lado.
B9: Visitas a la página de ventas | E9: =IF($C$7=0,0,$C$8/$C$7) | F9: ='Modelo'!$C$7 | G9: =IF(AND(ISNUMBER(E9),ISNUMBER(F9)),E9-F9,"") | H9: Inversión ÷ costo por visita.
B10: % de visitas que compran la entrada | C10: ='Supuestos'!$C$13 | D10: ='Supuestos'!$C$13 | G10: =IF(C10<>D10,"← cambiado","") | H10: Supuesto. Escribí encima para probar; la base queda al lado.
B11: Costo por entrada vendida | E11: =IF($C$10=0,0,$C$7/$C$10) | F11: ='Modelo'!$C$8 | G11: =IF(AND(ISNUMBER(E11),ISNUMBER(F11)),E11-F11,"") | H11: Costo por visita ÷ % que compra la entrada.
B12: Entradas vendidas | E12: =IF($E$11=0,0,$C$8/$E$11) | F12: ='Modelo'!$C$9 | G12: =IF(AND(ISNUMBER(E12),ISNUMBER(F12)),E12-F12,"") | H12: Inversión ÷ costo por entrada.
B13: Precio promedio cobrado por entrada | C13: ='Supuestos'!$C$14 | D13: ='Supuestos'!$C$14 | G13: =IF(C13<>D13,"← cambiado","") | H13: Supuesto. Escribí encima para probar; la base queda al lado.
B14: Facturado: entradas | E14: =$E$12*$C$13 | F14: ='Modelo'!$C$10 | G14: =IF(AND(ISNUMBER(E14),ISNUMBER(F14)),E14-F14,"") | H14: Entradas × precio promedio.
B15: Bump: % de compradores de entrada que lo toman | C15: ='Supuestos'!$C$16 | D15: ='Supuestos'!$C$16 | G15: =IF(C15<>D15,"← cambiado","") | H15: Supuesto. Escribí encima para probar; la base queda al lado.
B16: Ventas: bump de la entrada | E16: =$E$12*$C$15 | F16: ='Modelo'!$C$11 | G16: =IF(AND(ISNUMBER(E16),ISNUMBER(F16)),E16-F16,"") | H16: Entradas × % que lo toma.
B17: Bump en el checkout de la entrada: precio | C17: ='Supuestos'!$C$15 | D17: ='Supuestos'!$C$15 | G17: =IF(C17<>D17,"← cambiado","") | H17: Supuesto. Escribí encima para probar; la base queda al lado.
B18: Facturado: bump de la entrada | E18: =$E$16*$C$17 | F18: ='Modelo'!$C$12 | G18: =IF(AND(ISNUMBER(E18),ISNUMBER(F18)),E18-F18,"") | H18: Ventas × precio.
B19: Facturado del front (entradas + bump) | E19: =$E$14+$E$18 | F19: ='Modelo'!$C$13 | G19: =IF(AND(ISNUMBER(E19),ISNUMBER(F19)),E19-F19,"") | H19: Lo que entra antes del evento.
B20: ROAS del front (qué parte de la pauta recupera la entrada) | E20: =IF($C$8=0,0,$E$19/$C$8) | F20: ='Modelo'!$C$14 | G20: =IF(AND(ISNUMBER(E20),ISNUMBER(F20)),E20-F20,"") | H20: Facturado del front ÷ inversión. Cerca de 1 = el evento se paga solo.
B21: Grupo y asistencia
B22: % que entra al grupo de WhatsApp | C22: ='Supuestos'!$C$19 | D22: ='Supuestos'!$C$19 | G22: =IF(C22<>D22,"← cambiado","") | H22: Supuesto. Escribí encima para probar; la base queda al lado.
B23: Personas en el grupo | E23: =$E$12*$C$22 | F23: ='Modelo'!$C$16 | G23: =IF(AND(ISNUMBER(E23),ISNUMBER(F23)),E23-F23,"") | H23: Entradas × % que entra.
B24: Costo por persona en el grupo | E24: =IF($E$23=0,0,$C$8/$E$23) | F24: ='Modelo'!$C$17 | G24: =IF(AND(ISNUMBER(E24),ISNUMBER(F24)),E24-F24,"") | H24: Inversión ÷ personas en el grupo.
B25: % que asiste en vivo | C25: ='Supuestos'!$C$20 | D25: ='Supuestos'!$C$20 | G25: =IF(C25<>D25,"← cambiado","") | H25: Supuesto. Escribí encima para probar; la base queda al lado.
B26: Asistentes en vivo | E26: =$E$12*$C$25 | F26: ='Modelo'!$C$18 | G26: =IF(AND(ISNUMBER(E26),ISNUMBER(F26)),E26-F26,"") | H26: Entradas × asistencia en vivo.
B27: % que ve el replay (sin contar los que fueron en vivo) | C27: ='Supuestos'!$C$21 | D27: ='Supuestos'!$C$21 | G27: =IF(C27<>D27,"← cambiado","") | H27: Supuesto. Escribí encima para probar; la base queda al lado.
B28: Vieron el replay | E28: =$E$12*$C$27 | F28: ='Modelo'!$C$19 | G28: =IF(AND(ISNUMBER(E28),ISNUMBER(F28)),E28-F28,"") | H28: Entradas × % que ve el replay.
B29: Costo por asistente en vivo | E29: =IF($E$26=0,0,$C$8/$E$26) | F29: ='Modelo'!$C$20 | G29: =IF(AND(ISNUMBER(E29),ISNUMBER(F29)),E29-F29,"") | H29: Inversión ÷ asistentes.
B30: Solicitudes (formulario de compra, aplicación o vendedor), oferta, programa y facturación
B31: % de asistentes en vivo que solicitan (formulario de compra, de aplicación o hablar con un vendedor) | C31: ='Supuestos'!$C$25 | D31: ='Supuestos'!$C$25 | G31: =IF(C31<>D31,"← cambiado","") | H31: Supuesto. Escribí encima para probar; la base queda al lado.
B32: Solicitudes: en vivo | E32: =$E$26*$C$31 | F32: ='Modelo'!$C$22 | G32: =IF(AND(ISNUMBER(E32),ISNUMBER(F32)),E32-F32,"") | H32: Asistentes en vivo × % que solicita.
B33: % de los que ven el replay que solicitan | C33: ='Supuestos'!$C$26 | D33: ='Supuestos'!$C$26 | G33: =IF(C33<>D33,"← cambiado","") | H33: Supuesto. Escribí encima para probar; la base queda al lado.
B34: Solicitudes: replay | E34: =$E$28*$C$33 | F34: ='Modelo'!$C$23 | G34: =IF(AND(ISNUMBER(E34),ISNUMBER(F34)),E34-F34,"") | H34: Replay × % que solicita.
B35: Solicitudes (total) | E35: =$E$32+$E$34 | F35: ='Modelo'!$C$24 | G35: =IF(AND(ISNUMBER(E35),ISNUMBER(F35)),E35-F35,"") | H35: En vivo + replay.
B36: % de compradores de entrada que solicitan | E36: =IF($E$12=0,0,$E$35/$E$12) | F36: ='Modelo'!$C$25 | G36: =IF(AND(ISNUMBER(E36),ISNUMBER(F36)),E36-F36,"") | H36: Solicitudes ÷ entradas.
B37: Costo por solicitud | E37: =IF($E$35=0,0,$C$8/$E$35) | F37: ='Modelo'!$C$26 | G37: =IF(AND(ISNUMBER(E37),ISNUMBER(F37)),E37-F37,"") | H37: Inversión ÷ solicitudes.
B38: % de solicitudes que terminan en compra | C38: ='Supuestos'!$C$27 | D38: ='Supuestos'!$C$27 | G38: =IF(C38<>D38,"← cambiado","") | H38: Supuesto. Escribí encima para probar; la base queda al lado.
B39: Ventas de la oferta | E39: =$E$35*$C$38 | F39: ='Modelo'!$C$27 | G39: =IF(AND(ISNUMBER(E39),ISNUMBER(F39)),E39-F39,"") | H39: Solicitudes × % que termina en compra.
B40: % de compradores de entrada que compran la oferta | E40: =IF($E$12=0,0,$E$39/$E$12) | F40: ='Modelo'!$C$28 | G40: =IF(AND(ISNUMBER(E40),ISNUMBER(F40)),E40-F40,"") | H40: Ventas ÷ entradas.
B41: Costo por comprador de la oferta | E41: =IF($E$39=0,0,$C$8/$E$39) | F41: ='Modelo'!$C$29 | G41: =IF(AND(ISNUMBER(E41),ISNUMBER(F41)),E41-F41,"") | H41: Inversión ÷ ventas de la oferta.
...

Sheet Embudo
B1: © Jesús Tassarolo · TooAudience · youtube.com/@JesusTassaroloSinFiltro · uso personal; no redistribuir modificado
B2: Embudo: todos los pasos, cuántos pasan y, por cada uno, qué pagás, qué te queda y hasta cuánto podrías pagar
B3: Cada fila es un paso del embudo en orden. '% que pasa' compara con el paso anterior (o con el que dice la nota). Tres números por paso: lo que pagás hoy por cada uno (inversión ÷ cantidad), lo que te queda por cada uno (ganancia ÷ cantidad) y lo máximo que podrías pagar (el techo: lo que cada uno genera en cash neto). Techo = costo + ganancia + fijos repartidos.
B5: Paso | C5: Cantidad | D5: % que pasa | E5: % acumulado | F5: Costo por paso (pagás hoy) | G5: Ganancia por paso (te queda) | H5: Techo por paso (máximo a pagar) | I5: Qué se paga acá / cómo se lee
B6: Visitas a la página de ventas de la entrada | C6: ='Modelo'!$C$7 | D6: — | E6: — | F6: =IF('Modelo'!$C$7=0,0,'Supuestos'!$C$8*1/'Modelo'!$C$7) | G6: =IF('Modelo'!$C$7=0,0,'Modelo'!$C$44*1/'Modelo'!$C$7) | H6: =IF('Modelo'!$C$7=0,0,'Modelo'!$C$50*'Modelo'!$C$9*1/'Modelo'!$C$7) | I6: Costo por visita.
B7: Compran la entrada | C7: ='Modelo'!$C$9 | D7: =IF('Modelo'!$C$7=0,0,'Modelo'!$C$9/'Modelo'!$C$7) | E7: =IF('Modelo'!$C$9=0,0,'Modelo'!$C$9/'Modelo'!$C$9) | F7: =IF('Modelo'!$C$9=0,0,'Supuestos'!$C$8*1/'Modelo'!$C$9) | G7: =IF('Modelo'!$C$9=0,0,'Modelo'!$C$44*1/'Modelo'!$C$9) | H7: =IF('Modelo'!$C$9=0,0,'Modelo'!$C$50*'Modelo'!$C$9*1/'Modelo'!$C$9) | I7: Costo por entrada. La unidad de este embudo: acá los leads ya son compradores.
B8: Toman el bump de la entrada | C8: ='Modelo'!$C$11 | D8: =IF('Modelo'!$C$9=0,0,'Modelo'!$C$11/'Modelo'!$C$9) | E8: =IF('Modelo'!$C$9=0,0,'Modelo'!$C$11/'Modelo'!$C$9) | F8: sin costo propio | G8: — | H8: — | I8: Sobre compradores de entrada. Suma al ROAS del front.
B9: Entran al grupo de WhatsApp | C9: ='Modelo'!$C$16 | D9: =IF('Modelo'!$C$9=0,0,'Modelo'!$C$16/'Modelo'!$C$9) | E9: =IF('Modelo'!$C$9=0,0,'Modelo'!$C$16/'Modelo'!$C$9) | F9: =IF('Modelo'!$C$16=0,0,'Supuestos'!$C$8*1/'Modelo'!$C$16) | G9: =IF('Modelo'!$C$16=0,0,'Modelo'!$C$44*1/'Modelo'!$C$16) | H9: =IF('Modelo'!$C$16=0,0,'Modelo'!$C$50*'Modelo'!$C$9*1/'Modelo'!$C$16) | I9: Costo por persona en el grupo.
B10: Asisten en vivo | C10: ='Modelo'!$C$18 | D10: =IF('Modelo'!$C$9=0,0,'Modelo'!$C$18/'Modelo'!$C$9) | E10: =IF('Modelo'!$C$9=0,0,'Modelo'!$C$18/'Modelo'!$C$9) | F10: =IF('Modelo'!$C$18=0,0,'Supuestos'!$C$8*1/'Modelo'!$C$18) | G10: =IF('Modelo'!$C$18=0,0,'Modelo'!$C$44*1/'Modelo'!$C$18) | H10: =IF('Modelo'!$C$18=0,0,'Modelo'!$C$50*'Modelo'!$C$9*1/'Modelo'!$C$18) | I10: Costo por asistente en vivo. Sobre compradores de entrada.
B11: Ven el replay | C11: ='Modelo'!$C$19 | D11: =IF('Modelo'!$C$9=0,0,'Modelo'!$C$19/'Modelo'!$C$9) | E11: =IF('Modelo'!$C$9=0,0,'Modelo'!$C$19/'Modelo'!$C$9) | F11: =IF('Modelo'!$C$19=0,0,'Supuestos'!$C$8*1/'Modelo'!$C$19) | G11: =IF('Modelo'!$C$19=0,0,'Modelo'!$C$44*1/'Modelo'!$C$19) | H11: =IF('Modelo'!$C$19=0,0,'Modelo'!$C$50*'Modelo'!$C$9*1/'Modelo'!$C$19) | I11: Sobre compradores de entrada.
B12: Solicitan, de los que estuvieron en vivo | C12: ='Modelo'!$C$22 | D12: =IF('Modelo'!$C$18=0,0,'Modelo'!$C$22/'Modelo'!$C$18) | E12: =IF('Modelo'!$C$9=0,0,'Modelo'!$C$22/'Modelo'!$C$9) | F12: =IF('Modelo'!$C$22=0,0,'Supuestos'!$C$8*1/'Modelo'!$C$22) | G12: =IF('Modelo'!$C$22=0,0,'Modelo'!$C$44*1/'Modelo'!$C$22) | H12: =IF('Modelo'!$C$22=0,0,'Modelo'!$C$50*'Modelo'!$C$9*1/'Modelo'!$C$22) | I12: Formulario de compra, aplicación o vendedor. Sobre asistentes en vivo.
B13: Solicitan, de los que vieron el replay | C13: ='Modelo'!$C$23 | D13: =IF('Modelo'!$C$19=0,0,'Modelo'!$C$23/'Modelo'!$C$19) | E13: =IF('Modelo'!$C$9=0,0,'Modelo'!$C$23/'Modelo'!$C$9) | F13: =IF('Modelo'!$C$23=0,0,'Supuestos'!$C$8*1/'Modelo'!$C$23) | G13: =IF('Modelo'!$C$23=0,0,'Modelo'!$C$44*1/'Modelo'!$C$23) | H13: =IF('Modelo'!$C$23=0,0,'Modelo'!$C$50*'Modelo'!$C$9*1/'Modelo'!$C$23) | I13: Sobre los que vieron el replay.
B14: Solicitudes (total) | C14: ='Modelo'!$C$24 | D14: =IF('Modelo'!$C$9=0,0,'Modelo'!$C$24/'Modelo'!$C$9) | E14: =IF('Modelo'!$C$9=0,0,'Modelo'!$C$24/'Modelo'!$C$9) | F14: =IF('Modelo'!$C$24=0,0,'Supuestos'!$C$8*1/'Modelo'!$C$24) | G14: =IF('Modelo'!$C$24=0,0,'Modelo'!$C$44*1/'Modelo'!$C$24) | H14: =IF('Modelo'!$C$24=0,0,'Modelo'!$C$50*'Modelo'!$C$9*1/'Modelo'!$C$24) | I14: Costo por solicitud. Sobre compradores de entrada.
B15: Compran la oferta | C15: ='Modelo'!$C$27 | D15: =IF('Modelo'!$C$24=0,0,'Modelo'!$C$27/'Modelo'!$C$24) | E15: =IF('Modelo'!$C$9=0,0,'Modelo'!$C$27/'Modelo'!$C$9) | F15: =IF('Modelo'!$C$27=0,0,'Supuestos'!$C$8*1/'Modelo'!$C$27) | G15: =IF('Modelo'!$C$27=0,0,'Modelo'!$C$44*1/'Modelo'!$C$27) | H15: =IF('Modelo'!$C$27=0,0,'Modelo'!$C$50*'Modelo'!$C$9*1/'Modelo'!$C$27) | I15: Costo por comprador de la oferta. Sobre solicitudes (cierre).
B16: Pasan al programa superior | C16: ='Modelo'!$C$31 | D16: =IF('Modelo'!$C$27=0,0,'Modelo'!$C$31/'Modelo'!$C$27) | E16: =IF('Modelo'!$C$9=0,0,'Modelo'!$C$31/'Modelo'!$C$9) | F16: sin costo propio | G16: — | H16: — | I16: Sobre compradores de la oferta.
B18: Comprobalo con la fila de la unidad: costo + ganancia + fijos repartidos = techo | F18: =F7 | G18: =G7 | H18: =F7+G7+'Supuestos'!$C$36/'Modelo'!$C$9 | I18: Techo = costo + ganancia + fijos ÷ unidades. Lo que falta entre (costo + ganancia) y el techo son los costos fijos repartidos entre las unidades.
B19: Cómo se lee
B20: Cantidad: cuántas acciones o personas hubo en ese paso con los supuestos del escenario en uso.
B21: % que pasa: de los que estaban en el paso anterior (o en el paso que indica la nota), cuántos llegan a este. % acumulado: cuántos llegan a este paso por cada 100 unidades que compra la pauta.
B22: Costo por paso: inversión ÷ cantidad. Es lo que te está costando hoy cada persona que llega a ese paso.
B23: Ganancia por paso: ganancia del período ÷ cantidad. Lo que te queda por cada persona de ese paso después de pagar la pauta, las comisiones, los reembolsos y los fijos. La ganancia por visita es la métrica más valiosa del embudo: resume todo lo que pasa después.
B24: Techo por paso: lo que cada persona de ese paso genera en cash neto (cash neto menos costos por unidad, dividido por la cantidad). Es lo máximo que podrías pagar por ese paso antes de que la ganancia llegue a cero, si lo demás se mantiene. Por eso siempre es mayor que la ganancia: techo = costo + ganancia + fijos repartidos.
B25: Los bumps, las OTOs y la ascensión no tienen costo propio: se pagan con el CPA del comprador principal y se miden por lo que suman al AOV.

Sheet Supuestos
B1: © Jesús Tassarolo · TooAudience · youtube.com/@JesusTassaroloSinFiltro · uso personal; no redistribuir modificado
B2: Supuestos
B3: Celdas amarillas = las editás vos. Celdas azules = se calculan solas. Cada fila dice en qué unidad va y de dónde sale el valor del ejemplo.
B5: Supuesto | C5: Valor en uso | D5: Conservador | E5: Base | F5: Optimista | G5: Unidad | H5: Nota / fuente del ejemplo
B6: Escenario en uso (1 = conservador · 2 = base · 3 = optimista) | C6: 2 | G6: 1 / 2 / 3 | H6: Cambia todas las filas que tienen tres valores. Si una fila no tiene tres valores, se usa el de 'Valor en uso'.
B7: 1. Inversión y tráfico
B8: Inversión en publicidad por lanzamiento | C8: 3000 | G8: USD / lanzamiento | H8: Un lanzamiento = una tanda de venta de entradas + evento + oferta.
B9: Lanzamientos por mes (para la proyección) | C9: 2 | G9: lanzamientos / mes | H9: Cuántos eventos como este hacés por mes. La proyección multiplica inversión, costos fijos y ventas por este número.
B10: Costo por visita a la página de ventas de la entrada | C10: =IF('Supuestos'!$C$6=1,D10,IF('Supuestos'!$C$6=2,E10,F10)) | D10: 0.5 | E10: 0.35 | F10: 0.25 | G10: USD / visita | H10: Lo que pagás por cada persona que llega a la página.
B12: 2. Entrada y bump
B13: % de visitas que compran la entrada | C13: =IF('Supuestos'!$C$6=1,D13,IF('Supuestos'!$C$6=2,E13,F13)) | D13: 0.015 | E13: 0.025 | F13: 0.035 | G13: % | H13: Página de ventas de un producto de 5 a 15 USD.
B14: Precio promedio cobrado por entrada | C14: 9 | G14: USD | H14: Si escalonás el precio (5 → 10 → 15), poné el promedio que cobrás.
B15: Bump en el checkout de la entrada: precio | C15: 27 | G15: USD | H15: Grabaciones, plantillas, acceso extendido.
B16: Bump: % de compradores de entrada que lo toman | C16: =IF('Supuestos'!$C$6=1,D16,IF('Supuestos'!$C$6=2,E16,F16)) | D16: 0.12 | E16: 0.2 | F16: 0.3 | G16: %
B18: 3. Grupo y asistencia (sobre compradores de entrada)
B19: % que entra al grupo de WhatsApp | C19: =IF('Supuestos'!$C$6=1,D19,IF('Supuestos'!$C$6=2,E19,F19)) | D19: 0.7 | E19: 0.85 | F19: 0.95 | G19: % | H19: Pagaron: entran casi todos.
B20: % que asiste en vivo | C20: =IF('Supuestos'!$C$6=1,D20,IF('Supuestos'!$C$6=2,E20,F20)) | D20: 0.4 | E20: 0.55 | F20: 0.65 | G20: % | H20: Mucho más alto que en gratuito.
B21: % que ve el replay (sin contar los que fueron en vivo) | C21: =IF('Supuestos'!$C$6=1,D21,IF('Supuestos'!$C$6=2,E21,F21)) | D21: 0.15 | E21: 0.25 | F21: 0.3 | G21: %
B23: 4. Oferta del evento y programa superior
B24: Oferta principal: precio | C24: 497 | G24: USD | H24: Lo que se presenta al final del evento.
B25: % de asistentes en vivo que solicitan (formulario de compra, de aplicación o hablar con un vendedor) | C25: =IF('Supuestos'!$C$6=1,D25,IF('Supuestos'!$C$6=2,E25,F25)) | D25: 0.1 | E25: 0.16 | F25: 0.22 | G25: % | H25: Público que pagó por estar: solicita más que en un webinar gratuito.
B26: % de los que ven el replay que solicitan | C26: =IF('Supuestos'!$C$6=1,D26,IF('Supuestos'!$C$6=2,E26,F26)) | D26: 0.02 | E26: 0.04 | F26: 0.06 | G26: %
B27: % de solicitudes que terminan en compra | C27: =IF('Supuestos'!$C$6=1,D27,IF('Supuestos'!$C$6=2,E27,F27)) | D27: 0.4 | E27: 0.5 | F27: 0.6 | G27: % | H27: Con compra directa en el formulario suele ser alto; con vendedor, 40 a 60 %.
B28: Programa superior: precio | C28: 1997 | G28: USD | H28: Por llamada o por ascenso.
B29: Programa superior: % de compradores de la oferta que lo toman | C29: =IF('Supuestos'!$C$6=1,D29,IF('Supuestos'!$C$6=2,E29,F29)) | D29: 0.05 | E29: 0.1 | F29: 0.15 | G29: %
B31: 5. Costos
B32: Comisión de la pasarela o plataforma de pago | C32: 0.08 | G32: % del cash | H32: Hotmart, Stripe, Mercado Pago: lo que se queda la plataforma.
B33: Comisión del equipo de ventas | C33: 0 | G33: % del cash | H33: Sobre el cash cobrado. Si el programa superior se vende por llamada, poné acá la comisión del closer.
B34: Reembolsos y contracargos | C34: 0.05 | G34: % del cash | H34: 5 % es normal en productos digitales. Más de 10 % es un problema de oferta o de expectativa.
B35: Costos por entrada (herramientas, WhatsApp, IA) | C35: 0.3 | G35: USD / entrada | H35: WhatsApp, soporte, plataforma del evento: lo que pagás por cada entrada.
B36: Costos fijos por lanzamiento | C36: 800 | G36: USD / lanzamiento | H36: Equipo, herramientas, edición: lo que pagás aunque no vendas.
B38: 6. Cobranza
B39: % del facturado que entra en el mes 1 | C39: 0.5 | G39: % | H39: Se aplica a todo el facturado como promedio ponderado: la entrada se cobra al contado, la oferta y el programa en cuotas. El ejemplo usa 50 / 25 / 25.
B40: % que entra en el mes 2 | C40: 0.25 | G40: % | H40: Cuotas o pagos diferidos.
B41: % que entra en el mes 3 | C41: 0.25 | G41: % | H41: Los tres deben sumar 100 %.
B43: 7. Objetivos y proyección
B44: ROAS objetivo sobre cash neto | C44: 2 | G44: x | H44: El retorno mínimo que querés por cada dólar invertido, después de comisiones y reembolsos. Entra en el semáforo: sin llegar a este ROAS no hay verde.
B45: Margen de seguridad | C45: 0.3 | G45: % | H45: Colchón entre el techo (donde no ganás ni perdés) y el objetivo. 30 % es el estándar que usamos.
B46: Meta de ventas del producto principal | C46: 25 | G46: ventas de la oferta / lanzamiento | H46: Para calcular cuánto invertir.
B47: Crecimiento de la inversión por mes (proyección) | C47: 0.1 | G47: % / mes | H47: Cuánto sube la inversión cada mes en la proyección. 10 % por mes es un ritmo prudente; más de 25 % suele encarecer el CPM.
...

Sheet Modelo
B1: © Jesús Tassarolo · TooAudience · youtube.com/@JesusTassaroloSinFiltro · uso personal; no redistribuir modificado
B2: Modelo: la cadena completa del embudo
B3: Cada fila es una etapa o un resultado. No se edita: todo sale de Supuestos. La columna de la derecha dice cómo se calcula.
B5: Etapa / resultado | C5: Valor | D5: Cómo se calcula
B6: Tráfico y entradas
B7: Visitas a la página de ventas | C7: =IF('Supuestos'!$C$10=0,0,'Supuestos'!$C$8/'Supuestos'!$C$10) | D7: Inversión ÷ costo por visita.
B8: Costo por entrada vendida | C8: =IF('Supuestos'!$C$13=0,0,'Supuestos'!$C$10/'Supuestos'!$C$13) | D8: Costo por visita ÷ % que compra la entrada.
B9: Entradas vendidas | C9: =IF('Modelo'!$C$8=0,0,'Supuestos'!$C$8/'Modelo'!$C$8) | D9: Inversión ÷ costo por entrada.
B10: Facturado: entradas | C10: ='Modelo'!$C$9*'Supuestos'!$C$14 | D10: Entradas × precio promedio.
B11: Ventas: bump de la entrada | C11: ='Modelo'!$C$9*'Supuestos'!$C$16 | D11: Entradas × % que lo toma.
B12: Facturado: bump de la entrada | C12: ='Modelo'!$C$11*'Supuestos'!$C$15 | D12: Ventas × precio.
B13: Facturado del front (entradas + bump) | C13: ='Modelo'!$C$10+'Modelo'!$C$12 | D13: Lo que entra antes del evento.
B14: ROAS del front (qué parte de la pauta recupera la entrada) | C14: =IF('Supuestos'!$C$8=0,0,'Modelo'!$C$13/'Supuestos'!$C$8) | D14: Facturado del front ÷ inversión. Cerca de 1 = el evento se paga solo.
B15: Grupo y asistencia
B16: Personas en el grupo | C16: ='Modelo'!$C$9*'Supuestos'!$C$19 | D16: Entradas × % que entra.
B17: Costo por persona en el grupo | C17: =IF('Modelo'!$C$16=0,0,'Supuestos'!$C$8/'Modelo'!$C$16) | D17: Inversión ÷ personas en el grupo.
B18: Asistentes en vivo | C18: ='Modelo'!$C$9*'Supuestos'!$C$20 | D18: Entradas × asistencia en vivo.
B19: Vieron el replay | C19: ='Modelo'!$C$9*'Supuestos'!$C$21 | D19: Entradas × % que ve el replay.
B20: Costo por asistente en vivo | C20: =IF('Modelo'!$C$18=0,0,'Supuestos'!$C$8/'Modelo'!$C$18) | D20: Inversión ÷ asistentes.
B21: Solicitudes (formulario de compra, aplicación o vendedor), oferta, programa y facturación
B22: Solicitudes: en vivo | C22: ='Modelo'!$C$18*'Supuestos'!$C$25 | D22: Asistentes en vivo × % que solicita.
B23: Solicitudes: replay | C23: ='Modelo'!$C$19*'Supuestos'!$C$26 | D23: Replay × % que solicita.
B24: Solicitudes (total) | C24: ='Modelo'!$C$22+'Modelo'!$C$23 | D24: En vivo + replay.
B25: % de compradores de entrada que solicitan | C25: =IF('Modelo'!$C$9=0,0,'Modelo'!$C$24/'Modelo'!$C$9) | D25: Solicitudes ÷ entradas.
B26: Costo por solicitud | C26: =IF('Modelo'!$C$24=0,0,'Supuestos'!$C$8/'Modelo'!$C$24) | D26: Inversión ÷ solicitudes.
B27: Ventas de la oferta | C27: ='Modelo'!$C$24*'Supuestos'!$C$27 | D27: Solicitudes × % que termina en compra.
B28: % de compradores de entrada que compran la oferta | C28: =IF('Modelo'!$C$9=0,0,'Modelo'!$C$27/'Modelo'!$C$9) | D28: Ventas ÷ entradas.
B29: Costo por comprador de la oferta | C29: =IF('Modelo'!$C$27=0,0,'Supuestos'!$C$8/'Modelo'!$C$27) | D29: Inversión ÷ ventas de la oferta.
B30: Facturado: oferta | C30: ='Modelo'!$C$27*'Supuestos'!$C$24 | D30: Ventas × precio.
B31: Ventas: programa superior | C31: ='Modelo'!$C$27*'Supuestos'!$C$29 | D31: Compradores de la oferta × % que asciende.
B32: Facturado: programa superior | C32: ='Modelo'!$C$31*'Supuestos'!$C$28 | D32: Ventas × precio.
B33: Facturado total | C33: ='Modelo'!$C$13+'Modelo'!$C$30+'Modelo'!$C$32 | D33: Front + oferta + programa.
B34: Facturado por comprador de la oferta | C34: =IF('Modelo'!$C$27=0,0,'Modelo'!$C$33/'Modelo'!$C$27) | D34: Facturado total ÷ ventas de la oferta.
B35: Ventas de la oferta por entrada (para la proyección) | C35: =IF('Modelo'!$C$9=0,0,'Modelo'!$C$27/'Modelo'!$C$9) | D35: Igual a '% que compra la oferta'.
B36: Facturado por entrada | C36: =IF('Modelo'!$C$9=0,0,'Modelo'!$C$33/'Modelo'!$C$9) | D36: Facturado total ÷ entradas.
B37: Cash, costos y ganancia del período
B38: Cash a cobrar (facturado × cobranza completa) | C38: ='Modelo'!$C$33*('Supuestos'!$C$39+'Supuestos'!$C$40+'Supuestos'!$C$41) | D38: Facturado × (mes 1 + mes 2 + mes 3). Si la cobranza suma 100 %, es igual al facturado.
B39: Cash que entra en el primer mes | C39: ='Modelo'!$C$33*'Supuestos'!$C$39 | D39: Facturado × % del mes 1.
B40: Comisiones (pasarela + ventas) | C40: ='Modelo'!$C$38*('Supuestos'!$C$32+'Supuestos'!$C$33) | D40: Cash × (pasarela + equipo de ventas).
B41: Reembolsos | C41: ='Modelo'!$C$38*'Supuestos'!$C$34 | D41: Cash × % de reembolsos.
...

Sheet Escenarios
B1: © Jesús Tassarolo · TooAudience · youtube.com/@JesusTassaroloSinFiltro · uso personal; no redistribuir modificado
B2: Escenarios: qué pasa si cambian el precio, la conversión o el costo
B3: Las celdas amarillas de cada tabla (fila y columna) se pueden cambiar. Verde = ganancia, amarillo = cerca del cero, rojo = pérdida. Todo lo demás queda como en Supuestos.
B5: Umbral de 'cerca del cero' (inversión × margen de seguridad) | C5: ='Supuestos'!$C$8*'Supuestos'!$C$45
B7: Precio de la oferta × % de solicitudes que terminan en compra → ganancia del lanzamiento
B8: A más precio, menos cierre: la tabla muestra qué combinación gana.
B9: Precio ↓ / % solicitud → compra → | C9: 0.3 | D9: 0.4 | E9: 0.5 | F9: 0.6 | G9: 0.7
B10: 197 | C10: =(((((((IF((IF('Supuestos'!$C$13=0,0,'Supuestos'!$C$10/'Supuestos'!$C$13))=0,0,'Supuestos'!$C$8/(IF('Supuestos'!$C$13=0,0,'Supuestos'!$C$10/'Supuestos'!$C$13))))*'Supuestos'!$C$14)+(((IF((IF('Supuestos'!$C$13=0,0,'Supuestos'!$C$10/'Supuestos'!$C$13))=0,0,'Supuestos'!$C$8/(IF('Supuestos'!$C$13=0,0,'Supuestos'!$C$10/'Supuestos'!$C$13))))*'Supuestos'!$C$16)*'Supuestos'!$C$15))+((((((IF((IF('Supuestos'!$C$13=0,0,'Supuestos'!$C$10/'Supuestos'!$C$13))=0,0,'Supuestos'!$C$8/(IF('Supuestos'!$C$13=0,0,'Supuestos'!$C$10/'Supuestos'!$C$13))))*'Supuestos'!$C$20)*'Supuestos'!$C$25)+(((IF((IF('Supuestos'!$C$13=0,0,'Supuestos'!$C$10/'Supuestos'!$C$13))=0,0,'Supuestos'!$C$8/(IF('Supuestos'!$C$13=0,0,'Supuestos'!$C$10/'Supuestos'!$C$13))))*'Supuestos'!$C$21)*'Supuestos'!$C$26))*C$9)*$B10)+(((((((IF((IF('Supuestos'!$C$13=0,0,'Supuestos'!$C$10/'Supuestos'!$C$13))=0,0,'Supuestos'!$C$8/(IF('Supuestos'!$C$13=0,0,'Supuestos'!$C$10/'Supuestos'!$C$13))))*'Supuestos'!$C$20)*'Supuestos'!$C$25)+(((IF((IF('Supuestos'!$C$13=0,0,'Supuestos'!$C$10/'Supuestos'!$C$13))=0,0,'Supuestos'!$C$8/(IF('Supuestos'!$C$13=0,0,'Supuestos'!$C$10/'Supuestos'!$C$13))))*'Supuestos'!$C$21)*'Supuestos'!$C$26))*C$9)*'Supuestos'!$C$29)*'Supuestos'!$C$28))*('Supuestos'!$C$39+'Supuestos'!$C$40+'Supuestos'!$C$41))*(1-'Supuestos'!$C$32-'Supuestos'!$C$33-'Supuestos'!$C$34))-((IF((IF('Supuestos'!$C$13=0,0,'Supuestos'!$C$10/'Supuestos'!$C$13))=0,0,'Supuestos'!$C$8/(IF('Supuestos'!$C$13=0,0,'Supuestos'!$C$10/'Supuestos'!$C$13))))*'Supuestos'!$C$35)-'Supuestos'!$C$36-'Supuestos'!$C$8) | D10: =(((((((IF((IF('Supuestos'!$C$13=0,0,'Supuestos'!$C$10/'Supuestos'!$C$13))=0,0,'Supuestos'!$C$8/(IF('Supuestos'!$C$13=0,0,'Supuestos'!$C$10/'Supuestos'!$C$13))))*'Supuestos'!$C$14)+(((IF((IF('Supuestos'!$C$13=0,0,'Supuestos'!$C$10/'Supuestos'!$C$13))=0,0,'Supuestos'!$C$8/(IF('Supuestos'!$C$13=0,0,'Supuestos'!$C$10/'Supuestos'!$C$13))))*'Supuestos'!$C$16)*'Supuestos'!$C$15))+((((((IF((IF('Supuestos'!$C$13=0,0,'Supuestos'!$C$10/'Supuestos'!$C$13))=0,0,'Supuestos'!$C$8/(IF('Supuestos'!$C$13=0,0,'Supuestos'!$C$10/'Supuestos'!$C$13))))*'Supuestos'!$C$20)*'Supuestos'!$C$25)+(((IF((IF('Supuestos'!$C$13=0,0,'Supuestos'!$C$10/'Supuestos'!$C$13))=0,0,'Supuestos'!$C$8/(IF('Supuestos'!$C$13=0,0,'Supuestos'!$C$10/'Supuestos'!$C$13))))*'Supuestos'!$C$21)*'Supuestos'!$C$26))*D$9)*$B10)+(((((((IF((IF('Supuestos'!$C$13=0,0,'Supuestos'!$C$10/'Supuestos'!$C$13))=0,0,'Supuestos'!$C$8/(IF('Supuestos'!$C$13=0,0,'Supuestos'!$C$10/'Supuestos'!$C$13))))*'Supuestos'!$C$20)*'Supuestos'!$C$25)+(((IF((IF('Supuestos'!$C$13=0,0,'Supuestos'!$C$10/'Supuestos'!$C$13))=0,0,'Supuestos'!$C$8/(IF('Supuestos'!$C$13=0,0,'Supuestos'!$C$10/'Supuestos'!$C$13))))*'Supuestos'!$C$21)*'Supuestos'!$C$26))*D$9)*'Supuestos'!$C$29)*'Supuestos'!$C$28))*('Supuestos'!$C$39+'Supuestos'!$C$40+'Supuestos'!$C$41))*(1-'Supuestos'!$C$32-'Supuestos'!$C$33-'Supuestos'!$C$34))-((IF((IF('Supuestos'!$C$13=0,0,'Supuestos'!$C$10/'Supuestos'!$C$13))=0,0,'Supuestos'!$C$8/(IF('Supuestos'!$C$13=0,0,'Supuestos'!$C$10/'Supuestos'!$C$13))))*'Supuestos'!$C$35)-'Supuestos'!$C$36-'Supuestos'!$C$8) | E10: =(((((((IF((IF('Supuestos'!$C$13=0,0,'Supuestos'!$C$10/'Supuestos'!$C$13))=0,0,'Supuestos'!$C$8/(IF('Supuestos'!$C$13=0,0,'Supuestos'!$C$10/'Supuestos'!$C$13))))*'Supuestos'!$C$14)+(((IF((IF('Supuestos'!$C$13=0,0,'Supuestos'!$C$10/'Supuestos'!$C$13))=0,0,'Supuestos'!$C$8/(IF('Supuestos'!$C$13=0,0,'Supuestos'!$C$10/'Supuestos'!$C$13))))*'Supuestos'!$C$16)*'Supuestos'!$C$15))+((((((IF((IF('Supuestos'!$C$13=0,0,'Supuestos'!$C$10/'Supuestos'!$C$13))=0,0,'Supuestos'!$C$8/(IF('Supuestos'!$C$13=0,0,'Supuestos'!$C$10/'Supuestos'!$C$13))))*'Supuestos'!$C$20)*'Supuestos'!$C$25)+(((IF((IF('Supuestos'!$C$13=0,0,'Supuestos'!$C$10/'Supuestos'!$C$13))=0,0,'Supuestos'!$C$8/(IF('Supuestos'!$C$13=0,0,'Supuestos'!$C$10/'Supuestos'!$C$13))))*'Supuestos'!$C$21)*'Supuestos'!$C$26))*E$9)*$B10)+(((((((IF((IF('Supuestos'!$C$13=0,0,'Supuestos'!$C$10/'Supuestos'!$C$13))=0,0,'Supuestos'!$C$8/(IF('Supuestos'!$C$13=0,0,'Supuestos'!$C$10/'Supuestos'!$C$13))))*'Supuestos'!$C$20)*'Supuestos'!$C$25)+(((IF((IF('Supuestos'!$C$13=0,0,'Supuestos'!$C$10/'Supuestos'!$C$13))=0,0,'Supuestos'!$C$8/(IF('Supuestos'!$C$13=0,0,'Supuestos'!$C$10/'Supuestos'!$C$13))))*'Supuestos'!$C$21)*'Supuestos'!$C$26))*E$9)*'Supuestos'!$C$29)*'Supuestos'!$C$28))*('Supuestos'!$C$39+'Supuestos'!$C$40+'Supuestos'!$C$41))*(1-'Supuestos'!$C$32-'Supuestos'!$C$33-'Supuestos'!$C$34))-((IF((IF('Supuestos'!$C$13=0,0,'Supuestos'!$C$10/'Supuestos'!$C$13))=0,0,'Supuestos'!$C$8/(IF('Supuestos'!$C$13=0,0,'Supuestos'!$C$10/'Supuestos'!$C$13))))*'Supuestos'!$C$35)-'Supuestos'!$C$36-'Supuestos'!$C$8) | F10: =(((((((IF((IF('Supuestos'!$C$13=0,0,'Supuestos'!$C$10/'Supuestos'!$C$13))=0,0,'Supuestos'!$C$8/(IF('Supuestos'!$C$13=0,0,'Supuestos'!$C$10/'Supuestos'!$C$13))))*'Supuestos'!$C$14)+(((IF((IF('Supuestos'!$C$13=0,0,'Supuestos'!$C$10/'Supuestos'!$C$13))=0,0,'Supuestos'!$C$8/(IF('Supuestos'!$C$13=0,0,'Supuestos'!$C$10/'Supuestos'!$C$13))))*'Supuestos'!$C$16)*'Supuestos'!$C$15))+((((((IF((IF('Supuestos'!$C$13=0,0,'Supuestos'!$C$10/'Supuestos'!$C$13))=0,0,'Supuestos'!$C$8/(IF('Supuestos'!$C$13=0,0,'Supuestos'!$C$10/'Supuestos'!$C$13))))*'Supuestos'!$C$20)*'Supuestos'!$C$25)+(((IF((IF('Supuestos'!$C$13=0,0,'Supuestos'!$C$10/'Supuestos'!$C$13))=0,0,'Supuestos'!$C$8/(IF('Supuestos'!$C$13=0,0,'Supuestos'!$C$10/'Supuestos'!$C$13))))*'Supuestos'!$C$21)*'Supuestos'!$C$26))*F$9)*$B10)+(((((((IF((IF('Supuestos'!$C$13=0,0,'Supuestos'!$C$10/'Supuestos'!$C$13))=0,0,'Supuestos'!$C$8/(IF('Supuestos'!$C$13=0,0,'Supuestos'!$C$10/'Supuestos'!$C$13))))*'Supuestos'!$C$20)*'Supuestos'!$C$25)+(((IF((IF('Supuestos'!$C$13=0,0,'Supuestos'!$C$10/'Supuestos'!$C$13))=0,0,'Supuestos'!$C$8/(IF('Supuestos'!$C$13=0,0,'Supuestos'!$C$10/'Supuestos'!$C$13))))*'Supuestos'!$C$21)*'Supuestos'!$C$26))*F$9)*'Supuestos'!$C$29)*'Supuestos'!$C$28))*('Supuestos'!$C$39+'Supuestos'!$C$40+'Supuestos'!$C$41))*(1-'Supuestos'!$C$32-'Supuestos'!$C$33-'Supuestos'!$C$34))-((IF((IF('Supuestos'!$C$13=0,0,'Supuestos'!$C$10/'Supuestos'!$C$13))=0,0,'Supuestos'!$C$8/(IF('Supuestos'!$C$13=0,0,'Supuestos'!$C$10/'Supuestos'!$C$13))))*'Supuestos'!$C$35)-'Supuestos'!$C$36-'Supuestos'!$C$8) | G10: =(((((((IF((IF('Supuestos'!$C$13=0,0,'Supuestos'!$C$10/'Supuestos'!$C$13))=0,0,'Supuestos'!$C$8/(IF('Supuestos'!$C$13=0,0,'Supuestos'!$C$10/'Supuestos'!$C$13))))*'Supuestos'!$C$14)+(((IF((IF('Supuestos'!$C$13=0,0,'Supuestos'!$C$10/'Supuestos'!$C$13))=0,0,'Supuestos'!$C$8/(IF('Supuestos'!$C$13=0,0,'Supuestos'!$C$10/'Supuestos'!$C$13))))*'Supuestos'!$C$16)*'Supuestos'!$C$15))+((((((IF((IF('Supuestos'!$C$13=0,0,'Supuestos'!$C$10/'Supuestos'!$C$13))=0,0,'Supuestos'!$C$8/(IF('Supuestos'!$C$13=0,0,'Supuestos'!$C$10/'Supuestos'!$C$13))))*'Supuestos'!$C$20)*'Supuestos'!$C$25)+(((IF((IF('Supuestos'!$C$13=0,0,'Supuestos'!$C$10/'Supuestos'!$C$13))=0,0,'Supuestos'!$C$8/(IF('Supuestos'!$C$13=0,0,'Supuestos'!$C$10/'Supuestos'!$C$13))))*'Supuestos'!$C$21)*'Supuestos'!$C$26))*G$9)*$B10)+(((((((IF((IF('Supuestos'!$C$13=0,0,'Supuestos'!$C$10/'Supuestos'!$C$13))=0,0,'Supuestos'!$C$8/(IF('Supuestos'!$C$13=0,0,'Supuestos'!$C$10/'Supuestos'!$C$13))))*'Supuestos'!$C$20)*'Supuestos'!$C$25)+(((IF((IF('Supuestos'!$C$13=0,0,'Supuestos'!$C$10/'Supuestos'!$C$13))=0,0,'Supuestos'!$C$8/(IF('Supuestos'!$C$13=0,0,'Supuestos'!$C$10/'Supuestos'!$C$13))))*'Supuestos'!$C$21)*'Supuestos'!$C$26))*G$9)*'Supuestos'!$C$29)*'Supuestos'!$C$28))*('Supuestos'!$C$39+'Supuestos'!$C$40+'Supuestos'!$C$41))*(1-'Supuestos'!$C$32-'Supuestos'!$C$33-'Supuestos'!$C$34))-((IF((IF('Supuestos'!$C$13=0,0,'Supuestos'!$C$10/'Supuestos'!$C$13))=0,0,'Supuestos'!$C$8/(IF('Supuestos'!$C$13=0,0,'Supuestos'!$C$10/'Supuestos'!$C$13))))*'Supuestos'!$C$35)-'Supuestos'!$C$36-'Supuestos'!$C$8)
B11: 297 | C11: =(((((((IF((IF('Supuestos'!$C$13=0,0,'Supuestos'!$C$10/'Supuestos'!$C$13))=0,0,'Supuestos'!$C$8/(IF('Supuestos'!$C$13=0,0,'Supuestos'!$C$10/'Supuestos'!$C$13))))*'Supuestos'!$C$14)+(((IF((IF('Supuestos'!$C$13=0,0,'Supuestos'!$C$10/'Supuestos'!$C$13))=0,0,'Supuestos'!$C$8/(IF('Supuestos'!$C$13=0,0,'Supuestos'!$C$10/'Supuestos'!$C$13))))*'Supuestos'!$C$16)*'Supuestos'!$C$15))+((((((IF((IF('Supuestos'!$C$13=0,0,'Supuestos'!$C$10/'Supuestos'!$C$13))=0,0,'Supuestos'!$C$8/(IF('Supuestos'!$C$13=0,0,'Supuestos'!$C$10/'Supuestos'!$C$13))))*'Supuestos'!$C$20)*'Supuestos'!$C$25)+(((IF((IF('Supuestos'!$C$13=0,0,'Supuestos'!$C$10/'Supuestos'!$C$13))=0,0,'Supuestos'!$C$8/(IF('Supuestos'!$C$13=0,0,'Supuestos'!$C$10/'Supuestos'!$C$13))))*'Supuestos'!$C$21)*'Supuestos'!$C$26))*C$9)*$B11)+(((((((IF((IF('Supuestos'!$C$13=0,0,'Supuestos'!$C$10/'Supuestos'!$C$13))=0,0,'Supuestos'!$C$8/(IF('Supuestos'!$C$13=0,0,'Supuestos'!$C$10/'Supuestos'!$C$13))))*'Supuestos'!$C$20)*'Supuestos'!$C$25)+(((IF((IF('Supuestos'!$C$13=0,0,'Supuestos'!$C$10/'Supuestos'!$C$13))=0,0,'Supuestos'!$C$8/(IF('Supuestos'!$C$13=0,0,'Supuestos'!$C$10/'Supuestos'!$C$13))))*'Supuestos'!$C$21)*'Supuestos'!$C$26))*C$9)*'Supuestos'!$C$29)*'Supuestos'!$C$28))*('Supuestos'!$C$39+'Supuestos'!$C$40+'Supuestos'!$C$41))*(1-'Supuestos'!$C$32-'Supuestos'!$C$33-'Supuestos'!$C$34))-((IF((IF('Supuestos'!$C$13=0,0,'Supuestos'!$C$10/'Supuestos'!$C$13))=0,0,'Supuestos'!$C$8/(IF('Supuestos'!$C$13=0,0,'Supuestos'!$C$10/'Supuestos'!$C$13))))*'Supuestos'!$C$35)-'Supuestos'!$C$36-'Supuestos'!$C$8) | D11: =(((((((IF((IF('Supuestos'!$C$13=0,0,'Supuestos'!$C$10/'Supuestos'!$C$13))=0,0,'Supuestos'!$C$8/(IF('Supuestos'!$C$13=0,0,'Supuestos'!$C$10/'Supuestos'!$C$13))))*'Supuestos'!$C$14)+(((IF((IF('Supuestos'!$C$13=0,0,'Supuestos'!$C$10/'Supuestos'!$C$13))=0,0,'Supuestos'!$C$8/(IF('Supuestos'!$C$13=0,0,'Supuestos'!$C$10/'Supuestos'!$C$13))))*'Supuestos'!$C$16)*'Supuestos'!$C$15))+((((((IF((IF('Supuestos'!$C$13=0,0,'Supuestos'!$C$10/'Supuestos'!$C$13))=0,0,'Supuestos'!$C$8/(IF('Supuestos'!$C$13=0,0,'Supuestos'!$C$10/'Supuestos'!$C$13))))*'Supuestos'!$C$20)*'Supuestos'!$C$25)+(((IF((IF('Supuestos'!$C$13=0,0,'Supuestos'!$C$10/'Supuestos'!$C$13))=0,0,'Supuestos'!$C$8/(IF('Supuestos'!$C$13=0,0,'Supuestos'!$C$10/'Supuestos'!$C$13))))*'Supuestos'!$C$21)*'Supuestos'!$C$26))*D$9)*$B11)+(((((((IF((IF('Supuestos'!$C$13=0,0,'Supuestos'!$C$10/'Supuestos'!$C$13))=0,0,'Supuestos'!$C$8/(IF('Supuestos'!$C$13=0,0,'Supuestos'!$C$10/'Supuestos'!$C$13))))*'Supuestos'!$C$20)*'Supuestos'!$C$25)+(((IF((IF('Supuestos'!$C$13=0,0,'Supuestos'!$C$10/'Supuestos'!$C$13))=0,0,'Supuestos'!$C$8/(IF('Supuestos'!$C$13=0,0,'Supuestos'!$C$10/'Supuestos'!$C$13))))*'Supuestos'!$C$21)*'Supuestos'!$C$26))*D$9)*'Supuestos'!$C$29)*'Supuestos'!$C$28))*('Supuestos'!$C$39+'Supuestos'!$C$40+'Supuestos'!$C$41))*(1-'Supuestos'!$C$32-'Supuestos'!$C$33-'Supuestos'!$C$34))-((IF((IF('Supuestos'!$C$13=0,0,'Supuestos'!$C$10/'Supuestos'!$C$13))=0,0,'Supuestos'!$C$8/(IF('Supuestos'!$C$13=0,0,'Supuestos'!$C$10/'Supuestos'!$C$13))))*'Supuestos'!$C$35)-'Supuestos'!$C$36-'Supuestos'!$C$8) | E11: =(((((((IF((IF('Supuestos'!$C$13=0,0,'Supuestos'!$C$10/'Supuestos'!$C$13))=0,0,'Supuestos'!$C$8/(IF('Supuestos'!$C$13=0,0,'Supuestos'!$C$10/'Supuestos'!$C$13))))*'Supuestos'!$C$14)+(((IF((IF('Supuestos'!$C$13=0,0,'Supuestos'!$C$10/'Supuestos'!$C$13))=0,0,'Supuestos'!$C$8/(IF('Supuestos'!$C$13=0,0,'Supuestos'!$C$10/'Supuestos'!$C$13))))*'Supuestos'!$C$16)*'Supuestos'!$C$15))+((((((IF((IF('Supuestos'!$C$13=0,0,'Supuestos'!$C$10/'Supuestos'!$C$13))=0,0,'Supuestos'!$C$8/(IF('Supuestos'!$C$13=0,0,'Supuestos'!$C$10/'Supuestos'!$C$13))))*'Supuestos'!$C$20)*'Supuestos'!$C$25)+(((IF((IF('Supuestos'!$C$13=0,0,'Supuestos'!$C$10/'Supuestos'!$C$13))=0,0,'Supuestos'!$C$8/(IF('Supuestos'!$C$13=0,0,'Supuestos'!$C$10/'Supuestos'!$C$13))))*'Supuestos'!$C$21)*'Supuestos'!$C$26))*E$9)*$B11)+(((((((IF((IF('Supuestos'!$C$13=0,0,'Supuestos'!$C$10/'Supuestos'!$C$13))=0,0,'Supuestos'!$C$8/(IF('Supuestos'!$C$13=0,0,'Supuestos'!$C$10/'Supuestos'!$C$13))))*'Supuestos'!$C$20)*'Supuestos'!$C$25)+(((IF((IF('Supuestos'!$C$13=0,0,'Supuestos'!$C$10/'Supuestos'!$C$13))=0,0,'Supuestos'!$C$8/(IF('Supuestos'!$C$13=0,0,'Supuestos'!$C$10/'Supuestos'!$C$13))))*'Supuestos'!$C$21)*'Supuestos'!$C$26))*E$9)*'Supuestos'!$C$29)*'Supuestos'!$C$28))*('Supuestos'!$C$39+'Supuestos'!$C$40+'Supuestos'!$C$41))*(1-'Supuestos'!$C$32-'Supuestos'!$C$33-'Supuestos'!$C$34))-((IF((IF('Supuestos'!$C$13=0,0,'Supuestos'!$C$10/'Supuestos'!$C$13))=0,0,'Supuestos'!$C$8/(IF('Supuestos'!$C$13=0,0,'Supuestos'!$C$10/'Supuestos'!$C$13))))*'Supuestos'!$C$35)-'Supuestos'!$C$36-'Supuestos'!$C$8) | F11: =(((((((IF((IF('Supuestos'!$C$13=0,0,'Supuestos'!$C$10/'Supuestos'!$C$13))=0,0,'Supuestos'!$C$8/(IF('Supuestos'!$C$13=0,0,'Supuestos'!$C$10/'Supuestos'!$C$13))))*'Supuestos'!$C$14)+(((IF((IF('Supuestos'!$C$13=0,0,'Supuestos'!$C$10/'Supuestos'!$C$13))=0,0,'Supuestos'!$C$8/(IF('Supuestos'!$C$13=0,0,'Supuestos'!$C$10/'Supuestos'!$C$13))))*'Supuestos'!$C$16)*'Supuestos'!$C$15))+((((((IF((IF('Supuestos'!$C$13=0,0,'Supuestos'!$C$10/'Supuestos'!$C$13))=0,0,'Supuestos'!$C$8/(IF('Supuestos'!$C$13=0,0,'Supuestos'!$C$10/'Supuestos'!$C$13))))*'Supuestos'!$C$20)*'Supuestos'!$C$25)+(((IF((IF('Supuestos'!$C$13=0,0,'Supuestos'!$C$10/'Supuestos'!$C$13))=0,0,'Supuestos'!$C$8/(IF('Supuestos'!$C$13=0,0,'Supuestos'!$C$10/'Supuestos'!$C$13))))*'Supuestos'!$C$21)*'Supuestos'!$C$26))*F$9)*$B11)+(((((((IF((IF('Supuestos'!$C$13=0,0,'Supuestos'!$C$10/'Supuestos'!$C$13))=0,0,'Supuestos'!$C$8/(IF('Supuestos'!$C$13=0,0,'Supuestos'!$C$10/'Supuestos'!$C$13))))*'Supuestos'!$C$20)*'Supuestos'!$C$25)+(((IF((IF('Supuestos'!$C$13=0,0,'Supuestos'!$C$10/'Supuestos'!$C$13))=0,0,'Supuestos'!$C$8/(IF('Supuestos'!$C$13=0,0,'Supuestos'!$C$10/'Supuestos'!$C$13))))*'Supuestos'!$C$21)*'Supuestos'!$C$26))*F$9)*'Supuestos'!$C$29)*'Supuestos'!$C$28))*('Supuestos'!$C$39+'Supuestos'!$C$40+'Supuestos'!$C$41))*(1-'Supuestos'!$C$32-'Supuestos'!$C$33-'Supuestos'!$C$34))-((IF((IF('Supuestos'!$C$13=0,0,'Supuestos'!$C$10/'Supuestos'!$C$13))=0,0,'Supuestos'!$C$8/(IF('Supuestos'!$C$13=0,0,'Supuestos'!$C$10/'Supuestos'!$C$13))))*'Supuestos'!$C$35)-'Supuestos'!$C$36-'Supuestos'!$C$8) | G11: =(((((((IF((IF('Supuestos'!$C$13=0,0,'Supuestos'!$C$10/'Supuestos'!$C$13))=0,0,'Supuestos'!$C$8/(IF('Supuestos'!$C$13=0,0,'Supuestos'!$C$10/'Supuestos'!$C$13))))*'Supuestos'!$C$14)+(((IF((IF('Supuestos'!$C$13=0,0,'Supuestos'!$C$10/'Supuestos'!$C$13))=0,0,'Supuestos'!$C$8/(IF('Supuestos'!$C$13=0,0,'Supuestos'!$C$10/'Supuestos'!$C$13))))*'Supuestos'!$C$16)*'Supuestos'!$C$15))+((((((IF((IF('Supuestos'!$C$13=0,0,'Supuestos'!$C$10/'Supuestos'!$C$13))=0,0,'Supuestos'!$C$8/(IF('Supuestos'!$C$13=0,0,'Supuestos'!$C$10/'Supuestos'!$C$13))))*'Supuestos'!$C$20)*'Supuestos'!$C$25)+(((IF((IF('Supuestos'!$C$13=0,0,'Supuestos'!$C$10/'Supuestos'!$C$13))=0,0,'Supuestos'!$C$8/(IF('Supuestos'!$C$13=0,0,'Supuestos'!$C$10/'Supuestos'!$C$13))))*'Supuestos'!$C$21)*'Supuestos'!$C$26))*G$9)*$B11)+(((((((IF((IF('Supuestos'!$C$13=0,0,'Supuestos'!$C$10/'Supuestos'!$C$13))=0,0,'Supuestos'!$C$8/(IF('Supuestos'!$C$13=0,0,'Supuestos'!$C$10/'Supuestos'!$C$13))))*'Supuestos'!$C$20)*'Supuestos'!$C$25)+(((IF((IF('Supuestos'!$C$13=0,0,'Supuestos'!$C$10/'Supuestos'!$C$13))=0,0,'Supuestos'!$C$8/(IF('Supuestos'!$C$13=0,0,'Supuestos'!$C$10/'Supuestos'!$C$13))))*'Supuestos'!$C$21)*'Supuestos'!$C$26))*G$9)*'Supuestos'!$C$29)*'Supuestos'!$C$28))*('Supuestos'!$C$39+'Supuestos'!$C$40+'Supuestos'!$C$41))*(1-'Supuestos'!$C$32-'Supuestos'!$C$33-'Supuestos'!$C$34))-((IF((IF('Supuestos'!$C$13=0,0,'Supuestos'!$C$10/'Supuestos'!$C$13))=0,0,'Supuestos'!$C$8/(IF('Supuestos'!$C$13=0,0,'Supuestos'!$C$10/'Supuestos'!$C$13))))*'Supuestos'!$C$35)-'Supuestos'!$C$36-'Supuestos'!$C$8)
B12: 497 | C12: =(((((((IF((IF('Supuestos'!$C$13=0,0,'Supuestos'!$C$10/'Supuestos'!$C$13))=0,0,'Supuestos'!$C$8/(IF('Supuestos'!$C$13=0,0,'Supuestos'!$C$10/'Supuestos'!$C$13))))*'Supuestos'!$C$14)+(((IF((IF('Supuestos'!$C$13=0,0,'Supuestos'!$C$10/'Supuestos'!$C$13))=0,0,'Supuestos'!$C$8/(IF('Supuestos'!$C$13=0,0,'Supuestos'!$C$10/'Supuestos'!$C$13))))*'Supuestos'!$C$16)*'Supuestos'!$C$15))+((((((IF((IF('Supuestos'!$C$13=0,0,'Supuestos'!$C$10/'Supuestos'!$C$13))=0,0,'Supuestos'!$C$8/(IF('Supuestos'!$C$13=0,0,'Supuestos'!$C$10/'Supuestos'!$C$13))))*'Supuestos'!$C$20)*'Supuestos'!$C$25)+(((IF((IF('Supuestos'!$C$13=0,0,'Supuestos'!$C$10/'Supuestos'!$C$13))=0,0,'Supuestos'!$C$8/(IF('Supuestos'!$C$13=0,0,'Supuestos'!$C$10/'Supuestos'!$C$13))))*'Supuestos'!$C$21)*'Supuestos'!$C$26))*C$9)*$B12)+(((((((IF((IF('Supuestos'!$C$13=0,0,'Supuestos'!$C$10/'Supuestos'!$C$13))=0,0,'Supuestos'!$C$8/(IF('Supuestos'!$C$13=0,0,'Supuestos'!$C$10/'Supuestos'!$C$13))))*'Supuestos'!$C$20)*'Supuestos'!$C$25)+(((IF((IF('Supuestos'!$C$13=0,0,'Supuestos'!$C$10/'Supuestos'!$C$13))=0,0,'Supuestos'!$C$8/(IF('Supuestos'!$C$13=0,0,'Supuestos'!$C$10/'Supuestos'!$C$13))))*'Supuestos'!$C$21)*'Supuestos'!$C$26))*C$9)*'Supuestos'!$C$29)*'Supuestos'!$C$28))*('Supuestos'!$C$39+'Supuestos'!$C$40+'Supuestos'!$C$41))*(1-'Supuestos'!$C$32-'Supuestos'!$C$33-'Supuestos'!$C$34))-((IF((IF('Supuestos'!$C$13=0,0,'Supuestos'!$C$10/'Supuestos'!$C$13))=0,0,'Supuestos'!$C$8/(IF('Supuestos'!$C$13=0,0,'Supuestos'!$C$10/'Supuestos'!$C$13))))*'Supuestos'!$C$35)-'Supuestos'!$C$36-'Supuestos'!$C$8) | D12: =(((((((IF((IF('Supuestos'!$C$13=0,0,'Supuestos'!$C$10/'Supuestos'!$C$13))=0,0,'Supuestos'!$C$8/(IF('Supuestos'!$C$13=0,0,'Supuestos'!$C$10/'Supuestos'!$C$13))))*'Supuestos'!$C$14)+(((IF((IF('Supuestos'!$C$13=0,0,'Supuestos'!$C$10/'Supuestos'!$C$13))=0,0,'Supuestos'!$C$8/(IF('Supuestos'!$C$13=0,0,'Supuestos'!$C$10/'Supuestos'!$C$13))))*'Supuestos'!$C$16)*'Supuestos'!$C$15))+((((((IF((IF('Supuestos'!$C$13=0,0,'Supuestos'!$C$10/'Supuestos'!$C$13))=0,0,'Supuestos'!$C$8/(IF('Supuestos'!$C$13=0,0,'Supuestos'!$C$10/'Supuestos'!$C$13))))*'Supuestos'!$C$20)*'Supuestos'!$C$25)+(((IF((IF('Supuestos'!$C$13=0,0,'Supuestos'!$C$10/'Supuestos'!$C$13))=0,0,'Supuestos'!$C$8/(IF('Supuestos'!$C$13=0,0,'Supuestos'!$C$10/'Supuestos'!$C$13))))*'Supuestos'!$C$21)*'Supuestos'!$C$26))*D$9)*$B12)+(((((((IF((IF('Supuestos'!$C$13=0,0,'Supuestos'!$C$10/'Supuestos'!$C$13))=0,0,'Supuestos'!$C$8/(IF('Supuestos'!$C$13=0,0,'Supuestos'!$C$10/'Supuestos'!$C$13))))*'Supuestos'!$C$20)*'Supuestos'!$C$25)+(((IF((IF('Supuestos'!$C$13=0,0,'Supuestos'!$C$10/'Supuestos'!$C$13))=0,0,'Supuestos'!$C$8/(IF('Supuestos'!$C$13=0,0,'Supuestos'!$C$10/'Supuestos'!$C$13))))*'Supuestos'!$C$21)*'Supuestos'!$C$26))*D$9)*'Supuestos'!$C$29)*'Supuestos'!$C$28))*('Supuestos'!$C$39+'Supuestos'!$C$40+'Supuestos'!$C$41))*(1-'Supuestos'!$C$32-'Supuestos'!$C$33-'Supuestos'!$C$34))-((IF((IF('Supuestos'!$C$13=0,0,'Supuestos'!$C$10/'Supuestos'!$C$13))=0,0,'Supuestos'!$C$8/(IF('Supuestos'!$C$13=0,0,'Supuestos'!$C$10/'Supuestos'!$C$13))))*'Supuestos'!$C$35)-'Supuestos'!$C$36-'Supuestos'!$C$8) | E12: =(((((((IF((IF('Supuestos'!$C$13=0,0,'Supuestos'!$C$10/'Supuestos'!$C$13))=0,0,'Supuestos'!$C$8/(IF('Supuestos'!$C$13=0,0,'Supuestos'!$C$10/'Supuestos'!$C$13))))*'Supuestos'!$C$14)+(((IF((IF('Supuestos'!$C$13=0,0,'Supuestos'!$C$10/'Supuestos'!$C$13))=0,0,'Supuestos'!$C$8/(IF('Supuestos'!$C$13=0,0,'Supuestos'!$C$10/'Supuestos'!$C$13))))*'Supuestos'!$C$16)*'Supuestos'!$C$15))+((((((IF((IF('Supuestos'!$C$13=0,0,'Supuestos'!$C$10/'Supuestos'!$C$13))=0,0,'Supuestos'!$C$8/(IF('Supuestos'!$C$13=0,0,'Supuestos'!$C$10/'Supuestos'!$C$13))))*'Supuestos'!$C$20)*'Supuestos'!$C$25)+(((IF((IF('Supuestos'!$C$13=0,0,'Supuestos'!$C$10/'Supuestos'!$C$13))=0,0,'Supuestos'!$C$8/(IF('Supuestos'!$C$13=0,0,'Supuestos'!$C$10/'Supuestos'!$C$13))))*'Supuestos'!$C$21)*'Supuestos'!$C$26))*E$9)*$B12)+(((((((IF((IF('Supuestos'!$C$13=0,0,'Supuestos'!$C$10/'Supuestos'!$C$13))=0,0,'Supuestos'!$C$8/(IF('Supuestos'!$C$13=0,0,'Supuestos'!$C$10/'Supuestos'!$C$13))))*'Supuestos'!$C$20)*'Supuestos'!$C$25)+(((IF((IF('Supuestos'!$C$13=0,0,'Supuestos'!$C$10/'Supuestos'!$C$13))=0,0,'Supuestos'!$C$8/(IF('Supuestos'!$C$13=0,0,'Supuestos'!$C$10/'Supuestos'!$C$13))))*'Supuestos'!$C$21)*'Supuestos'!$C$26))*E$9)*'Supuestos'!$C$29)*'Supuestos'!$C$28))*('Supuestos'!$C$39+'Supuestos'!$C$40+'Supuestos'!$C$41))*(1-'Supuestos'!$C$32-'Supuestos'!$C$33-'Supuestos'!$C$34))-((IF((IF('Supuestos'!$C$13=0,0,'Supuestos'!$C$10/'Supuestos'!$C$13))=0,0,'Supuestos'!$C$8/(IF('Supuestos'!$C$13=0,0,'Supuestos'!$C$10/'Supuestos'!$C$13))))*'Supuestos'!$C$35)-'Supuestos'!$C$36-'Supuestos'!$C$8) | F12: =(((((((IF((IF('Supuestos'!$C$13=0,0,'Supuestos'!$C$10/'Supuestos'!$C$13))=0,0,'Supuestos'!$C$8/(IF('Supuestos'!$C$13=0,0,'Supuestos'!$C$10/'Supuestos'!$C$13))))*'Supuestos'!$C$14)+(((IF((IF('Supuestos'!$C$13=0,0,'Supuestos'!$C$10/'Supuestos'!$C$13))=0,0,'Supuestos'!$C$8/(IF('Supuestos'!$C$13=0,0,'Supuestos'!$C$10/'Supuestos'!$C$13))))*'Supuestos'!$C$16)*'Supuestos'!$C$15))+((((((IF((IF('Supuestos'!$C$13=0,0,'Supuestos'!$C$10/'Supuestos'!$C$13))=0,0,'Supuestos'!$C$8/(IF('Supuestos'!$C$13=0,0,'Supuestos'!$C$10/'Supuestos'!$C$13))))*'Supuestos'!$C$20)*'Supuestos'!$C$25)+(((IF((IF('Supuestos'!$C$13=0,0,'Supuestos'!$C$10/'Supuestos'!$C$13))=0,0,'Supuestos'!$C$8/(IF('Supuestos'!$C$13=0,0,'Supuestos'!$C$10/'Supuestos'!$C$13))))*'Supuestos'!$C$21)*'Supuestos'!$C$26))*F$9)*$B12)+(((((((IF((IF('Supuestos'!$C$13=0,0,'Supuestos'!$C$10/'Supuestos'!$C$13))=0,0,'Supuestos'!$C$8/(IF('Supuestos'!$C$13=0,0,'Supuestos'!$C$10/'Supuestos'!$C$13))))*'Supuestos'!$C$20)*'Supuestos'!$C$25)+(((IF((IF('Supuestos'!$C$13=0,0,'Supuestos'!$C$10/'Supuestos'!$C$13))=0,0,'Supuestos'!$C$8/(IF('Supuestos'!$C$13=0,0,'Supuestos'!$C$10/'Supuestos'!$C$13))))*'Supuestos'!$C$21)*'Supuestos'!$C$26))*F$9)*'Supuestos'!$C$29)*'Supuestos'!$C$28))*('Supuestos'!$C$39+'Supuestos'!$C$40+'Supuestos'!$C$41))*(1-'Supuestos'!$C$32-'Supuestos'!$C$33-'Supuestos'!$C$34))-((IF((IF('Supuestos'!$C$13=0,0,'Supuestos'!$C$10/'Supuestos'!$C$13))=0,0,'Supuestos'!$C$8/(IF('Supuestos'!$C$13=0,0,'Supuestos'!$C$10/'Supuestos'!$C$13))))*'Supuestos'!$C$35)-'Supuestos'!$C$36-'Supuestos'!$C$8) | G12: =(((((((IF((IF('Supuestos'!$C$13=0,0,'Supuestos'!$C$10/'Supuestos'!$C$13))=0,0,'Supuestos'!$C$8/(IF('Supuestos'!$C$13=0,0,'Supuestos'!$C$10/'Supuestos'!$C$13))))*'Supuestos'!$C$14)+(((IF((IF('Supuestos'!$C$13=0,0,'Supuestos'!$C$10/'Supuestos'!$C$13))=0,0,'Supuestos'!$C$8/(IF('Supuestos'!$C$13=0,0,'Supuestos'!$C$10/'Supuestos'!$C$13))))*'Supuestos'!$C$16)*'Supuestos'!$C$15))+((((((IF((IF('Supuestos'!$C$13=0,0,'Supuestos'!$C$10/'Supuestos'!$C$13))=0,0,'Supuestos'!$C$8/(IF('Supuestos'!$C$13=0,0,'Supuestos'!$C$10/'Supuestos'!$C$13))))*'Supuestos'!$C$20)*'Supuestos'!$C$25)+(((IF((IF('Supuestos'!$C$13=0,0,'Supuestos'!$C$10/'Supuestos'!$C$13))=0,0,'Supuestos'!$C$8/(IF('Supuestos'!$C$13=0,0,'Supuestos'!$C$10/'Supuestos'!$C$13))))*'Supuestos'!$C$21)*'Supuestos'!$C$26))*G$9)*$B12)+(((((((IF((IF('Supuestos'!$C$13=0,0,'Supuestos'!$C$10/'Supuestos'!$C$13))=0,0,'Supuestos'!$C$8/(IF('Supuestos'!$C$13=0,0,'Supuestos'!$C$10/'Supuestos'!$C$13))))*'Supuestos'!$C$20)*'Supuestos'!$C$25)+(((IF((IF('Supuestos'!$C$13=0,0,'Supuestos'!$C$10/'Supuestos'!$C$13))=0,0,'Supuestos'!$C$8/(IF('Supuestos'!$C$13=0,0,'Supuestos'!$C$10/'Supuestos'!$C$13))))*'Supuestos'!$C$21)*'Supuestos'!$C$26))*G$9)*'Supuestos'!$C$29)*'Supuestos'!$C$28))*('Supuestos'!$C$39+'Supuestos'!$C$40+'Supuestos'!$C$41))*(1-'Supuestos'!$C$32-'Supuestos'!$C$33-'Supuestos'!$C$34))-((IF((IF('Supuestos'!$C$13=0,0,'Supuestos'!$C$10/'Supuestos'!$C$13))=0,0,'Supuestos'!$C$8/(IF('Supuestos'!$C$13=0,0,'Supuestos'!$C$10/'Supuestos'!$C$13))))*'Supuestos'!$C$35)-'Supuestos'!$C$36-'Supuestos'!$C$8)
