Workbook
Name Autor_Jesus_Tassarolo: "Modelo financiero de embudos · creado por Jesús Tassarolo · TooAudience · youtube.com/@JesusTassaroloSinFiltro"

Sheet Inicio
B1: © Jesús Tassarolo · TooAudience · youtube.com/@JesusTassaroloSinFiltro · uso personal; no redistribuir modificado
B2: Métricas diarias · Embudo low-ticket con VSL, bumps y OTOs
B3: Las métricas diarias de todo el embudo, para saber cómo estás con tus propios números. Acompaña al modelo financiero del mismo embudo.
B5: Qué es
B6: Un registro diario de cada paso del embudo (anuncios, página, unidades, etapas, ventas, cash) que se convierte solo en un comparativo semanal y en un resumen con semáforo. El semáforo no usa números de mercado: compara cada semana con la mediana de tus 4 semanas anteriores, con una tolerancia del 25 % (la cambiás en Config).
B8: 1. Config
B9: Poné tus precios, comisiones, reembolsos, costos fijos por día y la fecha de inicio (un lunes). Todo lo demás se calcula con eso.
B11: 2. Diario (todos los días, 3 minutos)
B12: Una fila por día. Cargá las celdas amarillas con lo que hubo: inversión, impresiones, alcance, clics en el enlace, visitas y cada paso del embudo. Si un día no hubo evento, dejá vacío. Las celdas azules se calculan solas (CPM, CTR, costo por visita, CPL, conversiones, facturado, cash neto, ganancia, ROAS y la ganancia por visita).
B14: 3. Semanal (los lunes, 10 minutos)
B15: No se carga nada: suma Diario por semana y calcula las conversiones y los costos de la semana, el promedio, la mediana, la mejor y la peor. Abajo, el bloque «contra tu promedio» marca en verde, amarillo o rojo cada métrica clave contra la mediana de tus 4 semanas anteriores.
B17: 4. Resumen
... B36: Modelo financiero de embudos · creado por Jesús Tassarolo · TooAudience · youtube.com/@JesusTassaroloSinFiltro · v1.2 · octubre 2026

Sheet Config
B1: © Jesús Tassarolo · TooAudience · youtube.com/@JesusTassaroloSinFiltro · uso personal; no redistribuir modificado
B2: Config: tus precios, comisiones y la fecha de inicio
B3: Amarillo = podés cambiarlo. Todo lo demás del libro se calcula con esto.
B5: Dato | C5: Valor | D5: Nota
B6: Fecha de inicio del registro (un lunes) | C6: 46272 | D6: Desde este día se numeran las semanas en Diario y Semanal. Elegí un lunes.
B7: Precio del producto principal | C7: 37
B8: Precio del bump 1 | C8: 17
B9: Precio del bump 2 | C9: 17
B10: Precio de la OTO 1 | C10: 47
B11: Precio de la OTO 2 | C11: 17
B12: Precio de la OTO 3 | C12: 97
B13: Precio de la OTO 4 | C13: 27
B14: Precio del programa (ascensión) | C14: 297
B15: Comisión de la pasarela de pago | C15: 0.1 | D15: Lo que se queda la plataforma de cobro.
B16: Comisión del equipo de ventas | C16: 0 | D16: Si vendés por llamada: lo que cobra el closer sobre lo cobrado.
B17: Reembolsos y contracargos | C17: 0.05 | D17: Promedio histórico. 5 % es normal en productos digitales.
B18: Costos fijos por día (USD) | C18: 50 | D18: Equipo, herramientas, edición: lo que pagás aunque no vendas, dividido por 30.
B19: ROAS objetivo sobre cash neto | C19: 2 | D19: El retorno mínimo que querés por cada dólar, ya neto.
B20: Tolerancia del semáforo contra tu promedio | C20: 0.25 | D20: Igual o mejor que tu mediana = verde; hasta esta distancia peor = amarillo; más = rojo. 20 a 30 %.
A23: Modelo financiero de embudos · creado por Jesús Tassarolo · TooAudience · youtube.com/@JesusTassaroloSinFiltro · v1.2 · octubre 2026

Sheet Diario
A1: © Jesús Tassarolo · TooAudience · youtube.com/@JesusTassaroloSinFiltro · uso personal; no redistribuir modificado
A2: Diario: una fila por día. Amarillo = lo que cargás; azul = lo que calcula el libro
A3: Cargá cada día lo que hubo (vacío si no hubo). Los porcentajes de un solo día pueden ser raros en embudos con evento semanal: la lectura buena está en Semanal.
A5: Fecha | B5: Semana | C5: Inversión en publicidad (USD) | D5: Impresiones | E5: Alcance (personas únicas) | F5: Clics en el enlace | G5: Visitas a la página | H5: Inician el checkout | I5: Compran el producto principal | J5: Toman el bump 1 | K5: Toman el bump 2 | L5: Toman la OTO 1 | M5: Toman la OTO 2 | N5: Toman la OTO 3 | O5: Toman la OTO 4 | P5: Ascienden al programa | Q5: CPM | R5: Frecuencia | S5: CTR al enlace | T5: CPC (por clic en el enlace) | U5: % clic → visita | V5: Costo por visita | W5: Visitas por cada 1.000 impresiones | X5: % visita → checkout | Y5: % checkout → compra | Z5: % visita → compra | AA5: CPA (costo por comprador) | AB5: % toman el bump 1 | AC5: % toman el bump 2 | AD5: % toman la OTO 1 | AE5: % ascienden | AF5: Facturado (toda la escalera) | AG5: Order value (facturado por comprador) | AH5: Cash neto (después de comisiones y reembolsos) | AI5: Ganancia (cash neto − pauta − fijos) | AJ5: ROAS sobre cash neto | AK5: Ganancia por visita (la métrica más valiosa) | AL5: Margen por visita (ganancia por visita ÷ costo por visita) | AM5: Ganancia por comprador | AN5: AOV neto − CPA (lo que queda por comprador)
A6: =Config!$C$6+0 | B6: =INT((A6-Config!$C$6)/7)+1 | C6: 297 | D6: 69614 | E6: 39488 | F6: 1070 | G6: 965 | H6: 34 | I6: 8 | J6: 2 | K6: 1 | L6: 1 | M6: 0 | N6: 0 | O6: 0 | P6: 0 | Q6: =IF(COUNT(C6:P6)=0,"",IFERROR(C6/D6*1000,0)) | R6: =IF(COUNT(C6:P6)=0,"",IFERROR(D6/E6,0)) | S6: =IF(COUNT(C6:P6)=0,"",IFERROR(F6/D6,0)) | T6: =IF(COUNT(C6:P6)=0,"",IFERROR(C6/F6,0)) | U6: =IF(COUNT(C6:P6)=0,"",IFERROR(G6/F6,0)) | V6: =IF(COUNT(C6:P6)=0,"",IFERROR(C6/G6,0)) | W6: =IF(COUNT(C6:P6)=0,"",IFERROR(G6/D6*1000,0)) | X6: =IF(COUNT(C6:P6)=0,"",IFERROR(H6/G6,0)) | Y6: =IF(COUNT(C6:P6)=0,"",IFERROR(I6/H6,0)) | Z6: =IF(COUNT(C6:P6)=0,"",IFERROR(I6/G6,0)) | AA6: =IF(COUNT(C6:P6)=0,"",IFERROR(C6/I6,0)) | AB6: =IF(COUNT(C6:P6)=0,"",IFERROR(J6/I6,0)) | AC6: =IF(COUNT(C6:P6)=0,"",IFERROR(K6/I6,0)) | AD6: =IF(COUNT(C6:P6)=0,"",IFERROR(L6/I6,0)) | AE6: =IF(COUNT(C6:P6)=0,"",IFERROR(P6/I6,0)) | AF6: =IF(COUNT(C6:P6)=0,"",IFERROR(I6*Config!$C$7+J6*Config!$C$8+K6*Config!$C$9+L6*Config!$C$10+M6*Config!$C$11+N6*Config!$C$12+O6*Config!$C$13+P6*Config!$C$14,0)) | AG6: =IF(COUNT(C6:P6)=0,"",IFERROR(AF6/I6,0)) | AH6: =IF(COUNT(C6:P6)=0,"",IFERROR(AF6*(1-Config!$C$15-Config!$C$16-Config!$C$17),0)) | AI6: =IF(COUNT(C6:P6)=0,"",IFERROR(AH6-C6-Config!$C$18,0)) | AJ6: =IF(COUNT(C6:P6)=0,"",IFERROR(AH6/C6,0)) | AK6: =IF(COUNT(C6:P6)=0,"",IFERROR(AI6/G6,0)) | AL6: =IF(COUNT(C6:P6)=0,"",IFERROR(AK6/V6,0)) | AM6: =IF(COUNT(C6:P6)=0,"",IFERROR(AI6/I6,0)) | AN6: =IF(COUNT(C6:P6)=0,"",IFERROR(AH6/I6-AA6,0))
A7: =Config!$C$6+1 | B7: =INT((A7-Config!$C$6)/7)+1 | C7: 301 | D7: 69467 | E7: 40565 | F7: 972 | G7: 833 | H7: 26 | I7: 7 | J7: 2 | K7: 1 | L7: 1 | M7: 0 | N7: 0 | O7: 0 | P7: 0 | Q7: =IF(COUNT(C7:P7)=0,"",IFERROR(C7/D7*1000,0)) | R7: =IF(COUNT(C7:P7)=0,"",IFERROR(D7/E7,0)) | S7: =IF(COUNT(C7:P7)=0,"",IFERROR(F7/D7,0)) | T7: =IF(COUNT(C7:P7)=0,"",IFERROR(C7/F7,0)) | U7: =IF(COUNT(C7:P7)=0,"",IFERROR(G7/F7,0)) | V7: =IF(COUNT(C7:P7)=0,"",IFERROR(C7/G7,0)) | W7: =IF(COUNT(C7:P7)=0,"",IFERROR(G7/D7*1000,0)) | X7: =IF(COUNT(C7:P7)=0,"",IFERROR(H7/G7,0)) | Y7: =IF(COUNT(C7:P7)=0,"",IFERROR(I7/H7,0)) | Z7: =IF(COUNT(C7:P7)=0,"",IFERROR(I7/G7,0)) | AA7: =IF(COUNT(C7:P7)=0,"",IFERROR(C7/I7,0)) | AB7: =IF(COUNT(C7:P7)=0,"",IFERROR(J7/I7,0)) | AC7: =IF(COUNT(C7:P7)=0,"",IFERROR(K7/I7,0)) | AD7: =IF(COUNT(C7:P7)=0,"",IFERROR(L7/I7,0)) | AE7: =IF(COUNT(C7:P7)=0,"",IFERROR(P7/I7,0)) | AF7: =IF(COUNT(C7:P7)=0,"",IFERROR(I7*Config!$C$7+J7*Config!$C$8+K7*Config!$C$9+L7*Config!$C$10+M7*Config!$C$11+N7*Config!$C$12+O7*Config!$C$13+P7*Config!$C$14,0)) | AG7: =IF(COUNT(C7:P7)=0,"",IFERROR(AF7/I7,0)) | AH7: =IF(COUNT(C7:P7)=0,"",IFERROR(AF7*(1-Config!$C$15-Config!$C$16-Config!$C$17),0)) | AI7: =IF(COUNT(C7:P7)=0,"",IFERROR(AH7-C7-Config!$C$18,0)) | AJ7: =IF(COUNT(C7:P7)=0,"",IFERROR(AH7/C7,0)) | AK7: =IF(COUNT(C7:P7)=0,"",IFERROR(AI7/G7,0)) | AL7: =IF(COUNT(C7:P7)=0,"",IFERROR(AK7/V7,0)) | AM7: =IF(COUNT(C7:P7)=0,"",IFERROR(AI7/I7,0)) | AN7: =IF(COUNT(C7:P7)=0,"",IFERROR(AH7/I7-AA7,0))
A8: =Config!$C$6+2 | B8: =INT((A8-Config!$C$6)/7)+1 | C8: 314 | D8: 83978 | E8: 47042 | F8: 1447 | G8: 1350 | H8: 49 | I8: 12 | J8: 3 | K8: 2 | L8: 1 | M8: 1 | N8: 0 | O8: 0 | P8: 0 | Q8: =IF(COUNT(C8:P8)=0,"",IFERROR(C8/D8*1000,0)) | R8: =IF(COUNT(C8:P8)=0,"",IFERROR(D8/E8,0)) | S8: =IF(COUNT(C8:P8)=0,"",IFERROR(F8/D8,0)) | T8: =IF(COUNT(C8:P8)=0,"",IFERROR(C8/F8,0)) | U8: =IF(COUNT(C8:P8)=0,"",IFERROR(G8/F8,0)) | V8: =IF(COUNT(C8:P8)=0,"",IFERROR(C8/G8,0)) | W8: =IF(COUNT(C8:P8)=0,"",IFERROR(G8/D8*1000,0)) | X8: =IF(COUNT(C8:P8)=0,"",IFERROR(H8/G8,0)) | Y8: =IF(COUNT(C8:P8)=0,"",IFERROR(I8/H8,0)) | Z8: =IF(COUNT(C8:P8)=0,"",IFERROR(I8/G8,0)) | AA8: =IF(COUNT(C8:P8)=0,"",IFERROR(C8/I8,0)) | AB8: =IF(COUNT(C8:P8)=0,"",IFERROR(J8/I8,0)) | AC8: =IF(COUNT(C8:P8)=0,"",IFERROR(K8/I8,0)) | AD8: =IF(COUNT(C8:P8)=0,"",IFERROR(L8/I8,0)) | AE8: =IF(COUNT(C8:P8)=0,"",IFERROR(P8/I8,0)) | AF8: =IF(COUNT(C8:P8)=0,"",IFERROR(I8*Config!$C$7+J8*Config!$C$8+K8*Config!$C$9+L8*Config!$C$10+M8*Config!$C$11+N8*Config!$C$12+O8*Config!$C$13+P8*Config!$C$14,0)) | AG8: =IF(COUNT(C8:P8)=0,"",IFERROR(AF8/I8,0)) | AH8: =IF(COUNT(C8:P8)=0,"",IFERROR(AF8*(1-Config!$C$15-Config!$C$16-Config!$C$17),0)) | AI8: =IF(COUNT(C8:P8)=0,"",IFERROR(AH8-C8-Config!$C$18,0)) | AJ8: =IF(COUNT(C8:P8)=0,"",IFERROR(AH8/C8,0)) | AK8: =IF(COUNT(C8:P8)=0,"",IFERROR(AI8/G8,0)) | AL8: =IF(COUNT(C8:P8)=0,"",IFERROR(AK8/V8,0)) | AM8: =IF(COUNT(C8:P8)=0,"",IFERROR(AI8/I8,0)) | AN8: =IF(COUNT(C8:P8)=0,"",IFERROR(AH8/I8-AA8,0))
A9: =Config!$C$6+3 | B9: =INT((A9-Config!$C$6)/7)+1 | C9: 265 | D9: 62687 | E9: 43811 | F9: 899 | G9: 759 | H9: 24 | I9: 6 | J9: 2 | K9: 1 | L9: 1 | M9: 0 | N9: 0 | O9: 0 | P9: 0 | Q9: =IF(COUNT(C9:P9)=0,"",IFERROR(C9/D9*1000,0)) | R9: =IF(COUNT(C9:P9)=0,"",IFERROR(D9/E9,0)) | S9: =IF(COUNT(C9:P9)=0,"",IFERROR(F9/D9,0)) | T9: =IF(COUNT(C9:P9)=0,"",IFERROR(C9/F9,0)) | U9: =IF(COUNT(C9:P9)=0,"",IFERROR(G9/F9,0)) | V9: =IF(COUNT(C9:P9)=0,"",IFERROR(C9/G9,0)) | W9: =IF(COUNT(C9:P9)=0,"",IFERROR(G9/D9*1000,0)) | X9: =IF(COUNT(C9:P9)=0,"",IFERROR(H9/G9,0)) | Y9: =IF(COUNT(C9:P9)=0,"",IFERROR(I9/H9,0)) | Z9: =IF(COUNT(C9:P9)=0,"",IFERROR(I9/G9,0)) | AA9: =IF(COUNT(C9:P9)=0,"",IFERROR(C9/I9,0)) | AB9: =IF(COUNT(C9:P9)=0,"",IFERROR(J9/I9,0)) | AC9: =IF(COUNT(C9:P9)=0,"",IFERROR(K9/I9,0)) | AD9: =IF(COUNT(C9:P9)=0,"",IFERROR(L9/I9,0)) | AE9: =IF(COUNT(C9:P9)=0,"",IFERROR(P9/I9,0)) | AF9: =IF(COUNT(C9:P9)=0,"",IFERROR(I9*Config!$C$7+J9*Config!$C$8+K9*Config!$C$9+L9*Config!$C$10+M9*Config!$C$11+N9*Config!$C$12+O9*Config!$C$13+P9*Config!$C$14,0)) | AG9: =IF(COUNT(C9:P9)=0,"",IFERROR(AF9/I9,0)) | AH9: =IF(COUNT(C9:P9)=0,"",IFERROR(AF9*(1-Config!$C$15-Config!$C$16-Config!$C$17),0)) | AI9: =IF(COUNT(C9:P9)=0,"",IFERROR(AH9-C9-Config!$C$18,0)) | AJ9: =IF(COUNT(C9:P9)=0,"",IFERROR(AH9/C9,0)) | AK9: =IF(COUNT(C9:P9)=0,"",IFERROR(AI9/G9,0)) | AL9: =IF(COUNT(C9:P9)=0,"",IFERROR(AK9/V9,0)) | AM9: =IF(COUNT(C9:P9)=0,"",IFERROR(AI9/I9,0)) | AN9: =IF(COUNT(C9:P9)=0,"",IFERROR(AH9/I9-AA9,0))
A10: =Config!$C$6+4 | B10: =INT((A10-Config!$C$6)/7)+1 | C10: 296 | D10: 65062 | E10: 40478 | F10: 1042 | G10: 938 | H10: 34 | I10: 9 | J10: 2 | K10: 2 | L10: 1 | M10: 1 | N10: 0 | O10: 0 | P10: 0 | Q10: =IF(COUNT(C10:P10)=0,"",IFERROR(C10/D10*1000,0)) | R10: =IF(COUNT(C10:P10)=0,"",IFERROR(D10/E10,0)) | S10: =IF(COUNT(C10:P10)=0,"",IFERROR(F10/D10,0)) | T10: =IF(COUNT(C10:P10)=0,"",IFERROR(C10/F10,0)) | U10: =IF(COUNT(C10:P10)=0,"",IFERROR(G10/F10,0)) | V10: =IF(COUNT(C10:P10)=0,"",IFERROR(C10/G10,0)) | W10: =IF(COUNT(C10:P10)=0,"",IFERROR(G10/D10*1000,0)) | X10: =IF(COUNT(C10:P10)=0,"",IFERROR(H10/G10,0)) | Y10: =IF(COUNT(C10:P10)=0,"",IFERROR(I10/H10,0)) | Z10: =IF(COUNT(C10:P10)=0,"",IFERROR(I10/G10,0)) | AA10: =IF(COUNT(C10:P10)=0,"",IFERROR(C10/I10,0)) | AB10: =IF(COUNT(C10:P10)=0,"",IFERROR(J10/I10,0)) | AC10: =IF(COUNT(C10:P10)=0,"",IFERROR(K10/I10,0)) | AD10: =IF(COUNT(C10:P10)=0,"",IFERROR(L10/I10,0)) | AE10: =IF(COUNT(C10:P10)=0,"",IFERROR(P10/I10,0)) | AF10: =IF(COUNT(C10:P10)=0,"",IFERROR(I10*Config!$C$7+J10*Config!$C$8+K10*Config!$C$9+L10*Config!$C$10+M10*Config!$C$11+N10*Config!$C$12+O10*Config!$C$13+P10*Config!$C$14,0)) | AG10: =IF(COUNT(C10:P10)=0,"",IFERROR(AF10/I10,0)) | AH10: =IF(COUNT(C10:P10)=0,"",IFERROR(AF10*(1-Config!$C$15-Config!$C$16-Config!$C$17),0)) | AI10: =IF(COUNT(C10:P10)=0,"",IFERROR(AH10-C10-Config!$C$18,0)) | AJ10: =IF(COUNT(C10:P10)=0,"",IFERROR(AH10/C10,0)) | AK10: =IF(COUNT(C10:P10)=0,"",IFERROR(AI10/G10,0)) | AL10: =IF(COUNT(C10:P10)=0,"",IFERROR(AK10/V10,0)) | AM10: =IF(COUNT(C10:P10)=0,"",IFERROR(AI10/I10,0)) | AN10: =IF(COUNT(C10:P10)=0,"",IFERROR(AH10/I10-AA10,0))
A11: =Config!$C$6+5 | B11: =INT((A11-Config!$C$6)/7)+1 | C11: 284 | D11: 60410 | E11: 33742 | F11: 1013 | G11: 957 | H11: 32 | I11: 8 | J11: 2 | K11: 1 | L11: 1 | M11: 0 | N11: 0 | O11: 0 | P11: 0 | Q11: =IF(COUNT(C11:P11)=0,"",IFERROR(C11/D11*1000,0)) | R11: =IF(COUNT(C11:P11)=0,"",IFERROR(D11/E11,0)) | S11: =IF(COUNT(C11:P11)=0,"",IFERROR(F11/D11,0)) | T11: =IF(COUNT(C11:P11)=0,"",IFERROR(C11/F11,0)) | U11: =IF(COUNT(C11:P11)=0,"",IFERROR(G11/F11,0)) | V11: =IF(COUNT(C11:P11)=0,"",IFERROR(C11/G11,0)) | W11: =IF(COUNT(C11:P11)=0,"",IFERROR(G11/D11*1000,0)) | X11: =IF(COUNT(C11:P11)=0,"",IFERROR(H11/G11,0)) | Y11: =IF(COUNT(C11:P11)=0,"",IFERROR(I11/H11,0)) | Z11: =IF(COUNT(C11:P11)=0,"",IFERROR(I11/G11,0)) | AA11: =IF(COUNT(C11:P11)=0,"",IFERROR(C11/I11,0)) | AB11: =IF(COUNT(C11:P11)=0,"",IFERROR(J11/I11,0)) | AC11: =IF(COUNT(C11:P11)=0,"",IFERROR(K11/I11,0)) | AD11: =IF(COUNT(C11:P11)=0,"",IFERROR(L11/I11,0)) | AE11: =IF(COUNT(C11:P11)=0,"",IFERROR(P11/I11,0)) | AF11: =IF(COUNT(C11:P11)=0,"",IFERROR(I11*Config!$C$7+J11*Config!$C$8+K11*Config!$C$9+L11*Config!$C$10+M11*Config!$C$11+N11*Config!$C$12+O11*Config!$C$13+P11*Config!$C$14,0)) | AG11: =IF(COUNT(C11:P11)=0,"",IFERROR(AF11/I11,0)) | AH11: =IF(COUNT(C11:P11)=0,"",IFERROR(AF11*(1-Config!$C$15-Config!$C$16-Config!$C$17),0)) | AI11: =IF(COUNT(C11:P11)=0,"",IFERROR(AH11-C11-Config!$C$18,0)) | AJ11: =IF(COUNT(C11:P11)=0,"",IFERROR(AH11/C11,0)) | AK11: =IF(COUNT(C11:P11)=0,"",IFERROR(AI11/G11,0)) | AL11: =IF(COUNT(C11:P11)=0,"",IFERROR(AK11/V11,0)) | AM11: =IF(COUNT(C11:P11)=0,"",IFERROR(AI11/I11,0)) | AN11: =IF(COUNT(C11:P11)=0,"",IFERROR(AH11/I11-AA11,0))
A12: =Config!$C$6+6 | B12: =INT((A12-Config!$C$6)/7)+1 | C12: 285 | D12: 75611 | E12: 44418 | F12: 1144 | G12: 1115 | H12: 38 | I12: 11 | J12: 3 | K12: 2 | L12: 1 | M12: 1 | N12: 0 | O12: 0 | P12: 0 | Q12: =IF(COUNT(C12:P12)=0,"",IFERROR(C12/D12*1000,0)) | R12: =IF(COUNT(C12:P12)=0,"",IFERROR(D12/E12,0)) | S12: =IF(COUNT(C12:P12)=0,"",IFERROR(F12/D12,0)) | T12: =IF(COUNT(C12:P12)=0,"",IFERROR(C12/F12,0)) | U12: =IF(COUNT(C12:P12)=0,"",IFERROR(G12/F12,0)) | V12: =IF(COUNT(C12:P12)=0,"",IFERROR(C12/G12,0)) | W12: =IF(COUNT(C12:P12)=0,"",IFERROR(G12/D12*1000,0)) | X12: =IF(COUNT(C12:P12)=0,"",IFERROR(H12/G12,0)) | Y12: =IF(COUNT(C12:P12)=0,"",IFERROR(I12/H12,0)) | Z12: =IF(COUNT(C12:P12)=0,"",IFERROR(I12/G12,0)) | AA12: =IF(COUNT(C12:P12)=0,"",IFERROR(C12/I12,0)) | AB12: =IF(COUNT(C12:P12)=0,"",IFERROR(J12/I12,0)) | AC12: =IF(COUNT(C12:P12)=0,"",IFERROR(K12/I12,0)) | AD12: =IF(COUNT(C12:P12)=0,"",IFERROR(L12/I12,0)) | AE12: =IF(COUNT(C12:P12)=0,"",IFERROR(P12/I12,0)) | AF12: =IF(COUNT(C12:P12)=0,"",IFERROR(I12*Config!$C$7+J12*Config!$C$8+K12*Config!$C$9+L12*Config!$C$10+M12*Config!$C$11+N12*Config!$C$12+O12*Config!$C$13+P12*Config!$C$14,0)) | AG12: =IF(COUNT(C12:P12)=0,"",IFERROR(AF12/I12,0)) | AH12: =IF(COUNT(C12:P12)=0,"",IFERROR(AF12*(1-Config!$C$15-Config!$C$16-Config!$C$17),0)) | AI12: =IF(COUNT(C12:P12)=0,"",IFERROR(AH12-C12-Config!$C$18,0)) | AJ12: =IF(COUNT(C12:P12)=0,"",IFERROR(AH12/C12,0)) | AK12: =IF(COUNT(C12:P12)=0,"",IFERROR(AI12/G12,0)) | AL12: =IF(COUNT(C12:P12)=0,"",IFERROR(AK12/V12,0)) | AM12: =IF(COUNT(C12:P12)=0,"",IFERROR(AI12/I12,0)) | AN12: =IF(COUNT(C12:P12)=0,"",IFERROR(AH12/I12-AA12,0))
A13: =Config!$C$6+7 | B13: =INT((A13-Config!$C$6)/7)+1 | C13: 325 | D13: 87922 | E13: 59066 | F13: 1497 | G13: 1338 | H13: 52 | I13: 13 | J13: 3 | K13: 2 | L13: 1 | M13: 1 | N13: 0 | O13: 1 | P13: 0 | Q13: =IF(COUNT(C13:P13)=0,"",IFERROR(C13/D13*1000,0)) | R13: =IF(COUNT(C13:P13)=0,"",IFERROR(D13/E13,0)) | S13: =IF(COUNT(C13:P13)=0,"",IFERROR(F13/D13,0)) | T13: =IF(COUNT(C13:P13)=0,"",IFERROR(C13/F13,0)) | U13: =IF(COUNT(C13:P13)=0,"",IFERROR(G13/F13,0)) | V13: =IF(COUNT(C13:P13)=0,"",IFERROR(C13/G13,0)) | W13: =IF(COUNT(C13:P13)=0,"",IFERROR(G13/D13*1000,0)) | X13: =IF(COUNT(C13:P13)=0,"",IFERROR(H13/G13,0)) | Y13: =IF(COUNT(C13:P13)=0,"",IFERROR(I13/H13,0)) | Z13: =IF(COUNT(C13:P13)=0,"",IFERROR(I13/G13,0)) | AA13: =IF(COUNT(C13:P13)=0,"",IFERROR(C13/I13,0)) | AB13: =IF(COUNT(C13:P13)=0,"",IFERROR(J13/I13,0)) | AC13: =IF(COUNT(C13:P13)=0,"",IFERROR(K13/I13,0)) | AD13: =IF(COUNT(C13:P13)=0,"",IFERROR(L13/I13,0)) | AE13: =IF(COUNT(C13:P13)=0,"",IFERROR(P13/I13,0)) | AF13: =IF(COUNT(C13:P13)=0,"",IFERROR(I13*Config!$C$7+J13*Config!$C$8+K13*Config!$C$9+L13*Config!$C$10+M13*Config!$C$11+N13*Config!$C$12+O13*Config!$C$13+P13*Config!$C$14,0)) | AG13: =IF(COUNT(C13:P13)=0,"",IFERROR(AF13/I13,0)) | AH13: =IF(COUNT(C13:P13)=0,"",IFERROR(AF13*(1-Config!$C$15-Config!$C$16-Config!$C$17),0)) | AI13: =IF(COUNT(C13:P13)=0,"",IFERROR(AH13-C13-Config!$C$18,0)) | AJ13: =IF(COUNT(C13:P13)=0,"",IFERROR(AH13/C13,0)) | AK13: =IF(COUNT(C13:P13)=0,"",IFERROR(AI13/G13,0)) | AL13: =IF(COUNT(C13:P13)=0,"",IFERROR(AK13/V13,0)) | AM13: =IF(COUNT(C13:P13)=0,"",IFERROR(AI13/I13,0)) | AN13: =IF(COUNT(C13:P13)=0,"",IFERROR(AH13/I13-AA13,0))
A14: =Config!$C$6+8 | B14: =INT((A14-Config!$C$6)/7)+1 | C14: 269 | D14: 62177 | E14: 36426 | F14: 910 | G14: 738 | H14: 25 | I14: 7 | J14: 2 | K14: 1 | L14: 1 | M14: 0 | N14: 0 | O14: 0 | P14: 0 | Q14: =IF(COUNT(C14:P14)=0,"",IFERROR(C14/D14*1000,0)) | R14: =IF(COUNT(C14:P14)=0,"",IFERROR(D14/E14,0)) | S14: =IF(COUNT(C14:P14)=0,"",IFERROR(F14/D14,0)) | T14: =IF(COUNT(C14:P14)=0,"",IFERROR(C14/F14,0)) | U14: =IF(COUNT(C14:P14)=0,"",IFERROR(G14/F14,0)) | V14: =IF(COUNT(C14:P14)=0,"",IFERROR(C14/G14,0)) | W14: =IF(COUNT(C14:P14)=0,"",IFERROR(G14/D14*1000,0)) | X14: =IF(COUNT(C14:P14)=0,"",IFERROR(H14/G14,0)) | Y14: =IF(COUNT(C14:P14)=0,"",IFERROR(I14/H14,0)) | Z14: =IF(COUNT(C14:P14)=0,"",IFERROR(I14/G14,0)) | AA14: =IF(COUNT(C14:P14)=0,"",IFERROR(C14/I14,0)) | AB14: =IF(COUNT(C14:P14)=0,"",IFERROR(J14/I14,0)) | AC14: =IF(COUNT(C14:P14)=0,"",IFERROR(K14/I14,0)) | AD14: =IF(COUNT(C14:P14)=0,"",IFERROR(L14/I14,0)) | AE14: =IF(COUNT(C14:P14)=0,"",IFERROR(P14/I14,0)) | AF14: =IF(COUNT(C14:P14)=0,"",IFERROR(I14*Config!$C$7+J14*Config!$C$8+K14*Config!$C$9+L14*Config!$C$10+M14*Config!$C$11+N14*Config!$C$12+O14*Config!$C$13+P14*Config!$C$14,0)) | AG14: =IF(COUNT(C14:P14)=0,"",IFERROR(AF14/I14,0)) | AH14: =IF(COUNT(C14:P14)=0,"",IFERROR(AF14*(1-Config!$C$15-Config!$C$16-Config!$C$17),0)) | AI14: =IF(COUNT(C14:P14)=0,"",IFERROR(AH14-C14-Config!$C$18,0)) | AJ14: =IF(COUNT(C14:P14)=0,"",IFERROR(AH14/C14,0)) | AK14: =IF(COUNT(C14:P14)=0,"",IFERROR(AI14/G14,0)) | AL14: =IF(COUNT(C14:P14)=0,"",IFERROR(AK14/V14,0)) | AM14: =IF(COUNT(C14:P14)=0,"",IFERROR(AI14/I14,0)) | AN14: =IF(COUNT(C14:P14)=0,"",IFERROR(AH14/I14-AA14,0))
A15: =Config!$C$6+9 | B15: =INT((A15-Config!$C$6)/7)+1 | C15: 319 | D15: 83508 | E15: 55575 | F15: 1170 | G15: 942 | H15: 35 | I15: 8 | J15: 2 | K15: 2 | L15: 1 | M15: 1 | N15: 0 | O15: 0 | P15: 0 | Q15: =IF(COUNT(C15:P15)=0,"",IFERROR(C15/D15*1000,0)) | R15: =IF(COUNT(C15:P15)=0,"",IFERROR(D15/E15,0)) | S15: =IF(COUNT(C15:P15)=0,"",IFERROR(F15/D15,0)) | T15: =IF(COUNT(C15:P15)=0,"",IFERROR(C15/F15,0)) | U15: =IF(COUNT(C15:P15)=0,"",IFERROR(G15/F15,0)) | V15: =IF(COUNT(C15:P15)=0,"",IFERROR(C15/G15,0)) | W15: =IF(COUNT(C15:P15)=0,"",IFERROR(G15/D15*1000,0)) | X15: =IF(COUNT(C15:P15)=0,"",IFERROR(H15/G15,0)) | Y15: =IF(COUNT(C15:P15)=0,"",IFERROR(I15/H15,0)) | Z15: =IF(COUNT(C15:P15)=0,"",IFERROR(I15/G15,0)) | AA15: =IF(COUNT(C15:P15)=0,"",IFERROR(C15/I15,0)) | AB15: =IF(COUNT(C15:P15)=0,"",IFERROR(J15/I15,0)) | AC15: =IF(COUNT(C15:P15)=0,"",IFERROR(K15/I15,0)) | AD15: =IF(COUNT(C15:P15)=0,"",IFERROR(L15/I15,0)) | AE15: =IF(COUNT(C15:P15)=0,"",IFERROR(P15/I15,0)) | AF15: =IF(COUNT(C15:P15)=0,"",IFERROR(I15*Config!$C$7+J15*Config!$C$8+K15*Config!$C$9+L15*Config!$C$10+M15*Config!$C$11+N15*Config!$C$12+O15*Config!$C$13+P15*Config!$C$14,0)) | AG15: =IF(COUNT(C15:P15)=0,"",IFERROR(AF15/I15,0)) | AH15: =IF(COUNT(C15:P15)=0,"",IFERROR(AF15*(1-Config!$C$15-Config!$C$16-Config!$C$17),0)) | AI15: =IF(COUNT(C15:P15)=0,"",IFERROR(AH15-C15-Config!$C$18,0)) | AJ15: =IF(COUNT(C15:P15)=0,"",IFERROR(AH15/C15,0)) | AK15: =IF(COUNT(C15:P15)=0,"",IFERROR(AI15/G15,0)) | AL15: =IF(COUNT(C15:P15)=0,"",IFERROR(AK15/V15,0)) | AM15: =IF(COUNT(C15:P15)=0,"",IFERROR(AI15/I15,0)) | AN15: =IF(COUNT(C15:P15)=0,"",IFERROR(AH15/I15-AA15,0))
A16: =Config!$C$6+10 | B16: =INT((A16-Config!$C$6)/7)+1 | C16: 304 | D16: 73371 | E16: 49534 | F16: 1201 | G16: 985 | H16: 36 | I16: 8 | J16: 2 | K16: 2 | L16: 1 | M16: 1 | N16: 0 | O16: 0 | P16: 0 | Q16: =IF(COUNT(C16:P16)=0,"",IFERROR(C16/D16*1000,0)) | R16: =IF(COUNT(C16:P16)=0,"",IFERROR(D16/E16,0)) | S16: =IF(COUNT(C16:P16)=0,"",IFERROR(F16/D16,0)) | T16: =IF(COUNT(C16:P16)=0,"",IFERROR(C16/F16,0)) | U16: =IF(COUNT(C16:P16)=0,"",IFERROR(G16/F16,0)) | V16: =IF(COUNT(C16:P16)=0,"",IFERROR(C16/G16,0)) | W16: =IF(COUNT(C16:P16)=0,"",IFERROR(G16/D16*1000,0)) | X16: =IF(COUNT(C16:P16)=0,"",IFERROR(H16/G16,0)) | Y16: =IF(COUNT(C16:P16)=0,"",IFERROR(I16/H16,0)) | Z16: =IF(COUNT(C16:P16)=0,"",IFERROR(I16/G16,0)) | AA16: =IF(COUNT(C16:P16)=0,"",IFERROR(C16/I16,0)) | AB16: =IF(COUNT(C16:P16)=0,"",IFERROR(J16/I16,0)) | AC16: =IF(COUNT(C16:P16)=0,"",IFERROR(K16/I16,0)) | AD16: =IF(COUNT(C16:P16)=0,"",IFERROR(L16/I16,0)) | AE16: =IF(COUNT(C16:P16)=0,"",IFERROR(P16/I16,0)) | AF16: =IF(COUNT(C16:P16)=0,"",IFERROR(I16*Config!$C$7+J16*Config!$C$8+K16*Config!$C$9+L16*Config!$C$10+M16*Config!$C$11+N16*Config!$C$12+O16*Config!$C$13+P16*Config!$C$14,0)) | AG16: =IF(COUNT(C16:P16)=0,"",IFERROR(AF16/I16,0)) | AH16: =IF(COUNT(C16:P16)=0,"",IFERROR(AF16*(1-Config!$C$15-Config!$C$16-Config!$C$17),0)) | AI16: =IF(COUNT(C16:P16)=0,"",IFERROR(AH16-C16-Config!$C$18,0)) | AJ16: =IF(COUNT(C16:P16)=0,"",IFERROR(AH16/C16,0)) | AK16: =IF(COUNT(C16:P16)=0,"",IFERROR(AI16/G16,0)) | AL16: =IF(COUNT(C16:P16)=0,"",IFERROR(AK16/V16,0)) | AM16: =IF(COUNT(C16:P16)=0,"",IFERROR(AI16/I16,0)) | AN16: =IF(COUNT(C16:P16)=0,"",IFERROR(AH16/I16-AA16,0))
A17: =Config!$C$6+11 | B17: =INT((A17-Config!$C$6)/7)+1 | C17: 294 | D17: 75256 | E17: 49786 | F17: 1298 | G17: 1254 | H17: 42 | I17: 12 | J17: 3 | K17: 2 | L17: 1 | M17: 1 | N17: 0 | O17: 0 | P17: 0 | Q17: =IF(COUNT(C17:P17)=0,"",IFERROR(C17/D17*1000,0)) | R17: =IF(COUNT(C17:P17)=0,"",IFERROR(D17/E17,0)) | S17: =IF(COUNT(C17:P17)=0,"",IFERROR(F17/D17,0)) | T17: =IF(COUNT(C17:P17)=0,"",IFERROR(C17/F17,0)) | U17: =IF(COUNT(C17:P17)=0,"",IFERROR(G17/F17,0)) | V17: =IF(COUNT(C17:P17)=0,"",IFERROR(C17/G17,0)) | W17: =IF(COUNT(C17:P17)=0,"",IFERROR(G17/D17*1000,0)) | X17: =IF(COUNT(C17:P17)=0,"",IFERROR(H17/G17,0)) | Y17: =IF(COUNT(C17:P17)=0,"",IFERROR(I17/H17,0)) | Z17: =IF(COUNT(C17:P17)=0,"",IFERROR(I17/G17,0)) | AA17: =IF(COUNT(C17:P17)=0,"",IFERROR(C17/I17,0)) | AB17: =IF(COUNT(C17:P17)=0,"",IFERROR(J17/I17,0)) | AC17: =IF(COUNT(C17:P17)=0,"",IFERROR(K17/I17,0)) | AD17: =IF(COUNT(C17:P17)=0,"",IFERROR(L17/I17,0)) | AE17: =IF(COUNT(C17:P17)=0,"",IFERROR(P17/I17,0)) | AF17: =IF(COUNT(C17:P17)=0,"",IFERROR(I17*Config!$C$7+J17*Config!$C$8+K17*Config!$C$9+L17*Config!$C$10+M17*Config!$C$11+N17*Config!$C$12+O17*Config!$C$13+P17*Config!$C$14,0)) | AG17: =IF(COUNT(C17:P17)=0,"",IFERROR(AF17/I17,0)) | AH17: =IF(COUNT(C17:P17)=0,"",IFERROR(AF17*(1-Config!$C$15-Config!$C$16-Config!$C$17),0)) | AI17: =IF(COUNT(C17:P17)=0,"",IFERROR(AH17-C17-Config!$C$18,0)) | AJ17: =IF(COUNT(C17:P17)=0,"",IFERROR(AH17/C17,0)) | AK17: =IF(COUNT(C17:P17)=0,"",IFERROR(AI17/G17,0)) | AL17: =IF(COUNT(C17:P17)=0,"",IFERROR(AK17/V17,0)) | AM17: =IF(COUNT(C17:P17)=0,"",IFERROR(AI17/I17,0)) | AN17: =IF(COUNT(C17:P17)=0,"",IFERROR(AH17/I17-AA17,0))
A18: =Config!$C$6+12 | B18: =INT((A18-Config!$C$6)/7)+1 | C18: 279 | D18: 68200 | E18: 39284 | F18: 1093 | G18: 889 | H18: 35 | I18: 8 | J18: 2 | K18: 2 | L18: 1 | M18: 1 | N18: 0 | O18: 0 | P18: 0 | Q18: =IF(COUNT(C18:P18)=0,"",IFERROR(C18/D18*1000,0)) | R18: =IF(COUNT(C18:P18)=0,"",IFERROR(D18/E18,0)) | S18: =IF(COUNT(C18:P18)=0,"",IFERROR(F18/D18,0)) | T18: =IF(COUNT(C18:P18)=0,"",IFERROR(C18/F18,0)) | U18: =IF(COUNT(C18:P18)=0,"",IFERROR(G18/F18,0)) | V18: =IF(COUNT(C18:P18)=0,"",IFERROR(C18/G18,0)) | W18: =IF(COUNT(C18:P18)=0,"",IFERROR(G18/D18*1000,0)) | X18: =IF(COUNT(C18:P18)=0,"",IFERROR(H18/G18,0)) | Y18: =IF(COUNT(C18:P18)=0,"",IFERROR(I18/H18,0)) | Z18: =IF(COUNT(C18:P18)=0,"",IFERROR(I18/G18,0)) | AA18: =IF(COUNT(C18:P18)=0,"",IFERROR(C18/I18,0)) | AB18: =IF(COUNT(C18:P18)=0,"",IFERROR(J18/I18,0)) | AC18: =IF(COUNT(C18:P18)=0,"",IFERROR(K18/I18,0)) | AD18: =IF(COUNT(C18:P18)=0,"",IFERROR(L18/I18,0)) | AE18: =IF(COUNT(C18:P18)=0,"",IFERROR(P18/I18,0)) | AF18: =IF(COUNT(C18:P18)=0,"",IFERROR(I18*Config!$C$7+J18*Config!$C$8+K18*Config!$C$9+L18*Config!$C$10+M18*Config!$C$11+N18*Config!$C$12+O18*Config!$C$13+P18*Config!$C$14,0)) | AG18: =IF(COUNT(C18:P18)=0,"",IFERROR(AF18/I18,0)) | AH18: =IF(COUNT(C18:P18)=0,"",IFERROR(AF18*(1-Config!$C$15-Config!$C$16-Config!$C$17),0)) | AI18: =IF(COUNT(C18:P18)=0,"",IFERROR(AH18-C18-Config!$C$18,0)) | AJ18: =IF(COUNT(C18:P18)=0,"",IFERROR(AH18/C18,0)) | AK18: =IF(COUNT(C18:P18)=0,"",IFERROR(AI18/G18,0)) | AL18: =IF(COUNT(C18:P18)=0,"",IFERROR(AK18/V18,0)) | AM18: =IF(COUNT(C18:P18)=0,"",IFERROR(AI18/I18,0)) | AN18: =IF(COUNT(C18:P18)=0,"",IFERROR(AH18/I18-AA18,0))
A19: =Config!$C$6+13 | B19: =INT((A19-Config!$C$6)/7)+1 | C19: 283 | D19: 63152 | E19: 41159 | F19: 931 | G19: 752 | H19: 24 | I19: 6 | J19: 2 | K19: 1 | L19: 1 | M19: 0 | N19: 0 | O19: 0 | P19: 0 | Q19: =IF(COUNT(C19:P19)=0,"",IFERROR(C19/D19*1000,0)) | R19: =IF(COUNT(C19:P19)=0,"",IFERROR(D19/E19,0)) | S19: =IF(COUNT(C19:P19)=0,"",IFERROR(F19/D19,0)) | T19: =IF(COUNT(C19:P19)=0,"",IFERROR(C19/F19,0)) | U19: =IF(COUNT(C19:P19)=0,"",IFERROR(G19/F19,0)) | V19: =IF(COUNT(C19:P19)=0,"",IFERROR(C19/G19,0)) | W19: =IF(COUNT(C19:P19)=0,"",IFERROR(G19/D19*1000,0)) | X19: =IF(COUNT(C19:P19)=0,"",IFERROR(H19/G19,0)) | Y19: =IF(COUNT(C19:P19)=0,"",IFERROR(I19/H19,0)) | Z19: =IF(COUNT(C19:P19)=0,"",IFERROR(I19/G19,0)) | AA19: =IF(COUNT(C19:P19)=0,"",IFERROR(C19/I19,0)) | AB19: =IF(COUNT(C19:P19)=0,"",IFERROR(J19/I19,0)) | AC19: =IF(COUNT(C19:P19)=0,"",IFERROR(K19/I19,0)) | AD19: =IF(COUNT(C19:P19)=0,"",IFERROR(L19/I19,0)) | AE19: =IF(COUNT(C19:P19)=0,"",IFERROR(P19/I19,0)) | AF19: =IF(COUNT(C19:P19)=0,"",IFERROR(I19*Config!$C$7+J19*Config!$C$8+K19*Config!$C$9+L19*Config!$C$10+M19*Config!$C$11+N19*Config!$C$12+O19*Config!$C$13+P19*Config!$C$14,0)) | AG19: =IF(COUNT(C19:P19)=0,"",IFERROR(AF19/I19,0)) | AH19: =IF(COUNT(C19:P19)=0,"",IFERROR(AF19*(1-Config!$C$15-Config!$C$16-Config!$C$17),0)) | AI19: =IF(COUNT(C19:P19)=0,"",IFERROR(AH19-C19-Config!$C$18,0)) | AJ19: =IF(COUNT(C19:P19)=0,"",IFERROR(AH19/C19,0)) | AK19: =IF(COUNT(C19:P19)=0,"",IFERROR(AI19/G19,0)) | AL19: =IF(COUNT(C19:P19)=0,"",IFERROR(AK19/V19,0)) | AM19: =IF(COUNT(C19:P19)=0,"",IFERROR(AI19/I19,0)) | AN19: =IF(COUNT(C19:P19)=0,"",IFERROR(AH19/I19-AA19,0))
A20: =Config!$C$6+14 | B20: =INT((A20-Config!$C$6)/7)+1 | C20: 281 | D20: 65433 | E20: 42195 | F20: 1003 | G20: 1002 | H20: 35 | I20: 9 | J20: 2 | K20: 2 | L20: 1 | M20: 1 | N20: 0 | O20: 0 | P20: 0 | Q20: =IF(COUNT(C20:P20)=0,"",IFERROR(C20/D20*1000,0)) | R20: =IF(COUNT(C20:P20)=0,"",IFERROR(D20/E20,0)) | S20: =IF(COUNT(C20:P20)=0,"",IFERROR(F20/D20,0)) | T20: =IF(COUNT(C20:P20)=0,"",IFERROR(C20/F20,0)) | U20: =IF(COUNT(C20:P20)=0,"",IFERROR(G20/F20,0)) | V20: =IF(COUNT(C20:P20)=0,"",IFERROR(C20/G20,0)) | W20: =IF(COUNT(C20:P20)=0,"",IFERROR(G20/D20*1000,0)) | X20: =IF(COUNT(C20:P20)=0,"",IFERROR(H20/G20,0)) | Y20: =IF(COUNT(C20:P20)=0,"",IFERROR(I20/H20,0)) | Z20: =IF(COUNT(C20:P20)=0,"",IFERROR(I20/G20,0)) | AA20: =IF(COUNT(C20:P20)=0,"",IFERROR(C20/I20,0)) | AB20: =IF(COUNT(C20:P20)=0,"",IFERROR(J20/I20,0)) | AC20: =IF(COUNT(C20:P20)=0,"",IFERROR(K20/I20,0)) | AD20: =IF(COUNT(C20:P20)=0,"",IFERROR(L20/I20,0)) | AE20: =IF(COUNT(C20:P20)=0,"",IFERROR(P20/I20,0)) | AF20: =IF(COUNT(C20:P20)=0,"",IFERROR(I20*Config!$C$7+J20*Config!$C$8+K20*Config!$C$9+L20*Config!$C$10+M20*Config!$C$11+N20*Config!$C$12+O20*Config!$C$13+P20*Config!$C$14,0)) | AG20: =IF(COUNT(C20:P20)=0,"",IFERROR(AF20/I20,0)) | AH20: =IF(COUNT(C20:P20)=0,"",IFERROR(AF20*(1-Config!$C$15-Config!$C$16-Config!$C$17),0)) | AI20: =IF(COUNT(C20:P20)=0,"",IFERROR(AH20-C20-Config!$C$18,0)) | AJ20: =IF(COUNT(C20:P20)=0,"",IFERROR(AH20/C20,0)) | AK20: =IF(COUNT(C20:P20)=0,"",IFERROR(AI20/G20,0)) | AL20: =IF(COUNT(C20:P20)=0,"",IFERROR(AK20/V20,0)) | AM20: =IF(COUNT(C20:P20)=0,"",IFERROR(AI20/I20,0)) | AN20: =IF(COUNT(C20:P20)=0,"",IFERROR(AH20/I20-AA20,0))
A21: =Config!$C$6+15 | B21: =INT((A21-Config!$C$6)/7)+1 | C21: 326 | D21: 84115 | E21: 57331 | F21: 1432 | G21: 1387 | H21: 46 | I21: 11 | J21: 3 | K21: 2 | L21: 1 | M21: 1 | N21: 0 | O21: 0 | P21: 0 | Q21: =IF(COUNT(C21:P21)=0,"",IFERROR(C21/D21*1000,0)) | R21: =IF(COUNT(C21:P21)=0,"",IFERROR(D21/E21,0)) | S21: =IF(COUNT(C21:P21)=0,"",IFERROR(F21/D21,0)) | T21: =IF(COUNT(C21:P21)=0,"",IFERROR(C21/F21,0)) | U21: =IF(COUNT(C21:P21)=0,"",IFERROR(G21/F21,0)) | V21: =IF(COUNT(C21:P21)=0,"",IFERROR(C21/G21,0)) | W21: =IF(COUNT(C21:P21)=0,"",IFERROR(G21/D21*1000,0)) | X21: =IF(COUNT(C21:P21)=0,"",IFERROR(H21/G21,0)) | Y21: =IF(COUNT(C21:P21)=0,"",IFERROR(I21/H21,0)) | Z21: =IF(COUNT(C21:P21)=0,"",IFERROR(I21/G21,0)) | AA21: =IF(COUNT(C21:P21)=0,"",IFERROR(C21/I21,0)) | AB21: =IF(COUNT(C21:P21)=0,"",IFERROR(J21/I21,0)) | AC21: =IF(COUNT(C21:P21)=0,"",IFERROR(K21/I21,0)) | AD21: =IF(COUNT(C21:P21)=0,"",IFERROR(L21/I21,0)) | AE21: =IF(COUNT(C21:P21)=0,"",IFERROR(P21/I21,0)) | AF21: =IF(COUNT(C21:P21)=0,"",IFERROR(I21*Config!$C$7+J21*Config!$C$8+K21*Config!$C$9+L21*Config!$C$10+M21*Config!$C$11+N21*Config!$C$12+O21*Config!$C$13+P21*Config!$C$14,0)) | AG21: =IF(COUNT(C21:P21)=0,"",IFERROR(AF21/I21,0)) | AH21: =IF(COUNT(C21:P21)=0,"",IFERROR(AF21*(1-Config!$C$15-Config!$C$16-Config!$C$17),0)) | AI21: =IF(COUNT(C21:P21)=0,"",IFERROR(AH21-C21-Config!$C$18,0)) | AJ21: =IF(COUNT(C21:P21)=0,"",IFERROR(AH21/C21,0)) | AK21: =IF(COUNT(C21:P21)=0,"",IFERROR(AI21/G21,0)) | AL21: =IF(COUNT(C21:P21)=0,"",IFERROR(AK21/V21,0)) | AM21: =IF(COUNT(C21:P21)=0,"",IFERROR(AI21/I21,0)) | AN21: =IF(COUNT(C21:P21)=0,"",IFERROR(AH21/I21-AA21,0))
A22: =Config!$C$6+16 | B22: =INT((A22-Config!$C$6)/7)+1 | C22: 317 | D22: 68313 | E22: 46049 | F22: 1173 | G22: 1153 | H22: 41 | I22: 11 | J22: 3 | K22: 2 | L22: 1 | M22: 1 | N22: 0 | O22: 0 | P22: 0 | Q22: =IF(COUNT(C22:P22)=0,"",IFERROR(C22/D22*1000,0)) | R22: =IF(COUNT(C22:P22)=0,"",IFERROR(D22/E22,0)) | S22: =IF(COUNT(C22:P22)=0,"",IFERROR(F22/D22,0)) | T22: =IF(COUNT(C22:P22)=0,"",IFERROR(C22/F22,0)) | U22: =IF(COUNT(C22:P22)=0,"",IFERROR(G22/F22,0)) | V22: =IF(COUNT(C22:P22)=0,"",IFERROR(C22/G22,0)) | W22: =IF(COUNT(C22:P22)=0,"",IFERROR(G22/D22*1000,0)) | X22: =IF(COUNT(C22:P22)=0,"",IFERROR(H22/G22,0)) | Y22: =IF(COUNT(C22:P22)=0,"",IFERROR(I22/H22,0)) | Z22: =IF(COUNT(C22:P22)=0,"",IFERROR(I22/G22,0)) | AA22: =IF(COUNT(C22:P22)=0,"",IFERROR(C22/I22,0)) | AB22: =IF(COUNT(C22:P22)=0,"",IFERROR(J22/I22,0)) | AC22: =IF(COUNT(C22:P22)=0,"",IFERROR(K22/I22,0)) | AD22: =IF(COUNT(C22:P22)=0,"",IFERROR(L22/I22,0)) | AE22: =IF(COUNT(C22:P22)=0,"",IFERROR(P22/I22,0)) | AF22: =IF(COUNT(C22:P22)=0,"",IFERROR(I22*Config!$C$7+J22*Config!$C$8+K22*Config!$C$9+L22*Config!$C$10+M22*Config!$C$11+N22*Config!$C$12+O22*Config!$C$13+P22*Config!$C$14,0)) | AG22: =IF(COUNT(C22:P22)=0,"",IFERROR(AF22/I22,0)) | AH22: =IF(COUNT(C22:P22)=0,"",IFERROR(AF22*(1-Config!$C$15-Config!$C$16-Config!$C$17),0)) | AI22: =IF(COUNT(C22:P22)=0,"",IFERROR(AH22-C22-Config!$C$18,0)) | AJ22: =IF(COUNT(C22:P22)=0,"",IFERROR(AH22/C22,0)) | AK22: =IF(COUNT(C22:P22)=0,"",IFERROR(AI22/G22,0)) | AL22: =IF(COUNT(C22:P22)=0,"",IFERROR(AK22/V22,0)) | AM22: =IF(COUNT(C22:P22)=0,"",IFERROR(AI22/I22,0)) | AN22: =IF(COUNT(C22:P22)=0,"",IFERROR(AH22/I22-AA22,0))
A23: =Config!$C$6+17 | B23: =INT((A23-Config!$C$6)/7)+1 | C23: 271 | D23: 72684 | E23: 40887 | F23: 1056 | G23: 997 | H23: 33 | I23: 9 | J23: 2 | K23: 2 | L23: 1 | M23: 1 | N23: 0 | O23: 0 | P23: 0 | Q23: =IF(COUNT(C23:P23)=0,"",IFERROR(C23/D23*1000,0)) | R23: =IF(COUNT(C23:P23)=0,"",IFERROR(D23/E23,0)) | S23: =IF(COUNT(C23:P23)=0,"",IFERROR(F23/D23,0)) | T23: =IF(COUNT(C23:P23)=0,"",IFERROR(C23/F23,0)) | U23: =IF(COUNT(C23:P23)=0,"",IFERROR(G23/F23,0)) | V23: =IF(COUNT(C23:P23)=0,"",IFERROR(C23/G23,0)) | W23: =IF(COUNT(C23:P23)=0,"",IFERROR(G23/D23*1000,0)) | X23: =IF(COUNT(C23:P23)=0,"",IFERROR(H23/G23,0)) | Y23: =IF(COUNT(C23:P23)=0,"",IFERROR(I23/H23,0)) | Z23: =IF(COUNT(C23:P23)=0,"",IFERROR(I23/G23,0)) | AA23: =IF(COUNT(C23:P23)=0,"",IFERROR(C23/I23,0)) | AB23: =IF(COUNT(C23:P23)=0,"",IFERROR(J23/I23,0)) | AC23: =IF(COUNT(C23:P23)=0,"",IFERROR(K23/I23,0)) | AD23: =IF(COUNT(C23:P23)=0,"",IFERROR(L23/I23,0)) | AE23: =IF(COUNT(C23:P23)=0,"",IFERROR(P23/I23,0)) | AF23: =IF(COUNT(C23:P23)=0,"",IFERROR(I23*Config!$C$7+J23*Config!$C$8+K23*Config!$C$9+L23*Config!$C$10+M23*Config!$C$11+N23*Config!$C$12+O23*Config!$C$13+P23*Config!$C$14,0)) | AG23: =IF(COUNT(C23:P23)=0,"",IFERROR(AF23/I23,0)) | AH23: =IF(COUNT(C23:P23)=0,"",IFERROR(AF23*(1-Config!$C$15-Config!$C$16-Config!$C$17),0)) | AI23: =IF(COUNT(C23:P23)=0,"",IFERROR(AH23-C23-Config!$C$18,0)) | AJ23: =IF(COUNT(C23:P23)=0,"",IFERROR(AH23/C23,0)) | AK23: =IF(COUNT(C23:P23)=0,"",IFERROR(AI23/G23,0)) | AL23: =IF(COUNT(C23:P23)=0,"",IFERROR(AK23/V23,0)) | AM23: =IF(COUNT(C23:P23)=0,"",IFERROR(AI23/I23,0)) | AN23: =IF(COUNT(C23:P23)=0,"",IFERROR(AH23/I23-AA23,0))
A24: =Config!$C$6+18 | B24: =INT((A24-Config!$C$6)/7)+1 | C24: 307 | D24: 76894 | E24: 52119 | F24: 1255 | G24: 1013 | H24: 33 | I24: 9 | J24: 2 | K24: 2 | L24: 1 | M24: 1 | N24: 0 | O24: 0 | P24: 0 | Q24: =IF(COUNT(C24:P24)=0,"",IFERROR(C24/D24*1000,0)) | R24: =IF(COUNT(C24:P24)=0,"",IFERROR(D24/E24,0)) | S24: =IF(COUNT(C24:P24)=0,"",IFERROR(F24/D24,0)) | T24: =IF(COUNT(C24:P24)=0,"",IFERROR(C24/F24,0)) | U24: =IF(COUNT(C24:P24)=0,"",IFERROR(G24/F24,0)) | V24: =IF(COUNT(C24:P24)=0,"",IFERROR(C24/G24,0)) | W24: =IF(COUNT(C24:P24)=0,"",IFERROR(G24/D24*1000,0)) | X24: =IF(COUNT(C24:P24)=0,"",IFERROR(H24/G24,0)) | Y24: =IF(COUNT(C24:P24)=0,"",IFERROR(I24/H24,0)) | Z24: =IF(COUNT(C24:P24)=0,"",IFERROR(I24/G24,0)) | AA24: =IF(COUNT(C24:P24)=0,"",IFERROR(C24/I24,0)) | AB24: =IF(COUNT(C24:P24)=0,"",IFERROR(J24/I24,0)) | AC24: =IF(COUNT(C24:P24)=0,"",IFERROR(K24/I24,0)) | AD24: =IF(COUNT(C24:P24)=0,"",IFERROR(L24/I24,0)) | AE24: =IF(COUNT(C24:P24)=0,"",IFERROR(P24/I24,0)) | AF24: =IF(COUNT(C24:P24)=0,"",IFERROR(I24*Config!$C$7+J24*Config!$C$8+K24*Config!$C$9+L24*Config!$C$10+M24*Config!$C$11+N24*Config!$C$12+O24*Config!$C$13+P24*Config!$C$14,0)) | AG24: =IF(COUNT(C24:P24)=0,"",IFERROR(AF24/I24,0)) | AH24: =IF(COUNT(C24:P24)=0,"",IFERROR(AF24*(1-Config!$C$15-Config!$C$16-Config!$C$17),0)) | AI24: =IF(COUNT(C24:P24)=0,"",IFERROR(AH24-C24-Config!$C$18,0)) | AJ24: =IF(COUNT(C24:P24)=0,"",IFERROR(AH24/C24,0)) | AK24: =IF(COUNT(C24:P24)=0,"",IFERROR(AI24/G24,0)) | AL24: =IF(COUNT(C24:P24)=0,"",IFERROR(AK24/V24,0)) | AM24: =IF(COUNT(C24:P24)=0,"",IFERROR(AI24/I24,0)) | AN24: =IF(COUNT(C24:P24)=0,"",IFERROR(AH24/I24-AA24,0))
A25: =Config!$C$6+19 | B25: =INT((A25-Config!$C$6)/7)+1 | C25: 325 | D25: 75401 | E25: 49750 | F25: 1286 | G25: 1075 | H25: 33 | I25: 8 | J25: 2 | K25: 1 | L25: 1 | M25: 0 | N25: 0 | O25: 0 | P25: 0 | Q25: =IF(COUNT(C25:P25)=0,"",IFERROR(C25/D25*1000,0)) | R25: =IF(COUNT(C25:P25)=0,"",IFERROR(D25/E25,0)) | S25: =IF(COUNT(C25:P25)=0,"",IFERROR(F25/D25,0)) | T25: =IF(COUNT(C25:P25)=0,"",IFERROR(C25/F25,0)) | U25: =IF(COUNT(C25:P25)=0,"",IFERROR(G25/F25,0)) | V25: =IF(COUNT(C25:P25)=0,"",IFERROR(C25/G25,0)) | W25: =IF(COUNT(C25:P25)=0,"",IFERROR(G25/D25*1000,0)) | X25: =IF(COUNT(C25:P25)=0,"",IFERROR(H25/G25,0)) | Y25: =IF(COUNT(C25:P25)=0,"",IFERROR(I25/H25,0)) | Z25: =IF(COUNT(C25:P25)=0,"",IFERROR(I25/G25,0)) | AA25: =IF(COUNT(C25:P25)=0,"",IFERROR(C25/I25,0)) | AB25: =IF(COUNT(C25:P25)=0,"",IFERROR(J25/I25,0)) | AC25: =IF(COUNT(C25:P25)=0,"",IFERROR(K25/I25,0)) | AD25: =IF(COUNT(C25:P25)=0,"",IFERROR(L25/I25,0)) | AE25: =IF(COUNT(C25:P25)=0,"",IFERROR(P25/I25,0)) | AF25: =IF(COUNT(C25:P25)=0,"",IFERROR(I25*Config!$C$7+J25*Config!$C$8+K25*Config!$C$9+L25*Config!$C$10+M25*Config!$C$11+N25*Config!$C$12+O25*Config!$C$13+P25*Config!$C$14,0)) | AG25: =IF(COUNT(C25:P25)=0,"",IFERROR(AF25/I25,0)) | AH25: =IF(COUNT(C25:P25)=0,"",IFERROR(AF25*(1-Config!$C$15-Config!$C$16-Config!$C$17),0)) | AI25: =IF(COUNT(C25:P25)=0,"",IFERROR(AH25-C25-Config!$C$18,0)) | AJ25: =IF(COUNT(C25:P25)=0,"",IFERROR(AH25/C25,0)) | AK25: =IF(COUNT(C25:P25)=0,"",IFERROR(AI25/G25,0)) | AL25: =IF(COUNT(C25:P25)=0,"",IFERROR(AK25/V25,0)) | AM25: =IF(COUNT(C25:P25)=0,"",IFERROR(AI25/I25,0)) | AN25: =IF(COUNT(C25:P25)=0,"",IFERROR(AH25/I25-AA25,0))
A26: =Config!$C$6+20 | B26: =INT((A26-Config!$C$6)/7)+1 | C26: 296 | D26: 78812 | E26: 53407 | F26: 1183 | G26: 1083 | H26: 35 | I26: 9 | J26: 2 | K26: 2 | L26: 1 | M26: 1 | N26: 0 | O26: 0 | P26: 0 | Q26: =IF(COUNT(C26:P26)=0,"",IFERROR(C26/D26*1000,0)) | R26: =IF(COUNT(C26:P26)=0,"",IFERROR(D26/E26,0)) | S26: =IF(COUNT(C26:P26)=0,"",IFERROR(F26/D26,0)) | T26: =IF(COUNT(C26:P26)=0,"",IFERROR(C26/F26,0)) | U26: =IF(COUNT(C26:P26)=0,"",IFERROR(G26/F26,0)) | V26: =IF(COUNT(C26:P26)=0,"",IFERROR(C26/G26,0)) | W26: =IF(COUNT(C26:P26)=0,"",IFERROR(G26/D26*1000,0)) | X26: =IF(COUNT(C26:P26)=0,"",IFERROR(H26/G26,0)) | Y26: =IF(COUNT(C26:P26)=0,"",IFERROR(I26/H26,0)) | Z26: =IF(COUNT(C26:P26)=0,"",IFERROR(I26/G26,0)) | AA26: =IF(COUNT(C26:P26)=0,"",IFERROR(C26/I26,0)) | AB26: =IF(COUNT(C26:P26)=0,"",IFERROR(J26/I26,0)) | AC26: =IF(COUNT(C26:P26)=0,"",IFERROR(K26/I26,0)) | AD26: =IF(COUNT(C26:P26)=0,"",IFERROR(L26/I26,0)) | AE26: =IF(COUNT(C26:P26)=0,"",IFERROR(P26/I26,0)) | AF26: =IF(COUNT(C26:P26)=0,"",IFERROR(I26*Config!$C$7+J26*Config!$C$8+K26*Config!$C$9+L26*Config!$C$10+M26*Config!$C$11+N26*Config!$C$12+O26*Config!$C$13+P26*Config!$C$14,0)) | AG26: =IF(COUNT(C26:P26)=0,"",IFERROR(AF26/I26,0)) | AH26: =IF(COUNT(C26:P26)=0,"",IFERROR(AF26*(1-Config!$C$15-Config!$C$16-Config!$C$17),0)) | AI26: =IF(COUNT(C26:P26)=0,"",IFERROR(AH26-C26-Config!$C$18,0)) | AJ26: =IF(COUNT(C26:P26)=0,"",IFERROR(AH26/C26,0)) | AK26: =IF(COUNT(C26:P26)=0,"",IFERROR(AI26/G26,0)) | AL26: =IF(COUNT(C26:P26)=0,"",IFERROR(AK26/V26,0)) | AM26: =IF(COUNT(C26:P26)=0,"",IFERROR(AI26/I26,0)) | AN26: =IF(COUNT(C26:P26)=0,"",IFERROR(AH26/I26-AA26,0))
A27: =Config!$C$6+21 | B27: =INT((A27-Config!$C$6)/7)+1 | C27: 328 | D27: 70052 | E27: 42193 | F27: 1136 | G27: 1043 | H27: 33 | I27: 8 | J27: 2 | K27: 1 | L27: 1 | M27: 0 | N27: 0 | O27: 0 | P27: 0 | Q27: =IF(COUNT(C27:P27)=0,"",IFERROR(C27/D27*1000,0)) | R27: =IF(COUNT(C27:P27)=0,"",IFERROR(D27/E27,0)) | S27: =IF(COUNT(C27:P27)=0,"",IFERROR(F27/D27,0)) | T27: =IF(COUNT(C27:P27)=0,"",IFERROR(C27/F27,0)) | U27: =IF(COUNT(C27:P27)=0,"",IFERROR(G27/F27,0)) | V27: =IF(COUNT(C27:P27)=0,"",IFERROR(C27/G27,0)) | W27: =IF(COUNT(C27:P27)=0,"",IFERROR(G27/D27*1000,0)) | X27: =IF(COUNT(C27:P27)=0,"",IFERROR(H27/G27,0)) | Y27: =IF(COUNT(C27:P27)=0,"",IFERROR(I27/H27,0)) | Z27: =IF(COUNT(C27:P27)=0,"",IFERROR(I27/G27,0)) | AA27: =IF(COUNT(C27:P27)=0,"",IFERROR(C27/I27,0)) | AB27: =IF(COUNT(C27:P27)=0,"",IFERROR(J27/I27,0)) | AC27: =IF(COUNT(C27:P27)=0,"",IFERROR(K27/I27,0)) | AD27: =IF(COUNT(C27:P27)=0,"",IFERROR(L27/I27,0)) | AE27: =IF(COUNT(C27:P27)=0,"",IFERROR(P27/I27,0)) | AF27: =IF(COUNT(C27:P27)=0,"",IFERROR(I27*Config!$C$7+J27*Config!$C$8+K27*Config!$C$9+L27*Config!$C$10+M27*Config!$C$11+N27*Config!$C$12+O27*Config!$C$13+P27*Config!$C$14,0)) | AG27: =IF(COUNT(C27:P27)=0,"",IFERROR(AF27/I27,0)) | AH27: =IF(COUNT(C27:P27)=0,"",IFERROR(AF27*(1-Config!$C$15-Config!$C$16-Config!$C$17),0)) | AI27: =IF(COUNT(C27:P27)=0,"",IFERROR(AH27-C27-Config!$C$18,0)) | AJ27: =IF(COUNT(C27:P27)=0,"",IFERROR(AH27/C27,0)) | AK27: =IF(COUNT(C27:P27)=0,"",IFERROR(AI27/G27,0)) | AL27: =IF(COUNT(C27:P27)=0,"",IFERROR(AK27/V27,0)) | AM27: =IF(COUNT(C27:P27)=0,"",IFERROR(AI27/I27,0)) | AN27: =IF(COUNT(C27:P27)=0,"",IFERROR(AH27/I27-AA27,0))
A28: =Config!$C$6+22 | B28: =INT((A28-Config!$C$6)/7)+1 | C28: 265 | D28: 57503 | E28: 34286 | F28: 990 | G28: 789 | H28: 29 | I28: 7 | J28: 2 | K28: 1 | L28: 1 | M28: 0 | N28: 0 | O28: 0 | P28: 0 | Q28: =IF(COUNT(C28:P28)=0,"",IFERROR(C28/D28*1000,0)) | R28: =IF(COUNT(C28:P28)=0,"",IFERROR(D28/E28,0)) | S28: =IF(COUNT(C28:P28)=0,"",IFERROR(F28/D28,0)) | T28: =IF(COUNT(C28:P28)=0,"",IFERROR(C28/F28,0)) | U28: =IF(COUNT(C28:P28)=0,"",IFERROR(G28/F28,0)) | V28: =IF(COUNT(C28:P28)=0,"",IFERROR(C28/G28,0)) | W28: =IF(COUNT(C28:P28)=0,"",IFERROR(G28/D28*1000,0)) | X28: =IF(COUNT(C28:P28)=0,"",IFERROR(H28/G28,0)) | Y28: =IF(COUNT(C28:P28)=0,"",IFERROR(I28/H28,0)) | Z28: =IF(COUNT(C28:P28)=0,"",IFERROR(I28/G28,0)) | AA28: =IF(COUNT(C28:P28)=0,"",IFERROR(C28/I28,0)) | AB28: =IF(COUNT(C28:P28)=0,"",IFERROR(J28/I28,0)) | AC28: =IF(COUNT(C28:P28)=0,"",IFERROR(K28/I28,0)) | AD28: =IF(COUNT(C28:P28)=0,"",IFERROR(L28/I28,0)) | AE28: =IF(COUNT(C28:P28)=0,"",IFERROR(P28/I28,0)) | AF28: =IF(COUNT(C28:P28)=0,"",IFERROR(I28*Config!$C$7+J28*Config!$C$8+K28*Config!$C$9+L28*Config!$C$10+M28*Config!$C$11+N28*Config!$C$12+O28*Config!$C$13+P28*Config!$C$14,0)) | AG28: =IF(COUNT(C28:P28)=0,"",IFERROR(AF28/I28,0)) | AH28: =IF(COUNT(C28:P28)=0,"",IFERROR(AF28*(1-Config!$C$15-Config!$C$16-Config!$C$17),0)) | AI28: =IF(COUNT(C28:P28)=0,"",IFERROR(AH28-C28-Config!$C$18,0)) | AJ28: =IF(COUNT(C28:P28)=0,"",IFERROR(AH28/C28,0)) | AK28: =IF(COUNT(C28:P28)=0,"",IFERROR(AI28/G28,0)) | AL28: =IF(COUNT(C28:P28)=0,"",IFERROR(AK28/V28,0)) | AM28: =IF(COUNT(C28:P28)=0,"",IFERROR(AI28/I28,0)) | AN28: =IF(COUNT(C28:P28)=0,"",IFERROR(AH28/I28-AA28,0))
A29: =Config!$C$6+23 | B29: =INT((A29-Config!$C$6)/7)+1 | C29: 317 | D29: 78805 | E29: 43982 | F29: 1097 | G29: 998 | H29: 37 | I29: 11 | J29: 3 | K29: 2 | L29: 1 | M29: 1 | N29: 0 | O29: 0 | P29: 0 | Q29: =IF(COUNT(C29:P29)=0,"",IFERROR(C29/D29*1000,0)) | R29: =IF(COUNT(C29:P29)=0,"",IFERROR(D29/E29,0)) | S29: =IF(COUNT(C29:P29)=0,"",IFERROR(F29/D29,0)) | T29: =IF(COUNT(C29:P29)=0,"",IFERROR(C29/F29,0)) | U29: =IF(COUNT(C29:P29)=0,"",IFERROR(G29/F29,0)) | V29: =IF(COUNT(C29:P29)=0,"",IFERROR(C29/G29,0)) | W29: =IF(COUNT(C29:P29)=0,"",IFERROR(G29/D29*1000,0)) | X29: =IF(COUNT(C29:P29)=0,"",IFERROR(H29/G29,0)) | Y29: =IF(COUNT(C29:P29)=0,"",IFERROR(I29/H29,0)) | Z29: =IF(COUNT(C29:P29)=0,"",IFERROR(I29/G29,0)) | AA29: =IF(COUNT(C29:P29)=0,"",IFERROR(C29/I29,0)) | AB29: =IF(COUNT(C29:P29)=0,"",IFERROR(J29/I29,0)) | AC29: =IF(COUNT(C29:P29)=0,"",IFERROR(K29/I29,0)) | AD29: =IF(COUNT(C29:P29)=0,"",IFERROR(L29/I29,0)) | AE29: =IF(COUNT(C29:P29)=0,"",IFERROR(P29/I29,0)) | AF29: =IF(COUNT(C29:P29)=0,"",IFERROR(I29*Config!$C$7+J29*Config!$C$8+K29*Config!$C$9+L29*Config!$C$10+M29*Config!$C$11+N29*Config!$C$12+O29*Config!$C$13+P29*Config!$C$14,0)) | AG29: =IF(COUNT(C29:P29)=0,"",IFERROR(AF29/I29,0)) | AH29: =IF(COUNT(C29:P29)=0,"",IFERROR(AF29*(1-Config!$C$15-Config!$C$16-Config!$C$17),0)) | AI29: =IF(COUNT(C29:P29)=0,"",IFERROR(AH29-C29-Config!$C$18,0)) | AJ29: =IF(COUNT(C29:P29)=0,"",IFERROR(AH29/C29,0)) | AK29: =IF(COUNT(C29:P29)=0,"",IFERROR(AI29/G29,0)) | AL29: =IF(COUNT(C29:P29)=0,"",IFERROR(AK29/V29,0)) | AM29: =IF(COUNT(C29:P29)=0,"",IFERROR(AI29/I29,0)) | AN29: =IF(COUNT(C29:P29)=0,"",IFERROR(AH29/I29-AA29,0))
A30: =Config!$C$6+24 | B30: =INT((A30-Config!$C$6)/7)+1 | C30: 317 | D30: 71974 | E30: 42026 | F30: 1227 | G30: 1065 | H30: 39 | I30: 11 | J30: 3 | K30: 2 | L30: 1 | M30: 1 | N30: 0 | O30: 0 | P30: 0 | Q30: =IF(COUNT(C30:P30)=0,"",IFERROR(C30/D30*1000,0)) | R30: =IF(COUNT(C30:P30)=0,"",IFERROR(D30/E30,0)) | S30: =IF(COUNT(C30:P30)=0,"",IFERROR(F30/D30,0)) | T30: =IF(COUNT(C30:P30)=0,"",IFERROR(C30/F30,0)) | U30: =IF(COUNT(C30:P30)=0,"",IFERROR(G30/F30,0)) | V30: =IF(COUNT(C30:P30)=0,"",IFERROR(C30/G30,0)) | W30: =IF(COUNT(C30:P30)=0,"",IFERROR(G30/D30*1000,0)) | X30: =IF(COUNT(C30:P30)=0,"",IFERROR(H30/G30,0)) | Y30: =IF(COUNT(C30:P30)=0,"",IFERROR(I30/H30,0)) | Z30: =IF(COUNT(C30:P30)=0,"",IFERROR(I30/G30,0)) | AA30: =IF(COUNT(C30:P30)=0,"",IFERROR(C30/I30,0)) | AB30: =IF(COUNT(C30:P30)=0,"",IFERROR(J30/I30,0)) | AC30: =IF(COUNT(C30:P30)=0,"",IFERROR(K30/I30,0)) | AD30: =IF(COUNT(C30:P30)=0,"",IFERROR(L30/I30,0)) | AE30: =IF(COUNT(C30:P30)=0,"",IFERROR(P30/I30,0)) | AF30: =IF(COUNT(C30:P30)=0,"",IFERROR(I30*Config!$C$7+J30*Config!$C$8+K30*Config!$C$9+L30*Config!$C$10+M30*Config!$C$11+N30*Config!$C$12+O30*Config!$C$13+P30*Config!$C$14,0)) | AG30: =IF(COUNT(C30:P30)=0,"",IFERROR(AF30/I30,0)) | AH30: =IF(COUNT(C30:P30)=0,"",IFERROR(AF30*(1-Config!$C$15-Config!$C$16-Config!$C$17),0)) | AI30: =IF(COUNT(C30:P30)=0,"",IFERROR(AH30-C30-Config!$C$18,0)) | AJ30: =IF(COUNT(C30:P30)=0,"",IFERROR(AH30/C30,0)) | AK30: =IF(COUNT(C30:P30)=0,"",IFERROR(AI30/G30,0)) | AL30: =IF(COUNT(C30:P30)=0,"",IFERROR(AK30/V30,0)) | AM30: =IF(COUNT(C30:P30)=0,"",IFERROR(AI30/I30,0)) | AN30: =IF(COUNT(C30:P30)=0,"",IFERROR(AH30/I30-AA30,0))
A31: =Config!$C$6+25 | B31: =INT((A31-Config!$C$6)/7)+1 | C31: 327 | D31: 79368 | E31: 46372 | F31: 1338 | G31: 1225 | H31: 44 | I31: 11 | J31: 3 | K31: 2 | L31: 1 | M31: 1 | N31: 0 | O31: 0 | P31: 0 | Q31: =IF(COUNT(C31:P31)=0,"",IFERROR(C31/D31*1000,0)) | R31: =IF(COUNT(C31:P31)=0,"",IFERROR(D31/E31,0)) | S31: =IF(COUNT(C31:P31)=0,"",IFERROR(F31/D31,0)) | T31: =IF(COUNT(C31:P31)=0,"",IFERROR(C31/F31,0)) | U31: =IF(COUNT(C31:P31)=0,"",IFERROR(G31/F31,0)) | V31: =IF(COUNT(C31:P31)=0,"",IFERROR(C31/G31,0)) | W31: =IF(COUNT(C31:P31)=0,"",IFERROR(G31/D31*1000,0)) | X31: =IF(COUNT(C31:P31)=0,"",IFERROR(H31/G31,0)) | Y31: =IF(COUNT(C31:P31)=0,"",IFERROR(I31/H31,0)) | Z31: =IF(COUNT(C31:P31)=0,"",IFERROR(I31/G31,0)) | AA31: =IF(COUNT(C31:P31)=0,"",IFERROR(C31/I31,0)) | AB31: =IF(COUNT(C31:P31)=0,"",IFERROR(J31/I31,0)) | AC31: =IF(COUNT(C31:P31)=0,"",IFERROR(K31/I31,0)) | AD31: =IF(COUNT(C31:P31)=0,"",IFERROR(L31/I31,0)) | AE31: =IF(COUNT(C31:P31)=0,"",IFERROR(P31/I31,0)) | AF31: =IF(COUNT(C31:P31)=0,"",IFERROR(I31*Config!$C$7+J31*Config!$C$8+K31*Config!$C$9+L31*Config!$C$10+M31*Config!$C$11+N31*Config!$C$12+O31*Config!$C$13+P31*Config!$C$14,0)) | AG31: =IF(COUNT(C31:P31)=0,"",IFERROR(AF31/I31,0)) | AH31: =IF(COUNT(C31:P31)=0,"",IFERROR(AF31*(1-Config!$C$15-Config!$C$16-Config!$C$17),0)) | AI31: =IF(COUNT(C31:P31)=0,"",IFERROR(AH31-C31-Config!$C$18,0)) | AJ31: =IF(COUNT(C31:P31)=0,"",IFERROR(AH31/C31,0)) | AK31: =IF(COUNT(C31:P31)=0,"",IFERROR(AI31/G31,0)) | AL31: =IF(COUNT(C31:P31)=0,"",IFERROR(AK31/V31,0)) | AM31: =IF(COUNT(C31:P31)=0,"",IFERROR(AI31/I31,0)) | AN31: =IF(COUNT(C31:P31)=0,"",IFERROR(AH31/I31-AA31,0))
A32: =Config!$C$6+26 | B32: =INT((A32-Config!$C$6)/7)+1 | C32: 306 | D32: 70991 | E32: 49341 | F32: 1137 | G32: 1145 | H32: 44 | I32: 12 | J32: 3 | K32: 2 | L32: 1 | M32: 1 | N32: 0 | O32: 0 | P32: 0 | Q32: =IF(COUNT(C32:P32)=0,"",IFERROR(C32/D32*1000,0)) | R32: =IF(COUNT(C32:P32)=0,"",IFERROR(D32/E32,0)) | S32: =IF(COUNT(C32:P32)=0,"",IFERROR(F32/D32,0)) | T32: =IF(COUNT(C32:P32)=0,"",IFERROR(C32/F32,0)) | U32: =IF(COUNT(C32:P32)=0,"",IFERROR(G32/F32,0)) | V32: =IF(COUNT(C32:P32)=0,"",IFERROR(C32/G32,0)) | W32: =IF(COUNT(C32:P32)=0,"",IFERROR(G32/D32*1000,0)) | X32: =IF(COUNT(C32:P32)=0,"",IFERROR(H32/G32,0)) | Y32: =IF(COUNT(C32:P32)=0,"",IFERROR(I32/H32,0)) | Z32: =IF(COUNT(C32:P32)=0,"",IFERROR(I32/G32,0)) | AA32: =IF(COUNT(C32:P32)=0,"",IFERROR(C32/I32,0)) | AB32: =IF(COUNT(C32:P32)=0,"",IFERROR(J32/I32,0)) | AC32: =IF(COUNT(C32:P32)=0,"",IFERROR(K32/I32,0)) | AD32: =IF(COUNT(C32:P32)=0,"",IFERROR(L32/I32,0)) | AE32: =IF(COUNT(C32:P32)=0,"",IFERROR(P32/I32,0)) | AF32: =IF(COUNT(C32:P32)=0,"",IFERROR(I32*Config!$C$7+J32*Config!$C$8+K32*Config!$C$9+L32*Config!$C$10+M32*Config!$C$11+N32*Config!$C$12+O32*Config!$C$13+P32*Config!$C$14,0)) | AG32: =IF(COUNT(C32:P32)=0,"",IFERROR(AF32/I32,0)) | AH32: =IF(COUNT(C32:P32)=0,"",IFERROR(AF32*(1-Config!$C$15-Config!$C$16-Config!$C$17),0)) | AI32: =IF(COUNT(C32:P32)=0,"",IFERROR(AH32-C32-Config!$C$18,0)) | AJ32: =IF(COUNT(C32:P32)=0,"",IFERROR(AH32/C32,0)) | AK32: =IF(COUNT(C32:P32)=0,"",IFERROR(AI32/G32,0)) | AL32: =IF(COUNT(C32:P32)=0,"",IFERROR(AK32/V32,0)) | AM32: =IF(COUNT(C32:P32)=0,"",IFERROR(AI32/I32,0)) | AN32: =IF(COUNT(C32:P32)=0,"",IFERROR(AH32/I32-AA32,0))
A33: =Config!$C$6+27 | B33: =INT((A33-Config!$C$6)/7)+1 | C33: 292 | D33: 65804 | E33: 40344 | F33: 1005 | G33: 978 | H33: 31 | I33: 8 | J33: 2 | K33: 2 | L33: 1 | M33: 1 | N33: 0 | O33: 0 | P33: 0 | Q33: =IF(COUNT(C33:P33)=0,"",IFERROR(C33/D33*1000,0)) | R33: =IF(COUNT(C33:P33)=0,"",IFERROR(D33/E33,0)) | S33: =IF(COUNT(C33:P33)=0,"",IFERROR(F33/D33,0)) | T33: =IF(COUNT(C33:P33)=0,"",IFERROR(C33/F33,0)) | U33: =IF(COUNT(C33:P33)=0,"",IFERROR(G33/F33,0)) | V33: =IF(COUNT(C33:P33)=0,"",IFERROR(C33/G33,0)) | W33: =IF(COUNT(C33:P33)=0,"",IFERROR(G33/D33*1000,0)) | X33: =IF(COUNT(C33:P33)=0,"",IFERROR(H33/G33,0)) | Y33: =IF(COUNT(C33:P33)=0,"",IFERROR(I33/H33,0)) | Z33: =IF(COUNT(C33:P33)=0,"",IFERROR(I33/G33,0)) | AA33: =IF(COUNT(C33:P33)=0,"",IFERROR(C33/I33,0)) | AB33: =IF(COUNT(C33:P33)=0,"",IFERROR(J33/I33,0)) | AC33: =IF(COUNT(C33:P33)=0,"",IFERROR(K33/I33,0)) | AD33: =IF(COUNT(C33:P33)=0,"",IFERROR(L33/I33,0)) | AE33: =IF(COUNT(C33:P33)=0,"",IFERROR(P33/I33,0)) | AF33: =IF(COUNT(C33:P33)=0,"",IFERROR(I33*Config!$C$7+J33*Config!$C$8+K33*Config!$C$9+L33*Config!$C$10+M33*Config!$C$11+N33*Config!$C$12+O33*Config!$C$13+P33*Config!$C$14,0)) | AG33: =IF(COUNT(C33:P33)=0,"",IFERROR(AF33/I33,0)) | AH33: =IF(COUNT(C33:P33)=0,"",IFERROR(AF33*(1-Config!$C$15-Config!$C$16-Config!$C$17),0)) | AI33: =IF(COUNT(C33:P33)=0,"",IFERROR(AH33-C33-Config!$C$18,0)) | AJ33: =IF(COUNT(C33:P33)=0,"",IFERROR(AH33/C33,0)) | AK33: =IF(COUNT(C33:P33)=0,"",IFERROR(AI33/G33,0)) | AL33: =IF(COUNT(C33:P33)=0,"",IFERROR(AK33/V33,0)) | AM33: =IF(COUNT(C33:P33)=0,"",IFERROR(AI33/I33,0)) | AN33: =IF(COUNT(C33:P33)=0,"",IFERROR(AH33/I33-AA33,0))
A34: =Config!$C$6+28 | B34: =INT((A34-Config!$C$6)/7)+1 | Q34: =IF(COUNT(C34:P34)=0,"",IFERROR(C34/D34*1000,0)) | R34: =IF(COUNT(C34:P34)=0,"",IFERROR(D34/E34,0)) | S34: =IF(COUNT(C34:P34)=0,"",IFERROR(F34/D34,0)) | T34: =IF(COUNT(C34:P34)=0,"",IFERROR(C34/F34,0)) | U34: =IF(COUNT(C34:P34)=0,"",IFERROR(G34/F34,0)) | V34: =IF(COUNT(C34:P34)=0,"",IFERROR(C34/G34,0)) | W34: =IF(COUNT(C34:P34)=0,"",IFERROR(G34/D34*1000,0)) | X34: =IF(COUNT(C34:P34)=0,"",IFERROR(H34/G34,0)) | Y34: =IF(COUNT(C34:P34)=0,"",IFERROR(I34/H34,0)) | Z34: =IF(COUNT(C34:P34)=0,"",IFERROR(I34/G34,0)) | AA34: =IF(COUNT(C34:P34)=0,"",IFERROR(C34/I34,0)) | AB34: =IF(COUNT(C34:P34)=0,"",IFERROR(J34/I34,0)) | AC34: =IF(COUNT(C34:P34)=0,"",IFERROR(K34/I34,0)) | AD34: =IF(COUNT(C34:P34)=0,"",IFERROR(L34/I34,0)) | AE34: =IF(COUNT(C34:P34)=0,"",IFERROR(P34/I34,0)) | AF34: =IF(COUNT(C34:P34)=0,"",IFERROR(I34*Config!$C$7+J34*Config!$C$8+K34*Config!$C$9+L34*Config!$C$10+M34*Config!$C$11+N34*Config!$C$12+O34*Config!$C$13+P34*Config!$C$14,0)) | AG34: =IF(COUNT(C34:P34)=0,"",IFERROR(AF34/I34,0)) | AH34: =IF(COUNT(C34:P34)=0,"",IFERROR(AF34*(1-Config!$C$15-Config!$C$16-Config!$C$17),0)) | AI34: =IF(COUNT(C34:P34)=0,"",IFERROR(AH34-C34-Config!$C$18,0)) | AJ34: =IF(COUNT(C34:P34)=0,"",IFERROR(AH34/C34,0)) | AK34: =IF(COUNT(C34:P34)=0,"",IFERROR(AI34/G34,0)) | AL34: =IF(COUNT(C34:P34)=0,"",IFERROR(AK34/V34,0)) | AM34: =IF(COUNT(C34:P34)=0,"",IFERROR(AI34/I34,0)) | AN34: =IF(COUNT(C34:P34)=0,"",IFERROR(AH34/I34-AA34,0))
A35: =Config!$C$6+29 | B35: =INT((A35-Config!$C$6)/7)+1 | Q35: =IF(COUNT(C35:P35)=0,"",IFERROR(C35/D35*1000,0)) | R35: =IF(COUNT(C35:P35)=0,"",IFERROR(D35/E35,0)) | S35: =IF(COUNT(C35:P35)=0,"",IFERROR(F35/D35,0)) | T35: =IF(COUNT(C35:P35)=0,"",IFERROR(C35/F35,0)) | U35: =IF(COUNT(C35:P35)=0,"",IFERROR(G35/F35,0)) | V35: =IF(COUNT(C35:P35)=0,"",IFERROR(C35/G35,0)) | W35: =IF(COUNT(C35:P35)=0,"",IFERROR(G35/D35*1000,0)) | X35: =IF(COUNT(C35:P35)=0,"",IFERROR(H35/G35,0)) | Y35: =IF(COUNT(C35:P35)=0,"",IFERROR(I35/H35,0)) | Z35: =IF(COUNT(C35:P35)=0,"",IFERROR(I35/G35,0)) | AA35: =IF(COUNT(C35:P35)=0,"",IFERROR(C35/I35,0)) | AB35: =IF(COUNT(C35:P35)=0,"",IFERROR(J35/I35,0)) | AC35: =IF(COUNT(C35:P35)=0,"",IFERROR(K35/I35,0)) | AD35: =IF(COUNT(C35:P35)=0,"",IFERROR(L35/I35,0)) | AE35: =IF(COUNT(C35:P35)=0,"",IFERROR(P35/I35,0)) | AF35: =IF(COUNT(C35:P35)=0,"",IFERROR(I35*Config!$C$7+J35*Config!$C$8+K35*Config!$C$9+L35*Config!$C$10+M35*Config!$C$11+N35*Config!$C$12+O35*Config!$C$13+P35*Config!$C$14,0)) | AG35: =IF(COUNT(C35:P35)=0,"",IFERROR(AF35/I35,0)) | AH35: =IF(COUNT(C35:P35)=0,"",IFERROR(AF35*(1-Config!$C$15-Config!$C$16-Config!$C$17),0)) | AI35: =IF(COUNT(C35:P35)=0,"",IFERROR(AH35-C35-Config!$C$18,0)) | AJ35: =IF(COUNT(C35:P35)=0,"",IFERROR(AH35/C35,0)) | AK35: =IF(COUNT(C35:P35)=0,"",IFERROR(AI35/G35,0)) | AL35: =IF(COUNT(C35:P35)=0,"",IFERROR(AK35/V35,0)) | AM35: =IF(COUNT(C35:P35)=0,"",IFERROR(AI35/I35,0)) | AN35: =IF(COUNT(C35:P35)=0,"",IFERROR(AH35/I35-AA35,0))
A36: =Config!$C$6+30 | B36: =INT((A36-Config!$C$6)/7)+1 | Q36: =IF(COUNT(C36:P36)=0,"",IFERROR(C36/D36*1000,0)) | R36: =IF(COUNT(C36:P36)=0,"",IFERROR(D36/E36,0)) | S36: =IF(COUNT(C36:P36)=0,"",IFERROR(F36/D36,0)) | T36: =IF(COUNT(C36:P36)=0,"",IFERROR(C36/F36,0)) | U36: =IF(COUNT(C36:P36)=0,"",IFERROR(G36/F36,0)) | V36: =IF(COUNT(C36:P36)=0,"",IFERROR(C36/G36,0)) | W36: =IF(COUNT(C36:P36)=0,"",IFERROR(G36/D36*1000,0)) | X36: =IF(COUNT(C36:P36)=0,"",IFERROR(H36/G36,0)) | Y36: =IF(COUNT(C36:P36)=0,"",IFERROR(I36/H36,0)) | Z36: =IF(COUNT(C36:P36)=0,"",IFERROR(I36/G36,0)) | AA36: =IF(COUNT(C36:P36)=0,"",IFERROR(C36/I36,0)) | AB36: =IF(COUNT(C36:P36)=0,"",IFERROR(J36/I36,0)) | AC36: =IF(COUNT(C36:P36)=0,"",IFERROR(K36/I36,0)) | AD36: =IF(COUNT(C36:P36)=0,"",IFERROR(L36/I36,0)) | AE36: =IF(COUNT(C36:P36)=0,"",IFERROR(P36/I36,0)) | AF36: =IF(COUNT(C36:P36)=0,"",IFERROR(I36*Config!$C$7+J36*Config!$C$8+K36*Config!$C$9+L36*Config!$C$10+M36*Config!$C$11+N36*Config!$C$12+O36*Config!$C$13+P36*Config!$C$14,0)) | AG36: =IF(COUNT(C36:P36)=0,"",IFERROR(AF36/I36,0)) | AH36: =IF(COUNT(C36:P36)=0,"",IFERROR(AF36*(1-Config!$C$15-Config!$C$16-Config!$C$17),0)) | AI36: =IF(COUNT(C36:P36)=0,"",IFERROR(AH36-C36-Config!$C$18,0)) | AJ36: =IF(COUNT(C36:P36)=0,"",IFERROR(AH36/C36,0)) | AK36: =IF(COUNT(C36:P36)=0,"",IFERROR(AI36/G36,0)) | AL36: =IF(COUNT(C36:P36)=0,"",IFERROR(AK36/V36,0)) | AM36: =IF(COUNT(C36:P36)=0,"",IFERROR(AI36/I36,0)) | AN36: =IF(COUNT(C36:P36)=0,"",IFERROR(AH36/I36-AA36,0))
A37: =Config!$C$6+31 | B37: =INT((A37-Config!$C$6)/7)+1 | Q37: =IF(COUNT(C37:P37)=0,"",IFERROR(C37/D37*1000,0)) | R37: =IF(COUNT(C37:P37)=0,"",IFERROR(D37/E37,0)) | S37: =IF(COUNT(C37:P37)=0,"",IFERROR(F37/D37,0)) | T37: =IF(COUNT(C37:P37)=0,"",IFERROR(C37/F37,0)) | U37: =IF(COUNT(C37:P37)=0,"",IFERROR(G37/F37,0)) | V37: =IF(COUNT(C37:P37)=0,"",IFERROR(C37/G37,0)) | W37: =IF(COUNT(C37:P37)=0,"",IFERROR(G37/D37*1000,0)) | X37: =IF(COUNT(C37:P37)=0,"",IFERROR(H37/G37,0)) | Y37: =IF(COUNT(C37:P37)=0,"",IFERROR(I37/H37,0)) | Z37: =IF(COUNT(C37:P37)=0,"",IFERROR(I37/G37,0)) | AA37: =IF(COUNT(C37:P37)=0,"",IFERROR(C37/I37,0)) | AB37: =IF(COUNT(C37:P37)=0,"",IFERROR(J37/I37,0)) | AC37: =IF(COUNT(C37:P37)=0,"",IFERROR(K37/I37,0)) | AD37: =IF(COUNT(C37:P37)=0,"",IFERROR(L37/I37,0)) | AE37: =IF(COUNT(C37:P37)=0,"",IFERROR(P37/I37,0)) | AF37: =IF(COUNT(C37:P37)=0,"",IFERROR(I37*Config!$C$7+J37*Config!$C$8+K37*Config!$C$9+L37*Config!$C$10+M37*Config!$C$11+N37*Config!$C$12+O37*Config!$C$13+P37*Config!$C$14,0)) | AG37: =IF(COUNT(C37:P37)=0,"",IFERROR(AF37/I37,0)) | AH37: =IF(COUNT(C37:P37)=0,"",IFERROR(AF37*(1-Config!$C$15-Config!$C$16-Config!$C$17),0)) | AI37: =IF(COUNT(C37:P37)=0,"",IFERROR(AH37-C37-Config!$C$18,0)) | AJ37: =IF(COUNT(C37:P37)=0,"",IFERROR(AH37/C37,0)) | AK37: =IF(COUNT(C37:P37)=0,"",IFERROR(AI37/G37,0)) | AL37: =IF(COUNT(C37:P37)=0,"",IFERROR(AK37/V37,0)) | AM37: =IF(COUNT(C37:P37)=0,"",IFERROR(AI37/I37,0)) | AN37: =IF(COUNT(C37:P37)=0,"",IFERROR(AH37/I37-AA37,0))
A38: =Config!$C$6+32 | B38: =INT((A38-Config!$C$6)/7)+1 | Q38: =IF(COUNT(C38:P38)=0,"",IFERROR(C38/D38*1000,0)) | R38: =IF(COUNT(C38:P38)=0,"",IFERROR(D38/E38,0)) | S38: =IF(COUNT(C38:P38)=0,"",IFERROR(F38/D38,0)) | T38: =IF(COUNT(C38:P38)=0,"",IFERROR(C38/F38,0)) | U38: =IF(COUNT(C38:P38)=0,"",IFERROR(G38/F38,0)) | V38: =IF(COUNT(C38:P38)=0,"",IFERROR(C38/G38,0)) | W38: =IF(COUNT(C38:P38)=0,"",IFERROR(G38/D38*1000,0)) | X38: =IF(COUNT(C38:P38)=0,"",IFERROR(H38/G38,0)) | Y38: =IF(COUNT(C38:P38)=0,"",IFERROR(I38/H38,0)) | Z38: =IF(COUNT(C38:P38)=0,"",IFERROR(I38/G38,0)) | AA38: =IF(COUNT(C38:P38)=0,"",IFERROR(C38/I38,0)) | AB38: =IF(COUNT(C38:P38)=0,"",IFERROR(J38/I38,0)) | AC38: =IF(COUNT(C38:P38)=0,"",IFERROR(K38/I38,0)) | AD38: =IF(COUNT(C38:P38)=0,"",IFERROR(L38/I38,0)) | AE38: =IF(COUNT(C38:P38)=0,"",IFERROR(P38/I38,0)) | AF38: =IF(COUNT(C38:P38)=0,"",IFERROR(I38*Config!$C$7+J38*Config!$C$8+K38*Config!$C$9+L38*Config!$C$10+M38*Config!$C$11+N38*Config!$C$12+O38*Config!$C$13+P38*Config!$C$14,0)) | AG38: =IF(COUNT(C38:P38)=0,"",IFERROR(AF38/I38,0)) | AH38: =IF(COUNT(C38:P38)=0,"",IFERROR(AF38*(1-Config!$C$15-Config!$C$16-Config!$C$17),0)) | AI38: =IF(COUNT(C38:P38)=0,"",IFERROR(AH38-C38-Config!$C$18,0)) | AJ38: =IF(COUNT(C38:P38)=0,"",IFERROR(AH38/C38,0)) | AK38: =IF(COUNT(C38:P38)=0,"",IFERROR(AI38/G38,0)) | AL38: =IF(COUNT(C38:P38)=0,"",IFERROR(AK38/V38,0)) | AM38: =IF(COUNT(C38:P38)=0,"",IFERROR(AI38/I38,0)) | AN38: =IF(COUNT(C38:P38)=0,"",IFERROR(AH38/I38-AA38,0))
A39: =Config!$C$6+33 | B39: =INT((A39-Config!$C$6)/7)+1 | Q39: =IF(COUNT(C39:P39)=0,"",IFERROR(C39/D39*1000,0)) | R39: =IF(COUNT(C39:P39)=0,"",IFERROR(D39/E39,0)) | S39: =IF(COUNT(C39:P39)=0,"",IFERROR(F39/D39,0)) | T39: =IF(COUNT(C39:P39)=0,"",IFERROR(C39/F39,0)) | U39: =IF(COUNT(C39:P39)=0,"",IFERROR(G39/F39,0)) | V39: =IF(COUNT(C39:P39)=0,"",IFERROR(C39/G39,0)) | W39: =IF(COUNT(C39:P39)=0,"",IFERROR(G39/D39*1000,0)) | X39: =IF(COUNT(C39:P39)=0,"",IFERROR(H39/G39,0)) | Y39: =IF(COUNT(C39:P39)=0,"",IFERROR(I39/H39,0)) | Z39: =IF(COUNT(C39:P39)=0,"",IFERROR(I39/G39,0)) | AA39: =IF(COUNT(C39:P39)=0,"",IFERROR(C39/I39,0)) | AB39: =IF(COUNT(C39:P39)=0,"",IFERROR(J39/I39,0)) | AC39: =IF(COUNT(C39:P39)=0,"",IFERROR(K39/I39,0)) | AD39: =IF(COUNT(C39:P39)=0,"",IFERROR(L39/I39,0)) | AE39: =IF(COUNT(C39:P39)=0,"",IFERROR(P39/I39,0)) | AF39: =IF(COUNT(C39:P39)=0,"",IFERROR(I39*Config!$C$7+J39*Config!$C$8+K39*Config!$C$9+L39*Config!$C$10+M39*Config!$C$11+N39*Config!$C$12+O39*Config!$C$13+P39*Config!$C$14,0)) | AG39: =IF(COUNT(C39:P39)=0,"",IFERROR(AF39/I39,0)) | AH39: =IF(COUNT(C39:P39)=0,"",IFERROR(AF39*(1-Config!$C$15-Config!$C$16-Config!$C$17),0)) | AI39: =IF(COUNT(C39:P39)=0,"",IFERROR(AH39-C39-Config!$C$18,0)) | AJ39: =IF(COUNT(C39:P39)=0,"",IFERROR(AH39/C39,0)) | AK39: =IF(COUNT(C39:P39)=0,"",IFERROR(AI39/G39,0)) | AL39: =IF(COUNT(C39:P39)=0,"",IFERROR(AK39/V39,0)) | AM39: =IF(COUNT(C39:P39)=0,"",IFERROR(AI39/I39,0)) | AN39: =IF(COUNT(C39:P39)=0,"",IFERROR(AH39/I39-AA39,0))
