Workbook

Sheet Inicio
B2: Métricas diarias · Embudo de webinar gratuito
B3: Las métricas diarias de todo el embudo, para saber cómo estás con tus propios números. Acompaña al modelo financiero del mismo embudo.
B5: Qué es
B6: Un registro diario de cada paso del embudo (anuncios, página, unidades, etapas, ventas, cash) que se convierte solo en un comparativo semanal y en un resumen con semáforo. El semáforo no usa números de mercado: compara cada semana con la mediana de tus 4 semanas anteriores, con una tolerancia del 25 % (la cambiás en Config).
B8: 1. Config
B9: Poné tus precios, comisiones, reembolsos, costos fijos por día y la fecha de inicio (un lunes). Todo lo demás se calcula con eso.
B11: 2. Diario (todos los días, 3 minutos)
B12: Una fila por día. Cargá las celdas amarillas con lo que hubo: inversión, impresiones, alcance, clics en el enlace, visitas y cada paso del embudo. Si un día no hubo evento, dejá vacío. Las celdas azules se calculan solas (CPM, CTR, costo por visita, CPL, conversiones, facturado, cash neto, ganancia, ROAS y la ganancia por visita).
B14: 3. Semanal (los lunes, 10 minutos)
B15: No se carga nada: suma Diario por semana y calcula las conversiones y los costos de la semana, el promedio, la mediana, la mejor y la peor. Abajo, el bloque «contra tu promedio» marca en verde, amarillo o rojo cada métrica clave contra la mediana de tus 4 semanas anteriores.
B17: 4. Resumen
B18: La semana elegida (por defecto la última con datos) contra la anterior, contra tu mediana y contra la meta que vos escribas. Las filas van en el orden en que se mira un embudo: primero el tráfico y la ganancia por visita, después la página, después las etapas, después las ventas y la caja.
... B36: Modelo financiero de embudos · creado por Jesús Tassarolo · TooAudience · youtube.com/@JesusTassaroloSinFiltro · v1.2 · octubre 2026

Sheet Config
B2: Config: tus precios, comisiones y la fecha de inicio
B3: Amarillo = podés cambiarlo. Todo lo demás del libro se calcula con esto.
B5: Dato | C5: Valor | D5: Nota
B6: Fecha de inicio del registro (un lunes) | C6: 46272 | D6: Desde este día se numeran las semanas en Diario y Semanal. Elegí un lunes.
B7: Precio de la oferta del webinar | C7: 297
B8: Precio del bump | C8: 47
B9: Precio del programa superior | C9: 997
B10: Comisión de la pasarela de pago | C10: 0.1 | D10: Lo que se queda la plataforma de cobro.
B11: Comisión del equipo de ventas | C11: 0 | D11: Si vendés por llamada: lo que cobra el closer sobre lo cobrado.
B12: Reembolsos y contracargos | C12: 0.05 | D12: Promedio histórico. 5 % es normal en productos digitales.
B13: Costos fijos por día (USD) | C13: 170 | D13: Lo que pagás aunque no vendas, dividido por los días del período.
B14: ROAS objetivo sobre cash neto | C14: 2 | D14: El retorno mínimo que querés por cada dólar, ya neto.
B15: Tolerancia del semáforo contra tu promedio | C15: 0.25 | D15: Igual o mejor que tu mediana = verde; hasta esta distancia peor = amarillo; más = rojo. 20 a 30 %.
A18: Modelo financiero de embudos · creado por Jesús Tassarolo · TooAudience · youtube.com/@JesusTassaroloSinFiltro · v1.2 · octubre 2026

Sheet Diario
A2: Diario: una fila por día. Amarillo = lo que cargás; azul = lo que calcula el libro
A3: Cargá cada día lo que hubo (vacío si no hubo). Los porcentajes de un solo día pueden ser raros en embudos con evento semanal: la lectura buena está en Semanal.
A5: Fecha | B5: Semana | C5: Inversión en publicidad (USD) | D5: Impresiones | E5: Alcance (personas únicas) | F5: Clics en el enlace | G5: Visitas a la página | H5: Registros (leads) | I5: Registros calificados | J5: Entran al grupo de WhatsApp | K5: Asistentes en vivo | L5: Ven el replay | M5: Solicitudes (formulario de compra, aplicación o vendedor) | N5: Compran la oferta | O5: Toman el bump | P5: Pasan al programa superior | Q5: CPM | R5: Frecuencia | S5: CTR al enlace | T5: CPC (por clic en el enlace) | U5: % clic → visita | V5: Costo por visita | W5: Visitas por cada 1.000 impresiones | X5: % visita → registro (conversión de la landing) | Y5: CPL (costo por registro) | Z5: CPL calificado | AA5: CPL como % del CPM (el umbral depende del nicho) | AB5: Registros por cada 1.000 impresiones | AC5: % registro → grupo | AD5: Costo por persona en el grupo | AE5: % registro → en vivo | AF5: % registro → replay | AG5: Costo por asistente en vivo | AH5: % en vivo → solicitud | AI5: Costo por solicitud | AJ5: % solicitud → compra | AK5: % registro → compra | AL5: CPA (costo por comprador) | AM5: % toman el bump | AN5: % pasan al programa | AO5: Facturado (oferta + bump + programa) | AP5: Order value (facturado por comprador) | AQ5: Cash neto (después de comisiones y reembolsos) | AR5: Ganancia (cash neto − pauta − fijos) | AS5: ROAS sobre cash neto | AT5: Ganancia por visita (la métrica más valiosa) | AU5: Margen por visita (ganancia por visita ÷ costo por visita) | AV5: Ganancia por registro
A6: =Config!$C$6+0 | B6: =INT((A6-Config!$C$6)/7)+1 | C6: 847 | D6: 185605 | E6: 112303 | F6: 4050 | G6: 3652 | H6: 857 | I6: 514 | J6: 575 | Q6: =IF(COUNT(C6:P6)=0,"",IFERROR(C6/D6*1000,0)) | R6: =IF(COUNT(C6:P6)=0,"",IFERROR(D6/E6,0)) | S6: =IF(COUNT(C6:P6)=0,"",IFERROR(F6/D6,0)) | T6: =IF(COUNT(C6:P6)=0,"",IFERROR(C6/F6,0)) | U6: =IF(COUNT(C6:P6)=0,"",IFERROR(G6/F6,0)) | V6: =IF(COUNT(C6:P6)=0,"",IFERROR(C6/G6,0)) | W6: =IF(COUNT(C6:P6)=0,"",IFERROR(G6/D6*1000,0)) | X6: =IF(COUNT(C6:P6)=0,"",IFERROR(H6/G6,0)) | Y6: =IF(COUNT(C6:P6)=0,"",IFERROR(C6/H6,0)) | Z6: =IF(COUNT(C6:P6)=0,"",IFERROR(C6/I6,0)) | AA6: =IF(COUNT(C6:P6)=0,"",IFERROR(Y6/Q6,0)) | AB6: =IF(COUNT(C6:P6)=0,"",IFERROR(H6/D6*1000,0)) | AC6: =IF(COUNT(C6:P6)=0,"",IFERROR(J6/H6,0)) | AD6: =IF(COUNT(C6:P6)=0,"",IFERROR(C6/J6,0)) | AE6: =IF(COUNT(C6:P6)=0,"",IFERROR(K6/H6,0)) | AF6: =IF(COUNT(C6:P6)=0,"",IFERROR(L6/H6,0)) | AG6: =IF(COUNT(C6:P6)=0,"",IFERROR(C6/K6,0)) | AH6: =IF(COUNT(C6:P6)=0,"",IFERROR(M6/K6,0)) | AI6: =IF(COUNT(C6:P6)=0,"",IFERROR(C6/M6,0)) | AJ6: =IF(COUNT(C6:P6)=0,"",IFERROR(N6/M6,0)) | AK6: =IF(COUNT(C6:P6)=0,"",IFERROR(N6/H6,0)) | AL6: =IF(COUNT(C6:P6)=0,"",IFERROR(C6/N6,0)) | AM6: =IF(COUNT(C6:P6)=0,"",IFERROR(O6/N6,0)) | AN6: =IF(COUNT(C6:P6)=0,"",IFERROR(P6/N6,0)) | AO6: =IF(COUNT(C6:P6)=0,"",IFERROR(N6*Config!$C$7+O6*Config!$C$8+P6*Config!$C$9,0)) | AP6: =IF(COUNT(C6:P6)=0,"",IFERROR(AO6/N6,0)) | AQ6: =IF(COUNT(C6:P6)=0,"",IFERROR(AO6*(1-Config!$C$10-Config!$C$11-Config!$C$12),0)) | AR6: =IF(COUNT(C6:P6)=0,"",IFERROR(AQ6-C6-Config!$C$13,0)) | AS6: =IF(COUNT(C6:P6)=0,"",IFERROR(AQ6/C6,0)) | AT6: =IF(COUNT(C6:P6)=0,"",IFERROR(AR6/G6,0)) | AU6: =IF(COUNT(C6:P6)=0,"",IFERROR(AT6/V6,0)) | AV6: =IF(COUNT(C6:P6)=0,"",IFERROR(AR6/H6,0))
A7: =Config!$C$6+1 | B7: =INT((A7-Config!$C$6)/7)+1 | C7: 859 | D7: 185215 | E7: 115365 | F7: 3678 | G7: 3154 | H7: 654 | I7: 392 | J7: 438 | Q7: =IF(COUNT(C7:P7)=0,"",IFERROR(C7/D7*1000,0)) | R7: =IF(COUNT(C7:P7)=0,"",IFERROR(D7/E7,0)) | S7: =IF(COUNT(C7:P7)=0,"",IFERROR(F7/D7,0)) | T7: =IF(COUNT(C7:P7)=0,"",IFERROR(C7/F7,0)) | U7: =IF(COUNT(C7:P7)=0,"",IFERROR(G7/F7,0)) | V7: =IF(COUNT(C7:P7)=0,"",IFERROR(C7/G7,0)) | W7: =IF(COUNT(C7:P7)=0,"",IFERROR(G7/D7*1000,0)) | X7: =IF(COUNT(C7:P7)=0,"",IFERROR(H7/G7,0)) | Y7: =IF(COUNT(C7:P7)=0,"",IFERROR(C7/H7,0)) | Z7: =IF(COUNT(C7:P7)=0,"",IFERROR(C7/I7,0)) | AA7: =IF(COUNT(C7:P7)=0,"",IFERROR(Y7/Q7,0)) | AB7: =IF(COUNT(C7:P7)=0,"",IFERROR(H7/D7*1000,0)) | AC7: =IF(COUNT(C7:P7)=0,"",IFERROR(J7/H7,0)) | AD7: =IF(COUNT(C7:P7)=0,"",IFERROR(C7/J7,0)) | AE7: =IF(COUNT(C7:P7)=0,"",IFERROR(K7/H7,0)) | AF7: =IF(COUNT(C7:P7)=0,"",IFERROR(L7/H7,0)) | AG7: =IF(COUNT(C7:P7)=0,"",IFERROR(C7/K7,0)) | AH7: =IF(COUNT(C7:P7)=0,"",IFERROR(M7/K7,0)) | AI7: =IF(COUNT(C7:P7)=0,"",IFERROR(C7/M7,0)) | AJ7: =IF(COUNT(C7:P7)=0,"",IFERROR(N7/M7,0)) | AK7: =IF(COUNT(C7:P7)=0,"",IFERROR(N7/H7,0)) | AL7: =IF(COUNT(C7:P7)=0,"",IFERROR(C7/N7,0)) | AM7: =IF(COUNT(C7:P7)=0,"",IFERROR(O7/N7,0)) | AN7: =IF(COUNT(C7:P7)=0,"",IFERROR(P7/N7,0)) | AO7: =IF(COUNT(C7:P7)=0,"",IFERROR(N7*Config!$C$7+O7*Config!$C$8+P7*Config!$C$9,0)) | AP7: =IF(COUNT(C7:P7)=0,"",IFERROR(AO7/N7,0)) | AQ7: =IF(COUNT(C7:P7)=0,"",IFERROR(AO7*(1-Config!$C$10-Config!$C$11-Config!$C$12),0)) | AR7: =IF(COUNT(C7:P7)=0,"",IFERROR(AQ7-C7-Config!$C$13,0)) | AS7: =IF(COUNT(C7:P7)=0,"",IFERROR(AQ7/C7,0)) | AT7: =IF(COUNT(C7:P7)=0,"",IFERROR(AR7/G7,0)) | AU7: =IF(COUNT(C7:P7)=0,"",IFERROR(AT7/V7,0)) | AV7: =IF(COUNT(C7:P7)=0,"",IFERROR(AR7/H7,0))
A8: =Config!$C$6+2 | B8: =INT((A8-Config!$C$6)/7)+1 | C8: 897 | D8: 223904 | E8: 133787 | F8: 5475 | G8: 5110 | H8: 1208 | I8: 725 | J8: 809 | Q8: =IF(COUNT(C8:P8)=0,"",IFERROR(C8/D8*1000,0)) | R8: =IF(COUNT(C8:P8)=0,"",IFERROR(D8/E8,0)) | S8: =IF(COUNT(C8:P8)=0,"",IFERROR(F8/D8,0)) | T8: =IF(COUNT(C8:P8)=0,"",IFERROR(C8/F8,0)) | U8: =IF(COUNT(C8:P8)=0,"",IFERROR(G8/F8,0)) | V8: =IF(COUNT(C8:P8)=0,"",IFERROR(C8/G8,0)) | W8: =IF(COUNT(C8:P8)=0,"",IFERROR(G8/D8*1000,0)) | X8: =IF(COUNT(C8:P8)=0,"",IFERROR(H8/G8,0)) | Y8: =IF(COUNT(C8:P8)=0,"",IFERROR(C8/H8,0)) | Z8: =IF(COUNT(C8:P8)=0,"",IFERROR(C8/I8,0)) | AA8: =IF(COUNT(C8:P8)=0,"",IFERROR(Y8/Q8,0)) | AB8: =IF(COUNT(C8:P8)=0,"",IFERROR(H8/D8*1000,0)) | AC8: =IF(COUNT(C8:P8)=0,"",IFERROR(J8/H8,0)) | AD8: =IF(COUNT(C8:P8)=0,"",IFERROR(C8/J8,0)) | AE8: =IF(COUNT(C8:P8)=0,"",IFERROR(K8/H8,0)) | AF8: =IF(COUNT(C8:P8)=0,"",IFERROR(L8/H8,0)) | AG8: =IF(COUNT(C8:P8)=0,"",IFERROR(C8/K8,0)) | AH8: =IF(COUNT(C8:P8)=0,"",IFERROR(M8/K8,0)) | AI8: =IF(COUNT(C8:P8)=0,"",IFERROR(C8/M8,0)) | AJ8: =IF(COUNT(C8:P8)=0,"",IFERROR(N8/M8,0)) | AK8: =IF(COUNT(C8:P8)=0,"",IFERROR(N8/H8,0)) | AL8: =IF(COUNT(C8:P8)=0,"",IFERROR(C8/N8,0)) | AM8: =IF(COUNT(C8:P8)=0,"",IFERROR(O8/N8,0)) | AN8: =IF(COUNT(C8:P8)=0,"",IFERROR(P8/N8,0)) | AO8: =IF(COUNT(C8:P8)=0,"",IFERROR(N8*Config!$C$7+O8*Config!$C$8+P8*Config!$C$9,0)) | AP8: =IF(COUNT(C8:P8)=0,"",IFERROR(AO8/N8,0)) | AQ8: =IF(COUNT(C8:P8)=0,"",IFERROR(AO8*(1-Config!$C$10-Config!$C$11-Config!$C$12),0)) | AR8: =IF(COUNT(C8:P8)=0,"",IFERROR(AQ8-C8-Config!$C$13,0)) | AS8: =IF(COUNT(C8:P8)=0,"",IFERROR(AQ8/C8,0)) | AT8: =IF(COUNT(C8:P8)=0,"",IFERROR(AR8/G8,0)) | AU8: =IF(COUNT(C8:P8)=0,"",IFERROR(AT8/V8,0)) | AV8: =IF(COUNT(C8:P8)=0,"",IFERROR(AR8/H8,0))
A9: =Config!$C$6+3 | B9: =INT((A9-Config!$C$6)/7)+1 | C9: 757 | D9: 167138 | E9: 124596 | F9: 3404 | G9: 2874 | H9: 586 | I9: 352 | J9: 393 | K9: 888 | L9: 1195 | M9: 95 | N9: 38 | O9: 8 | P9: 0 | Q9: =IF(COUNT(C9:P9)=0,"",IFERROR(C9/D9*1000,0)) | R9: =IF(COUNT(C9:P9)=0,"",IFERROR(D9/E9,0)) | S9: =IF(COUNT(C9:P9)=0,"",IFERROR(F9/D9,0)) | T9: =IF(COUNT(C9:P9)=0,"",IFERROR(C9/F9,0)) | U9: =IF(COUNT(C9:P9)=0,"",IFERROR(G9/F9,0)) | V9: =IF(COUNT(C9:P9)=0,"",IFERROR(C9/G9,0)) | W9: =IF(COUNT(C9:P9)=0,"",IFERROR(G9/D9*1000,0)) | X9: =IF(COUNT(C9:P9)=0,"",IFERROR(H9/G9,0)) | Y9: =IF(COUNT(C9:P9)=0,"",IFERROR(C9/H9,0)) | Z9: =IF(COUNT(C9:P9)=0,"",IFERROR(C9/I9,0)) | AA9: =IF(COUNT(C9:P9)=0,"",IFERROR(Y9/Q9,0)) | AB9: =IF(COUNT(C9:P9)=0,"",IFERROR(H9/D9*1000,0)) | AC9: =IF(COUNT(C9:P9)=0,"",IFERROR(J9/H9,0)) | AD9: =IF(COUNT(C9:P9)=0,"",IFERROR(C9/J9,0)) | AE9: =IF(COUNT(C9:P9)=0,"",IFERROR(K9/H9,0)) | AF9: =IF(COUNT(C9:P9)=0,"",IFERROR(L9/H9,0)) | AG9: =IF(COUNT(C9:P9)=0,"",IFERROR(C9/K9,0)) | AH9: =IF(COUNT(C9:P9)=0,"",IFERROR(M9/K9,0)) | AI9: =IF(COUNT(C9:P9)=0,"",IFERROR(C9/M9,0)) | AJ9: =IF(COUNT(C9:P9)=0,"",IFERROR(N9/M9,0)) | AK9: =IF(COUNT(C9:P9)=0,"",IFERROR(N9/H9,0)) | AL9: =IF(COUNT(C9:P9)=0,"",IFERROR(C9/N9,0)) | AM9: =IF(COUNT(C9:P9)=0,"",IFERROR(O9/N9,0)) | AN9: =IF(COUNT(C9:P9)=0,"",IFERROR(P9/N9,0)) | AO9: =IF(COUNT(C9:P9)=0,"",IFERROR(N9*Config!$C$7+O9*Config!$C$8+P9*Config!$C$9,0)) | AP9: =IF(COUNT(C9:P9)=0,"",IFERROR(AO9/N9,0)) | AQ9: =IF(COUNT(C9:P9)=0,"",IFERROR(AO9*(1-Config!$C$10-Config!$C$11-Config!$C$12),0)) | AR9: =IF(COUNT(C9:P9)=0,"",IFERROR(AQ9-C9-Config!$C$13,0)) | AS9: =IF(COUNT(C9:P9)=0,"",IFERROR(AQ9/C9,0)) | AT9: =IF(COUNT(C9:P9)=0,"",IFERROR(AR9/G9,0)) | AU9: =IF(COUNT(C9:P9)=0,"",IFERROR(AT9/V9,0)) | AV9: =IF(COUNT(C9:P9)=0,"",IFERROR(AR9/H9,0))
A10: =Config!$C$6+4 | B10: =INT((A10-Config!$C$6)/7)+1 | C10: 861 | D10: 185087 | E10: 123398 | F10: 4231 | G10: 3769 | H10: 821 | I10: 492 | J10: 550 | L10: 1590 | M10: 110 | N10: 44 | O10: 9 | P10: 2 | Q10: =IF(COUNT(C10:P10)=0,"",IFERROR(C10/D10*1000,0)) | R10: =IF(COUNT(C10:P10)=0,"",IFERROR(D10/E10,0)) | S10: =IF(COUNT(C10:P10)=0,"",IFERROR(F10/D10,0)) | T10: =IF(COUNT(C10:P10)=0,"",IFERROR(C10/F10,0)) | U10: =IF(COUNT(C10:P10)=0,"",IFERROR(G10/F10,0)) | V10: =IF(COUNT(C10:P10)=0,"",IFERROR(C10/G10,0)) | W10: =IF(COUNT(C10:P10)=0,"",IFERROR(G10/D10*1000,0)) | X10: =IF(COUNT(C10:P10)=0,"",IFERROR(H10/G10,0)) | Y10: =IF(COUNT(C10:P10)=0,"",IFERROR(C10/H10,0)) | Z10: =IF(COUNT(C10:P10)=0,"",IFERROR(C10/I10,0)) | AA10: =IF(COUNT(C10:P10)=0,"",IFERROR(Y10/Q10,0)) | AB10: =IF(COUNT(C10:P10)=0,"",IFERROR(H10/D10*1000,0)) | AC10: =IF(COUNT(C10:P10)=0,"",IFERROR(J10/H10,0)) | AD10: =IF(COUNT(C10:P10)=0,"",IFERROR(C10/J10,0)) | AE10: =IF(COUNT(C10:P10)=0,"",IFERROR(K10/H10,0)) | AF10: =IF(COUNT(C10:P10)=0,"",IFERROR(L10/H10,0)) | AG10: =IF(COUNT(C10:P10)=0,"",IFERROR(C10/K10,0)) | AH10: =IF(COUNT(C10:P10)=0,"",IFERROR(M10/K10,0)) | AI10: =IF(COUNT(C10:P10)=0,"",IFERROR(C10/M10,0)) | AJ10: =IF(COUNT(C10:P10)=0,"",IFERROR(N10/M10,0)) | AK10: =IF(COUNT(C10:P10)=0,"",IFERROR(N10/H10,0)) | AL10: =IF(COUNT(C10:P10)=0,"",IFERROR(C10/N10,0)) | AM10: =IF(COUNT(C10:P10)=0,"",IFERROR(O10/N10,0)) | AN10: =IF(COUNT(C10:P10)=0,"",IFERROR(P10/N10,0)) | AO10: =IF(COUNT(C10:P10)=0,"",IFERROR(N10*Config!$C$7+O10*Config!$C$8+P10*Config!$C$9,0)) | AP10: =IF(COUNT(C10:P10)=0,"",IFERROR(AO10/N10,0)) | AQ10: =IF(COUNT(C10:P10)=0,"",IFERROR(AO10*(1-Config!$C$10-Config!$C$11-Config!$C$12),0)) | AR10: =IF(COUNT(C10:P10)=0,"",IFERROR(AQ10-C10-Config!$C$13,0)) | AS10: =IF(COUNT(C10:P10)=0,"",IFERROR(AQ10/C10,0)) | AT10: =IF(COUNT(C10:P10)=0,"",IFERROR(AR10/G10,0)) | AU10: =IF(COUNT(C10:P10)=0,"",IFERROR(AT10/V10,0)) | AV10: =IF(COUNT(C10:P10)=0,"",IFERROR(AR10/H10,0))
A11: =Config!$C$6+5 | B11: =INT((A11-Config!$C$6)/7)+1 | C11: 927 | D11: 196209 | E11: 136874 | F11: 4037 | G11: 3449 | H11: 711 | I11: 427 | J11: 477 | L11: 619 | M11: 33 | N11: 13 | O11: 3 | P11: 1 | Q11: =IF(COUNT(C11:P11)=0,"",IFERROR(C11/D11*1000,0)) | R11: =IF(COUNT(C11:P11)=0,"",IFERROR(D11/E11,0)) | S11: =IF(COUNT(C11:P11)=0,"",IFERROR(F11/D11,0)) | T11: =IF(COUNT(C11:P11)=0,"",IFERROR(C11/F11,0)) | U11: =IF(COUNT(C11:P11)=0,"",IFERROR(G11/F11,0)) | V11: =IF(COUNT(C11:P11)=0,"",IFERROR(C11/G11,0)) | W11: =IF(COUNT(C11:P11)=0,"",IFERROR(G11/D11*1000,0)) | X11: =IF(COUNT(C11:P11)=0,"",IFERROR(H11/G11,0)) | Y11: =IF(COUNT(C11:P11)=0,"",IFERROR(C11/H11,0)) | Z11: =IF(COUNT(C11:P11)=0,"",IFERROR(C11/I11,0)) | AA11: =IF(COUNT(C11:P11)=0,"",IFERROR(Y11/Q11,0)) | AB11: =IF(COUNT(C11:P11)=0,"",IFERROR(H11/D11*1000,0)) | AC11: =IF(COUNT(C11:P11)=0,"",IFERROR(J11/H11,0)) | AD11: =IF(COUNT(C11:P11)=0,"",IFERROR(C11/J11,0)) | AE11: =IF(COUNT(C11:P11)=0,"",IFERROR(K11/H11,0)) | AF11: =IF(COUNT(C11:P11)=0,"",IFERROR(L11/H11,0)) | AG11: =IF(COUNT(C11:P11)=0,"",IFERROR(C11/K11,0)) | AH11: =IF(COUNT(C11:P11)=0,"",IFERROR(M11/K11,0)) | AI11: =IF(COUNT(C11:P11)=0,"",IFERROR(C11/M11,0)) | AJ11: =IF(COUNT(C11:P11)=0,"",IFERROR(N11/M11,0)) | AK11: =IF(COUNT(C11:P11)=0,"",IFERROR(N11/H11,0)) | AL11: =IF(COUNT(C11:P11)=0,"",IFERROR(C11/N11,0)) | AM11: =IF(COUNT(C11:P11)=0,"",IFERROR(O11/N11,0)) | AN11: =IF(COUNT(C11:P11)=0,"",IFERROR(P11/N11,0)) | AO11: =IF(COUNT(C11:P11)=0,"",IFERROR(N11*Config!$C$7+O11*Config!$C$8+P11*Config!$C$9,0)) | AP11: =IF(COUNT(C11:P11)=0,"",IFERROR(AO11/N11,0)) | AQ11: =IF(COUNT(C11:P11)=0,"",IFERROR(AO11*(1-Config!$C$10-Config!$C$11-Config!$C$12),0)) | AR11: =IF(COUNT(C11:P11)=0,"",IFERROR(AQ11-C11-Config!$C$13,0)) | AS11: =IF(COUNT(C11:P11)=0,"",IFERROR(AQ11/C11,0)) | AT11: =IF(COUNT(C11:P11)=0,"",IFERROR(AR11/G11,0)) | AU11: =IF(COUNT(C11:P11)=0,"",IFERROR(AT11/V11,0)) | AV11: =IF(COUNT(C11:P11)=0,"",IFERROR(AR11/H11,0))
A12: =Config!$C$6+6 | B12: =INT((A12-Config!$C$6)/7)+1 | C12: 928 | D12: 212061 | E12: 127372 | F12: 5054 | G12: 4004 | H12: 857 | I12: 514 | J12: 574 | Q12: =IF(COUNT(C12:P12)=0,"",IFERROR(C12/D12*1000,0)) | R12: =IF(COUNT(C12:P12)=0,"",IFERROR(D12/E12,0)) | S12: =IF(COUNT(C12:P12)=0,"",IFERROR(F12/D12,0)) | T12: =IF(COUNT(C12:P12)=0,"",IFERROR(C12/F12,0)) | U12: =IF(COUNT(C12:P12)=0,"",IFERROR(G12/F12,0)) | V12: =IF(COUNT(C12:P12)=0,"",IFERROR(C12/G12,0)) | W12: =IF(COUNT(C12:P12)=0,"",IFERROR(G12/D12*1000,0)) | X12: =IF(COUNT(C12:P12)=0,"",IFERROR(H12/G12,0)) | Y12: =IF(COUNT(C12:P12)=0,"",IFERROR(C12/H12,0)) | Z12: =IF(COUNT(C12:P12)=0,"",IFERROR(C12/I12,0)) | AA12: =IF(COUNT(C12:P12)=0,"",IFERROR(Y12/Q12,0)) | AB12: =IF(COUNT(C12:P12)=0,"",IFERROR(H12/D12*1000,0)) | AC12: =IF(COUNT(C12:P12)=0,"",IFERROR(J12/H12,0)) | AD12: =IF(COUNT(C12:P12)=0,"",IFERROR(C12/J12,0)) | AE12: =IF(COUNT(C12:P12)=0,"",IFERROR(K12/H12,0)) | AF12: =IF(COUNT(C12:P12)=0,"",IFERROR(L12/H12,0)) | AG12: =IF(COUNT(C12:P12)=0,"",IFERROR(C12/K12,0)) | AH12: =IF(COUNT(C12:P12)=0,"",IFERROR(M12/K12,0)) | AI12: =IF(COUNT(C12:P12)=0,"",IFERROR(C12/M12,0)) | AJ12: =IF(COUNT(C12:P12)=0,"",IFERROR(N12/M12,0)) | AK12: =IF(COUNT(C12:P12)=0,"",IFERROR(N12/H12,0)) | AL12: =IF(COUNT(C12:P12)=0,"",IFERROR(C12/N12,0)) | AM12: =IF(COUNT(C12:P12)=0,"",IFERROR(O12/N12,0)) | AN12: =IF(COUNT(C12:P12)=0,"",IFERROR(P12/N12,0)) | AO12: =IF(COUNT(C12:P12)=0,"",IFERROR(N12*Config!$C$7+O12*Config!$C$8+P12*Config!$C$9,0)) | AP12: =IF(COUNT(C12:P12)=0,"",IFERROR(AO12/N12,0)) | AQ12: =IF(COUNT(C12:P12)=0,"",IFERROR(AO12*(1-Config!$C$10-Config!$C$11-Config!$C$12),0)) | AR12: =IF(COUNT(C12:P12)=0,"",IFERROR(AQ12-C12-Config!$C$13,0)) | AS12: =IF(COUNT(C12:P12)=0,"",IFERROR(AQ12/C12,0)) | AT12: =IF(COUNT(C12:P12)=0,"",IFERROR(AR12/G12,0)) | AU12: =IF(COUNT(C12:P12)=0,"",IFERROR(AT12/V12,0)) | AV12: =IF(COUNT(C12:P12)=0,"",IFERROR(AR12/H12,0))
A13: =Config!$C$6+7 | B13: =INT((A13-Config!$C$6)/7)+1 | C13: 851 | D13: 169528 | E13: 115871 | F13: 3347 | G13: 3106 | H13: 762 | I13: 457 | J13: 511 | Q13: =IF(COUNT(C13:P13)=0,"",IFERROR(C13/D13*1000,0)) | R13: =IF(COUNT(C13:P13)=0,"",IFERROR(D13/E13,0)) | S13: =IF(COUNT(C13:P13)=0,"",IFERROR(F13/D13,0)) | T13: =IF(COUNT(C13:P13)=0,"",IFERROR(C13/F13,0)) | U13: =IF(COUNT(C13:P13)=0,"",IFERROR(G13/F13,0)) | V13: =IF(COUNT(C13:P13)=0,"",IFERROR(C13/G13,0)) | W13: =IF(COUNT(C13:P13)=0,"",IFERROR(G13/D13*1000,0)) | X13: =IF(COUNT(C13:P13)=0,"",IFERROR(H13/G13,0)) | Y13: =IF(COUNT(C13:P13)=0,"",IFERROR(C13/H13,0)) | Z13: =IF(COUNT(C13:P13)=0,"",IFERROR(C13/I13,0)) | AA13: =IF(COUNT(C13:P13)=0,"",IFERROR(Y13/Q13,0)) | AB13: =IF(COUNT(C13:P13)=0,"",IFERROR(H13/D13*1000,0)) | AC13: =IF(COUNT(C13:P13)=0,"",IFERROR(J13/H13,0)) | AD13: =IF(COUNT(C13:P13)=0,"",IFERROR(C13/J13,0)) | AE13: =IF(COUNT(C13:P13)=0,"",IFERROR(K13/H13,0)) | AF13: =IF(COUNT(C13:P13)=0,"",IFERROR(L13/H13,0)) | AG13: =IF(COUNT(C13:P13)=0,"",IFERROR(C13/K13,0)) | AH13: =IF(COUNT(C13:P13)=0,"",IFERROR(M13/K13,0)) | AI13: =IF(COUNT(C13:P13)=0,"",IFERROR(C13/M13,0)) | AJ13: =IF(COUNT(C13:P13)=0,"",IFERROR(N13/M13,0)) | AK13: =IF(COUNT(C13:P13)=0,"",IFERROR(N13/H13,0)) | AL13: =IF(COUNT(C13:P13)=0,"",IFERROR(C13/N13,0)) | AM13: =IF(COUNT(C13:P13)=0,"",IFERROR(O13/N13,0)) | AN13: =IF(COUNT(C13:P13)=0,"",IFERROR(P13/N13,0)) | AO13: =IF(COUNT(C13:P13)=0,"",IFERROR(N13*Config!$C$7+O13*Config!$C$8+P13*Config!$C$9,0)) | AP13: =IF(COUNT(C13:P13)=0,"",IFERROR(AO13/N13,0)) | AQ13: =IF(COUNT(C13:P13)=0,"",IFERROR(AO13*(1-Config!$C$10-Config!$C$11-Config!$C$12),0)) | AR13: =IF(COUNT(C13:P13)=0,"",IFERROR(AQ13-C13-Config!$C$13,0)) | AS13: =IF(COUNT(C13:P13)=0,"",IFERROR(AQ13/C13,0)) | AT13: =IF(COUNT(C13:P13)=0,"",IFERROR(AR13/G13,0)) | AU13: =IF(COUNT(C13:P13)=0,"",IFERROR(AT13/V13,0)) | AV13: =IF(COUNT(C13:P13)=0,"",IFERROR(AR13/H13,0))
A14: =Config!$C$6+8 | B14: =INT((A14-Config!$C$6)/7)+1 | C14: 772 | D14: 178757 | E14: 107228 | F14: 4176 | G14: 3414 | H14: 737 | I14: 442 | J14: 494 | Q14: =IF(COUNT(C14:P14)=0,"",IFERROR(C14/D14*1000,0)) | R14: =IF(COUNT(C14:P14)=0,"",IFERROR(D14/E14,0)) | S14: =IF(COUNT(C14:P14)=0,"",IFERROR(F14/D14,0)) | T14: =IF(COUNT(C14:P14)=0,"",IFERROR(C14/F14,0)) | U14: =IF(COUNT(C14:P14)=0,"",IFERROR(G14/F14,0)) | V14: =IF(COUNT(C14:P14)=0,"",IFERROR(C14/G14,0)) | W14: =IF(COUNT(C14:P14)=0,"",IFERROR(G14/D14*1000,0)) | X14: =IF(COUNT(C14:P14)=0,"",IFERROR(H14/G14,0)) | Y14: =IF(COUNT(C14:P14)=0,"",IFERROR(C14/H14,0)) | Z14: =IF(COUNT(C14:P14)=0,"",IFERROR(C14/I14,0)) | AA14: =IF(COUNT(C14:P14)=0,"",IFERROR(Y14/Q14,0)) | AB14: =IF(COUNT(C14:P14)=0,"",IFERROR(H14/D14*1000,0)) | AC14: =IF(COUNT(C14:P14)=0,"",IFERROR(J14/H14,0)) | AD14: =IF(COUNT(C14:P14)=0,"",IFERROR(C14/J14,0)) | AE14: =IF(COUNT(C14:P14)=0,"",IFERROR(K14/H14,0)) | AF14: =IF(COUNT(C14:P14)=0,"",IFERROR(L14/H14,0)) | AG14: =IF(COUNT(C14:P14)=0,"",IFERROR(C14/K14,0)) | AH14: =IF(COUNT(C14:P14)=0,"",IFERROR(M14/K14,0)) | AI14: =IF(COUNT(C14:P14)=0,"",IFERROR(C14/M14,0)) | AJ14: =IF(COUNT(C14:P14)=0,"",IFERROR(N14/M14,0)) | AK14: =IF(COUNT(C14:P14)=0,"",IFERROR(N14/H14,0)) | AL14: =IF(COUNT(C14:P14)=0,"",IFERROR(C14/N14,0)) | AM14: =IF(COUNT(C14:P14)=0,"",IFERROR(O14/N14,0)) | AN14: =IF(COUNT(C14:P14)=0,"",IFERROR(P14/N14,0)) | AO14: =IF(COUNT(C14:P14)=0,"",IFERROR(N14*Config!$C$7+O14*Config!$C$8+P14*Config!$C$9,0)) | AP14: =IF(COUNT(C14:P14)=0,"",IFERROR(AO14/N14,0)) | AQ14: =IF(COUNT(C14:P14)=0,"",IFERROR(AO14*(1-Config!$C$10-Config!$C$11-Config!$C$12),0)) | AR14: =IF(COUNT(C14:P14)=0,"",IFERROR(AQ14-C14-Config!$C$13,0)) | AS14: =IF(COUNT(C14:P14)=0,"",IFERROR(AQ14/C14,0)) | AT14: =IF(COUNT(C14:P14)=0,"",IFERROR(AR14/G14,0)) | AU14: =IF(COUNT(C14:P14)=0,"",IFERROR(AT14/V14,0)) | AV14: =IF(COUNT(C14:P14)=0,"",IFERROR(AR14/H14,0))
A15: =Config!$C$6+9 | B15: =INT((A15-Config!$C$6)/7)+1 | C15: 766 | D15: 158995 | E15: 114884 | F15: 3548 | G15: 3153 | H15: 671 | I15: 403 | J15: 450 | Q15: =IF(COUNT(C15:P15)=0,"",IFERROR(C15/D15*1000,0)) | R15: =IF(COUNT(C15:P15)=0,"",IFERROR(D15/E15,0)) | S15: =IF(COUNT(C15:P15)=0,"",IFERROR(F15/D15,0)) | T15: =IF(COUNT(C15:P15)=0,"",IFERROR(C15/F15,0)) | U15: =IF(COUNT(C15:P15)=0,"",IFERROR(G15/F15,0)) | V15: =IF(COUNT(C15:P15)=0,"",IFERROR(C15/G15,0)) | W15: =IF(COUNT(C15:P15)=0,"",IFERROR(G15/D15*1000,0)) | X15: =IF(COUNT(C15:P15)=0,"",IFERROR(H15/G15,0)) | Y15: =IF(COUNT(C15:P15)=0,"",IFERROR(C15/H15,0)) | Z15: =IF(COUNT(C15:P15)=0,"",IFERROR(C15/I15,0)) | AA15: =IF(COUNT(C15:P15)=0,"",IFERROR(Y15/Q15,0)) | AB15: =IF(COUNT(C15:P15)=0,"",IFERROR(H15/D15*1000,0)) | AC15: =IF(COUNT(C15:P15)=0,"",IFERROR(J15/H15,0)) | AD15: =IF(COUNT(C15:P15)=0,"",IFERROR(C15/J15,0)) | AE15: =IF(COUNT(C15:P15)=0,"",IFERROR(K15/H15,0)) | AF15: =IF(COUNT(C15:P15)=0,"",IFERROR(L15/H15,0)) | AG15: =IF(COUNT(C15:P15)=0,"",IFERROR(C15/K15,0)) | AH15: =IF(COUNT(C15:P15)=0,"",IFERROR(M15/K15,0)) | AI15: =IF(COUNT(C15:P15)=0,"",IFERROR(C15/M15,0)) | AJ15: =IF(COUNT(C15:P15)=0,"",IFERROR(N15/M15,0)) | AK15: =IF(COUNT(C15:P15)=0,"",IFERROR(N15/H15,0)) | AL15: =IF(COUNT(C15:P15)=0,"",IFERROR(C15/N15,0)) | AM15: =IF(COUNT(C15:P15)=0,"",IFERROR(O15/N15,0)) | AN15: =IF(COUNT(C15:P15)=0,"",IFERROR(P15/N15,0)) | AO15: =IF(COUNT(C15:P15)=0,"",IFERROR(N15*Config!$C$7+O15*Config!$C$8+P15*Config!$C$9,0)) | AP15: =IF(COUNT(C15:P15)=0,"",IFERROR(AO15/N15,0)) | AQ15: =IF(COUNT(C15:P15)=0,"",IFERROR(AO15*(1-Config!$C$10-Config!$C$11-Config!$C$12),0)) | AR15: =IF(COUNT(C15:P15)=0,"",IFERROR(AQ15-C15-Config!$C$13,0)) | AS15: =IF(COUNT(C15:P15)=0,"",IFERROR(AQ15/C15,0)) | AT15: =IF(COUNT(C15:P15)=0,"",IFERROR(AR15/G15,0)) | AU15: =IF(COUNT(C15:P15)=0,"",IFERROR(AT15/V15,0)) | AV15: =IF(COUNT(C15:P15)=0,"",IFERROR(AR15/H15,0))
A16: =Config!$C$6+10 | B16: =INT((A16-Config!$C$6)/7)+1 | C16: 781 | D16: 167790 | E16: 123199 | F16: 3621 | G16: 3034 | H16: 659 | I16: 396 | J16: 442 | K16: 997 | L16: 1268 | M16: 96 | N16: 38 | O16: 8 | P16: 0 | Q16: =IF(COUNT(C16:P16)=0,"",IFERROR(C16/D16*1000,0)) | R16: =IF(COUNT(C16:P16)=0,"",IFERROR(D16/E16,0)) | S16: =IF(COUNT(C16:P16)=0,"",IFERROR(F16/D16,0)) | T16: =IF(COUNT(C16:P16)=0,"",IFERROR(C16/F16,0)) | U16: =IF(COUNT(C16:P16)=0,"",IFERROR(G16/F16,0)) | V16: =IF(COUNT(C16:P16)=0,"",IFERROR(C16/G16,0)) | W16: =IF(COUNT(C16:P16)=0,"",IFERROR(G16/D16*1000,0)) | X16: =IF(COUNT(C16:P16)=0,"",IFERROR(H16/G16,0)) | Y16: =IF(COUNT(C16:P16)=0,"",IFERROR(C16/H16,0)) | Z16: =IF(COUNT(C16:P16)=0,"",IFERROR(C16/I16,0)) | AA16: =IF(COUNT(C16:P16)=0,"",IFERROR(Y16/Q16,0)) | AB16: =IF(COUNT(C16:P16)=0,"",IFERROR(H16/D16*1000,0)) | AC16: =IF(COUNT(C16:P16)=0,"",IFERROR(J16/H16,0)) | AD16: =IF(COUNT(C16:P16)=0,"",IFERROR(C16/J16,0)) | AE16: =IF(COUNT(C16:P16)=0,"",IFERROR(K16/H16,0)) | AF16: =IF(COUNT(C16:P16)=0,"",IFERROR(L16/H16,0)) | AG16: =IF(COUNT(C16:P16)=0,"",IFERROR(C16/K16,0)) | AH16: =IF(COUNT(C16:P16)=0,"",IFERROR(M16/K16,0)) | AI16: =IF(COUNT(C16:P16)=0,"",IFERROR(C16/M16,0)) | AJ16: =IF(COUNT(C16:P16)=0,"",IFERROR(N16/M16,0)) | AK16: =IF(COUNT(C16:P16)=0,"",IFERROR(N16/H16,0)) | AL16: =IF(COUNT(C16:P16)=0,"",IFERROR(C16/N16,0)) | AM16: =IF(COUNT(C16:P16)=0,"",IFERROR(O16/N16,0)) | AN16: =IF(COUNT(C16:P16)=0,"",IFERROR(P16/N16,0)) | AO16: =IF(COUNT(C16:P16)=0,"",IFERROR(N16*Config!$C$7+O16*Config!$C$8+P16*Config!$C$9,0)) | AP16: =IF(COUNT(C16:P16)=0,"",IFERROR(AO16/N16,0)) | AQ16: =IF(COUNT(C16:P16)=0,"",IFERROR(AO16*(1-Config!$C$10-Config!$C$11-Config!$C$12),0)) | AR16: =IF(COUNT(C16:P16)=0,"",IFERROR(AQ16-C16-Config!$C$13,0)) | AS16: =IF(COUNT(C16:P16)=0,"",IFERROR(AQ16/C16,0)) | AT16: =IF(COUNT(C16:P16)=0,"",IFERROR(AR16/G16,0)) | AU16: =IF(COUNT(C16:P16)=0,"",IFERROR(AT16/V16,0)) | AV16: =IF(COUNT(C16:P16)=0,"",IFERROR(AR16/H16,0))
A17: =Config!$C$6+11 | B17: =INT((A17-Config!$C$6)/7)+1 | C17: 936 | D17: 223557 | E17: 152918 | F17: 5337 | G17: 4966 | H17: 1033 | I17: 620 | J17: 692 | L17: 1588 | M17: 87 | N17: 35 | O17: 7 | P17: 2 | Q17: =IF(COUNT(C17:P17)=0,"",IFERROR(C17/D17*1000,0)) | R17: =IF(COUNT(C17:P17)=0,"",IFERROR(D17/E17,0)) | S17: =IF(COUNT(C17:P17)=0,"",IFERROR(F17/D17,0)) | T17: =IF(COUNT(C17:P17)=0,"",IFERROR(C17/F17,0)) | U17: =IF(COUNT(C17:P17)=0,"",IFERROR(G17/F17,0)) | V17: =IF(COUNT(C17:P17)=0,"",IFERROR(C17/G17,0)) | W17: =IF(COUNT(C17:P17)=0,"",IFERROR(G17/D17*1000,0)) | X17: =IF(COUNT(C17:P17)=0,"",IFERROR(H17/G17,0)) | Y17: =IF(COUNT(C17:P17)=0,"",IFERROR(C17/H17,0)) | Z17: =IF(COUNT(C17:P17)=0,"",IFERROR(C17/I17,0)) | AA17: =IF(COUNT(C17:P17)=0,"",IFERROR(Y17/Q17,0)) | AB17: =IF(COUNT(C17:P17)=0,"",IFERROR(H17/D17*1000,0)) | AC17: =IF(COUNT(C17:P17)=0,"",IFERROR(J17/H17,0)) | AD17: =IF(COUNT(C17:P17)=0,"",IFERROR(C17/J17,0)) | AE17: =IF(COUNT(C17:P17)=0,"",IFERROR(K17/H17,0)) | AF17: =IF(COUNT(C17:P17)=0,"",IFERROR(L17/H17,0)) | AG17: =IF(COUNT(C17:P17)=0,"",IFERROR(C17/K17,0)) | AH17: =IF(COUNT(C17:P17)=0,"",IFERROR(M17/K17,0)) | AI17: =IF(COUNT(C17:P17)=0,"",IFERROR(C17/M17,0)) | AJ17: =IF(COUNT(C17:P17)=0,"",IFERROR(N17/M17,0)) | AK17: =IF(COUNT(C17:P17)=0,"",IFERROR(N17/H17,0)) | AL17: =IF(COUNT(C17:P17)=0,"",IFERROR(C17/N17,0)) | AM17: =IF(COUNT(C17:P17)=0,"",IFERROR(O17/N17,0)) | AN17: =IF(COUNT(C17:P17)=0,"",IFERROR(P17/N17,0)) | AO17: =IF(COUNT(C17:P17)=0,"",IFERROR(N17*Config!$C$7+O17*Config!$C$8+P17*Config!$C$9,0)) | AP17: =IF(COUNT(C17:P17)=0,"",IFERROR(AO17/N17,0)) | AQ17: =IF(COUNT(C17:P17)=0,"",IFERROR(AO17*(1-Config!$C$10-Config!$C$11-Config!$C$12),0)) | AR17: =IF(COUNT(C17:P17)=0,"",IFERROR(AQ17-C17-Config!$C$13,0)) | AS17: =IF(COUNT(C17:P17)=0,"",IFERROR(AQ17/C17,0)) | AT17: =IF(COUNT(C17:P17)=0,"",IFERROR(AR17/G17,0)) | AU17: =IF(COUNT(C17:P17)=0,"",IFERROR(AT17/V17,0)) | AV17: =IF(COUNT(C17:P17)=0,"",IFERROR(AR17/H17,0))
A18: =Config!$C$6+12 | B18: =INT((A18-Config!$C$6)/7)+1 | C18: 807 | D18: 168377 | E18: 117056 | F18: 3523 | G18: 2846 | H18: 590 | I18: 354 | J18: 395 | L18: 606 | M18: 31 | N18: 12 | O18: 2 | P18: 1 | Q18: =IF(COUNT(C18:P18)=0,"",IFERROR(C18/D18*1000,0)) | R18: =IF(COUNT(C18:P18)=0,"",IFERROR(D18/E18,0)) | S18: =IF(COUNT(C18:P18)=0,"",IFERROR(F18/D18,0)) | T18: =IF(COUNT(C18:P18)=0,"",IFERROR(C18/F18,0)) | U18: =IF(COUNT(C18:P18)=0,"",IFERROR(G18/F18,0)) | V18: =IF(COUNT(C18:P18)=0,"",IFERROR(C18/G18,0)) | W18: =IF(COUNT(C18:P18)=0,"",IFERROR(G18/D18*1000,0)) | X18: =IF(COUNT(C18:P18)=0,"",IFERROR(H18/G18,0)) | Y18: =IF(COUNT(C18:P18)=0,"",IFERROR(C18/H18,0)) | Z18: =IF(COUNT(C18:P18)=0,"",IFERROR(C18/I18,0)) | AA18: =IF(COUNT(C18:P18)=0,"",IFERROR(Y18/Q18,0)) | AB18: =IF(COUNT(C18:P18)=0,"",IFERROR(H18/D18*1000,0)) | AC18: =IF(COUNT(C18:P18)=0,"",IFERROR(J18/H18,0)) | AD18: =IF(COUNT(C18:P18)=0,"",IFERROR(C18/J18,0)) | AE18: =IF(COUNT(C18:P18)=0,"",IFERROR(K18/H18,0)) | AF18: =IF(COUNT(C18:P18)=0,"",IFERROR(L18/H18,0)) | AG18: =IF(COUNT(C18:P18)=0,"",IFERROR(C18/K18,0)) | AH18: =IF(COUNT(C18:P18)=0,"",IFERROR(M18/K18,0)) | AI18: =IF(COUNT(C18:P18)=0,"",IFERROR(C18/M18,0)) | AJ18: =IF(COUNT(C18:P18)=0,"",IFERROR(N18/M18,0)) | AK18: =IF(COUNT(C18:P18)=0,"",IFERROR(N18/H18,0)) | AL18: =IF(COUNT(C18:P18)=0,"",IFERROR(C18/N18,0)) | AM18: =IF(COUNT(C18:P18)=0,"",IFERROR(O18/N18,0)) | AN18: =IF(COUNT(C18:P18)=0,"",IFERROR(P18/N18,0)) | AO18: =IF(COUNT(C18:P18)=0,"",IFERROR(N18*Config!$C$7+O18*Config!$C$8+P18*Config!$C$9,0)) | AP18: =IF(COUNT(C18:P18)=0,"",IFERROR(AO18/N18,0)) | AQ18: =IF(COUNT(C18:P18)=0,"",IFERROR(AO18*(1-Config!$C$10-Config!$C$11-Config!$C$12),0)) | AR18: =IF(COUNT(C18:P18)=0,"",IFERROR(AQ18-C18-Config!$C$13,0)) | AS18: =IF(COUNT(C18:P18)=0,"",IFERROR(AQ18/C18,0)) | AT18: =IF(COUNT(C18:P18)=0,"",IFERROR(AR18/G18,0)) | AU18: =IF(COUNT(C18:P18)=0,"",IFERROR(AT18/V18,0)) | AV18: =IF(COUNT(C18:P18)=0,"",IFERROR(AR18/H18,0))
A19: =Config!$C$6+13 | B19: =INT((A19-Config!$C$6)/7)+1 | C19: 878 | D19: 201271 | E19: 135705 | F19: 4916 | G19: 4407 | H19: 1032 | I19: 619 | J19: 691 | Q19: =IF(COUNT(C19:P19)=0,"",IFERROR(C19/D19*1000,0)) | R19: =IF(COUNT(C19:P19)=0,"",IFERROR(D19/E19,0)) | S19: =IF(COUNT(C19:P19)=0,"",IFERROR(F19/D19,0)) | T19: =IF(COUNT(C19:P19)=0,"",IFERROR(C19/F19,0)) | U19: =IF(COUNT(C19:P19)=0,"",IFERROR(G19/F19,0)) | V19: =IF(COUNT(C19:P19)=0,"",IFERROR(C19/G19,0)) | W19: =IF(COUNT(C19:P19)=0,"",IFERROR(G19/D19*1000,0)) | X19: =IF(COUNT(C19:P19)=0,"",IFERROR(H19/G19,0)) | Y19: =IF(COUNT(C19:P19)=0,"",IFERROR(C19/H19,0)) | Z19: =IF(COUNT(C19:P19)=0,"",IFERROR(C19/I19,0)) | AA19: =IF(COUNT(C19:P19)=0,"",IFERROR(Y19/Q19,0)) | AB19: =IF(COUNT(C19:P19)=0,"",IFERROR(H19/D19*1000,0)) | AC19: =IF(COUNT(C19:P19)=0,"",IFERROR(J19/H19,0)) | AD19: =IF(COUNT(C19:P19)=0,"",IFERROR(C19/J19,0)) | AE19: =IF(COUNT(C19:P19)=0,"",IFERROR(K19/H19,0)) | AF19: =IF(COUNT(C19:P19)=0,"",IFERROR(L19/H19,0)) | AG19: =IF(COUNT(C19:P19)=0,"",IFERROR(C19/K19,0)) | AH19: =IF(COUNT(C19:P19)=0,"",IFERROR(M19/K19,0)) | AI19: =IF(COUNT(C19:P19)=0,"",IFERROR(C19/M19,0)) | AJ19: =IF(COUNT(C19:P19)=0,"",IFERROR(N19/M19,0)) | AK19: =IF(COUNT(C19:P19)=0,"",IFERROR(N19/H19,0)) | AL19: =IF(COUNT(C19:P19)=0,"",IFERROR(C19/N19,0)) | AM19: =IF(COUNT(C19:P19)=0,"",IFERROR(O19/N19,0)) | AN19: =IF(COUNT(C19:P19)=0,"",IFERROR(P19/N19,0)) | AO19: =IF(COUNT(C19:P19)=0,"",IFERROR(N19*Config!$C$7+O19*Config!$C$8+P19*Config!$C$9,0)) | AP19: =IF(COUNT(C19:P19)=0,"",IFERROR(AO19/N19,0)) | AQ19: =IF(COUNT(C19:P19)=0,"",IFERROR(AO19*(1-Config!$C$10-Config!$C$11-Config!$C$12),0)) | AR19: =IF(COUNT(C19:P19)=0,"",IFERROR(AQ19-C19-Config!$C$13,0)) | AS19: =IF(COUNT(C19:P19)=0,"",IFERROR(AQ19/C19,0)) | AT19: =IF(COUNT(C19:P19)=0,"",IFERROR(AR19/G19,0)) | AU19: =IF(COUNT(C19:P19)=0,"",IFERROR(AT19/V19,0)) | AV19: =IF(COUNT(C19:P19)=0,"",IFERROR(AR19/H19,0))
A20: =Config!$C$6+14 | B20: =INT((A20-Config!$C$6)/7)+1 | C20: 792 | D20: 191875 | E20: 116497 | F20: 4543 | G20: 3843 | H20: 818 | I20: 491 | J20: 548 | Q20: =IF(COUNT(C20:P20)=0,"",IFERROR(C20/D20*1000,0)) | R20: =IF(COUNT(C20:P20)=0,"",IFERROR(D20/E20,0)) | S20: =IF(COUNT(C20:P20)=0,"",IFERROR(F20/D20,0)) | T20: =IF(COUNT(C20:P20)=0,"",IFERROR(C20/F20,0)) | U20: =IF(COUNT(C20:P20)=0,"",IFERROR(G20/F20,0)) | V20: =IF(COUNT(C20:P20)=0,"",IFERROR(C20/G20,0)) | W20: =IF(COUNT(C20:P20)=0,"",IFERROR(G20/D20*1000,0)) | X20: =IF(COUNT(C20:P20)=0,"",IFERROR(H20/G20,0)) | Y20: =IF(COUNT(C20:P20)=0,"",IFERROR(C20/H20,0)) | Z20: =IF(COUNT(C20:P20)=0,"",IFERROR(C20/I20,0)) | AA20: =IF(COUNT(C20:P20)=0,"",IFERROR(Y20/Q20,0)) | AB20: =IF(COUNT(C20:P20)=0,"",IFERROR(H20/D20*1000,0)) | AC20: =IF(COUNT(C20:P20)=0,"",IFERROR(J20/H20,0)) | AD20: =IF(COUNT(C20:P20)=0,"",IFERROR(C20/J20,0)) | AE20: =IF(COUNT(C20:P20)=0,"",IFERROR(K20/H20,0)) | AF20: =IF(COUNT(C20:P20)=0,"",IFERROR(L20/H20,0)) | AG20: =IF(COUNT(C20:P20)=0,"",IFERROR(C20/K20,0)) | AH20: =IF(COUNT(C20:P20)=0,"",IFERROR(M20/K20,0)) | AI20: =IF(COUNT(C20:P20)=0,"",IFERROR(C20/M20,0)) | AJ20: =IF(COUNT(C20:P20)=0,"",IFERROR(N20/M20,0)) | AK20: =IF(COUNT(C20:P20)=0,"",IFERROR(N20/H20,0)) | AL20: =IF(COUNT(C20:P20)=0,"",IFERROR(C20/N20,0)) | AM20: =IF(COUNT(C20:P20)=0,"",IFERROR(O20/N20,0)) | AN20: =IF(COUNT(C20:P20)=0,"",IFERROR(P20/N20,0)) | AO20: =IF(COUNT(C20:P20)=0,"",IFERROR(N20*Config!$C$7+O20*Config!$C$8+P20*Config!$C$9,0)) | AP20: =IF(COUNT(C20:P20)=0,"",IFERROR(AO20/N20,0)) | AQ20: =IF(COUNT(C20:P20)=0,"",IFERROR(AO20*(1-Config!$C$10-Config!$C$11-Config!$C$12),0)) | AR20: =IF(COUNT(C20:P20)=0,"",IFERROR(AQ20-C20-Config!$C$13,0)) | AS20: =IF(COUNT(C20:P20)=0,"",IFERROR(AQ20/C20,0)) | AT20: =IF(COUNT(C20:P20)=0,"",IFERROR(AR20/G20,0)) | AU20: =IF(COUNT(C20:P20)=0,"",IFERROR(AT20/V20,0)) | AV20: =IF(COUNT(C20:P20)=0,"",IFERROR(AR20/H20,0))
A21: =Config!$C$6+15 | B21: =INT((A21-Config!$C$6)/7)+1 | C21: 948 | D21: 227112 | E21: 136646 | F21: 5455 | G21: 5031 | H21: 1135 | I21: 681 | J21: 761 | Q21: =IF(COUNT(C21:P21)=0,"",IFERROR(C21/D21*1000,0)) | R21: =IF(COUNT(C21:P21)=0,"",IFERROR(D21/E21,0)) | S21: =IF(COUNT(C21:P21)=0,"",IFERROR(F21/D21,0)) | T21: =IF(COUNT(C21:P21)=0,"",IFERROR(C21/F21,0)) | U21: =IF(COUNT(C21:P21)=0,"",IFERROR(G21/F21,0)) | V21: =IF(COUNT(C21:P21)=0,"",IFERROR(C21/G21,0)) | W21: =IF(COUNT(C21:P21)=0,"",IFERROR(G21/D21*1000,0)) | X21: =IF(COUNT(C21:P21)=0,"",IFERROR(H21/G21,0)) | Y21: =IF(COUNT(C21:P21)=0,"",IFERROR(C21/H21,0)) | Z21: =IF(COUNT(C21:P21)=0,"",IFERROR(C21/I21,0)) | AA21: =IF(COUNT(C21:P21)=0,"",IFERROR(Y21/Q21,0)) | AB21: =IF(COUNT(C21:P21)=0,"",IFERROR(H21/D21*1000,0)) | AC21: =IF(COUNT(C21:P21)=0,"",IFERROR(J21/H21,0)) | AD21: =IF(COUNT(C21:P21)=0,"",IFERROR(C21/J21,0)) | AE21: =IF(COUNT(C21:P21)=0,"",IFERROR(K21/H21,0)) | AF21: =IF(COUNT(C21:P21)=0,"",IFERROR(L21/H21,0)) | AG21: =IF(COUNT(C21:P21)=0,"",IFERROR(C21/K21,0)) | AH21: =IF(COUNT(C21:P21)=0,"",IFERROR(M21/K21,0)) | AI21: =IF(COUNT(C21:P21)=0,"",IFERROR(C21/M21,0)) | AJ21: =IF(COUNT(C21:P21)=0,"",IFERROR(N21/M21,0)) | AK21: =IF(COUNT(C21:P21)=0,"",IFERROR(N21/H21,0)) | AL21: =IF(COUNT(C21:P21)=0,"",IFERROR(C21/N21,0)) | AM21: =IF(COUNT(C21:P21)=0,"",IFERROR(O21/N21,0)) | AN21: =IF(COUNT(C21:P21)=0,"",IFERROR(P21/N21,0)) | AO21: =IF(COUNT(C21:P21)=0,"",IFERROR(N21*Config!$C$7+O21*Config!$C$8+P21*Config!$C$9,0)) | AP21: =IF(COUNT(C21:P21)=0,"",IFERROR(AO21/N21,0)) | AQ21: =IF(COUNT(C21:P21)=0,"",IFERROR(AO21*(1-Config!$C$10-Config!$C$11-Config!$C$12),0)) | AR21: =IF(COUNT(C21:P21)=0,"",IFERROR(AQ21-C21-Config!$C$13,0)) | AS21: =IF(COUNT(C21:P21)=0,"",IFERROR(AQ21/C21,0)) | AT21: =IF(COUNT(C21:P21)=0,"",IFERROR(AR21/G21,0)) | AU21: =IF(COUNT(C21:P21)=0,"",IFERROR(AT21/V21,0)) | AV21: =IF(COUNT(C21:P21)=0,"",IFERROR(AR21/H21,0))
A22: =Config!$C$6+16 | B22: =INT((A22-Config!$C$6)/7)+1 | C22: 762 | D22: 152433 | E22: 108430 | F22: 3518 | G22: 2982 | H22: 739 | I22: 443 | J22: 495 | Q22: =IF(COUNT(C22:P22)=0,"",IFERROR(C22/D22*1000,0)) | R22: =IF(COUNT(C22:P22)=0,"",IFERROR(D22/E22,0)) | S22: =IF(COUNT(C22:P22)=0,"",IFERROR(F22/D22,0)) | T22: =IF(COUNT(C22:P22)=0,"",IFERROR(C22/F22,0)) | U22: =IF(COUNT(C22:P22)=0,"",IFERROR(G22/F22,0)) | V22: =IF(COUNT(C22:P22)=0,"",IFERROR(C22/G22,0)) | W22: =IF(COUNT(C22:P22)=0,"",IFERROR(G22/D22*1000,0)) | X22: =IF(COUNT(C22:P22)=0,"",IFERROR(H22/G22,0)) | Y22: =IF(COUNT(C22:P22)=0,"",IFERROR(C22/H22,0)) | Z22: =IF(COUNT(C22:P22)=0,"",IFERROR(C22/I22,0)) | AA22: =IF(COUNT(C22:P22)=0,"",IFERROR(Y22/Q22,0)) | AB22: =IF(COUNT(C22:P22)=0,"",IFERROR(H22/D22*1000,0)) | AC22: =IF(COUNT(C22:P22)=0,"",IFERROR(J22/H22,0)) | AD22: =IF(COUNT(C22:P22)=0,"",IFERROR(C22/J22,0)) | AE22: =IF(COUNT(C22:P22)=0,"",IFERROR(K22/H22,0)) | AF22: =IF(COUNT(C22:P22)=0,"",IFERROR(L22/H22,0)) | AG22: =IF(COUNT(C22:P22)=0,"",IFERROR(C22/K22,0)) | AH22: =IF(COUNT(C22:P22)=0,"",IFERROR(M22/K22,0)) | AI22: =IF(COUNT(C22:P22)=0,"",IFERROR(C22/M22,0)) | AJ22: =IF(COUNT(C22:P22)=0,"",IFERROR(N22/M22,0)) | AK22: =IF(COUNT(C22:P22)=0,"",IFERROR(N22/H22,0)) | AL22: =IF(COUNT(C22:P22)=0,"",IFERROR(C22/N22,0)) | AM22: =IF(COUNT(C22:P22)=0,"",IFERROR(O22/N22,0)) | AN22: =IF(COUNT(C22:P22)=0,"",IFERROR(P22/N22,0)) | AO22: =IF(COUNT(C22:P22)=0,"",IFERROR(N22*Config!$C$7+O22*Config!$C$8+P22*Config!$C$9,0)) | AP22: =IF(COUNT(C22:P22)=0,"",IFERROR(AO22/N22,0)) | AQ22: =IF(COUNT(C22:P22)=0,"",IFERROR(AO22*(1-Config!$C$10-Config!$C$11-Config!$C$12),0)) | AR22: =IF(COUNT(C22:P22)=0,"",IFERROR(AQ22-C22-Config!$C$13,0)) | AS22: =IF(COUNT(C22:P22)=0,"",IFERROR(AQ22/C22,0)) | AT22: =IF(COUNT(C22:P22)=0,"",IFERROR(AR22/G22,0)) | AU22: =IF(COUNT(C22:P22)=0,"",IFERROR(AT22/V22,0)) | AV22: =IF(COUNT(C22:P22)=0,"",IFERROR(AR22/H22,0))
A23: =Config!$C$6+17 | B23: =INT((A23-Config!$C$6)/7)+1 | C23: 815 | D23: 196294 | E23: 124289 | F23: 3872 | G23: 3257 | H23: 760 | I23: 456 | J23: 509 | K23: 955 | L23: 1251 | M23: 91 | N23: 37 | O23: 7 | P23: 0 | Q23: =IF(COUNT(C23:P23)=0,"",IFERROR(C23/D23*1000,0)) | R23: =IF(COUNT(C23:P23)=0,"",IFERROR(D23/E23,0)) | S23: =IF(COUNT(C23:P23)=0,"",IFERROR(F23/D23,0)) | T23: =IF(COUNT(C23:P23)=0,"",IFERROR(C23/F23,0)) | U23: =IF(COUNT(C23:P23)=0,"",IFERROR(G23/F23,0)) | V23: =IF(COUNT(C23:P23)=0,"",IFERROR(C23/G23,0)) | W23: =IF(COUNT(C23:P23)=0,"",IFERROR(G23/D23*1000,0)) | X23: =IF(COUNT(C23:P23)=0,"",IFERROR(H23/G23,0)) | Y23: =IF(COUNT(C23:P23)=0,"",IFERROR(C23/H23,0)) | Z23: =IF(COUNT(C23:P23)=0,"",IFERROR(C23/I23,0)) | AA23: =IF(COUNT(C23:P23)=0,"",IFERROR(Y23/Q23,0)) | AB23: =IF(COUNT(C23:P23)=0,"",IFERROR(H23/D23*1000,0)) | AC23: =IF(COUNT(C23:P23)=0,"",IFERROR(J23/H23,0)) | AD23: =IF(COUNT(C23:P23)=0,"",IFERROR(C23/J23,0)) | AE23: =IF(COUNT(C23:P23)=0,"",IFERROR(K23/H23,0)) | AF23: =IF(COUNT(C23:P23)=0,"",IFERROR(L23/H23,0)) | AG23: =IF(COUNT(C23:P23)=0,"",IFERROR(C23/K23,0)) | AH23: =IF(COUNT(C23:P23)=0,"",IFERROR(M23/K23,0)) | AI23: =IF(COUNT(C23:P23)=0,"",IFERROR(C23/M23,0)) | AJ23: =IF(COUNT(C23:P23)=0,"",IFERROR(N23/M23,0)) | AK23: =IF(COUNT(C23:P23)=0,"",IFERROR(N23/H23,0)) | AL23: =IF(COUNT(C23:P23)=0,"",IFERROR(C23/N23,0)) | AM23: =IF(COUNT(C23:P23)=0,"",IFERROR(O23/N23,0)) | AN23: =IF(COUNT(C23:P23)=0,"",IFERROR(P23/N23,0)) | AO23: =IF(COUNT(C23:P23)=0,"",IFERROR(N23*Config!$C$7+O23*Config!$C$8+P23*Config!$C$9,0)) | AP23: =IF(COUNT(C23:P23)=0,"",IFERROR(AO23/N23,0)) | AQ23: =IF(COUNT(C23:P23)=0,"",IFERROR(AO23*(1-Config!$C$10-Config!$C$11-Config!$C$12),0)) | AR23: =IF(COUNT(C23:P23)=0,"",IFERROR(AQ23-C23-Config!$C$13,0)) | AS23: =IF(COUNT(C23:P23)=0,"",IFERROR(AQ23/C23,0)) | AT23: =IF(COUNT(C23:P23)=0,"",IFERROR(AR23/G23,0)) | AU23: =IF(COUNT(C23:P23)=0,"",IFERROR(AT23/V23,0)) | AV23: =IF(COUNT(C23:P23)=0,"",IFERROR(AR23/H23,0))
A24: =Config!$C$6+18 | B24: =INT((A24-Config!$C$6)/7)+1 | C24: 943 | D24: 225544 | E24: 170098 | F24: 4687 | G24: 4163 | H24: 857 | I24: 514 | J24: 574 | L24: 1442 | M24: 83 | N24: 33 | O24: 7 | P24: 2 | Q24: =IF(COUNT(C24:P24)=0,"",IFERROR(C24/D24*1000,0)) | R24: =IF(COUNT(C24:P24)=0,"",IFERROR(D24/E24,0)) | S24: =IF(COUNT(C24:P24)=0,"",IFERROR(F24/D24,0)) | T24: =IF(COUNT(C24:P24)=0,"",IFERROR(C24/F24,0)) | U24: =IF(COUNT(C24:P24)=0,"",IFERROR(G24/F24,0)) | V24: =IF(COUNT(C24:P24)=0,"",IFERROR(C24/G24,0)) | W24: =IF(COUNT(C24:P24)=0,"",IFERROR(G24/D24*1000,0)) | X24: =IF(COUNT(C24:P24)=0,"",IFERROR(H24/G24,0)) | Y24: =IF(COUNT(C24:P24)=0,"",IFERROR(C24/H24,0)) | Z24: =IF(COUNT(C24:P24)=0,"",IFERROR(C24/I24,0)) | AA24: =IF(COUNT(C24:P24)=0,"",IFERROR(Y24/Q24,0)) | AB24: =IF(COUNT(C24:P24)=0,"",IFERROR(H24/D24*1000,0)) | AC24: =IF(COUNT(C24:P24)=0,"",IFERROR(J24/H24,0)) | AD24: =IF(COUNT(C24:P24)=0,"",IFERROR(C24/J24,0)) | AE24: =IF(COUNT(C24:P24)=0,"",IFERROR(K24/H24,0)) | AF24: =IF(COUNT(C24:P24)=0,"",IFERROR(L24/H24,0)) | AG24: =IF(COUNT(C24:P24)=0,"",IFERROR(C24/K24,0)) | AH24: =IF(COUNT(C24:P24)=0,"",IFERROR(M24/K24,0)) | AI24: =IF(COUNT(C24:P24)=0,"",IFERROR(C24/M24,0)) | AJ24: =IF(COUNT(C24:P24)=0,"",IFERROR(N24/M24,0)) | AK24: =IF(COUNT(C24:P24)=0,"",IFERROR(N24/H24,0)) | AL24: =IF(COUNT(C24:P24)=0,"",IFERROR(C24/N24,0)) | AM24: =IF(COUNT(C24:P24)=0,"",IFERROR(O24/N24,0)) | AN24: =IF(COUNT(C24:P24)=0,"",IFERROR(P24/N24,0)) | AO24: =IF(COUNT(C24:P24)=0,"",IFERROR(N24*Config!$C$7+O24*Config!$C$8+P24*Config!$C$9,0)) | AP24: =IF(COUNT(C24:P24)=0,"",IFERROR(AO24/N24,0)) | AQ24: =IF(COUNT(C24:P24)=0,"",IFERROR(AO24*(1-Config!$C$10-Config!$C$11-Config!$C$12),0)) | AR24: =IF(COUNT(C24:P24)=0,"",IFERROR(AQ24-C24-Config!$C$13,0)) | AS24: =IF(COUNT(C24:P24)=0,"",IFERROR(AQ24/C24,0)) | AT24: =IF(COUNT(C24:P24)=0,"",IFERROR(AR24/G24,0)) | AU24: =IF(COUNT(C24:P24)=0,"",IFERROR(AT24/V24,0)) | AV24: =IF(COUNT(C24:P24)=0,"",IFERROR(AR24/H24,0))
A25: =Config!$C$6+19 | B25: =INT((A25-Config!$C$6)/7)+1 | C25: 872 | D25: 212536 | E25: 146539 | F25: 5114 | G25: 5134 | H25: 1225 | I25: 735 | J25: 821 | L25: 614 | M25: 35 | N25: 14 | O25: 3 | P25: 1 | Q25: =IF(COUNT(C25:P25)=0,"",IFERROR(C25/D25*1000,0)) | R25: =IF(COUNT(C25:P25)=0,"",IFERROR(D25/E25,0)) | S25: =IF(COUNT(C25:P25)=0,"",IFERROR(F25/D25,0)) | T25: =IF(COUNT(C25:P25)=0,"",IFERROR(C25/F25,0)) | U25: =IF(COUNT(C25:P25)=0,"",IFERROR(G25/F25,0)) | V25: =IF(COUNT(C25:P25)=0,"",IFERROR(C25/G25,0)) | W25: =IF(COUNT(C25:P25)=0,"",IFERROR(G25/D25*1000,0)) | X25: =IF(COUNT(C25:P25)=0,"",IFERROR(H25/G25,0)) | Y25: =IF(COUNT(C25:P25)=0,"",IFERROR(C25/H25,0)) | Z25: =IF(COUNT(C25:P25)=0,"",IFERROR(C25/I25,0)) | AA25: =IF(COUNT(C25:P25)=0,"",IFERROR(Y25/Q25,0)) | AB25: =IF(COUNT(C25:P25)=0,"",IFERROR(H25/D25*1000,0)) | AC25: =IF(COUNT(C25:P25)=0,"",IFERROR(J25/H25,0)) | AD25: =IF(COUNT(C25:P25)=0,"",IFERROR(C25/J25,0)) | AE25: =IF(COUNT(C25:P25)=0,"",IFERROR(K25/H25,0)) | AF25: =IF(COUNT(C25:P25)=0,"",IFERROR(L25/H25,0)) | AG25: =IF(COUNT(C25:P25)=0,"",IFERROR(C25/K25,0)) | AH25: =IF(COUNT(C25:P25)=0,"",IFERROR(M25/K25,0)) | AI25: =IF(COUNT(C25:P25)=0,"",IFERROR(C25/M25,0)) | AJ25: =IF(COUNT(C25:P25)=0,"",IFERROR(N25/M25,0)) | AK25: =IF(COUNT(C25:P25)=0,"",IFERROR(N25/H25,0)) | AL25: =IF(COUNT(C25:P25)=0,"",IFERROR(C25/N25,0)) | AM25: =IF(COUNT(C25:P25)=0,"",IFERROR(O25/N25,0)) | AN25: =IF(COUNT(C25:P25)=0,"",IFERROR(P25/N25,0)) | AO25: =IF(COUNT(C25:P25)=0,"",IFERROR(N25*Config!$C$7+O25*Config!$C$8+P25*Config!$C$9,0)) | AP25: =IF(COUNT(C25:P25)=0,"",IFERROR(AO25/N25,0)) | AQ25: =IF(COUNT(C25:P25)=0,"",IFERROR(AO25*(1-Config!$C$10-Config!$C$11-Config!$C$12),0)) | AR25: =IF(COUNT(C25:P25)=0,"",IFERROR(AQ25-C25-Config!$C$13,0)) | AS25: =IF(COUNT(C25:P25)=0,"",IFERROR(AQ25/C25,0)) | AT25: =IF(COUNT(C25:P25)=0,"",IFERROR(AR25/G25,0)) | AU25: =IF(COUNT(C25:P25)=0,"",IFERROR(AT25/V25,0)) | AV25: =IF(COUNT(C25:P25)=0,"",IFERROR(AR25/H25,0))
A26: =Config!$C$6+20 | B26: =INT((A26-Config!$C$6)/7)+1 | C26: 783 | D26: 195860 | E26: 147658 | F26: 4733 | G26: 4465 | H26: 1141 | I26: 685 | J26: 765 | Q26: =IF(COUNT(C26:P26)=0,"",IFERROR(C26/D26*1000,0)) | R26: =IF(COUNT(C26:P26)=0,"",IFERROR(D26/E26,0)) | S26: =IF(COUNT(C26:P26)=0,"",IFERROR(F26/D26,0)) | T26: =IF(COUNT(C26:P26)=0,"",IFERROR(C26/F26,0)) | U26: =IF(COUNT(C26:P26)=0,"",IFERROR(G26/F26,0)) | V26: =IF(COUNT(C26:P26)=0,"",IFERROR(C26/G26,0)) | W26: =IF(COUNT(C26:P26)=0,"",IFERROR(G26/D26*1000,0)) | X26: =IF(COUNT(C26:P26)=0,"",IFERROR(H26/G26,0)) | Y26: =IF(COUNT(C26:P26)=0,"",IFERROR(C26/H26,0)) | Z26: =IF(COUNT(C26:P26)=0,"",IFERROR(C26/I26,0)) | AA26: =IF(COUNT(C26:P26)=0,"",IFERROR(Y26/Q26,0)) | AB26: =IF(COUNT(C26:P26)=0,"",IFERROR(H26/D26*1000,0)) | AC26: =IF(COUNT(C26:P26)=0,"",IFERROR(J26/H26,0)) | AD26: =IF(COUNT(C26:P26)=0,"",IFERROR(C26/J26,0)) | AE26: =IF(COUNT(C26:P26)=0,"",IFERROR(K26/H26,0)) | AF26: =IF(COUNT(C26:P26)=0,"",IFERROR(L26/H26,0)) | AG26: =IF(COUNT(C26:P26)=0,"",IFERROR(C26/K26,0)) | AH26: =IF(COUNT(C26:P26)=0,"",IFERROR(M26/K26,0)) | AI26: =IF(COUNT(C26:P26)=0,"",IFERROR(C26/M26,0)) | AJ26: =IF(COUNT(C26:P26)=0,"",IFERROR(N26/M26,0)) | AK26: =IF(COUNT(C26:P26)=0,"",IFERROR(N26/H26,0)) | AL26: =IF(COUNT(C26:P26)=0,"",IFERROR(C26/N26,0)) | AM26: =IF(COUNT(C26:P26)=0,"",IFERROR(O26/N26,0)) | AN26: =IF(COUNT(C26:P26)=0,"",IFERROR(P26/N26,0)) | AO26: =IF(COUNT(C26:P26)=0,"",IFERROR(N26*Config!$C$7+O26*Config!$C$8+P26*Config!$C$9,0)) | AP26: =IF(COUNT(C26:P26)=0,"",IFERROR(AO26/N26,0)) | AQ26: =IF(COUNT(C26:P26)=0,"",IFERROR(AO26*(1-Config!$C$10-Config!$C$11-Config!$C$12),0)) | AR26: =IF(COUNT(C26:P26)=0,"",IFERROR(AQ26-C26-Config!$C$13,0)) | AS26: =IF(COUNT(C26:P26)=0,"",IFERROR(AQ26/C26,0)) | AT26: =IF(COUNT(C26:P26)=0,"",IFERROR(AR26/G26,0)) | AU26: =IF(COUNT(C26:P26)=0,"",IFERROR(AT26/V26,0)) | AV26: =IF(COUNT(C26:P26)=0,"",IFERROR(AR26/H26,0))
A27: =Config!$C$6+21 | B27: =INT((A27-Config!$C$6)/7)+1 | C27: 885 | D27: 197511 | E27: 124772 | F27: 4156 | G27: 4189 | H27: 865 | I27: 519 | J27: 580 | Q27: =IF(COUNT(C27:P27)=0,"",IFERROR(C27/D27*1000,0)) | R27: =IF(COUNT(C27:P27)=0,"",IFERROR(D27/E27,0)) | S27: =IF(COUNT(C27:P27)=0,"",IFERROR(F27/D27,0)) | T27: =IF(COUNT(C27:P27)=0,"",IFERROR(C27/F27,0)) | U27: =IF(COUNT(C27:P27)=0,"",IFERROR(G27/F27,0)) | V27: =IF(COUNT(C27:P27)=0,"",IFERROR(C27/G27,0)) | W27: =IF(COUNT(C27:P27)=0,"",IFERROR(G27/D27*1000,0)) | X27: =IF(COUNT(C27:P27)=0,"",IFERROR(H27/G27,0)) | Y27: =IF(COUNT(C27:P27)=0,"",IFERROR(C27/H27,0)) | Z27: =IF(COUNT(C27:P27)=0,"",IFERROR(C27/I27,0)) | AA27: =IF(COUNT(C27:P27)=0,"",IFERROR(Y27/Q27,0)) | AB27: =IF(COUNT(C27:P27)=0,"",IFERROR(H27/D27*1000,0)) | AC27: =IF(COUNT(C27:P27)=0,"",IFERROR(J27/H27,0)) | AD27: =IF(COUNT(C27:P27)=0,"",IFERROR(C27/J27,0)) | AE27: =IF(COUNT(C27:P27)=0,"",IFERROR(K27/H27,0)) | AF27: =IF(COUNT(C27:P27)=0,"",IFERROR(L27/H27,0)) | AG27: =IF(COUNT(C27:P27)=0,"",IFERROR(C27/K27,0)) | AH27: =IF(COUNT(C27:P27)=0,"",IFERROR(M27/K27,0)) | AI27: =IF(COUNT(C27:P27)=0,"",IFERROR(C27/M27,0)) | AJ27: =IF(COUNT(C27:P27)=0,"",IFERROR(N27/M27,0)) | AK27: =IF(COUNT(C27:P27)=0,"",IFERROR(N27/H27,0)) | AL27: =IF(COUNT(C27:P27)=0,"",IFERROR(C27/N27,0)) | AM27: =IF(COUNT(C27:P27)=0,"",IFERROR(O27/N27,0)) | AN27: =IF(COUNT(C27:P27)=0,"",IFERROR(P27/N27,0)) | AO27: =IF(COUNT(C27:P27)=0,"",IFERROR(N27*Config!$C$7+O27*Config!$C$8+P27*Config!$C$9,0)) | AP27: =IF(COUNT(C27:P27)=0,"",IFERROR(AO27/N27,0)) | AQ27: =IF(COUNT(C27:P27)=0,"",IFERROR(AO27*(1-Config!$C$10-Config!$C$11-Config!$C$12),0)) | AR27: =IF(COUNT(C27:P27)=0,"",IFERROR(AQ27-C27-Config!$C$13,0)) | AS27: =IF(COUNT(C27:P27)=0,"",IFERROR(AQ27/C27,0)) | AT27: =IF(COUNT(C27:P27)=0,"",IFERROR(AR27/G27,0)) | AU27: =IF(COUNT(C27:P27)=0,"",IFERROR(AT27/V27,0)) | AV27: =IF(COUNT(C27:P27)=0,"",IFERROR(AR27/H27,0))
A28: =Config!$C$6+22 | B28: =INT((A28-Config!$C$6)/7)+1 | C28: 906 | D28: 183639 | E28: 115835 | F28: 4238 | G28: 4082 | H28: 1032 | I28: 619 | J28: 692 | Q28: =IF(COUNT(C28:P28)=0,"",IFERROR(C28/D28*1000,0)) | R28: =IF(COUNT(C28:P28)=0,"",IFERROR(D28/E28,0)) | S28: =IF(COUNT(C28:P28)=0,"",IFERROR(F28/D28,0)) | T28: =IF(COUNT(C28:P28)=0,"",IFERROR(C28/F28,0)) | U28: =IF(COUNT(C28:P28)=0,"",IFERROR(G28/F28,0)) | V28: =IF(COUNT(C28:P28)=0,"",IFERROR(C28/G28,0)) | W28: =IF(COUNT(C28:P28)=0,"",IFERROR(G28/D28*1000,0)) | X28: =IF(COUNT(C28:P28)=0,"",IFERROR(H28/G28,0)) | Y28: =IF(COUNT(C28:P28)=0,"",IFERROR(C28/H28,0)) | Z28: =IF(COUNT(C28:P28)=0,"",IFERROR(C28/I28,0)) | AA28: =IF(COUNT(C28:P28)=0,"",IFERROR(Y28/Q28,0)) | AB28: =IF(COUNT(C28:P28)=0,"",IFERROR(H28/D28*1000,0)) | AC28: =IF(COUNT(C28:P28)=0,"",IFERROR(J28/H28,0)) | AD28: =IF(COUNT(C28:P28)=0,"",IFERROR(C28/J28,0)) | AE28: =IF(COUNT(C28:P28)=0,"",IFERROR(K28/H28,0)) | AF28: =IF(COUNT(C28:P28)=0,"",IFERROR(L28/H28,0)) | AG28: =IF(COUNT(C28:P28)=0,"",IFERROR(C28/K28,0)) | AH28: =IF(COUNT(C28:P28)=0,"",IFERROR(M28/K28,0)) | AI28: =IF(COUNT(C28:P28)=0,"",IFERROR(C28/M28,0)) | AJ28: =IF(COUNT(C28:P28)=0,"",IFERROR(N28/M28,0)) | AK28: =IF(COUNT(C28:P28)=0,"",IFERROR(N28/H28,0)) | AL28: =IF(COUNT(C28:P28)=0,"",IFERROR(C28/N28,0)) | AM28: =IF(COUNT(C28:P28)=0,"",IFERROR(O28/N28,0)) | AN28: =IF(COUNT(C28:P28)=0,"",IFERROR(P28/N28,0)) | AO28: =IF(COUNT(C28:P28)=0,"",IFERROR(N28*Config!$C$7+O28*Config!$C$8+P28*Config!$C$9,0)) | AP28: =IF(COUNT(C28:P28)=0,"",IFERROR(AO28/N28,0)) | AQ28: =IF(COUNT(C28:P28)=0,"",IFERROR(AO28*(1-Config!$C$10-Config!$C$11-Config!$C$12),0)) | AR28: =IF(COUNT(C28:P28)=0,"",IFERROR(AQ28-C28-Config!$C$13,0)) | AS28: =IF(COUNT(C28:P28)=0,"",IFERROR(AQ28/C28,0)) | AT28: =IF(COUNT(C28:P28)=0,"",IFERROR(AR28/G28,0)) | AU28: =IF(COUNT(C28:P28)=0,"",IFERROR(AT28/V28,0)) | AV28: =IF(COUNT(C28:P28)=0,"",IFERROR(AR28/H28,0))
A29: =Config!$C$6+23 | B29: =INT((A29-Config!$C$6)/7)+1 | C29: 895 | D29: 181451 | E29: 111075 | F29: 3913 | G29: 3767 | H29: 942 | I29: 565 | J29: 631 | Q29: =IF(COUNT(C29:P29)=0,"",IFERROR(C29/D29*1000,0)) | R29: =IF(COUNT(C29:P29)=0,"",IFERROR(D29/E29,0)) | S29: =IF(COUNT(C29:P29)=0,"",IFERROR(F29/D29,0)) | T29: =IF(COUNT(C29:P29)=0,"",IFERROR(C29/F29,0)) | U29: =IF(COUNT(C29:P29)=0,"",IFERROR(G29/F29,0)) | V29: =IF(COUNT(C29:P29)=0,"",IFERROR(C29/G29,0)) | W29: =IF(COUNT(C29:P29)=0,"",IFERROR(G29/D29*1000,0)) | X29: =IF(COUNT(C29:P29)=0,"",IFERROR(H29/G29,0)) | Y29: =IF(COUNT(C29:P29)=0,"",IFERROR(C29/H29,0)) | Z29: =IF(COUNT(C29:P29)=0,"",IFERROR(C29/I29,0)) | AA29: =IF(COUNT(C29:P29)=0,"",IFERROR(Y29/Q29,0)) | AB29: =IF(COUNT(C29:P29)=0,"",IFERROR(H29/D29*1000,0)) | AC29: =IF(COUNT(C29:P29)=0,"",IFERROR(J29/H29,0)) | AD29: =IF(COUNT(C29:P29)=0,"",IFERROR(C29/J29,0)) | AE29: =IF(COUNT(C29:P29)=0,"",IFERROR(K29/H29,0)) | AF29: =IF(COUNT(C29:P29)=0,"",IFERROR(L29/H29,0)) | AG29: =IF(COUNT(C29:P29)=0,"",IFERROR(C29/K29,0)) | AH29: =IF(COUNT(C29:P29)=0,"",IFERROR(M29/K29,0)) | AI29: =IF(COUNT(C29:P29)=0,"",IFERROR(C29/M29,0)) | AJ29: =IF(COUNT(C29:P29)=0,"",IFERROR(N29/M29,0)) | AK29: =IF(COUNT(C29:P29)=0,"",IFERROR(N29/H29,0)) | AL29: =IF(COUNT(C29:P29)=0,"",IFERROR(C29/N29,0)) | AM29: =IF(COUNT(C29:P29)=0,"",IFERROR(O29/N29,0)) | AN29: =IF(COUNT(C29:P29)=0,"",IFERROR(P29/N29,0)) | AO29: =IF(COUNT(C29:P29)=0,"",IFERROR(N29*Config!$C$7+O29*Config!$C$8+P29*Config!$C$9,0)) | AP29: =IF(COUNT(C29:P29)=0,"",IFERROR(AO29/N29,0)) | AQ29: =IF(COUNT(C29:P29)=0,"",IFERROR(AO29*(1-Config!$C$10-Config!$C$11-Config!$C$12),0)) | AR29: =IF(COUNT(C29:P29)=0,"",IFERROR(AQ29-C29-Config!$C$13,0)) | AS29: =IF(COUNT(C29:P29)=0,"",IFERROR(AQ29/C29,0)) | AT29: =IF(COUNT(C29:P29)=0,"",IFERROR(AR29/G29,0)) | AU29: =IF(COUNT(C29:P29)=0,"",IFERROR(AT29/V29,0)) | AV29: =IF(COUNT(C29:P29)=0,"",IFERROR(AR29/H29,0))
A30: =Config!$C$6+24 | B30: =INT((A30-Config!$C$6)/7)+1 | C30: 883 | D30: 201856 | E30: 131953 | F30: 4557 | G30: 3688 | H30: 877 | I30: 526 | J30: 587 | K30: 1011 | L30: 1271 | M30: 106 | N30: 42 | O30: 8 | P30: 0 | Q30: =IF(COUNT(C30:P30)=0,"",IFERROR(C30/D30*1000,0)) | R30: =IF(COUNT(C30:P30)=0,"",IFERROR(D30/E30,0)) | S30: =IF(COUNT(C30:P30)=0,"",IFERROR(F30/D30,0)) | T30: =IF(COUNT(C30:P30)=0,"",IFERROR(C30/F30,0)) | U30: =IF(COUNT(C30:P30)=0,"",IFERROR(G30/F30,0)) | V30: =IF(COUNT(C30:P30)=0,"",IFERROR(C30/G30,0)) | W30: =IF(COUNT(C30:P30)=0,"",IFERROR(G30/D30*1000,0)) | X30: =IF(COUNT(C30:P30)=0,"",IFERROR(H30/G30,0)) | Y30: =IF(COUNT(C30:P30)=0,"",IFERROR(C30/H30,0)) | Z30: =IF(COUNT(C30:P30)=0,"",IFERROR(C30/I30,0)) | AA30: =IF(COUNT(C30:P30)=0,"",IFERROR(Y30/Q30,0)) | AB30: =IF(COUNT(C30:P30)=0,"",IFERROR(H30/D30*1000,0)) | AC30: =IF(COUNT(C30:P30)=0,"",IFERROR(J30/H30,0)) | AD30: =IF(COUNT(C30:P30)=0,"",IFERROR(C30/J30,0)) | AE30: =IF(COUNT(C30:P30)=0,"",IFERROR(K30/H30,0)) | AF30: =IF(COUNT(C30:P30)=0,"",IFERROR(L30/H30,0)) | AG30: =IF(COUNT(C30:P30)=0,"",IFERROR(C30/K30,0)) | AH30: =IF(COUNT(C30:P30)=0,"",IFERROR(M30/K30,0)) | AI30: =IF(COUNT(C30:P30)=0,"",IFERROR(C30/M30,0)) | AJ30: =IF(COUNT(C30:P30)=0,"",IFERROR(N30/M30,0)) | AK30: =IF(COUNT(C30:P30)=0,"",IFERROR(N30/H30,0)) | AL30: =IF(COUNT(C30:P30)=0,"",IFERROR(C30/N30,0)) | AM30: =IF(COUNT(C30:P30)=0,"",IFERROR(O30/N30,0)) | AN30: =IF(COUNT(C30:P30)=0,"",IFERROR(P30/N30,0)) | AO30: =IF(COUNT(C30:P30)=0,"",IFERROR(N30*Config!$C$7+O30*Config!$C$8+P30*Config!$C$9,0)) | AP30: =IF(COUNT(C30:P30)=0,"",IFERROR(AO30/N30,0)) | AQ30: =IF(COUNT(C30:P30)=0,"",IFERROR(AO30*(1-Config!$C$10-Config!$C$11-Config!$C$12),0)) | AR30: =IF(COUNT(C30:P30)=0,"",IFERROR(AQ30-C30-Config!$C$13,0)) | AS30: =IF(COUNT(C30:P30)=0,"",IFERROR(AQ30/C30,0)) | AT30: =IF(COUNT(C30:P30)=0,"",IFERROR(AR30/G30,0)) | AU30: =IF(COUNT(C30:P30)=0,"",IFERROR(AT30/V30,0)) | AV30: =IF(COUNT(C30:P30)=0,"",IFERROR(AR30/H30,0))
A31: =Config!$C$6+25 | B31: =INT((A31-Config!$C$6)/7)+1 | C31: 834 | D31: 175448 | E31: 114736 | F31: 3805 | G31: 3702 | H31: 766 | I31: 460 | J31: 514 | L31: 1545 | M31: 80 | N31: 32 | O31: 6 | P31: 2 | Q31: =IF(COUNT(C31:P31)=0,"",IFERROR(C31/D31*1000,0)) | R31: =IF(COUNT(C31:P31)=0,"",IFERROR(D31/E31,0)) | S31: =IF(COUNT(C31:P31)=0,"",IFERROR(F31/D31,0)) | T31: =IF(COUNT(C31:P31)=0,"",IFERROR(C31/F31,0)) | U31: =IF(COUNT(C31:P31)=0,"",IFERROR(G31/F31,0)) | V31: =IF(COUNT(C31:P31)=0,"",IFERROR(C31/G31,0)) | W31: =IF(COUNT(C31:P31)=0,"",IFERROR(G31/D31*1000,0)) | X31: =IF(COUNT(C31:P31)=0,"",IFERROR(H31/G31,0)) | Y31: =IF(COUNT(C31:P31)=0,"",IFERROR(C31/H31,0)) | Z31: =IF(COUNT(C31:P31)=0,"",IFERROR(C31/I31,0)) | AA31: =IF(COUNT(C31:P31)=0,"",IFERROR(Y31/Q31,0)) | AB31: =IF(COUNT(C31:P31)=0,"",IFERROR(H31/D31*1000,0)) | AC31: =IF(COUNT(C31:P31)=0,"",IFERROR(J31/H31,0)) | AD31: =IF(COUNT(C31:P31)=0,"",IFERROR(C31/J31,0)) | AE31: =IF(COUNT(C31:P31)=0,"",IFERROR(K31/H31,0)) | AF31: =IF(COUNT(C31:P31)=0,"",IFERROR(L31/H31,0)) | AG31: =IF(COUNT(C31:P31)=0,"",IFERROR(C31/K31,0)) | AH31: =IF(COUNT(C31:P31)=0,"",IFERROR(M31/K31,0)) | AI31: =IF(COUNT(C31:P31)=0,"",IFERROR(C31/M31,0)) | AJ31: =IF(COUNT(C31:P31)=0,"",IFERROR(N31/M31,0)) | AK31: =IF(COUNT(C31:P31)=0,"",IFERROR(N31/H31,0)) | AL31: =IF(COUNT(C31:P31)=0,"",IFERROR(C31/N31,0)) | AM31: =IF(COUNT(C31:P31)=0,"",IFERROR(O31/N31,0)) | AN31: =IF(COUNT(C31:P31)=0,"",IFERROR(P31/N31,0)) | AO31: =IF(COUNT(C31:P31)=0,"",IFERROR(N31*Config!$C$7+O31*Config!$C$8+P31*Config!$C$9,0)) | AP31: =IF(COUNT(C31:P31)=0,"",IFERROR(AO31/N31,0)) | AQ31: =IF(COUNT(C31:P31)=0,"",IFERROR(AO31*(1-Config!$C$10-Config!$C$11-Config!$C$12),0)) | AR31: =IF(COUNT(C31:P31)=0,"",IFERROR(AQ31-C31-Config!$C$13,0)) | AS31: =IF(COUNT(C31:P31)=0,"",IFERROR(AQ31/C31,0)) | AT31: =IF(COUNT(C31:P31)=0,"",IFERROR(AR31/G31,0)) | AU31: =IF(COUNT(C31:P31)=0,"",IFERROR(AT31/V31,0)) | AV31: =IF(COUNT(C31:P31)=0,"",IFERROR(AR31/H31,0))
A32: =Config!$C$6+26 | B32: =INT((A32-Config!$C$6)/7)+1 | C32: 878 | D32: 195970 | E32: 139691 | F32: 4517 | G32: 4062 | H32: 960 | I32: 576 | J32: 643 | L32: 630 | M32: 32 | N32: 13 | O32: 3 | P32: 1 | Q32: =IF(COUNT(C32:P32)=0,"",IFERROR(C32/D32*1000,0)) | R32: =IF(COUNT(C32:P32)=0,"",IFERROR(D32/E32,0)) | S32: =IF(COUNT(C32:P32)=0,"",IFERROR(F32/D32,0)) | T32: =IF(COUNT(C32:P32)=0,"",IFERROR(C32/F32,0)) | U32: =IF(COUNT(C32:P32)=0,"",IFERROR(G32/F32,0)) | V32: =IF(COUNT(C32:P32)=0,"",IFERROR(C32/G32,0)) | W32: =IF(COUNT(C32:P32)=0,"",IFERROR(G32/D32*1000,0)) | X32: =IF(COUNT(C32:P32)=0,"",IFERROR(H32/G32,0)) | Y32: =IF(COUNT(C32:P32)=0,"",IFERROR(C32/H32,0)) | Z32: =IF(COUNT(C32:P32)=0,"",IFERROR(C32/I32,0)) | AA32: =IF(COUNT(C32:P32)=0,"",IFERROR(Y32/Q32,0)) | AB32: =IF(COUNT(C32:P32)=0,"",IFERROR(H32/D32*1000,0)) | AC32: =IF(COUNT(C32:P32)=0,"",IFERROR(J32/H32,0)) | AD32: =IF(COUNT(C32:P32)=0,"",IFERROR(C32/J32,0)) | AE32: =IF(COUNT(C32:P32)=0,"",IFERROR(K32/H32,0)) | AF32: =IF(COUNT(C32:P32)=0,"",IFERROR(L32/H32,0)) | AG32: =IF(COUNT(C32:P32)=0,"",IFERROR(C32/K32,0)) | AH32: =IF(COUNT(C32:P32)=0,"",IFERROR(M32/K32,0)) | AI32: =IF(COUNT(C32:P32)=0,"",IFERROR(C32/M32,0)) | AJ32: =IF(COUNT(C32:P32)=0,"",IFERROR(N32/M32,0)) | AK32: =IF(COUNT(C32:P32)=0,"",IFERROR(N32/H32,0)) | AL32: =IF(COUNT(C32:P32)=0,"",IFERROR(C32/N32,0)) | AM32: =IF(COUNT(C32:P32)=0,"",IFERROR(O32/N32,0)) | AN32: =IF(COUNT(C32:P32)=0,"",IFERROR(P32/N32,0)) | AO32: =IF(COUNT(C32:P32)=0,"",IFERROR(N32*Config!$C$7+O32*Config!$C$8+P32*Config!$C$9,0)) | AP32: =IF(COUNT(C32:P32)=0,"",IFERROR(AO32/N32,0)) | AQ32: =IF(COUNT(C32:P32)=0,"",IFERROR(AO32*(1-Config!$C$10-Config!$C$11-Config!$C$12),0)) | AR32: =IF(COUNT(C32:P32)=0,"",IFERROR(AQ32-C32-Config!$C$13,0)) | AS32: =IF(COUNT(C32:P32)=0,"",IFERROR(AQ32/C32,0)) | AT32: =IF(COUNT(C32:P32)=0,"",IFERROR(AR32/G32,0)) | AU32: =IF(COUNT(C32:P32)=0,"",IFERROR(AT32/V32,0)) | AV32: =IF(COUNT(C32:P32)=0,"",IFERROR(AR32/H32,0))
A33: =Config!$C$6+27 | B33: =INT((A33-Config!$C$6)/7)+1 | C33: 756 | D33: 176538 | E33: 112867 | F33: 3607 | G33: 2989 | H33: 754 | I33: 453 | J33: 505 | Q33: =IF(COUNT(C33:P33)=0,"",IFERROR(C33/D33*1000,0)) | R33: =IF(COUNT(C33:P33)=0,"",IFERROR(D33/E33,0)) | S33: =IF(COUNT(C33:P33)=0,"",IFERROR(F33/D33,0)) | T33: =IF(COUNT(C33:P33)=0,"",IFERROR(C33/F33,0)) | U33: =IF(COUNT(C33:P33)=0,"",IFERROR(G33/F33,0)) | V33: =IF(COUNT(C33:P33)=0,"",IFERROR(C33/G33,0)) | W33: =IF(COUNT(C33:P33)=0,"",IFERROR(G33/D33*1000,0)) | X33: =IF(COUNT(C33:P33)=0,"",IFERROR(H33/G33,0)) | Y33: =IF(COUNT(C33:P33)=0,"",IFERROR(C33/H33,0)) | Z33: =IF(COUNT(C33:P33)=0,"",IFERROR(C33/I33,0)) | AA33: =IF(COUNT(C33:P33)=0,"",IFERROR(Y33/Q33,0)) | AB33: =IF(COUNT(C33:P33)=0,"",IFERROR(H33/D33*1000,0)) | AC33: =IF(COUNT(C33:P33)=0,"",IFERROR(J33/H33,0)) | AD33: =IF(COUNT(C33:P33)=0,"",IFERROR(C33/J33,0)) | AE33: =IF(COUNT(C33:P33)=0,"",IFERROR(K33/H33,0)) | AF33: =IF(COUNT(C33:P33)=0,"",IFERROR(L33/H33,0)) | AG33: =IF(COUNT(C33:P33)=0,"",IFERROR(C33/K33,0)) | AH33: =IF(COUNT(C33:P33)=0,"",IFERROR(M33/K33,0)) | AI33: =IF(COUNT(C33:P33)=0,"",IFERROR(C33/M33,0)) | AJ33: =IF(COUNT(C33:P33)=0,"",IFERROR(N33/M33,0)) | AK33: =IF(COUNT(C33:P33)=0,"",IFERROR(N33/H33,0)) | AL33: =IF(COUNT(C33:P33)=0,"",IFERROR(C33/N33,0)) | AM33: =IF(COUNT(C33:P33)=0,"",IFERROR(O33/N33,0)) | AN33: =IF(COUNT(C33:P33)=0,"",IFERROR(P33/N33,0)) | AO33: =IF(COUNT(C33:P33)=0,"",IFERROR(N33*Config!$C$7+O33*Config!$C$8+P33*Config!$C$9,0)) | AP33: =IF(COUNT(C33:P33)=0,"",IFERROR(AO33/N33,0)) | AQ33: =IF(COUNT(C33:P33)=0,"",IFERROR(AO33*(1-Config!$C$10-Config!$C$11-Config!$C$12),0)) | AR33: =IF(COUNT(C33:P33)=0,"",IFERROR(AQ33-C33-Config!$C$13,0)) | AS33: =IF(COUNT(C33:P33)=0,"",IFERROR(AQ33/C33,0)) | AT33: =IF(COUNT(C33:P33)=0,"",IFERROR(AR33/G33,0)) | AU33: =IF(COUNT(C33:P33)=0,"",IFERROR(AT33/V33,0)) | AV33: =IF(COUNT(C33:P33)=0,"",IFERROR(AR33/H33,0))
