Workbook
Name Autor_Jesus_Tassarolo: "Modelo financiero de embudos · creado por Jesús Tassarolo · TooAudience · youtube.com/@JesusTassaroloSinFiltro"

Sheet Inicio
B1: © Jesús Tassarolo · TooAudience · youtube.com/@JesusTassaroloSinFiltro · uso personal; no redistribuir modificado
B2: Métricas diarias · Embudo de llamada (high ticket)
B3: Las métricas diarias de todo el embudo, para saber cómo estás con tus propios números. Acompaña al modelo financiero del mismo embudo.
B5: Qué es
B6: Un registro diario de cada paso del embudo (anuncios, página, unidades, etapas, ventas, cash) que se convierte solo en un comparativo semanal y en un resumen con semáforo. El semáforo no usa números de mercado: compara cada semana con la mediana de tus 4 semanas anteriores, con una tolerancia del 25 % (la cambiás en Config).
B8: 1. Config
B9: Poné tus precios, comisiones, reembolsos, costos fijos por día y la fecha de inicio (un lunes). Todo lo demás se calcula con eso.
B11: 2. Diario (todos los días, 3 minutos)
B12: Una fila por día. Cargá las celdas amarillas con lo que hubo: inversión, impresiones, alcance, clics en el enlace, visitas y cada paso del embudo. Si un día no hubo evento, dejá vacío. Las celdas azules se calculan solas (CPM, CTR, costo por visita, CPL, conversiones, facturado, cash neto, ganancia, ROAS y la ganancia por visita).
B14: 3. Semanal (los lunes, 10 minutos)
B15: No se carga nada: suma Diario por semana y calcula las conversiones y los costos de la semana, el promedio, la mediana, la mejor y la peor. Abajo, el bloque «contra tu promedio» marca en verde, amarillo o rojo cada métrica clave contra la mediana de tus 4 semanas anteriores.
B17: 4. Resumen
... B36: Modelo financiero de embudos · creado por Jesús Tassarolo · TooAudience · youtube.com/@JesusTassaroloSinFiltro · v1.2 · octubre 2026

Sheet Config
B1: © Jesús Tassarolo · TooAudience · youtube.com/@JesusTassaroloSinFiltro · uso personal; no redistribuir modificado
B2: Config: tus precios, comisiones y la fecha de inicio
B3: Amarillo = podés cambiarlo. Todo lo demás del libro se calcula con esto.
B5: Dato | C5: Valor | D5: Nota
B6: Fecha de inicio del registro (un lunes) | C6: 46272 | D6: Desde este día se numeran las semanas en Diario y Semanal. Elegí un lunes.
B7: Precio del programa (ticket) | C7: 1500 | D7: A precio de lista; las cuotas van en el cash cobrado.
B8: Precio del downsell | C8: 497
B9: % del facturado que entra el primer mes (si no cargás el cash cobrado) | C9: 0.6 | D9: Se usa solo cuando la columna de cash cobrado está vacía.
B10: Comisión de la pasarela de pago | C10: 0.05
B11: Comisión del equipo de ventas | C11: 0.1 | D11: Sobre lo cobrado.
B12: Reembolsos y contracargos | C12: 0.05
B13: Costos fijos por día (USD) | C13: 83 | D13: 2.500 por mes ÷ 30.
B14: ROAS objetivo sobre cash neto | C14: 2.5 | D14: En llamada, 2,5 a 3 por la varianza.
B15: Tolerancia del semáforo contra tu promedio | C15: 0.25 | D15: Igual o mejor que tu mediana = verde; hasta esta distancia peor = amarillo; más = rojo. 20 a 30 %.
A18: Modelo financiero de embudos · creado por Jesús Tassarolo · TooAudience · youtube.com/@JesusTassaroloSinFiltro · v1.2 · octubre 2026

Sheet Diario
A1: © Jesús Tassarolo · TooAudience · youtube.com/@JesusTassaroloSinFiltro · uso personal; no redistribuir modificado
A2: Diario: una fila por día. Amarillo = lo que cargás; azul = lo que calcula el libro
A3: Cargá cada día lo que hubo (vacío si no hubo). Los porcentajes de un solo día pueden ser raros en embudos con evento semanal: la lectura buena está en Semanal.
A5: Fecha | B5: Semana | C5: Inversión en publicidad (USD) | D5: Impresiones | E5: Alcance (personas únicas) | F5: Clics en el enlace | G5: Visitas a la página | H5: Leads | I5: Completan la aplicación | J5: Califican | K5: Agendan la llamada | L5: Llamadas realizadas (show) | M5: Compran el programa | N5: Toman el downsell | O5: Cash cobrado ese día (USD) | P5: CPM | Q5: Frecuencia | R5: CTR al enlace | S5: CPC (por clic en el enlace) | T5: % clic → visita | U5: Costo por visita | V5: Visitas por cada 1.000 impresiones | W5: % visita → lead (conversión de la página) | X5: CPL (costo por lead) | Y5: CPL como % del CPM (el umbral depende del nicho) | Z5: Leads por cada 1.000 impresiones | AA5: % lead → aplicación | AB5: % aplicación → calificado | AC5: % calificado → agenda | AD5: Costo por agenda | AE5: % agenda → llamada (show) | AF5: % llamada → venta (cierre) | AG5: % lead → venta | AH5: CAC (costo por venta) | AI5: Facturado a precio de lista | AJ5: Cash cobrado (real, o estimado con el % del primer mes) | AK5: Cash neto (después de comisiones, closers y reembolsos) | AL5: Ganancia de caja (cash neto − pauta − fijos) | AM5: ROAS sobre cash neto | AN5: ROAS sobre facturado (no decidas con este) | AO5: Ganancia por visita (la métrica más valiosa) | AP5: Margen por visita (ganancia por visita ÷ costo por visita) | AQ5: Ganancia por lead
A6: =Config!$C$6+0 | B6: =INT((A6-Config!$C$6)/7)+1 | C6: 148 | D6: 14619 | E6: 9477 | F6: 217 | G6: 185 | H6: 53 | I6: 4 | J6: 3 | K6: 2 | L6: 1 | M6: 0 | N6: 0 | O6: 0 | P6: =IF(COUNT(C6:O6)=0,"",IFERROR(C6/D6*1000,0)) | Q6: =IF(COUNT(C6:O6)=0,"",IFERROR(D6/E6,0)) | R6: =IF(COUNT(C6:O6)=0,"",IFERROR(F6/D6,0)) | S6: =IF(COUNT(C6:O6)=0,"",IFERROR(C6/F6,0)) | T6: =IF(COUNT(C6:O6)=0,"",IFERROR(G6/F6,0)) | U6: =IF(COUNT(C6:O6)=0,"",IFERROR(C6/G6,0)) | V6: =IF(COUNT(C6:O6)=0,"",IFERROR(G6/D6*1000,0)) | W6: =IF(COUNT(C6:O6)=0,"",IFERROR(H6/G6,0)) | X6: =IF(COUNT(C6:O6)=0,"",IFERROR(C6/H6,0)) | Y6: =IF(COUNT(C6:O6)=0,"",IFERROR(X6/P6,0)) | Z6: =IF(COUNT(C6:O6)=0,"",IFERROR(H6/D6*1000,0)) | AA6: =IF(COUNT(C6:O6)=0,"",IFERROR(I6/H6,0)) | AB6: =IF(COUNT(C6:O6)=0,"",IFERROR(J6/I6,0)) | AC6: =IF(COUNT(C6:O6)=0,"",IFERROR(K6/J6,0)) | AD6: =IF(COUNT(C6:O6)=0,"",IFERROR(C6/K6,0)) | AE6: =IF(COUNT(C6:O6)=0,"",IFERROR(L6/K6,0)) | AF6: =IF(COUNT(C6:O6)=0,"",IFERROR(M6/L6,0)) | AG6: =IF(COUNT(C6:O6)=0,"",IFERROR(M6/H6,0)) | AH6: =IF(COUNT(C6:O6)=0,"",IFERROR(C6/M6,0)) | AI6: =IF(COUNT(C6:O6)=0,"",IFERROR(M6*Config!$C$7+N6*Config!$C$8,0)) | AJ6: =IF(COUNT(C6:O6)=0,"",IFERROR(IF(O6>0,O6,AI6*Config!$C$9),0)) | AK6: =IF(COUNT(C6:O6)=0,"",IFERROR(AJ6*(1-Config!$C$10-Config!$C$11-Config!$C$12),0)) | AL6: =IF(COUNT(C6:O6)=0,"",IFERROR(AK6-C6-Config!$C$13,0)) | AM6: =IF(COUNT(C6:O6)=0,"",IFERROR(AK6/C6,0)) | AN6: =IF(COUNT(C6:O6)=0,"",IFERROR(AI6/C6,0)) | AO6: =IF(COUNT(C6:O6)=0,"",IFERROR(AL6/G6,0)) | AP6: =IF(COUNT(C6:O6)=0,"",IFERROR(AO6/U6,0)) | AQ6: =IF(COUNT(C6:O6)=0,"",IFERROR(AL6/H6,0))
A7: =Config!$C$6+1 | B7: =INT((A7-Config!$C$6)/7)+1 | C7: 135 | D7: 14209 | E7: 11255 | F7: 229 | G7: 204 | H7: 51 | I7: 7 | J7: 4 | K7: 2 | L7: 2 | M7: 0 | N7: 0 | O7: 0 | P7: =IF(COUNT(C7:O7)=0,"",IFERROR(C7/D7*1000,0)) | Q7: =IF(COUNT(C7:O7)=0,"",IFERROR(D7/E7,0)) | R7: =IF(COUNT(C7:O7)=0,"",IFERROR(F7/D7,0)) | S7: =IF(COUNT(C7:O7)=0,"",IFERROR(C7/F7,0)) | T7: =IF(COUNT(C7:O7)=0,"",IFERROR(G7/F7,0)) | U7: =IF(COUNT(C7:O7)=0,"",IFERROR(C7/G7,0)) | V7: =IF(COUNT(C7:O7)=0,"",IFERROR(G7/D7*1000,0)) | W7: =IF(COUNT(C7:O7)=0,"",IFERROR(H7/G7,0)) | X7: =IF(COUNT(C7:O7)=0,"",IFERROR(C7/H7,0)) | Y7: =IF(COUNT(C7:O7)=0,"",IFERROR(X7/P7,0)) | Z7: =IF(COUNT(C7:O7)=0,"",IFERROR(H7/D7*1000,0)) | AA7: =IF(COUNT(C7:O7)=0,"",IFERROR(I7/H7,0)) | AB7: =IF(COUNT(C7:O7)=0,"",IFERROR(J7/I7,0)) | AC7: =IF(COUNT(C7:O7)=0,"",IFERROR(K7/J7,0)) | AD7: =IF(COUNT(C7:O7)=0,"",IFERROR(C7/K7,0)) | AE7: =IF(COUNT(C7:O7)=0,"",IFERROR(L7/K7,0)) | AF7: =IF(COUNT(C7:O7)=0,"",IFERROR(M7/L7,0)) | AG7: =IF(COUNT(C7:O7)=0,"",IFERROR(M7/H7,0)) | AH7: =IF(COUNT(C7:O7)=0,"",IFERROR(C7/M7,0)) | AI7: =IF(COUNT(C7:O7)=0,"",IFERROR(M7*Config!$C$7+N7*Config!$C$8,0)) | AJ7: =IF(COUNT(C7:O7)=0,"",IFERROR(IF(O7>0,O7,AI7*Config!$C$9),0)) | AK7: =IF(COUNT(C7:O7)=0,"",IFERROR(AJ7*(1-Config!$C$10-Config!$C$11-Config!$C$12),0)) | AL7: =IF(COUNT(C7:O7)=0,"",IFERROR(AK7-C7-Config!$C$13,0)) | AM7: =IF(COUNT(C7:O7)=0,"",IFERROR(AK7/C7,0)) | AN7: =IF(COUNT(C7:O7)=0,"",IFERROR(AI7/C7,0)) | AO7: =IF(COUNT(C7:O7)=0,"",IFERROR(AL7/G7,0)) | AP7: =IF(COUNT(C7:O7)=0,"",IFERROR(AO7/U7,0)) | AQ7: =IF(COUNT(C7:O7)=0,"",IFERROR(AL7/H7,0))
A8: =Config!$C$6+2 | B8: =INT((A8-Config!$C$6)/7)+1 | C8: 138 | D8: 15581 | E8: 11054 | F8: 209 | G8: 164 | H8: 43 | I8: 3 | J8: 2 | K8: 1 | L8: 1 | M8: 0 | N8: 0 | O8: 0 | P8: =IF(COUNT(C8:O8)=0,"",IFERROR(C8/D8*1000,0)) | Q8: =IF(COUNT(C8:O8)=0,"",IFERROR(D8/E8,0)) | R8: =IF(COUNT(C8:O8)=0,"",IFERROR(F8/D8,0)) | S8: =IF(COUNT(C8:O8)=0,"",IFERROR(C8/F8,0)) | T8: =IF(COUNT(C8:O8)=0,"",IFERROR(G8/F8,0)) | U8: =IF(COUNT(C8:O8)=0,"",IFERROR(C8/G8,0)) | V8: =IF(COUNT(C8:O8)=0,"",IFERROR(G8/D8*1000,0)) | W8: =IF(COUNT(C8:O8)=0,"",IFERROR(H8/G8,0)) | X8: =IF(COUNT(C8:O8)=0,"",IFERROR(C8/H8,0)) | Y8: =IF(COUNT(C8:O8)=0,"",IFERROR(X8/P8,0)) | Z8: =IF(COUNT(C8:O8)=0,"",IFERROR(H8/D8*1000,0)) | AA8: =IF(COUNT(C8:O8)=0,"",IFERROR(I8/H8,0)) | AB8: =IF(COUNT(C8:O8)=0,"",IFERROR(J8/I8,0)) | AC8: =IF(COUNT(C8:O8)=0,"",IFERROR(K8/J8,0)) | AD8: =IF(COUNT(C8:O8)=0,"",IFERROR(C8/K8,0)) | AE8: =IF(COUNT(C8:O8)=0,"",IFERROR(L8/K8,0)) | AF8: =IF(COUNT(C8:O8)=0,"",IFERROR(M8/L8,0)) | AG8: =IF(COUNT(C8:O8)=0,"",IFERROR(M8/H8,0)) | AH8: =IF(COUNT(C8:O8)=0,"",IFERROR(C8/M8,0)) | AI8: =IF(COUNT(C8:O8)=0,"",IFERROR(M8*Config!$C$7+N8*Config!$C$8,0)) | AJ8: =IF(COUNT(C8:O8)=0,"",IFERROR(IF(O8>0,O8,AI8*Config!$C$9),0)) | AK8: =IF(COUNT(C8:O8)=0,"",IFERROR(AJ8*(1-Config!$C$10-Config!$C$11-Config!$C$12),0)) | AL8: =IF(COUNT(C8:O8)=0,"",IFERROR(AK8-C8-Config!$C$13,0)) | AM8: =IF(COUNT(C8:O8)=0,"",IFERROR(AK8/C8,0)) | AN8: =IF(COUNT(C8:O8)=0,"",IFERROR(AI8/C8,0)) | AO8: =IF(COUNT(C8:O8)=0,"",IFERROR(AL8/G8,0)) | AP8: =IF(COUNT(C8:O8)=0,"",IFERROR(AO8/U8,0)) | AQ8: =IF(COUNT(C8:O8)=0,"",IFERROR(AL8/H8,0))
A9: =Config!$C$6+3 | B9: =INT((A9-Config!$C$6)/7)+1 | C9: 151 | D9: 14578 | E9: 10413 | F9: 227 | G9: 191 | H9: 51 | I9: 7 | J9: 4 | K9: 2 | L9: 2 | M9: 0 | N9: 0 | O9: 0 | P9: =IF(COUNT(C9:O9)=0,"",IFERROR(C9/D9*1000,0)) | Q9: =IF(COUNT(C9:O9)=0,"",IFERROR(D9/E9,0)) | R9: =IF(COUNT(C9:O9)=0,"",IFERROR(F9/D9,0)) | S9: =IF(COUNT(C9:O9)=0,"",IFERROR(C9/F9,0)) | T9: =IF(COUNT(C9:O9)=0,"",IFERROR(G9/F9,0)) | U9: =IF(COUNT(C9:O9)=0,"",IFERROR(C9/G9,0)) | V9: =IF(COUNT(C9:O9)=0,"",IFERROR(G9/D9*1000,0)) | W9: =IF(COUNT(C9:O9)=0,"",IFERROR(H9/G9,0)) | X9: =IF(COUNT(C9:O9)=0,"",IFERROR(C9/H9,0)) | Y9: =IF(COUNT(C9:O9)=0,"",IFERROR(X9/P9,0)) | Z9: =IF(COUNT(C9:O9)=0,"",IFERROR(H9/D9*1000,0)) | AA9: =IF(COUNT(C9:O9)=0,"",IFERROR(I9/H9,0)) | AB9: =IF(COUNT(C9:O9)=0,"",IFERROR(J9/I9,0)) | AC9: =IF(COUNT(C9:O9)=0,"",IFERROR(K9/J9,0)) | AD9: =IF(COUNT(C9:O9)=0,"",IFERROR(C9/K9,0)) | AE9: =IF(COUNT(C9:O9)=0,"",IFERROR(L9/K9,0)) | AF9: =IF(COUNT(C9:O9)=0,"",IFERROR(M9/L9,0)) | AG9: =IF(COUNT(C9:O9)=0,"",IFERROR(M9/H9,0)) | AH9: =IF(COUNT(C9:O9)=0,"",IFERROR(C9/M9,0)) | AI9: =IF(COUNT(C9:O9)=0,"",IFERROR(M9*Config!$C$7+N9*Config!$C$8,0)) | AJ9: =IF(COUNT(C9:O9)=0,"",IFERROR(IF(O9>0,O9,AI9*Config!$C$9),0)) | AK9: =IF(COUNT(C9:O9)=0,"",IFERROR(AJ9*(1-Config!$C$10-Config!$C$11-Config!$C$12),0)) | AL9: =IF(COUNT(C9:O9)=0,"",IFERROR(AK9-C9-Config!$C$13,0)) | AM9: =IF(COUNT(C9:O9)=0,"",IFERROR(AK9/C9,0)) | AN9: =IF(COUNT(C9:O9)=0,"",IFERROR(AI9/C9,0)) | AO9: =IF(COUNT(C9:O9)=0,"",IFERROR(AL9/G9,0)) | AP9: =IF(COUNT(C9:O9)=0,"",IFERROR(AO9/U9,0)) | AQ9: =IF(COUNT(C9:O9)=0,"",IFERROR(AL9/H9,0))
A10: =Config!$C$6+4 | B10: =INT((A10-Config!$C$6)/7)+1 | C10: 143 | D10: 15330 | E10: 11534 | F10: 206 | G10: 186 | H10: 51 | I10: 6 | J10: 4 | K10: 2 | L10: 2 | M10: 0 | N10: 0 | O10: 0 | P10: =IF(COUNT(C10:O10)=0,"",IFERROR(C10/D10*1000,0)) | Q10: =IF(COUNT(C10:O10)=0,"",IFERROR(D10/E10,0)) | R10: =IF(COUNT(C10:O10)=0,"",IFERROR(F10/D10,0)) | S10: =IF(COUNT(C10:O10)=0,"",IFERROR(C10/F10,0)) | T10: =IF(COUNT(C10:O10)=0,"",IFERROR(G10/F10,0)) | U10: =IF(COUNT(C10:O10)=0,"",IFERROR(C10/G10,0)) | V10: =IF(COUNT(C10:O10)=0,"",IFERROR(G10/D10*1000,0)) | W10: =IF(COUNT(C10:O10)=0,"",IFERROR(H10/G10,0)) | X10: =IF(COUNT(C10:O10)=0,"",IFERROR(C10/H10,0)) | Y10: =IF(COUNT(C10:O10)=0,"",IFERROR(X10/P10,0)) | Z10: =IF(COUNT(C10:O10)=0,"",IFERROR(H10/D10*1000,0)) | AA10: =IF(COUNT(C10:O10)=0,"",IFERROR(I10/H10,0)) | AB10: =IF(COUNT(C10:O10)=0,"",IFERROR(J10/I10,0)) | AC10: =IF(COUNT(C10:O10)=0,"",IFERROR(K10/J10,0)) | AD10: =IF(COUNT(C10:O10)=0,"",IFERROR(C10/K10,0)) | AE10: =IF(COUNT(C10:O10)=0,"",IFERROR(L10/K10,0)) | AF10: =IF(COUNT(C10:O10)=0,"",IFERROR(M10/L10,0)) | AG10: =IF(COUNT(C10:O10)=0,"",IFERROR(M10/H10,0)) | AH10: =IF(COUNT(C10:O10)=0,"",IFERROR(C10/M10,0)) | AI10: =IF(COUNT(C10:O10)=0,"",IFERROR(M10*Config!$C$7+N10*Config!$C$8,0)) | AJ10: =IF(COUNT(C10:O10)=0,"",IFERROR(IF(O10>0,O10,AI10*Config!$C$9),0)) | AK10: =IF(COUNT(C10:O10)=0,"",IFERROR(AJ10*(1-Config!$C$10-Config!$C$11-Config!$C$12),0)) | AL10: =IF(COUNT(C10:O10)=0,"",IFERROR(AK10-C10-Config!$C$13,0)) | AM10: =IF(COUNT(C10:O10)=0,"",IFERROR(AK10/C10,0)) | AN10: =IF(COUNT(C10:O10)=0,"",IFERROR(AI10/C10,0)) | AO10: =IF(COUNT(C10:O10)=0,"",IFERROR(AL10/G10,0)) | AP10: =IF(COUNT(C10:O10)=0,"",IFERROR(AO10/U10,0)) | AQ10: =IF(COUNT(C10:O10)=0,"",IFERROR(AL10/H10,0))
A11: =Config!$C$6+5 | B11: =INT((A11-Config!$C$6)/7)+1 | C11: 132 | D11: 14191 | E11: 9228 | F11: 211 | G11: 200 | H11: 55 | I11: 4 | J11: 2 | K11: 1 | L11: 1 | M11: 0 | N11: 0 | O11: 300 | P11: =IF(COUNT(C11:O11)=0,"",IFERROR(C11/D11*1000,0)) | Q11: =IF(COUNT(C11:O11)=0,"",IFERROR(D11/E11,0)) | R11: =IF(COUNT(C11:O11)=0,"",IFERROR(F11/D11,0)) | S11: =IF(COUNT(C11:O11)=0,"",IFERROR(C11/F11,0)) | T11: =IF(COUNT(C11:O11)=0,"",IFERROR(G11/F11,0)) | U11: =IF(COUNT(C11:O11)=0,"",IFERROR(C11/G11,0)) | V11: =IF(COUNT(C11:O11)=0,"",IFERROR(G11/D11*1000,0)) | W11: =IF(COUNT(C11:O11)=0,"",IFERROR(H11/G11,0)) | X11: =IF(COUNT(C11:O11)=0,"",IFERROR(C11/H11,0)) | Y11: =IF(COUNT(C11:O11)=0,"",IFERROR(X11/P11,0)) | Z11: =IF(COUNT(C11:O11)=0,"",IFERROR(H11/D11*1000,0)) | AA11: =IF(COUNT(C11:O11)=0,"",IFERROR(I11/H11,0)) | AB11: =IF(COUNT(C11:O11)=0,"",IFERROR(J11/I11,0)) | AC11: =IF(COUNT(C11:O11)=0,"",IFERROR(K11/J11,0)) | AD11: =IF(COUNT(C11:O11)=0,"",IFERROR(C11/K11,0)) | AE11: =IF(COUNT(C11:O11)=0,"",IFERROR(L11/K11,0)) | AF11: =IF(COUNT(C11:O11)=0,"",IFERROR(M11/L11,0)) | AG11: =IF(COUNT(C11:O11)=0,"",IFERROR(M11/H11,0)) | AH11: =IF(COUNT(C11:O11)=0,"",IFERROR(C11/M11,0)) | AI11: =IF(COUNT(C11:O11)=0,"",IFERROR(M11*Config!$C$7+N11*Config!$C$8,0)) | AJ11: =IF(COUNT(C11:O11)=0,"",IFERROR(IF(O11>0,O11,AI11*Config!$C$9),0)) | AK11: =IF(COUNT(C11:O11)=0,"",IFERROR(AJ11*(1-Config!$C$10-Config!$C$11-Config!$C$12),0)) | AL11: =IF(COUNT(C11:O11)=0,"",IFERROR(AK11-C11-Config!$C$13,0)) | AM11: =IF(COUNT(C11:O11)=0,"",IFERROR(AK11/C11,0)) | AN11: =IF(COUNT(C11:O11)=0,"",IFERROR(AI11/C11,0)) | AO11: =IF(COUNT(C11:O11)=0,"",IFERROR(AL11/G11,0)) | AP11: =IF(COUNT(C11:O11)=0,"",IFERROR(AO11/U11,0)) | AQ11: =IF(COUNT(C11:O11)=0,"",IFERROR(AL11/H11,0))
A12: =Config!$C$6+6 | B12: =INT((A12-Config!$C$6)/7)+1 | C12: 135 | D12: 14079 | E12: 9049 | F12: 224 | G12: 173 | H12: 46 | I12: 3 | J12: 2 | K12: 1 | L12: 1 | M12: 1 | N12: 0 | O12: 900 | P12: =IF(COUNT(C12:O12)=0,"",IFERROR(C12/D12*1000,0)) | Q12: =IF(COUNT(C12:O12)=0,"",IFERROR(D12/E12,0)) | R12: =IF(COUNT(C12:O12)=0,"",IFERROR(F12/D12,0)) | S12: =IF(COUNT(C12:O12)=0,"",IFERROR(C12/F12,0)) | T12: =IF(COUNT(C12:O12)=0,"",IFERROR(G12/F12,0)) | U12: =IF(COUNT(C12:O12)=0,"",IFERROR(C12/G12,0)) | V12: =IF(COUNT(C12:O12)=0,"",IFERROR(G12/D12*1000,0)) | W12: =IF(COUNT(C12:O12)=0,"",IFERROR(H12/G12,0)) | X12: =IF(COUNT(C12:O12)=0,"",IFERROR(C12/H12,0)) | Y12: =IF(COUNT(C12:O12)=0,"",IFERROR(X12/P12,0)) | Z12: =IF(COUNT(C12:O12)=0,"",IFERROR(H12/D12*1000,0)) | AA12: =IF(COUNT(C12:O12)=0,"",IFERROR(I12/H12,0)) | AB12: =IF(COUNT(C12:O12)=0,"",IFERROR(J12/I12,0)) | AC12: =IF(COUNT(C12:O12)=0,"",IFERROR(K12/J12,0)) | AD12: =IF(COUNT(C12:O12)=0,"",IFERROR(C12/K12,0)) | AE12: =IF(COUNT(C12:O12)=0,"",IFERROR(L12/K12,0)) | AF12: =IF(COUNT(C12:O12)=0,"",IFERROR(M12/L12,0)) | AG12: =IF(COUNT(C12:O12)=0,"",IFERROR(M12/H12,0)) | AH12: =IF(COUNT(C12:O12)=0,"",IFERROR(C12/M12,0)) | AI12: =IF(COUNT(C12:O12)=0,"",IFERROR(M12*Config!$C$7+N12*Config!$C$8,0)) | AJ12: =IF(COUNT(C12:O12)=0,"",IFERROR(IF(O12>0,O12,AI12*Config!$C$9),0)) | AK12: =IF(COUNT(C12:O12)=0,"",IFERROR(AJ12*(1-Config!$C$10-Config!$C$11-Config!$C$12),0)) | AL12: =IF(COUNT(C12:O12)=0,"",IFERROR(AK12-C12-Config!$C$13,0)) | AM12: =IF(COUNT(C12:O12)=0,"",IFERROR(AK12/C12,0)) | AN12: =IF(COUNT(C12:O12)=0,"",IFERROR(AI12/C12,0)) | AO12: =IF(COUNT(C12:O12)=0,"",IFERROR(AL12/G12,0)) | AP12: =IF(COUNT(C12:O12)=0,"",IFERROR(AO12/U12,0)) | AQ12: =IF(COUNT(C12:O12)=0,"",IFERROR(AL12/H12,0))
A13: =Config!$C$6+7 | B13: =INT((A13-Config!$C$6)/7)+1 | C13: 138 | D13: 13645 | E13: 9871 | F13: 189 | G13: 170 | H13: 43 | I13: 5 | J13: 3 | K13: 2 | L13: 1 | M13: 1 | N13: 0 | O13: 900 | P13: =IF(COUNT(C13:O13)=0,"",IFERROR(C13/D13*1000,0)) | Q13: =IF(COUNT(C13:O13)=0,"",IFERROR(D13/E13,0)) | R13: =IF(COUNT(C13:O13)=0,"",IFERROR(F13/D13,0)) | S13: =IF(COUNT(C13:O13)=0,"",IFERROR(C13/F13,0)) | T13: =IF(COUNT(C13:O13)=0,"",IFERROR(G13/F13,0)) | U13: =IF(COUNT(C13:O13)=0,"",IFERROR(C13/G13,0)) | V13: =IF(COUNT(C13:O13)=0,"",IFERROR(G13/D13*1000,0)) | W13: =IF(COUNT(C13:O13)=0,"",IFERROR(H13/G13,0)) | X13: =IF(COUNT(C13:O13)=0,"",IFERROR(C13/H13,0)) | Y13: =IF(COUNT(C13:O13)=0,"",IFERROR(X13/P13,0)) | Z13: =IF(COUNT(C13:O13)=0,"",IFERROR(H13/D13*1000,0)) | AA13: =IF(COUNT(C13:O13)=0,"",IFERROR(I13/H13,0)) | AB13: =IF(COUNT(C13:O13)=0,"",IFERROR(J13/I13,0)) | AC13: =IF(COUNT(C13:O13)=0,"",IFERROR(K13/J13,0)) | AD13: =IF(COUNT(C13:O13)=0,"",IFERROR(C13/K13,0)) | AE13: =IF(COUNT(C13:O13)=0,"",IFERROR(L13/K13,0)) | AF13: =IF(COUNT(C13:O13)=0,"",IFERROR(M13/L13,0)) | AG13: =IF(COUNT(C13:O13)=0,"",IFERROR(M13/H13,0)) | AH13: =IF(COUNT(C13:O13)=0,"",IFERROR(C13/M13,0)) | AI13: =IF(COUNT(C13:O13)=0,"",IFERROR(M13*Config!$C$7+N13*Config!$C$8,0)) | AJ13: =IF(COUNT(C13:O13)=0,"",IFERROR(IF(O13>0,O13,AI13*Config!$C$9),0)) | AK13: =IF(COUNT(C13:O13)=0,"",IFERROR(AJ13*(1-Config!$C$10-Config!$C$11-Config!$C$12),0)) | AL13: =IF(COUNT(C13:O13)=0,"",IFERROR(AK13-C13-Config!$C$13,0)) | AM13: =IF(COUNT(C13:O13)=0,"",IFERROR(AK13/C13,0)) | AN13: =IF(COUNT(C13:O13)=0,"",IFERROR(AI13/C13,0)) | AO13: =IF(COUNT(C13:O13)=0,"",IFERROR(AL13/G13,0)) | AP13: =IF(COUNT(C13:O13)=0,"",IFERROR(AO13/U13,0)) | AQ13: =IF(COUNT(C13:O13)=0,"",IFERROR(AL13/H13,0))
A14: =Config!$C$6+8 | B14: =INT((A14-Config!$C$6)/7)+1 | C14: 140 | D14: 14783 | E14: 9487 | F14: 238 | G14: 193 | H14: 59 | I14: 5 | J14: 3 | K14: 2 | L14: 1 | M14: 0 | N14: 0 | O14: 0 | P14: =IF(COUNT(C14:O14)=0,"",IFERROR(C14/D14*1000,0)) | Q14: =IF(COUNT(C14:O14)=0,"",IFERROR(D14/E14,0)) | R14: =IF(COUNT(C14:O14)=0,"",IFERROR(F14/D14,0)) | S14: =IF(COUNT(C14:O14)=0,"",IFERROR(C14/F14,0)) | T14: =IF(COUNT(C14:O14)=0,"",IFERROR(G14/F14,0)) | U14: =IF(COUNT(C14:O14)=0,"",IFERROR(C14/G14,0)) | V14: =IF(COUNT(C14:O14)=0,"",IFERROR(G14/D14*1000,0)) | W14: =IF(COUNT(C14:O14)=0,"",IFERROR(H14/G14,0)) | X14: =IF(COUNT(C14:O14)=0,"",IFERROR(C14/H14,0)) | Y14: =IF(COUNT(C14:O14)=0,"",IFERROR(X14/P14,0)) | Z14: =IF(COUNT(C14:O14)=0,"",IFERROR(H14/D14*1000,0)) | AA14: =IF(COUNT(C14:O14)=0,"",IFERROR(I14/H14,0)) | AB14: =IF(COUNT(C14:O14)=0,"",IFERROR(J14/I14,0)) | AC14: =IF(COUNT(C14:O14)=0,"",IFERROR(K14/J14,0)) | AD14: =IF(COUNT(C14:O14)=0,"",IFERROR(C14/K14,0)) | AE14: =IF(COUNT(C14:O14)=0,"",IFERROR(L14/K14,0)) | AF14: =IF(COUNT(C14:O14)=0,"",IFERROR(M14/L14,0)) | AG14: =IF(COUNT(C14:O14)=0,"",IFERROR(M14/H14,0)) | AH14: =IF(COUNT(C14:O14)=0,"",IFERROR(C14/M14,0)) | AI14: =IF(COUNT(C14:O14)=0,"",IFERROR(M14*Config!$C$7+N14*Config!$C$8,0)) | AJ14: =IF(COUNT(C14:O14)=0,"",IFERROR(IF(O14>0,O14,AI14*Config!$C$9),0)) | AK14: =IF(COUNT(C14:O14)=0,"",IFERROR(AJ14*(1-Config!$C$10-Config!$C$11-Config!$C$12),0)) | AL14: =IF(COUNT(C14:O14)=0,"",IFERROR(AK14-C14-Config!$C$13,0)) | AM14: =IF(COUNT(C14:O14)=0,"",IFERROR(AK14/C14,0)) | AN14: =IF(COUNT(C14:O14)=0,"",IFERROR(AI14/C14,0)) | AO14: =IF(COUNT(C14:O14)=0,"",IFERROR(AL14/G14,0)) | AP14: =IF(COUNT(C14:O14)=0,"",IFERROR(AO14/U14,0)) | AQ14: =IF(COUNT(C14:O14)=0,"",IFERROR(AL14/H14,0))
A15: =Config!$C$6+9 | B15: =INT((A15-Config!$C$6)/7)+1 | C15: 136 | D15: 12136 | E15: 9309 | F15: 171 | G15: 155 | H15: 42 | I15: 4 | J15: 2 | K15: 1 | L15: 1 | M15: 1 | N15: 0 | O15: 1200 | P15: =IF(COUNT(C15:O15)=0,"",IFERROR(C15/D15*1000,0)) | Q15: =IF(COUNT(C15:O15)=0,"",IFERROR(D15/E15,0)) | R15: =IF(COUNT(C15:O15)=0,"",IFERROR(F15/D15,0)) | S15: =IF(COUNT(C15:O15)=0,"",IFERROR(C15/F15,0)) | T15: =IF(COUNT(C15:O15)=0,"",IFERROR(G15/F15,0)) | U15: =IF(COUNT(C15:O15)=0,"",IFERROR(C15/G15,0)) | V15: =IF(COUNT(C15:O15)=0,"",IFERROR(G15/D15*1000,0)) | W15: =IF(COUNT(C15:O15)=0,"",IFERROR(H15/G15,0)) | X15: =IF(COUNT(C15:O15)=0,"",IFERROR(C15/H15,0)) | Y15: =IF(COUNT(C15:O15)=0,"",IFERROR(X15/P15,0)) | Z15: =IF(COUNT(C15:O15)=0,"",IFERROR(H15/D15*1000,0)) | AA15: =IF(COUNT(C15:O15)=0,"",IFERROR(I15/H15,0)) | AB15: =IF(COUNT(C15:O15)=0,"",IFERROR(J15/I15,0)) | AC15: =IF(COUNT(C15:O15)=0,"",IFERROR(K15/J15,0)) | AD15: =IF(COUNT(C15:O15)=0,"",IFERROR(C15/K15,0)) | AE15: =IF(COUNT(C15:O15)=0,"",IFERROR(L15/K15,0)) | AF15: =IF(COUNT(C15:O15)=0,"",IFERROR(M15/L15,0)) | AG15: =IF(COUNT(C15:O15)=0,"",IFERROR(M15/H15,0)) | AH15: =IF(COUNT(C15:O15)=0,"",IFERROR(C15/M15,0)) | AI15: =IF(COUNT(C15:O15)=0,"",IFERROR(M15*Config!$C$7+N15*Config!$C$8,0)) | AJ15: =IF(COUNT(C15:O15)=0,"",IFERROR(IF(O15>0,O15,AI15*Config!$C$9),0)) | AK15: =IF(COUNT(C15:O15)=0,"",IFERROR(AJ15*(1-Config!$C$10-Config!$C$11-Config!$C$12),0)) | AL15: =IF(COUNT(C15:O15)=0,"",IFERROR(AK15-C15-Config!$C$13,0)) | AM15: =IF(COUNT(C15:O15)=0,"",IFERROR(AK15/C15,0)) | AN15: =IF(COUNT(C15:O15)=0,"",IFERROR(AI15/C15,0)) | AO15: =IF(COUNT(C15:O15)=0,"",IFERROR(AL15/G15,0)) | AP15: =IF(COUNT(C15:O15)=0,"",IFERROR(AO15/U15,0)) | AQ15: =IF(COUNT(C15:O15)=0,"",IFERROR(AL15/H15,0))
A16: =Config!$C$6+10 | B16: =INT((A16-Config!$C$6)/7)+1 | C16: 153 | D16: 16303 | E16: 11369 | F16: 237 | G16: 199 | H16: 62 | I16: 6 | J16: 4 | K16: 2 | L16: 2 | M16: 0 | N16: 0 | O16: 300 | P16: =IF(COUNT(C16:O16)=0,"",IFERROR(C16/D16*1000,0)) | Q16: =IF(COUNT(C16:O16)=0,"",IFERROR(D16/E16,0)) | R16: =IF(COUNT(C16:O16)=0,"",IFERROR(F16/D16,0)) | S16: =IF(COUNT(C16:O16)=0,"",IFERROR(C16/F16,0)) | T16: =IF(COUNT(C16:O16)=0,"",IFERROR(G16/F16,0)) | U16: =IF(COUNT(C16:O16)=0,"",IFERROR(C16/G16,0)) | V16: =IF(COUNT(C16:O16)=0,"",IFERROR(G16/D16*1000,0)) | W16: =IF(COUNT(C16:O16)=0,"",IFERROR(H16/G16,0)) | X16: =IF(COUNT(C16:O16)=0,"",IFERROR(C16/H16,0)) | Y16: =IF(COUNT(C16:O16)=0,"",IFERROR(X16/P16,0)) | Z16: =IF(COUNT(C16:O16)=0,"",IFERROR(H16/D16*1000,0)) | AA16: =IF(COUNT(C16:O16)=0,"",IFERROR(I16/H16,0)) | AB16: =IF(COUNT(C16:O16)=0,"",IFERROR(J16/I16,0)) | AC16: =IF(COUNT(C16:O16)=0,"",IFERROR(K16/J16,0)) | AD16: =IF(COUNT(C16:O16)=0,"",IFERROR(C16/K16,0)) | AE16: =IF(COUNT(C16:O16)=0,"",IFERROR(L16/K16,0)) | AF16: =IF(COUNT(C16:O16)=0,"",IFERROR(M16/L16,0)) | AG16: =IF(COUNT(C16:O16)=0,"",IFERROR(M16/H16,0)) | AH16: =IF(COUNT(C16:O16)=0,"",IFERROR(C16/M16,0)) | AI16: =IF(COUNT(C16:O16)=0,"",IFERROR(M16*Config!$C$7+N16*Config!$C$8,0)) | AJ16: =IF(COUNT(C16:O16)=0,"",IFERROR(IF(O16>0,O16,AI16*Config!$C$9),0)) | AK16: =IF(COUNT(C16:O16)=0,"",IFERROR(AJ16*(1-Config!$C$10-Config!$C$11-Config!$C$12),0)) | AL16: =IF(COUNT(C16:O16)=0,"",IFERROR(AK16-C16-Config!$C$13,0)) | AM16: =IF(COUNT(C16:O16)=0,"",IFERROR(AK16/C16,0)) | AN16: =IF(COUNT(C16:O16)=0,"",IFERROR(AI16/C16,0)) | AO16: =IF(COUNT(C16:O16)=0,"",IFERROR(AL16/G16,0)) | AP16: =IF(COUNT(C16:O16)=0,"",IFERROR(AO16/U16,0)) | AQ16: =IF(COUNT(C16:O16)=0,"",IFERROR(AL16/H16,0))
A17: =Config!$C$6+11 | B17: =INT((A17-Config!$C$6)/7)+1 | C17: 138 | D17: 12527 | E17: 8314 | F17: 177 | G17: 139 | H17: 41 | I17: 5 | J17: 3 | K17: 2 | L17: 1 | M17: 1 | N17: 0 | O17: 900 | P17: =IF(COUNT(C17:O17)=0,"",IFERROR(C17/D17*1000,0)) | Q17: =IF(COUNT(C17:O17)=0,"",IFERROR(D17/E17,0)) | R17: =IF(COUNT(C17:O17)=0,"",IFERROR(F17/D17,0)) | S17: =IF(COUNT(C17:O17)=0,"",IFERROR(C17/F17,0)) | T17: =IF(COUNT(C17:O17)=0,"",IFERROR(G17/F17,0)) | U17: =IF(COUNT(C17:O17)=0,"",IFERROR(C17/G17,0)) | V17: =IF(COUNT(C17:O17)=0,"",IFERROR(G17/D17*1000,0)) | W17: =IF(COUNT(C17:O17)=0,"",IFERROR(H17/G17,0)) | X17: =IF(COUNT(C17:O17)=0,"",IFERROR(C17/H17,0)) | Y17: =IF(COUNT(C17:O17)=0,"",IFERROR(X17/P17,0)) | Z17: =IF(COUNT(C17:O17)=0,"",IFERROR(H17/D17*1000,0)) | AA17: =IF(COUNT(C17:O17)=0,"",IFERROR(I17/H17,0)) | AB17: =IF(COUNT(C17:O17)=0,"",IFERROR(J17/I17,0)) | AC17: =IF(COUNT(C17:O17)=0,"",IFERROR(K17/J17,0)) | AD17: =IF(COUNT(C17:O17)=0,"",IFERROR(C17/K17,0)) | AE17: =IF(COUNT(C17:O17)=0,"",IFERROR(L17/K17,0)) | AF17: =IF(COUNT(C17:O17)=0,"",IFERROR(M17/L17,0)) | AG17: =IF(COUNT(C17:O17)=0,"",IFERROR(M17/H17,0)) | AH17: =IF(COUNT(C17:O17)=0,"",IFERROR(C17/M17,0)) | AI17: =IF(COUNT(C17:O17)=0,"",IFERROR(M17*Config!$C$7+N17*Config!$C$8,0)) | AJ17: =IF(COUNT(C17:O17)=0,"",IFERROR(IF(O17>0,O17,AI17*Config!$C$9),0)) | AK17: =IF(COUNT(C17:O17)=0,"",IFERROR(AJ17*(1-Config!$C$10-Config!$C$11-Config!$C$12),0)) | AL17: =IF(COUNT(C17:O17)=0,"",IFERROR(AK17-C17-Config!$C$13,0)) | AM17: =IF(COUNT(C17:O17)=0,"",IFERROR(AK17/C17,0)) | AN17: =IF(COUNT(C17:O17)=0,"",IFERROR(AI17/C17,0)) | AO17: =IF(COUNT(C17:O17)=0,"",IFERROR(AL17/G17,0)) | AP17: =IF(COUNT(C17:O17)=0,"",IFERROR(AO17/U17,0)) | AQ17: =IF(COUNT(C17:O17)=0,"",IFERROR(AL17/H17,0))
A18: =Config!$C$6+12 | B18: =INT((A18-Config!$C$6)/7)+1 | C18: 164 | D18: 15979 | E18: 11633 | F18: 217 | G18: 164 | H18: 51 | I18: 4 | J18: 3 | K18: 2 | L18: 1 | M18: 0 | N18: 0 | O18: 0 | P18: =IF(COUNT(C18:O18)=0,"",IFERROR(C18/D18*1000,0)) | Q18: =IF(COUNT(C18:O18)=0,"",IFERROR(D18/E18,0)) | R18: =IF(COUNT(C18:O18)=0,"",IFERROR(F18/D18,0)) | S18: =IF(COUNT(C18:O18)=0,"",IFERROR(C18/F18,0)) | T18: =IF(COUNT(C18:O18)=0,"",IFERROR(G18/F18,0)) | U18: =IF(COUNT(C18:O18)=0,"",IFERROR(C18/G18,0)) | V18: =IF(COUNT(C18:O18)=0,"",IFERROR(G18/D18*1000,0)) | W18: =IF(COUNT(C18:O18)=0,"",IFERROR(H18/G18,0)) | X18: =IF(COUNT(C18:O18)=0,"",IFERROR(C18/H18,0)) | Y18: =IF(COUNT(C18:O18)=0,"",IFERROR(X18/P18,0)) | Z18: =IF(COUNT(C18:O18)=0,"",IFERROR(H18/D18*1000,0)) | AA18: =IF(COUNT(C18:O18)=0,"",IFERROR(I18/H18,0)) | AB18: =IF(COUNT(C18:O18)=0,"",IFERROR(J18/I18,0)) | AC18: =IF(COUNT(C18:O18)=0,"",IFERROR(K18/J18,0)) | AD18: =IF(COUNT(C18:O18)=0,"",IFERROR(C18/K18,0)) | AE18: =IF(COUNT(C18:O18)=0,"",IFERROR(L18/K18,0)) | AF18: =IF(COUNT(C18:O18)=0,"",IFERROR(M18/L18,0)) | AG18: =IF(COUNT(C18:O18)=0,"",IFERROR(M18/H18,0)) | AH18: =IF(COUNT(C18:O18)=0,"",IFERROR(C18/M18,0)) | AI18: =IF(COUNT(C18:O18)=0,"",IFERROR(M18*Config!$C$7+N18*Config!$C$8,0)) | AJ18: =IF(COUNT(C18:O18)=0,"",IFERROR(IF(O18>0,O18,AI18*Config!$C$9),0)) | AK18: =IF(COUNT(C18:O18)=0,"",IFERROR(AJ18*(1-Config!$C$10-Config!$C$11-Config!$C$12),0)) | AL18: =IF(COUNT(C18:O18)=0,"",IFERROR(AK18-C18-Config!$C$13,0)) | AM18: =IF(COUNT(C18:O18)=0,"",IFERROR(AK18/C18,0)) | AN18: =IF(COUNT(C18:O18)=0,"",IFERROR(AI18/C18,0)) | AO18: =IF(COUNT(C18:O18)=0,"",IFERROR(AL18/G18,0)) | AP18: =IF(COUNT(C18:O18)=0,"",IFERROR(AO18/U18,0)) | AQ18: =IF(COUNT(C18:O18)=0,"",IFERROR(AL18/H18,0))
A19: =Config!$C$6+13 | B19: =INT((A19-Config!$C$6)/7)+1 | C19: 153 | D19: 16148 | E19: 12509 | F19: 255 | G19: 194 | H19: 51 | I19: 5 | J19: 3 | K19: 2 | L19: 1 | M19: 0 | N19: 0 | O19: 300 | P19: =IF(COUNT(C19:O19)=0,"",IFERROR(C19/D19*1000,0)) | Q19: =IF(COUNT(C19:O19)=0,"",IFERROR(D19/E19,0)) | R19: =IF(COUNT(C19:O19)=0,"",IFERROR(F19/D19,0)) | S19: =IF(COUNT(C19:O19)=0,"",IFERROR(C19/F19,0)) | T19: =IF(COUNT(C19:O19)=0,"",IFERROR(G19/F19,0)) | U19: =IF(COUNT(C19:O19)=0,"",IFERROR(C19/G19,0)) | V19: =IF(COUNT(C19:O19)=0,"",IFERROR(G19/D19*1000,0)) | W19: =IF(COUNT(C19:O19)=0,"",IFERROR(H19/G19,0)) | X19: =IF(COUNT(C19:O19)=0,"",IFERROR(C19/H19,0)) | Y19: =IF(COUNT(C19:O19)=0,"",IFERROR(X19/P19,0)) | Z19: =IF(COUNT(C19:O19)=0,"",IFERROR(H19/D19*1000,0)) | AA19: =IF(COUNT(C19:O19)=0,"",IFERROR(I19/H19,0)) | AB19: =IF(COUNT(C19:O19)=0,"",IFERROR(J19/I19,0)) | AC19: =IF(COUNT(C19:O19)=0,"",IFERROR(K19/J19,0)) | AD19: =IF(COUNT(C19:O19)=0,"",IFERROR(C19/K19,0)) | AE19: =IF(COUNT(C19:O19)=0,"",IFERROR(L19/K19,0)) | AF19: =IF(COUNT(C19:O19)=0,"",IFERROR(M19/L19,0)) | AG19: =IF(COUNT(C19:O19)=0,"",IFERROR(M19/H19,0)) | AH19: =IF(COUNT(C19:O19)=0,"",IFERROR(C19/M19,0)) | AI19: =IF(COUNT(C19:O19)=0,"",IFERROR(M19*Config!$C$7+N19*Config!$C$8,0)) | AJ19: =IF(COUNT(C19:O19)=0,"",IFERROR(IF(O19>0,O19,AI19*Config!$C$9),0)) | AK19: =IF(COUNT(C19:O19)=0,"",IFERROR(AJ19*(1-Config!$C$10-Config!$C$11-Config!$C$12),0)) | AL19: =IF(COUNT(C19:O19)=0,"",IFERROR(AK19-C19-Config!$C$13,0)) | AM19: =IF(COUNT(C19:O19)=0,"",IFERROR(AK19/C19,0)) | AN19: =IF(COUNT(C19:O19)=0,"",IFERROR(AI19/C19,0)) | AO19: =IF(COUNT(C19:O19)=0,"",IFERROR(AL19/G19,0)) | AP19: =IF(COUNT(C19:O19)=0,"",IFERROR(AO19/U19,0)) | AQ19: =IF(COUNT(C19:O19)=0,"",IFERROR(AL19/H19,0))
A20: =Config!$C$6+14 | B20: =INT((A20-Config!$C$6)/7)+1 | C20: 165 | D20: 17765 | E20: 14354 | F20: 252 | G20: 211 | H20: 53 | I20: 4 | J20: 3 | K20: 2 | L20: 1 | M20: 0 | N20: 0 | O20: 300 | P20: =IF(COUNT(C20:O20)=0,"",IFERROR(C20/D20*1000,0)) | Q20: =IF(COUNT(C20:O20)=0,"",IFERROR(D20/E20,0)) | R20: =IF(COUNT(C20:O20)=0,"",IFERROR(F20/D20,0)) | S20: =IF(COUNT(C20:O20)=0,"",IFERROR(C20/F20,0)) | T20: =IF(COUNT(C20:O20)=0,"",IFERROR(G20/F20,0)) | U20: =IF(COUNT(C20:O20)=0,"",IFERROR(C20/G20,0)) | V20: =IF(COUNT(C20:O20)=0,"",IFERROR(G20/D20*1000,0)) | W20: =IF(COUNT(C20:O20)=0,"",IFERROR(H20/G20,0)) | X20: =IF(COUNT(C20:O20)=0,"",IFERROR(C20/H20,0)) | Y20: =IF(COUNT(C20:O20)=0,"",IFERROR(X20/P20,0)) | Z20: =IF(COUNT(C20:O20)=0,"",IFERROR(H20/D20*1000,0)) | AA20: =IF(COUNT(C20:O20)=0,"",IFERROR(I20/H20,0)) | AB20: =IF(COUNT(C20:O20)=0,"",IFERROR(J20/I20,0)) | AC20: =IF(COUNT(C20:O20)=0,"",IFERROR(K20/J20,0)) | AD20: =IF(COUNT(C20:O20)=0,"",IFERROR(C20/K20,0)) | AE20: =IF(COUNT(C20:O20)=0,"",IFERROR(L20/K20,0)) | AF20: =IF(COUNT(C20:O20)=0,"",IFERROR(M20/L20,0)) | AG20: =IF(COUNT(C20:O20)=0,"",IFERROR(M20/H20,0)) | AH20: =IF(COUNT(C20:O20)=0,"",IFERROR(C20/M20,0)) | AI20: =IF(COUNT(C20:O20)=0,"",IFERROR(M20*Config!$C$7+N20*Config!$C$8,0)) | AJ20: =IF(COUNT(C20:O20)=0,"",IFERROR(IF(O20>0,O20,AI20*Config!$C$9),0)) | AK20: =IF(COUNT(C20:O20)=0,"",IFERROR(AJ20*(1-Config!$C$10-Config!$C$11-Config!$C$12),0)) | AL20: =IF(COUNT(C20:O20)=0,"",IFERROR(AK20-C20-Config!$C$13,0)) | AM20: =IF(COUNT(C20:O20)=0,"",IFERROR(AK20/C20,0)) | AN20: =IF(COUNT(C20:O20)=0,"",IFERROR(AI20/C20,0)) | AO20: =IF(COUNT(C20:O20)=0,"",IFERROR(AL20/G20,0)) | AP20: =IF(COUNT(C20:O20)=0,"",IFERROR(AO20/U20,0)) | AQ20: =IF(COUNT(C20:O20)=0,"",IFERROR(AL20/H20,0))
A21: =Config!$C$6+15 | B21: =INT((A21-Config!$C$6)/7)+1 | C21: 145 | D21: 13260 | E21: 8492 | F21: 206 | G21: 183 | H21: 52 | I21: 4 | J21: 2 | K21: 1 | L21: 1 | M21: 1 | N21: 0 | O21: 1200 | P21: =IF(COUNT(C21:O21)=0,"",IFERROR(C21/D21*1000,0)) | Q21: =IF(COUNT(C21:O21)=0,"",IFERROR(D21/E21,0)) | R21: =IF(COUNT(C21:O21)=0,"",IFERROR(F21/D21,0)) | S21: =IF(COUNT(C21:O21)=0,"",IFERROR(C21/F21,0)) | T21: =IF(COUNT(C21:O21)=0,"",IFERROR(G21/F21,0)) | U21: =IF(COUNT(C21:O21)=0,"",IFERROR(C21/G21,0)) | V21: =IF(COUNT(C21:O21)=0,"",IFERROR(G21/D21*1000,0)) | W21: =IF(COUNT(C21:O21)=0,"",IFERROR(H21/G21,0)) | X21: =IF(COUNT(C21:O21)=0,"",IFERROR(C21/H21,0)) | Y21: =IF(COUNT(C21:O21)=0,"",IFERROR(X21/P21,0)) | Z21: =IF(COUNT(C21:O21)=0,"",IFERROR(H21/D21*1000,0)) | AA21: =IF(COUNT(C21:O21)=0,"",IFERROR(I21/H21,0)) | AB21: =IF(COUNT(C21:O21)=0,"",IFERROR(J21/I21,0)) | AC21: =IF(COUNT(C21:O21)=0,"",IFERROR(K21/J21,0)) | AD21: =IF(COUNT(C21:O21)=0,"",IFERROR(C21/K21,0)) | AE21: =IF(COUNT(C21:O21)=0,"",IFERROR(L21/K21,0)) | AF21: =IF(COUNT(C21:O21)=0,"",IFERROR(M21/L21,0)) | AG21: =IF(COUNT(C21:O21)=0,"",IFERROR(M21/H21,0)) | AH21: =IF(COUNT(C21:O21)=0,"",IFERROR(C21/M21,0)) | AI21: =IF(COUNT(C21:O21)=0,"",IFERROR(M21*Config!$C$7+N21*Config!$C$8,0)) | AJ21: =IF(COUNT(C21:O21)=0,"",IFERROR(IF(O21>0,O21,AI21*Config!$C$9),0)) | AK21: =IF(COUNT(C21:O21)=0,"",IFERROR(AJ21*(1-Config!$C$10-Config!$C$11-Config!$C$12),0)) | AL21: =IF(COUNT(C21:O21)=0,"",IFERROR(AK21-C21-Config!$C$13,0)) | AM21: =IF(COUNT(C21:O21)=0,"",IFERROR(AK21/C21,0)) | AN21: =IF(COUNT(C21:O21)=0,"",IFERROR(AI21/C21,0)) | AO21: =IF(COUNT(C21:O21)=0,"",IFERROR(AL21/G21,0)) | AP21: =IF(COUNT(C21:O21)=0,"",IFERROR(AO21/U21,0)) | AQ21: =IF(COUNT(C21:O21)=0,"",IFERROR(AL21/H21,0))
A22: =Config!$C$6+16 | B22: =INT((A22-Config!$C$6)/7)+1 | C22: 165 | D22: 15719 | E22: 10105 | F22: 209 | G22: 183 | H22: 51 | I22: 6 | J22: 3 | K22: 2 | L22: 1 | M22: 1 | N22: 0 | O22: 900 | P22: =IF(COUNT(C22:O22)=0,"",IFERROR(C22/D22*1000,0)) | Q22: =IF(COUNT(C22:O22)=0,"",IFERROR(D22/E22,0)) | R22: =IF(COUNT(C22:O22)=0,"",IFERROR(F22/D22,0)) | S22: =IF(COUNT(C22:O22)=0,"",IFERROR(C22/F22,0)) | T22: =IF(COUNT(C22:O22)=0,"",IFERROR(G22/F22,0)) | U22: =IF(COUNT(C22:O22)=0,"",IFERROR(C22/G22,0)) | V22: =IF(COUNT(C22:O22)=0,"",IFERROR(G22/D22*1000,0)) | W22: =IF(COUNT(C22:O22)=0,"",IFERROR(H22/G22,0)) | X22: =IF(COUNT(C22:O22)=0,"",IFERROR(C22/H22,0)) | Y22: =IF(COUNT(C22:O22)=0,"",IFERROR(X22/P22,0)) | Z22: =IF(COUNT(C22:O22)=0,"",IFERROR(H22/D22*1000,0)) | AA22: =IF(COUNT(C22:O22)=0,"",IFERROR(I22/H22,0)) | AB22: =IF(COUNT(C22:O22)=0,"",IFERROR(J22/I22,0)) | AC22: =IF(COUNT(C22:O22)=0,"",IFERROR(K22/J22,0)) | AD22: =IF(COUNT(C22:O22)=0,"",IFERROR(C22/K22,0)) | AE22: =IF(COUNT(C22:O22)=0,"",IFERROR(L22/K22,0)) | AF22: =IF(COUNT(C22:O22)=0,"",IFERROR(M22/L22,0)) | AG22: =IF(COUNT(C22:O22)=0,"",IFERROR(M22/H22,0)) | AH22: =IF(COUNT(C22:O22)=0,"",IFERROR(C22/M22,0)) | AI22: =IF(COUNT(C22:O22)=0,"",IFERROR(M22*Config!$C$7+N22*Config!$C$8,0)) | AJ22: =IF(COUNT(C22:O22)=0,"",IFERROR(IF(O22>0,O22,AI22*Config!$C$9),0)) | AK22: =IF(COUNT(C22:O22)=0,"",IFERROR(AJ22*(1-Config!$C$10-Config!$C$11-Config!$C$12),0)) | AL22: =IF(COUNT(C22:O22)=0,"",IFERROR(AK22-C22-Config!$C$13,0)) | AM22: =IF(COUNT(C22:O22)=0,"",IFERROR(AK22/C22,0)) | AN22: =IF(COUNT(C22:O22)=0,"",IFERROR(AI22/C22,0)) | AO22: =IF(COUNT(C22:O22)=0,"",IFERROR(AL22/G22,0)) | AP22: =IF(COUNT(C22:O22)=0,"",IFERROR(AO22/U22,0)) | AQ22: =IF(COUNT(C22:O22)=0,"",IFERROR(AL22/H22,0))
A23: =Config!$C$6+17 | B23: =INT((A23-Config!$C$6)/7)+1 | C23: 135 | D23: 13324 | E23: 9005 | F23: 219 | G23: 197 | H23: 58 | I23: 7 | J23: 4 | K23: 2 | L23: 2 | M23: 0 | N23: 0 | O23: 0 | P23: =IF(COUNT(C23:O23)=0,"",IFERROR(C23/D23*1000,0)) | Q23: =IF(COUNT(C23:O23)=0,"",IFERROR(D23/E23,0)) | R23: =IF(COUNT(C23:O23)=0,"",IFERROR(F23/D23,0)) | S23: =IF(COUNT(C23:O23)=0,"",IFERROR(C23/F23,0)) | T23: =IF(COUNT(C23:O23)=0,"",IFERROR(G23/F23,0)) | U23: =IF(COUNT(C23:O23)=0,"",IFERROR(C23/G23,0)) | V23: =IF(COUNT(C23:O23)=0,"",IFERROR(G23/D23*1000,0)) | W23: =IF(COUNT(C23:O23)=0,"",IFERROR(H23/G23,0)) | X23: =IF(COUNT(C23:O23)=0,"",IFERROR(C23/H23,0)) | Y23: =IF(COUNT(C23:O23)=0,"",IFERROR(X23/P23,0)) | Z23: =IF(COUNT(C23:O23)=0,"",IFERROR(H23/D23*1000,0)) | AA23: =IF(COUNT(C23:O23)=0,"",IFERROR(I23/H23,0)) | AB23: =IF(COUNT(C23:O23)=0,"",IFERROR(J23/I23,0)) | AC23: =IF(COUNT(C23:O23)=0,"",IFERROR(K23/J23,0)) | AD23: =IF(COUNT(C23:O23)=0,"",IFERROR(C23/K23,0)) | AE23: =IF(COUNT(C23:O23)=0,"",IFERROR(L23/K23,0)) | AF23: =IF(COUNT(C23:O23)=0,"",IFERROR(M23/L23,0)) | AG23: =IF(COUNT(C23:O23)=0,"",IFERROR(M23/H23,0)) | AH23: =IF(COUNT(C23:O23)=0,"",IFERROR(C23/M23,0)) | AI23: =IF(COUNT(C23:O23)=0,"",IFERROR(M23*Config!$C$7+N23*Config!$C$8,0)) | AJ23: =IF(COUNT(C23:O23)=0,"",IFERROR(IF(O23>0,O23,AI23*Config!$C$9),0)) | AK23: =IF(COUNT(C23:O23)=0,"",IFERROR(AJ23*(1-Config!$C$10-Config!$C$11-Config!$C$12),0)) | AL23: =IF(COUNT(C23:O23)=0,"",IFERROR(AK23-C23-Config!$C$13,0)) | AM23: =IF(COUNT(C23:O23)=0,"",IFERROR(AK23/C23,0)) | AN23: =IF(COUNT(C23:O23)=0,"",IFERROR(AI23/C23,0)) | AO23: =IF(COUNT(C23:O23)=0,"",IFERROR(AL23/G23,0)) | AP23: =IF(COUNT(C23:O23)=0,"",IFERROR(AO23/U23,0)) | AQ23: =IF(COUNT(C23:O23)=0,"",IFERROR(AL23/H23,0))
A24: =Config!$C$6+18 | B24: =INT((A24-Config!$C$6)/7)+1 | C24: 164 | D24: 15098 | E24: 11003 | F24: 242 | G24: 224 | H24: 64 | I24: 7 | J24: 4 | K24: 2 | L24: 2 | M24: 0 | N24: 0 | O24: 0 | P24: =IF(COUNT(C24:O24)=0,"",IFERROR(C24/D24*1000,0)) | Q24: =IF(COUNT(C24:O24)=0,"",IFERROR(D24/E24,0)) | R24: =IF(COUNT(C24:O24)=0,"",IFERROR(F24/D24,0)) | S24: =IF(COUNT(C24:O24)=0,"",IFERROR(C24/F24,0)) | T24: =IF(COUNT(C24:O24)=0,"",IFERROR(G24/F24,0)) | U24: =IF(COUNT(C24:O24)=0,"",IFERROR(C24/G24,0)) | V24: =IF(COUNT(C24:O24)=0,"",IFERROR(G24/D24*1000,0)) | W24: =IF(COUNT(C24:O24)=0,"",IFERROR(H24/G24,0)) | X24: =IF(COUNT(C24:O24)=0,"",IFERROR(C24/H24,0)) | Y24: =IF(COUNT(C24:O24)=0,"",IFERROR(X24/P24,0)) | Z24: =IF(COUNT(C24:O24)=0,"",IFERROR(H24/D24*1000,0)) | AA24: =IF(COUNT(C24:O24)=0,"",IFERROR(I24/H24,0)) | AB24: =IF(COUNT(C24:O24)=0,"",IFERROR(J24/I24,0)) | AC24: =IF(COUNT(C24:O24)=0,"",IFERROR(K24/J24,0)) | AD24: =IF(COUNT(C24:O24)=0,"",IFERROR(C24/K24,0)) | AE24: =IF(COUNT(C24:O24)=0,"",IFERROR(L24/K24,0)) | AF24: =IF(COUNT(C24:O24)=0,"",IFERROR(M24/L24,0)) | AG24: =IF(COUNT(C24:O24)=0,"",IFERROR(M24/H24,0)) | AH24: =IF(COUNT(C24:O24)=0,"",IFERROR(C24/M24,0)) | AI24: =IF(COUNT(C24:O24)=0,"",IFERROR(M24*Config!$C$7+N24*Config!$C$8,0)) | AJ24: =IF(COUNT(C24:O24)=0,"",IFERROR(IF(O24>0,O24,AI24*Config!$C$9),0)) | AK24: =IF(COUNT(C24:O24)=0,"",IFERROR(AJ24*(1-Config!$C$10-Config!$C$11-Config!$C$12),0)) | AL24: =IF(COUNT(C24:O24)=0,"",IFERROR(AK24-C24-Config!$C$13,0)) | AM24: =IF(COUNT(C24:O24)=0,"",IFERROR(AK24/C24,0)) | AN24: =IF(COUNT(C24:O24)=0,"",IFERROR(AI24/C24,0)) | AO24: =IF(COUNT(C24:O24)=0,"",IFERROR(AL24/G24,0)) | AP24: =IF(COUNT(C24:O24)=0,"",IFERROR(AO24/U24,0)) | AQ24: =IF(COUNT(C24:O24)=0,"",IFERROR(AL24/H24,0))
A25: =Config!$C$6+19 | B25: =INT((A25-Config!$C$6)/7)+1 | C25: 135 | D25: 13052 | E25: 8336 | F25: 214 | G25: 192 | H25: 52 | I25: 6 | J25: 4 | K25: 2 | L25: 2 | M25: 0 | N25: 0 | O25: 0 | P25: =IF(COUNT(C25:O25)=0,"",IFERROR(C25/D25*1000,0)) | Q25: =IF(COUNT(C25:O25)=0,"",IFERROR(D25/E25,0)) | R25: =IF(COUNT(C25:O25)=0,"",IFERROR(F25/D25,0)) | S25: =IF(COUNT(C25:O25)=0,"",IFERROR(C25/F25,0)) | T25: =IF(COUNT(C25:O25)=0,"",IFERROR(G25/F25,0)) | U25: =IF(COUNT(C25:O25)=0,"",IFERROR(C25/G25,0)) | V25: =IF(COUNT(C25:O25)=0,"",IFERROR(G25/D25*1000,0)) | W25: =IF(COUNT(C25:O25)=0,"",IFERROR(H25/G25,0)) | X25: =IF(COUNT(C25:O25)=0,"",IFERROR(C25/H25,0)) | Y25: =IF(COUNT(C25:O25)=0,"",IFERROR(X25/P25,0)) | Z25: =IF(COUNT(C25:O25)=0,"",IFERROR(H25/D25*1000,0)) | AA25: =IF(COUNT(C25:O25)=0,"",IFERROR(I25/H25,0)) | AB25: =IF(COUNT(C25:O25)=0,"",IFERROR(J25/I25,0)) | AC25: =IF(COUNT(C25:O25)=0,"",IFERROR(K25/J25,0)) | AD25: =IF(COUNT(C25:O25)=0,"",IFERROR(C25/K25,0)) | AE25: =IF(COUNT(C25:O25)=0,"",IFERROR(L25/K25,0)) | AF25: =IF(COUNT(C25:O25)=0,"",IFERROR(M25/L25,0)) | AG25: =IF(COUNT(C25:O25)=0,"",IFERROR(M25/H25,0)) | AH25: =IF(COUNT(C25:O25)=0,"",IFERROR(C25/M25,0)) | AI25: =IF(COUNT(C25:O25)=0,"",IFERROR(M25*Config!$C$7+N25*Config!$C$8,0)) | AJ25: =IF(COUNT(C25:O25)=0,"",IFERROR(IF(O25>0,O25,AI25*Config!$C$9),0)) | AK25: =IF(COUNT(C25:O25)=0,"",IFERROR(AJ25*(1-Config!$C$10-Config!$C$11-Config!$C$12),0)) | AL25: =IF(COUNT(C25:O25)=0,"",IFERROR(AK25-C25-Config!$C$13,0)) | AM25: =IF(COUNT(C25:O25)=0,"",IFERROR(AK25/C25,0)) | AN25: =IF(COUNT(C25:O25)=0,"",IFERROR(AI25/C25,0)) | AO25: =IF(COUNT(C25:O25)=0,"",IFERROR(AL25/G25,0)) | AP25: =IF(COUNT(C25:O25)=0,"",IFERROR(AO25/U25,0)) | AQ25: =IF(COUNT(C25:O25)=0,"",IFERROR(AL25/H25,0))
A26: =Config!$C$6+20 | B26: =INT((A26-Config!$C$6)/7)+1 | C26: 135 | D26: 12737 | E26: 10255 | F26: 196 | G26: 166 | H26: 43 | I26: 5 | J26: 3 | K26: 2 | L26: 1 | M26: 0 | N26: 0 | O26: 0 | P26: =IF(COUNT(C26:O26)=0,"",IFERROR(C26/D26*1000,0)) | Q26: =IF(COUNT(C26:O26)=0,"",IFERROR(D26/E26,0)) | R26: =IF(COUNT(C26:O26)=0,"",IFERROR(F26/D26,0)) | S26: =IF(COUNT(C26:O26)=0,"",IFERROR(C26/F26,0)) | T26: =IF(COUNT(C26:O26)=0,"",IFERROR(G26/F26,0)) | U26: =IF(COUNT(C26:O26)=0,"",IFERROR(C26/G26,0)) | V26: =IF(COUNT(C26:O26)=0,"",IFERROR(G26/D26*1000,0)) | W26: =IF(COUNT(C26:O26)=0,"",IFERROR(H26/G26,0)) | X26: =IF(COUNT(C26:O26)=0,"",IFERROR(C26/H26,0)) | Y26: =IF(COUNT(C26:O26)=0,"",IFERROR(X26/P26,0)) | Z26: =IF(COUNT(C26:O26)=0,"",IFERROR(H26/D26*1000,0)) | AA26: =IF(COUNT(C26:O26)=0,"",IFERROR(I26/H26,0)) | AB26: =IF(COUNT(C26:O26)=0,"",IFERROR(J26/I26,0)) | AC26: =IF(COUNT(C26:O26)=0,"",IFERROR(K26/J26,0)) | AD26: =IF(COUNT(C26:O26)=0,"",IFERROR(C26/K26,0)) | AE26: =IF(COUNT(C26:O26)=0,"",IFERROR(L26/K26,0)) | AF26: =IF(COUNT(C26:O26)=0,"",IFERROR(M26/L26,0)) | AG26: =IF(COUNT(C26:O26)=0,"",IFERROR(M26/H26,0)) | AH26: =IF(COUNT(C26:O26)=0,"",IFERROR(C26/M26,0)) | AI26: =IF(COUNT(C26:O26)=0,"",IFERROR(M26*Config!$C$7+N26*Config!$C$8,0)) | AJ26: =IF(COUNT(C26:O26)=0,"",IFERROR(IF(O26>0,O26,AI26*Config!$C$9),0)) | AK26: =IF(COUNT(C26:O26)=0,"",IFERROR(AJ26*(1-Config!$C$10-Config!$C$11-Config!$C$12),0)) | AL26: =IF(COUNT(C26:O26)=0,"",IFERROR(AK26-C26-Config!$C$13,0)) | AM26: =IF(COUNT(C26:O26)=0,"",IFERROR(AK26/C26,0)) | AN26: =IF(COUNT(C26:O26)=0,"",IFERROR(AI26/C26,0)) | AO26: =IF(COUNT(C26:O26)=0,"",IFERROR(AL26/G26,0)) | AP26: =IF(COUNT(C26:O26)=0,"",IFERROR(AO26/U26,0)) | AQ26: =IF(COUNT(C26:O26)=0,"",IFERROR(AL26/H26,0))
A27: =Config!$C$6+21 | B27: =INT((A27-Config!$C$6)/7)+1 | C27: 141 | D27: 15997 | E27: 12000 | F27: 250 | G27: 198 | H27: 51 | I27: 6 | J27: 4 | K27: 2 | L27: 2 | M27: 0 | N27: 0 | O27: 0 | P27: =IF(COUNT(C27:O27)=0,"",IFERROR(C27/D27*1000,0)) | Q27: =IF(COUNT(C27:O27)=0,"",IFERROR(D27/E27,0)) | R27: =IF(COUNT(C27:O27)=0,"",IFERROR(F27/D27,0)) | S27: =IF(COUNT(C27:O27)=0,"",IFERROR(C27/F27,0)) | T27: =IF(COUNT(C27:O27)=0,"",IFERROR(G27/F27,0)) | U27: =IF(COUNT(C27:O27)=0,"",IFERROR(C27/G27,0)) | V27: =IF(COUNT(C27:O27)=0,"",IFERROR(G27/D27*1000,0)) | W27: =IF(COUNT(C27:O27)=0,"",IFERROR(H27/G27,0)) | X27: =IF(COUNT(C27:O27)=0,"",IFERROR(C27/H27,0)) | Y27: =IF(COUNT(C27:O27)=0,"",IFERROR(X27/P27,0)) | Z27: =IF(COUNT(C27:O27)=0,"",IFERROR(H27/D27*1000,0)) | AA27: =IF(COUNT(C27:O27)=0,"",IFERROR(I27/H27,0)) | AB27: =IF(COUNT(C27:O27)=0,"",IFERROR(J27/I27,0)) | AC27: =IF(COUNT(C27:O27)=0,"",IFERROR(K27/J27,0)) | AD27: =IF(COUNT(C27:O27)=0,"",IFERROR(C27/K27,0)) | AE27: =IF(COUNT(C27:O27)=0,"",IFERROR(L27/K27,0)) | AF27: =IF(COUNT(C27:O27)=0,"",IFERROR(M27/L27,0)) | AG27: =IF(COUNT(C27:O27)=0,"",IFERROR(M27/H27,0)) | AH27: =IF(COUNT(C27:O27)=0,"",IFERROR(C27/M27,0)) | AI27: =IF(COUNT(C27:O27)=0,"",IFERROR(M27*Config!$C$7+N27*Config!$C$8,0)) | AJ27: =IF(COUNT(C27:O27)=0,"",IFERROR(IF(O27>0,O27,AI27*Config!$C$9),0)) | AK27: =IF(COUNT(C27:O27)=0,"",IFERROR(AJ27*(1-Config!$C$10-Config!$C$11-Config!$C$12),0)) | AL27: =IF(COUNT(C27:O27)=0,"",IFERROR(AK27-C27-Config!$C$13,0)) | AM27: =IF(COUNT(C27:O27)=0,"",IFERROR(AK27/C27,0)) | AN27: =IF(COUNT(C27:O27)=0,"",IFERROR(AI27/C27,0)) | AO27: =IF(COUNT(C27:O27)=0,"",IFERROR(AL27/G27,0)) | AP27: =IF(COUNT(C27:O27)=0,"",IFERROR(AO27/U27,0)) | AQ27: =IF(COUNT(C27:O27)=0,"",IFERROR(AL27/H27,0))
A28: =Config!$C$6+22 | B28: =INT((A28-Config!$C$6)/7)+1 | C28: 144 | D28: 13827 | E28: 10646 | F28: 204 | G28: 186 | H28: 57 | I28: 7 | J28: 4 | K28: 3 | L28: 2 | M28: 0 | N28: 0 | O28: 0 | P28: =IF(COUNT(C28:O28)=0,"",IFERROR(C28/D28*1000,0)) | Q28: =IF(COUNT(C28:O28)=0,"",IFERROR(D28/E28,0)) | R28: =IF(COUNT(C28:O28)=0,"",IFERROR(F28/D28,0)) | S28: =IF(COUNT(C28:O28)=0,"",IFERROR(C28/F28,0)) | T28: =IF(COUNT(C28:O28)=0,"",IFERROR(G28/F28,0)) | U28: =IF(COUNT(C28:O28)=0,"",IFERROR(C28/G28,0)) | V28: =IF(COUNT(C28:O28)=0,"",IFERROR(G28/D28*1000,0)) | W28: =IF(COUNT(C28:O28)=0,"",IFERROR(H28/G28,0)) | X28: =IF(COUNT(C28:O28)=0,"",IFERROR(C28/H28,0)) | Y28: =IF(COUNT(C28:O28)=0,"",IFERROR(X28/P28,0)) | Z28: =IF(COUNT(C28:O28)=0,"",IFERROR(H28/D28*1000,0)) | AA28: =IF(COUNT(C28:O28)=0,"",IFERROR(I28/H28,0)) | AB28: =IF(COUNT(C28:O28)=0,"",IFERROR(J28/I28,0)) | AC28: =IF(COUNT(C28:O28)=0,"",IFERROR(K28/J28,0)) | AD28: =IF(COUNT(C28:O28)=0,"",IFERROR(C28/K28,0)) | AE28: =IF(COUNT(C28:O28)=0,"",IFERROR(L28/K28,0)) | AF28: =IF(COUNT(C28:O28)=0,"",IFERROR(M28/L28,0)) | AG28: =IF(COUNT(C28:O28)=0,"",IFERROR(M28/H28,0)) | AH28: =IF(COUNT(C28:O28)=0,"",IFERROR(C28/M28,0)) | AI28: =IF(COUNT(C28:O28)=0,"",IFERROR(M28*Config!$C$7+N28*Config!$C$8,0)) | AJ28: =IF(COUNT(C28:O28)=0,"",IFERROR(IF(O28>0,O28,AI28*Config!$C$9),0)) | AK28: =IF(COUNT(C28:O28)=0,"",IFERROR(AJ28*(1-Config!$C$10-Config!$C$11-Config!$C$12),0)) | AL28: =IF(COUNT(C28:O28)=0,"",IFERROR(AK28-C28-Config!$C$13,0)) | AM28: =IF(COUNT(C28:O28)=0,"",IFERROR(AK28/C28,0)) | AN28: =IF(COUNT(C28:O28)=0,"",IFERROR(AI28/C28,0)) | AO28: =IF(COUNT(C28:O28)=0,"",IFERROR(AL28/G28,0)) | AP28: =IF(COUNT(C28:O28)=0,"",IFERROR(AO28/U28,0)) | AQ28: =IF(COUNT(C28:O28)=0,"",IFERROR(AL28/H28,0))
A29: =Config!$C$6+23 | B29: =INT((A29-Config!$C$6)/7)+1 | C29: 137 | D29: 13702 | E29: 9055 | F29: 223 | G29: 199 | H29: 62 | I29: 5 | J29: 3 | K29: 2 | L29: 1 | M29: 1 | N29: 0 | O29: 900 | P29: =IF(COUNT(C29:O29)=0,"",IFERROR(C29/D29*1000,0)) | Q29: =IF(COUNT(C29:O29)=0,"",IFERROR(D29/E29,0)) | R29: =IF(COUNT(C29:O29)=0,"",IFERROR(F29/D29,0)) | S29: =IF(COUNT(C29:O29)=0,"",IFERROR(C29/F29,0)) | T29: =IF(COUNT(C29:O29)=0,"",IFERROR(G29/F29,0)) | U29: =IF(COUNT(C29:O29)=0,"",IFERROR(C29/G29,0)) | V29: =IF(COUNT(C29:O29)=0,"",IFERROR(G29/D29*1000,0)) | W29: =IF(COUNT(C29:O29)=0,"",IFERROR(H29/G29,0)) | X29: =IF(COUNT(C29:O29)=0,"",IFERROR(C29/H29,0)) | Y29: =IF(COUNT(C29:O29)=0,"",IFERROR(X29/P29,0)) | Z29: =IF(COUNT(C29:O29)=0,"",IFERROR(H29/D29*1000,0)) | AA29: =IF(COUNT(C29:O29)=0,"",IFERROR(I29/H29,0)) | AB29: =IF(COUNT(C29:O29)=0,"",IFERROR(J29/I29,0)) | AC29: =IF(COUNT(C29:O29)=0,"",IFERROR(K29/J29,0)) | AD29: =IF(COUNT(C29:O29)=0,"",IFERROR(C29/K29,0)) | AE29: =IF(COUNT(C29:O29)=0,"",IFERROR(L29/K29,0)) | AF29: =IF(COUNT(C29:O29)=0,"",IFERROR(M29/L29,0)) | AG29: =IF(COUNT(C29:O29)=0,"",IFERROR(M29/H29,0)) | AH29: =IF(COUNT(C29:O29)=0,"",IFERROR(C29/M29,0)) | AI29: =IF(COUNT(C29:O29)=0,"",IFERROR(M29*Config!$C$7+N29*Config!$C$8,0)) | AJ29: =IF(COUNT(C29:O29)=0,"",IFERROR(IF(O29>0,O29,AI29*Config!$C$9),0)) | AK29: =IF(COUNT(C29:O29)=0,"",IFERROR(AJ29*(1-Config!$C$10-Config!$C$11-Config!$C$12),0)) | AL29: =IF(COUNT(C29:O29)=0,"",IFERROR(AK29-C29-Config!$C$13,0)) | AM29: =IF(COUNT(C29:O29)=0,"",IFERROR(AK29/C29,0)) | AN29: =IF(COUNT(C29:O29)=0,"",IFERROR(AI29/C29,0)) | AO29: =IF(COUNT(C29:O29)=0,"",IFERROR(AL29/G29,0)) | AP29: =IF(COUNT(C29:O29)=0,"",IFERROR(AO29/U29,0)) | AQ29: =IF(COUNT(C29:O29)=0,"",IFERROR(AL29/H29,0))
A30: =Config!$C$6+24 | B30: =INT((A30-Config!$C$6)/7)+1 | C30: 142 | D30: 15236 | E30: 11112 | F30: 235 | G30: 200 | H30: 53 | I30: 6 | J30: 4 | K30: 2 | L30: 2 | M30: 0 | N30: 0 | O30: 300 | P30: =IF(COUNT(C30:O30)=0,"",IFERROR(C30/D30*1000,0)) | Q30: =IF(COUNT(C30:O30)=0,"",IFERROR(D30/E30,0)) | R30: =IF(COUNT(C30:O30)=0,"",IFERROR(F30/D30,0)) | S30: =IF(COUNT(C30:O30)=0,"",IFERROR(C30/F30,0)) | T30: =IF(COUNT(C30:O30)=0,"",IFERROR(G30/F30,0)) | U30: =IF(COUNT(C30:O30)=0,"",IFERROR(C30/G30,0)) | V30: =IF(COUNT(C30:O30)=0,"",IFERROR(G30/D30*1000,0)) | W30: =IF(COUNT(C30:O30)=0,"",IFERROR(H30/G30,0)) | X30: =IF(COUNT(C30:O30)=0,"",IFERROR(C30/H30,0)) | Y30: =IF(COUNT(C30:O30)=0,"",IFERROR(X30/P30,0)) | Z30: =IF(COUNT(C30:O30)=0,"",IFERROR(H30/D30*1000,0)) | AA30: =IF(COUNT(C30:O30)=0,"",IFERROR(I30/H30,0)) | AB30: =IF(COUNT(C30:O30)=0,"",IFERROR(J30/I30,0)) | AC30: =IF(COUNT(C30:O30)=0,"",IFERROR(K30/J30,0)) | AD30: =IF(COUNT(C30:O30)=0,"",IFERROR(C30/K30,0)) | AE30: =IF(COUNT(C30:O30)=0,"",IFERROR(L30/K30,0)) | AF30: =IF(COUNT(C30:O30)=0,"",IFERROR(M30/L30,0)) | AG30: =IF(COUNT(C30:O30)=0,"",IFERROR(M30/H30,0)) | AH30: =IF(COUNT(C30:O30)=0,"",IFERROR(C30/M30,0)) | AI30: =IF(COUNT(C30:O30)=0,"",IFERROR(M30*Config!$C$7+N30*Config!$C$8,0)) | AJ30: =IF(COUNT(C30:O30)=0,"",IFERROR(IF(O30>0,O30,AI30*Config!$C$9),0)) | AK30: =IF(COUNT(C30:O30)=0,"",IFERROR(AJ30*(1-Config!$C$10-Config!$C$11-Config!$C$12),0)) | AL30: =IF(COUNT(C30:O30)=0,"",IFERROR(AK30-C30-Config!$C$13,0)) | AM30: =IF(COUNT(C30:O30)=0,"",IFERROR(AK30/C30,0)) | AN30: =IF(COUNT(C30:O30)=0,"",IFERROR(AI30/C30,0)) | AO30: =IF(COUNT(C30:O30)=0,"",IFERROR(AL30/G30,0)) | AP30: =IF(COUNT(C30:O30)=0,"",IFERROR(AO30/U30,0)) | AQ30: =IF(COUNT(C30:O30)=0,"",IFERROR(AL30/H30,0))
A31: =Config!$C$6+25 | B31: =INT((A31-Config!$C$6)/7)+1 | C31: 133 | D31: 12220 | E31: 9808 | F31: 192 | G31: 166 | H31: 44 | I31: 5 | J31: 3 | K31: 2 | L31: 1 | M31: 1 | N31: 0 | O31: 1200 | P31: =IF(COUNT(C31:O31)=0,"",IFERROR(C31/D31*1000,0)) | Q31: =IF(COUNT(C31:O31)=0,"",IFERROR(D31/E31,0)) | R31: =IF(COUNT(C31:O31)=0,"",IFERROR(F31/D31,0)) | S31: =IF(COUNT(C31:O31)=0,"",IFERROR(C31/F31,0)) | T31: =IF(COUNT(C31:O31)=0,"",IFERROR(G31/F31,0)) | U31: =IF(COUNT(C31:O31)=0,"",IFERROR(C31/G31,0)) | V31: =IF(COUNT(C31:O31)=0,"",IFERROR(G31/D31*1000,0)) | W31: =IF(COUNT(C31:O31)=0,"",IFERROR(H31/G31,0)) | X31: =IF(COUNT(C31:O31)=0,"",IFERROR(C31/H31,0)) | Y31: =IF(COUNT(C31:O31)=0,"",IFERROR(X31/P31,0)) | Z31: =IF(COUNT(C31:O31)=0,"",IFERROR(H31/D31*1000,0)) | AA31: =IF(COUNT(C31:O31)=0,"",IFERROR(I31/H31,0)) | AB31: =IF(COUNT(C31:O31)=0,"",IFERROR(J31/I31,0)) | AC31: =IF(COUNT(C31:O31)=0,"",IFERROR(K31/J31,0)) | AD31: =IF(COUNT(C31:O31)=0,"",IFERROR(C31/K31,0)) | AE31: =IF(COUNT(C31:O31)=0,"",IFERROR(L31/K31,0)) | AF31: =IF(COUNT(C31:O31)=0,"",IFERROR(M31/L31,0)) | AG31: =IF(COUNT(C31:O31)=0,"",IFERROR(M31/H31,0)) | AH31: =IF(COUNT(C31:O31)=0,"",IFERROR(C31/M31,0)) | AI31: =IF(COUNT(C31:O31)=0,"",IFERROR(M31*Config!$C$7+N31*Config!$C$8,0)) | AJ31: =IF(COUNT(C31:O31)=0,"",IFERROR(IF(O31>0,O31,AI31*Config!$C$9),0)) | AK31: =IF(COUNT(C31:O31)=0,"",IFERROR(AJ31*(1-Config!$C$10-Config!$C$11-Config!$C$12),0)) | AL31: =IF(COUNT(C31:O31)=0,"",IFERROR(AK31-C31-Config!$C$13,0)) | AM31: =IF(COUNT(C31:O31)=0,"",IFERROR(AK31/C31,0)) | AN31: =IF(COUNT(C31:O31)=0,"",IFERROR(AI31/C31,0)) | AO31: =IF(COUNT(C31:O31)=0,"",IFERROR(AL31/G31,0)) | AP31: =IF(COUNT(C31:O31)=0,"",IFERROR(AO31/U31,0)) | AQ31: =IF(COUNT(C31:O31)=0,"",IFERROR(AL31/H31,0))
A32: =Config!$C$6+26 | B32: =INT((A32-Config!$C$6)/7)+1 | C32: 148 | D32: 16748 | E32: 11086 | F32: 235 | G32: 183 | H32: 46 | I32: 5 | J32: 3 | K32: 2 | L32: 1 | M32: 0 | N32: 0 | O32: 0 | P32: =IF(COUNT(C32:O32)=0,"",IFERROR(C32/D32*1000,0)) | Q32: =IF(COUNT(C32:O32)=0,"",IFERROR(D32/E32,0)) | R32: =IF(COUNT(C32:O32)=0,"",IFERROR(F32/D32,0)) | S32: =IF(COUNT(C32:O32)=0,"",IFERROR(C32/F32,0)) | T32: =IF(COUNT(C32:O32)=0,"",IFERROR(G32/F32,0)) | U32: =IF(COUNT(C32:O32)=0,"",IFERROR(C32/G32,0)) | V32: =IF(COUNT(C32:O32)=0,"",IFERROR(G32/D32*1000,0)) | W32: =IF(COUNT(C32:O32)=0,"",IFERROR(H32/G32,0)) | X32: =IF(COUNT(C32:O32)=0,"",IFERROR(C32/H32,0)) | Y32: =IF(COUNT(C32:O32)=0,"",IFERROR(X32/P32,0)) | Z32: =IF(COUNT(C32:O32)=0,"",IFERROR(H32/D32*1000,0)) | AA32: =IF(COUNT(C32:O32)=0,"",IFERROR(I32/H32,0)) | AB32: =IF(COUNT(C32:O32)=0,"",IFERROR(J32/I32,0)) | AC32: =IF(COUNT(C32:O32)=0,"",IFERROR(K32/J32,0)) | AD32: =IF(COUNT(C32:O32)=0,"",IFERROR(C32/K32,0)) | AE32: =IF(COUNT(C32:O32)=0,"",IFERROR(L32/K32,0)) | AF32: =IF(COUNT(C32:O32)=0,"",IFERROR(M32/L32,0)) | AG32: =IF(COUNT(C32:O32)=0,"",IFERROR(M32/H32,0)) | AH32: =IF(COUNT(C32:O32)=0,"",IFERROR(C32/M32,0)) | AI32: =IF(COUNT(C32:O32)=0,"",IFERROR(M32*Config!$C$7+N32*Config!$C$8,0)) | AJ32: =IF(COUNT(C32:O32)=0,"",IFERROR(IF(O32>0,O32,AI32*Config!$C$9),0)) | AK32: =IF(COUNT(C32:O32)=0,"",IFERROR(AJ32*(1-Config!$C$10-Config!$C$11-Config!$C$12),0)) | AL32: =IF(COUNT(C32:O32)=0,"",IFERROR(AK32-C32-Config!$C$13,0)) | AM32: =IF(COUNT(C32:O32)=0,"",IFERROR(AK32/C32,0)) | AN32: =IF(COUNT(C32:O32)=0,"",IFERROR(AI32/C32,0)) | AO32: =IF(COUNT(C32:O32)=0,"",IFERROR(AL32/G32,0)) | AP32: =IF(COUNT(C32:O32)=0,"",IFERROR(AO32/U32,0)) | AQ32: =IF(COUNT(C32:O32)=0,"",IFERROR(AL32/H32,0))
A33: =Config!$C$6+27 | B33: =INT((A33-Config!$C$6)/7)+1 | C33: 161 | D33: 14510 | E33: 9925 | F33: 202 | G33: 171 | H33: 44 | I33: 3 | J33: 2 | K33: 1 | L33: 1 | M33: 0 | N33: 0 | O33: 300 | P33: =IF(COUNT(C33:O33)=0,"",IFERROR(C33/D33*1000,0)) | Q33: =IF(COUNT(C33:O33)=0,"",IFERROR(D33/E33,0)) | R33: =IF(COUNT(C33:O33)=0,"",IFERROR(F33/D33,0)) | S33: =IF(COUNT(C33:O33)=0,"",IFERROR(C33/F33,0)) | T33: =IF(COUNT(C33:O33)=0,"",IFERROR(G33/F33,0)) | U33: =IF(COUNT(C33:O33)=0,"",IFERROR(C33/G33,0)) | V33: =IF(COUNT(C33:O33)=0,"",IFERROR(G33/D33*1000,0)) | W33: =IF(COUNT(C33:O33)=0,"",IFERROR(H33/G33,0)) | X33: =IF(COUNT(C33:O33)=0,"",IFERROR(C33/H33,0)) | Y33: =IF(COUNT(C33:O33)=0,"",IFERROR(X33/P33,0)) | Z33: =IF(COUNT(C33:O33)=0,"",IFERROR(H33/D33*1000,0)) | AA33: =IF(COUNT(C33:O33)=0,"",IFERROR(I33/H33,0)) | AB33: =IF(COUNT(C33:O33)=0,"",IFERROR(J33/I33,0)) | AC33: =IF(COUNT(C33:O33)=0,"",IFERROR(K33/J33,0)) | AD33: =IF(COUNT(C33:O33)=0,"",IFERROR(C33/K33,0)) | AE33: =IF(COUNT(C33:O33)=0,"",IFERROR(L33/K33,0)) | AF33: =IF(COUNT(C33:O33)=0,"",IFERROR(M33/L33,0)) | AG33: =IF(COUNT(C33:O33)=0,"",IFERROR(M33/H33,0)) | AH33: =IF(COUNT(C33:O33)=0,"",IFERROR(C33/M33,0)) | AI33: =IF(COUNT(C33:O33)=0,"",IFERROR(M33*Config!$C$7+N33*Config!$C$8,0)) | AJ33: =IF(COUNT(C33:O33)=0,"",IFERROR(IF(O33>0,O33,AI33*Config!$C$9),0)) | AK33: =IF(COUNT(C33:O33)=0,"",IFERROR(AJ33*(1-Config!$C$10-Config!$C$11-Config!$C$12),0)) | AL33: =IF(COUNT(C33:O33)=0,"",IFERROR(AK33-C33-Config!$C$13,0)) | AM33: =IF(COUNT(C33:O33)=0,"",IFERROR(AK33/C33,0)) | AN33: =IF(COUNT(C33:O33)=0,"",IFERROR(AI33/C33,0)) | AO33: =IF(COUNT(C33:O33)=0,"",IFERROR(AL33/G33,0)) | AP33: =IF(COUNT(C33:O33)=0,"",IFERROR(AO33/U33,0)) | AQ33: =IF(COUNT(C33:O33)=0,"",IFERROR(AL33/H33,0))
A34: =Config!$C$6+28 | B34: =INT((A34-Config!$C$6)/7)+1 | P34: =IF(COUNT(C34:O34)=0,"",IFERROR(C34/D34*1000,0)) | Q34: =IF(COUNT(C34:O34)=0,"",IFERROR(D34/E34,0)) | R34: =IF(COUNT(C34:O34)=0,"",IFERROR(F34/D34,0)) | S34: =IF(COUNT(C34:O34)=0,"",IFERROR(C34/F34,0)) | T34: =IF(COUNT(C34:O34)=0,"",IFERROR(G34/F34,0)) | U34: =IF(COUNT(C34:O34)=0,"",IFERROR(C34/G34,0)) | V34: =IF(COUNT(C34:O34)=0,"",IFERROR(G34/D34*1000,0)) | W34: =IF(COUNT(C34:O34)=0,"",IFERROR(H34/G34,0)) | X34: =IF(COUNT(C34:O34)=0,"",IFERROR(C34/H34,0)) | Y34: =IF(COUNT(C34:O34)=0,"",IFERROR(X34/P34,0)) | Z34: =IF(COUNT(C34:O34)=0,"",IFERROR(H34/D34*1000,0)) | AA34: =IF(COUNT(C34:O34)=0,"",IFERROR(I34/H34,0)) | AB34: =IF(COUNT(C34:O34)=0,"",IFERROR(J34/I34,0)) | AC34: =IF(COUNT(C34:O34)=0,"",IFERROR(K34/J34,0)) | AD34: =IF(COUNT(C34:O34)=0,"",IFERROR(C34/K34,0)) | AE34: =IF(COUNT(C34:O34)=0,"",IFERROR(L34/K34,0)) | AF34: =IF(COUNT(C34:O34)=0,"",IFERROR(M34/L34,0)) | AG34: =IF(COUNT(C34:O34)=0,"",IFERROR(M34/H34,0)) | AH34: =IF(COUNT(C34:O34)=0,"",IFERROR(C34/M34,0)) | AI34: =IF(COUNT(C34:O34)=0,"",IFERROR(M34*Config!$C$7+N34*Config!$C$8,0)) | AJ34: =IF(COUNT(C34:O34)=0,"",IFERROR(IF(O34>0,O34,AI34*Config!$C$9),0)) | AK34: =IF(COUNT(C34:O34)=0,"",IFERROR(AJ34*(1-Config!$C$10-Config!$C$11-Config!$C$12),0)) | AL34: =IF(COUNT(C34:O34)=0,"",IFERROR(AK34-C34-Config!$C$13,0)) | AM34: =IF(COUNT(C34:O34)=0,"",IFERROR(AK34/C34,0)) | AN34: =IF(COUNT(C34:O34)=0,"",IFERROR(AI34/C34,0)) | AO34: =IF(COUNT(C34:O34)=0,"",IFERROR(AL34/G34,0)) | AP34: =IF(COUNT(C34:O34)=0,"",IFERROR(AO34/U34,0)) | AQ34: =IF(COUNT(C34:O34)=0,"",IFERROR(AL34/H34,0))
A35: =Config!$C$6+29 | B35: =INT((A35-Config!$C$6)/7)+1 | P35: =IF(COUNT(C35:O35)=0,"",IFERROR(C35/D35*1000,0)) | Q35: =IF(COUNT(C35:O35)=0,"",IFERROR(D35/E35,0)) | R35: =IF(COUNT(C35:O35)=0,"",IFERROR(F35/D35,0)) | S35: =IF(COUNT(C35:O35)=0,"",IFERROR(C35/F35,0)) | T35: =IF(COUNT(C35:O35)=0,"",IFERROR(G35/F35,0)) | U35: =IF(COUNT(C35:O35)=0,"",IFERROR(C35/G35,0)) | V35: =IF(COUNT(C35:O35)=0,"",IFERROR(G35/D35*1000,0)) | W35: =IF(COUNT(C35:O35)=0,"",IFERROR(H35/G35,0)) | X35: =IF(COUNT(C35:O35)=0,"",IFERROR(C35/H35,0)) | Y35: =IF(COUNT(C35:O35)=0,"",IFERROR(X35/P35,0)) | Z35: =IF(COUNT(C35:O35)=0,"",IFERROR(H35/D35*1000,0)) | AA35: =IF(COUNT(C35:O35)=0,"",IFERROR(I35/H35,0)) | AB35: =IF(COUNT(C35:O35)=0,"",IFERROR(J35/I35,0)) | AC35: =IF(COUNT(C35:O35)=0,"",IFERROR(K35/J35,0)) | AD35: =IF(COUNT(C35:O35)=0,"",IFERROR(C35/K35,0)) | AE35: =IF(COUNT(C35:O35)=0,"",IFERROR(L35/K35,0)) | AF35: =IF(COUNT(C35:O35)=0,"",IFERROR(M35/L35,0)) | AG35: =IF(COUNT(C35:O35)=0,"",IFERROR(M35/H35,0)) | AH35: =IF(COUNT(C35:O35)=0,"",IFERROR(C35/M35,0)) | AI35: =IF(COUNT(C35:O35)=0,"",IFERROR(M35*Config!$C$7+N35*Config!$C$8,0)) | AJ35: =IF(COUNT(C35:O35)=0,"",IFERROR(IF(O35>0,O35,AI35*Config!$C$9),0)) | AK35: =IF(COUNT(C35:O35)=0,"",IFERROR(AJ35*(1-Config!$C$10-Config!$C$11-Config!$C$12),0)) | AL35: =IF(COUNT(C35:O35)=0,"",IFERROR(AK35-C35-Config!$C$13,0)) | AM35: =IF(COUNT(C35:O35)=0,"",IFERROR(AK35/C35,0)) | AN35: =IF(COUNT(C35:O35)=0,"",IFERROR(AI35/C35,0)) | AO35: =IF(COUNT(C35:O35)=0,"",IFERROR(AL35/G35,0)) | AP35: =IF(COUNT(C35:O35)=0,"",IFERROR(AO35/U35,0)) | AQ35: =IF(COUNT(C35:O35)=0,"",IFERROR(AL35/H35,0))
A36: =Config!$C$6+30 | B36: =INT((A36-Config!$C$6)/7)+1 | P36: =IF(COUNT(C36:O36)=0,"",IFERROR(C36/D36*1000,0)) | Q36: =IF(COUNT(C36:O36)=0,"",IFERROR(D36/E36,0)) | R36: =IF(COUNT(C36:O36)=0,"",IFERROR(F36/D36,0)) | S36: =IF(COUNT(C36:O36)=0,"",IFERROR(C36/F36,0)) | T36: =IF(COUNT(C36:O36)=0,"",IFERROR(G36/F36,0)) | U36: =IF(COUNT(C36:O36)=0,"",IFERROR(C36/G36,0)) | V36: =IF(COUNT(C36:O36)=0,"",IFERROR(G36/D36*1000,0)) | W36: =IF(COUNT(C36:O36)=0,"",IFERROR(H36/G36,0)) | X36: =IF(COUNT(C36:O36)=0,"",IFERROR(C36/H36,0)) | Y36: =IF(COUNT(C36:O36)=0,"",IFERROR(X36/P36,0)) | Z36: =IF(COUNT(C36:O36)=0,"",IFERROR(H36/D36*1000,0)) | AA36: =IF(COUNT(C36:O36)=0,"",IFERROR(I36/H36,0)) | AB36: =IF(COUNT(C36:O36)=0,"",IFERROR(J36/I36,0)) | AC36: =IF(COUNT(C36:O36)=0,"",IFERROR(K36/J36,0)) | AD36: =IF(COUNT(C36:O36)=0,"",IFERROR(C36/K36,0)) | AE36: =IF(COUNT(C36:O36)=0,"",IFERROR(L36/K36,0)) | AF36: =IF(COUNT(C36:O36)=0,"",IFERROR(M36/L36,0)) | AG36: =IF(COUNT(C36:O36)=0,"",IFERROR(M36/H36,0)) | AH36: =IF(COUNT(C36:O36)=0,"",IFERROR(C36/M36,0)) | AI36: =IF(COUNT(C36:O36)=0,"",IFERROR(M36*Config!$C$7+N36*Config!$C$8,0)) | AJ36: =IF(COUNT(C36:O36)=0,"",IFERROR(IF(O36>0,O36,AI36*Config!$C$9),0)) | AK36: =IF(COUNT(C36:O36)=0,"",IFERROR(AJ36*(1-Config!$C$10-Config!$C$11-Config!$C$12),0)) | AL36: =IF(COUNT(C36:O36)=0,"",IFERROR(AK36-C36-Config!$C$13,0)) | AM36: =IF(COUNT(C36:O36)=0,"",IFERROR(AK36/C36,0)) | AN36: =IF(COUNT(C36:O36)=0,"",IFERROR(AI36/C36,0)) | AO36: =IF(COUNT(C36:O36)=0,"",IFERROR(AL36/G36,0)) | AP36: =IF(COUNT(C36:O36)=0,"",IFERROR(AO36/U36,0)) | AQ36: =IF(COUNT(C36:O36)=0,"",IFERROR(AL36/H36,0))
A37: =Config!$C$6+31 | B37: =INT((A37-Config!$C$6)/7)+1 | P37: =IF(COUNT(C37:O37)=0,"",IFERROR(C37/D37*1000,0)) | Q37: =IF(COUNT(C37:O37)=0,"",IFERROR(D37/E37,0)) | R37: =IF(COUNT(C37:O37)=0,"",IFERROR(F37/D37,0)) | S37: =IF(COUNT(C37:O37)=0,"",IFERROR(C37/F37,0)) | T37: =IF(COUNT(C37:O37)=0,"",IFERROR(G37/F37,0)) | U37: =IF(COUNT(C37:O37)=0,"",IFERROR(C37/G37,0)) | V37: =IF(COUNT(C37:O37)=0,"",IFERROR(G37/D37*1000,0)) | W37: =IF(COUNT(C37:O37)=0,"",IFERROR(H37/G37,0)) | X37: =IF(COUNT(C37:O37)=0,"",IFERROR(C37/H37,0)) | Y37: =IF(COUNT(C37:O37)=0,"",IFERROR(X37/P37,0)) | Z37: =IF(COUNT(C37:O37)=0,"",IFERROR(H37/D37*1000,0)) | AA37: =IF(COUNT(C37:O37)=0,"",IFERROR(I37/H37,0)) | AB37: =IF(COUNT(C37:O37)=0,"",IFERROR(J37/I37,0)) | AC37: =IF(COUNT(C37:O37)=0,"",IFERROR(K37/J37,0)) | AD37: =IF(COUNT(C37:O37)=0,"",IFERROR(C37/K37,0)) | AE37: =IF(COUNT(C37:O37)=0,"",IFERROR(L37/K37,0)) | AF37: =IF(COUNT(C37:O37)=0,"",IFERROR(M37/L37,0)) | AG37: =IF(COUNT(C37:O37)=0,"",IFERROR(M37/H37,0)) | AH37: =IF(COUNT(C37:O37)=0,"",IFERROR(C37/M37,0)) | AI37: =IF(COUNT(C37:O37)=0,"",IFERROR(M37*Config!$C$7+N37*Config!$C$8,0)) | AJ37: =IF(COUNT(C37:O37)=0,"",IFERROR(IF(O37>0,O37,AI37*Config!$C$9),0)) | AK37: =IF(COUNT(C37:O37)=0,"",IFERROR(AJ37*(1-Config!$C$10-Config!$C$11-Config!$C$12),0)) | AL37: =IF(COUNT(C37:O37)=0,"",IFERROR(AK37-C37-Config!$C$13,0)) | AM37: =IF(COUNT(C37:O37)=0,"",IFERROR(AK37/C37,0)) | AN37: =IF(COUNT(C37:O37)=0,"",IFERROR(AI37/C37,0)) | AO37: =IF(COUNT(C37:O37)=0,"",IFERROR(AL37/G37,0)) | AP37: =IF(COUNT(C37:O37)=0,"",IFERROR(AO37/U37,0)) | AQ37: =IF(COUNT(C37:O37)=0,"",IFERROR(AL37/H37,0))
